Workbook
Name VAL_DATE: Curve_Interface!$O$5

Sheet HOW_TO_MOVE
A1: Moving the reformed CDS_Pricer in
A3: Move the CDS_Pricer_NEW tab only. Leave this sheet behind.
A5: 1. Open both workbooks and keep both open.
A6: 2. Right-click the CDS_Pricer_NEW tab > Move or Copy > To book: your CDS_Pricer workbook.
A7: 3. On the moved tab: Ctrl+H, Options, Look in Formulas, Within Sheet.
A8: Find what: [CDS_PricerSheet_v7.xlsx]
A9: Replace with: (leave empty)
A10: 4. Delete the old CDS_Pricer tab, then rename this one to exactly CDS_Pricer
A12: Modules needed: CDSStrip.bas and CDSRisk.bas. Save as .xlsm.
A13: Sheets it reads: CDS_Parameters, CDS_Schedule, Curve_Interface, Hazard_Bootstrap,
A14: CDS_Quotes, CDS_Entities, Steps. All are in your workbook already.
A16: Opened on its own the tab shows #REF - expected, those sheets are not in this file.

Sheet CDS_Pricer_NEW
A1: CDS_Pricer
A2: Prices a CDS off the SOFR discount curve and the stripped hazard curve. Equations on Model_Notes.
J3: PRICING EQUATIONS
A4: Notional | B4: =CDS_Parameters!$B$9 | J4: (3.1) Market Value = Protection Leg - Premium Leg
A5: Recovery R | B5: =CDS_Parameters!$B$8 | J5: both discounted to the pricing date T
A6: Contractual coupon (bp) | B6: =CDS_Parameters!$B$10 | C6: Overtype to price an off-market coupon. | J6: (3.2) Upfront = Market Value / D(T_s) + Accrued Interest
A7: Maturity (tenor yrs) | B7: =IF(Steps!$B$9="",5,Steps!$B$9) | J7: (3.3) Par spread S = Protection / (Premium - AI*D(T_s)) at C=1bp
A8: Maturity date | B8: =EDATE('Curve_Interface'!$F$7,3*(4*B7-1))
A9: Direction | B9: =CDS_Parameters!$B$15 | J9: O-T (1b) MTM = +/- [ S(t_V,t_N) - S(t_0,t_N) ] * RPV01
J10: equivalent form, + for long protection
A11: RESULTS
A12: RPV01 (risky annuity) | B12: =SUMIF(CDS_Schedule!$C$7:$C$46,"<="&B8,CDS_Schedule!$M$7:$M$46)+SUMIF(CDS_Schedule!$C$7:$C$46,"<="&B8,CDS_Schedule!$N$7:$N$46) | C12: Scheduled + accrual-on-default. | J12: Accrued Interest = A * C * D0, D0 = accrued days / 360
A13: Protection PV | B13: =B4*(1-B5)*SUMIF(CDS_Schedule!$C$7:$C$46,"<="&B8,CDS_Schedule!$O$7:$O$46) | J13: accrued days include the pricing date (p.7)
A14: Premium PV (@ coupon) | B14: =B4*(B6/10000)*B12 | J14: T_s = T + 3 business days (p.6)
A15: Par spread (bp) (3.3) | B15: =(1-B5)*SUMIF(CDS_Schedule!$C$7:$C$46,"<="&B8,CDS_Schedule!$O$7:$O$46)/(B12-CDS_Parameters!$B$26)*10000 | C15: Protection / (RPV01 net of accrued interest x D(T_s)).
A16: PV: protection buyer | B16: =B13-B14 | C16: Protection − Premium. | J16: Upfront is identically 0 when C = S. That is the check that accrued
A17: PV to your direction | B17: =IF(B9="Buy protection",B13-B14,B14-B13) | J17: interest enters with a + sign, which the wording alone does not settle.
A18: Upfront (% notional) | B18: =B17/B4*100
A19: PV01 (premium leg net of AI, per 1bp) | B19: =B4*(B12-CDS_Parameters!$B$26)*0.0001
A20: Market Value (3.1) | B20: =B13-B14 | C20: Protection leg minus premium leg, both to the pricing date.
A21: RISK MEASURES (full revalue, curve re-stripped on each bump) | N21: full-revalue working
A22: CS01 / Spread DV01 (+1bp) | B22: =IF(OR($O$22="",$O$23=""),"",$O$23-$O$22) | C22: Spread DV01: revalue at +1bp on every quote, curve re-stripped (p.9). | N22: MV base | O22: =IFERROR(CDS_MarketValue(0,0,0,Hazard_Bootstrap!$B$7:$B$12,Hazard_Bootstrap!$C$7:$C$12,CDS_Parameters!$B$8,CDS_Parameters!$B$26,CDS_Schedule!$C$7:$C$46,CDS_Schedule!$D$7:$D$46,CDS_Schedule!$E$7:$E$46,CDS_Schedule!$F$7:$F$46,CDS_Schedule!$G$7:$G$46,CDS_Schedule!$H$7:$H$46,$B$4,$B$6,$B$8),"")
A23: IR DV01 (+1bp rates) | B23: =IF(OR($O$22="",$O$24=""),"",$O$24-$O$22) | C23: IR DV01: parallel +1bp on the discount curve, curve re-stripped. | N23: MV spreads +1bp | O23: =IFERROR(CDS_MarketValue(1,0,0,Hazard_Bootstrap!$B$7:$B$12,Hazard_Bootstrap!$C$7:$C$12,CDS_Parameters!$B$8,CDS_Parameters!$B$26,CDS_Schedule!$C$7:$C$46,CDS_Schedule!$D$7:$D$46,CDS_Schedule!$E$7:$E$46,CDS_Schedule!$F$7:$F$46,CDS_Schedule!$G$7:$G$46,CDS_Schedule!$H$7:$H$46,$B$4,$B$6,$B$8),"")
A24: Rec01 (+1% recovery) | B24: =IF(OR($O$22="",$O$25=""),"",$O$25-$O$22) | C24: Rec01: recovery +1%, hazards re-fitted so the quotes still reprice. | N24: MV rates +1bp | O24: =IFERROR(CDS_MarketValue(0,1,0,Hazard_Bootstrap!$B$7:$B$12,Hazard_Bootstrap!$C$7:$C$12,CDS_Parameters!$B$8,CDS_Parameters!$B$26,CDS_Schedule!$C$7:$C$46,CDS_Schedule!$D$7:$D$46,CDS_Schedule!$E$7:$E$46,CDS_Schedule!$F$7:$F$46,CDS_Schedule!$G$7:$G$46,CDS_Schedule!$H$7:$H$46,$B$4,$B$6,$B$8),"")
A25: Jump-to-default (immediate) | B25: =IF(B9="Buy protection",B4*(1-B5),-B4*(1-B5))-B17 | C25: Default-now P&L to your direction: LGD payout - current PV. | N25: MV recovery +1% | O25: =IFERROR(CDS_MarketValue(0,0,0.01,Hazard_Bootstrap!$B$7:$B$12,Hazard_Bootstrap!$C$7:$C$12,CDS_Parameters!$B$8,CDS_Parameters!$B$26,CDS_Schedule!$C$7:$C$46,CDS_Schedule!$D$7:$D$46,CDS_Schedule!$E$7:$E$46,CDS_Schedule!$F$7:$F$46,CDS_Schedule!$G$7:$G$46,CDS_Schedule!$H$7:$H$46,$B$4,$B$6,$B$8),"")
A26: Accrued Interest A*C*D0 | B26: =B4*(B6/10000)*CDS_Parameters!$B$25 | N26: Each measure is a difference of two full valuations. Holding hazards fixed and multiplying RPV01 by a bump answers a different question - that is what made Rec01 come out with the wrong sign.
A27: Upfront (3.2) | B27: =B20/CDS_Parameters!$B$22+B26 | C27: Market Value / D(T_s) + Accrued Interest. Identically zero when C = S.
A28: CDSW SCREEN OUTPUT
A29: Settlement figures in CDSW order. S = par spread from the curve (B15), C = contractual coupon (B6).
A30: 1st accrual start | B30: =IF(MONTH((EDATE(CDS_Parameters!$B$5,-3)+IF(WEEKDAY(EDATE(CDS_Parameters!$B$5,-3),2)=6,2,IF(WEEKDAY(EDATE(CDS_Parameters!$B$5,-3),2)=7,1,0))))<>MONTH(EDATE(CDS_Parameters!$B$5,-3)),(EDATE(CDS_Parameters!$B$5,-3)-IF(WEEKDAY(EDATE(CDS_Parameters!$B$5,-3),2)=6,1,IF(WEEKDAY(EDATE(CDS_Parameters!$B$5,-3),2)=7,2,0))),(EDATE(CDS_Parameters!$B$5,-3)+IF(WEEKDAY(EDATE(CDS_Parameters!$B$5,-3),2)=6,2,IF(WEEKDAY(EDATE(CDS_Parameters!$B$5,-3),2)=7,1,0)))) | C30: Previous IMM roll, business-day adjusted. 20 Jun 2026 is a Saturday, so the screen shows 06/22/26.
A31: Points upfront | B31: =(($B$15/10000)-CDS_Parameters!$B$10/10000)*$B$12*100 | C31: (S - C) * RPV01 * 100, protection buyer.
A32: Price | B32: =100-B31 | C32: 100 - points upfront.
A33: Principal | B33: =IF(CDS_Parameters!$B$15="Buy protection",1,-1)*(($B$15/10000)-CDS_Parameters!$B$10/10000)*$B$12*CDS_Parameters!$B$9 | C33: Clean upfront in cash.
A34: Accrued days | B34: =MAX(0,CDS_Parameters!$B$4-B30+1) | C34: ISDA counts both endpoints.
A35: Accrued | B35: =-IF(CDS_Parameters!$B$15="Buy protection",1,-1)*CDS_Parameters!$B$10/10000*CDS_Parameters!$B$9*B34/360 | C35: Coupon * notional * days/360.
A36: Cash Amount | B36: =B33+B35 | C36: Principal + accrued.
A37: Default Exposure | B37: =(1-CDS_Parameters!$B$8)*CDS_Parameters!$B$9-B33 | C37: (1-R) * notional less the principal already paid.
A38: Upfront (3.2) above is the paper's total. How it splits into CDSW's Principal / Accrued / Cash is INFERRED, not confirmed by the paper. A capture with non-zero accrued would settle it.
A41: MODEL vs CAPTURED CDSW (active entity)
A42: Blank until a CDSW capture is typed into CDS_Entities O:AC for the live name. A zero there reads as no capture, not as a captured zero.
...
