Workbook
Name VAL_DATE: Curve_Interface!$O$5

Sheet Entities
A1: Entities
A2: Type a name and its Bloomberg ticker on any free row. On = 0 removes a name. Overrides beat the BDP pull; blank uses the pull.
A4: Live name | B4: DEMO curve (not market) | C4: only this name is stripped and priced | E4: ticker in use | F4: =IFERROR(IF(ISTEXT(INDEX($C$7:$C$16,MATCH($B$4,$B$7:$B$16,0))),INDEX($C$7:$C$16,MATCH($B$4,$B$7:$B$16,0)),""),"")
A6: On | B6: Entity name | C6: Bloomberg ticker | D6: Ccy | E6: Recovery | F6: 1Y | G6: 2Y | H6: 3Y | I6: 5Y | J6: 7Y | K6: 10Y
A7: 1 | B7: China CITIC Bank Intl | D7: USD
A8: 1 | B8: DEMO curve (not market) | D8: USD
A19: Effective (what the strip uses) | F19: override > BDP pull > manual > 0. This block is what the strip uses.
B20: Entity | E20: Recovery | F20: 1Y | G20: 2Y | H20: 3Y | I20: 5Y | J20: 7Y | K20: 10Y
B21: =IF($B7="","",$B7) | E21: =IF($B7="","",IF($A7=0,"off",IF(ISNUMBER($E7),$E7,CDS_Entities!$F$5))) | F21: =IF($B7="","",IF($A7=0,0,IF(ISNUMBER($F7),$F7,IF(ISNUMBER(CDS_Entities!$AG$5),CDS_Entities!$AG$5,IF(ISNUMBER(CDS_Entities!$H$5),CDS_Entities!$H$5,0))))) | G21: =IF($B7="","",IF($A7=0,0,IF(ISNUMBER($G7),$G7,IF(ISNUMBER(CDS_Entities!$AI$5),CDS_Entities!$AI$5,IF(ISNUMBER(CDS_Entities!$I$5),CDS_Entities!$I$5,0))))) | H21: =IF($B7="","",IF($A7=0,0,IF(ISNUMBER($H7),$H7,IF(ISNUMBER(CDS_Entities!$AK$5),CDS_Entities!$AK$5,IF(ISNUMBER(CDS_Entities!$J$5),CDS_Entities!$J$5,0))))) | I21: =IF($B7="","",IF($A7=0,0,IF(ISNUMBER($I7),$I7,IF(ISNUMBER(CDS_Entities!$AM$5),CDS_Entities!$AM$5,IF(ISNUMBER(CDS_Entities!$K$5),CDS_Entities!$K$5,0))))) | J21: =IF($B7="","",IF($A7=0,0,IF(ISNUMBER($J7),$J7,IF(ISNUMBER(CDS_Entities!$AO$5),CDS_Entities!$AO$5,IF(ISNUMBER(CDS_Entities!$L$5),CDS_Entities!$L$5,0))))) | K21: =IF($B7="","",IF($A7=0,0,IF(ISNUMBER($K7),$K7,IF(ISNUMBER(CDS_Entities!$AQ$5),CDS_Entities!$AQ$5,IF(ISNUMBER(CDS_Entities!$M$5),CDS_Entities!$M$5,0)))))
B22: =IF($B8="","",$B8) | E22: =IF($B8="","",IF($A8=0,"off",IF(ISNUMBER($E8),$E8,CDS_Entities!$F$6))) | F22: =IF($B8="","",IF($A8=0,0,IF(ISNUMBER($F8),$F8,IF(ISNUMBER(CDS_Entities!$AG$6),CDS_Entities!$AG$6,IF(ISNUMBER(CDS_Entities!$H$6),CDS_Entities!$H$6,0))))) | G22: =IF($B8="","",IF($A8=0,0,IF(ISNUMBER($G8),$G8,IF(ISNUMBER(CDS_Entities!$AI$6),CDS_Entities!$AI$6,IF(ISNUMBER(CDS_Entities!$I$6),CDS_Entities!$I$6,0))))) | H22: =IF($B8="","",IF($A8=0,0,IF(ISNUMBER($H8),$H8,IF(ISNUMBER(CDS_Entities!$AK$6),CDS_Entities!$AK$6,IF(ISNUMBER(CDS_Entities!$J$6),CDS_Entities!$J$6,0))))) | I22: =IF($B8="","",IF($A8=0,0,IF(ISNUMBER($I8),$I8,IF(ISNUMBER(CDS_Entities!$AM$6),CDS_Entities!$AM$6,IF(ISNUMBER(CDS_Entities!$K$6),CDS_Entities!$K$6,0))))) | J22: =IF($B8="","",IF($A8=0,0,IF(ISNUMBER($J8),$J8,IF(ISNUMBER(CDS_Entities!$AO$6),CDS_Entities!$AO$6,IF(ISNUMBER(CDS_Entities!$L$6),CDS_Entities!$L$6,0))))) | K22: =IF($B8="","",IF($A8=0,0,IF(ISNUMBER($K8),$K8,IF(ISNUMBER(CDS_Entities!$AQ$6),CDS_Entities!$AQ$6,IF(ISNUMBER(CDS_Entities!$M$6),CDS_Entities!$M$6,0)))))
B23: =IF($B9="","",$B9) | E23: =IF($B9="","",IF($A9=0,"off",IF(ISNUMBER($E9),$E9,CDS_Entities!$F$7))) | F23: =IF($B9="","",IF($A9=0,0,IF(ISNUMBER($F9),$F9,IF(ISNUMBER(CDS_Entities!$AG$7),CDS_Entities!$AG$7,IF(ISNUMBER(CDS_Entities!$H$7),CDS_Entities!$H$7,0))))) | G23: =IF($B9="","",IF($A9=0,0,IF(ISNUMBER($G9),$G9,IF(ISNUMBER(CDS_Entities!$AI$7),CDS_Entities!$AI$7,IF(ISNUMBER(CDS_Entities!$I$7),CDS_Entities!$I$7,0))))) | H23: =IF($B9="","",IF($A9=0,0,IF(ISNUMBER($H9),$H9,IF(ISNUMBER(CDS_Entities!$AK$7),CDS_Entities!$AK$7,IF(ISNUMBER(CDS_Entities!$J$7),CDS_Entities!$J$7,0))))) | I23: =IF($B9="","",IF($A9=0,0,IF(ISNUMBER($I9),$I9,IF(ISNUMBER(CDS_Entities!$AM$7),CDS_Entities!$AM$7,IF(ISNUMBER(CDS_Entities!$K$7),CDS_Entities!$K$7,0))))) | J23: =IF($B9="","",IF($A9=0,0,IF(ISNUMBER($J9),$J9,IF(ISNUMBER(CDS_Entities!$AO$7),CDS_Entities!$AO$7,IF(ISNUMBER(CDS_Entities!$L$7),CDS_Entities!$L$7,0))))) | K23: =IF($B9="","",IF($A9=0,0,IF(ISNUMBER($K9),$K9,IF(ISNUMBER(CDS_Entities!$AQ$7),CDS_Entities!$AQ$7,IF(ISNUMBER(CDS_Entities!$M$7),CDS_Entities!$M$7,0)))))
B24: =IF($B10="","",$B10) | E24: =IF($B10="","",IF($A10=0,"off",IF(ISNUMBER($E10),$E10,CDS_Entities!$F$8))) | F24: =IF($B10="","",IF($A10=0,0,IF(ISNUMBER($F10),$F10,IF(ISNUMBER(CDS_Entities!$AG$8),CDS_Entities!$AG$8,IF(ISNUMBER(CDS_Entities!$H$8),CDS_Entities!$H$8,0))))) | G24: =IF($B10="","",IF($A10=0,0,IF(ISNUMBER($G10),$G10,IF(ISNUMBER(CDS_Entities!$AI$8),CDS_Entities!$AI$8,IF(ISNUMBER(CDS_Entities!$I$8),CDS_Entities!$I$8,0))))) | H24: =IF($B10="","",IF($A10=0,0,IF(ISNUMBER($H10),$H10,IF(ISNUMBER(CDS_Entities!$AK$8),CDS_Entities!$AK$8,IF(ISNUMBER(CDS_Entities!$J$8),CDS_Entities!$J$8,0))))) | I24: =IF($B10="","",IF($A10=0,0,IF(ISNUMBER($I10),$I10,IF(ISNUMBER(CDS_Entities!$AM$8),CDS_Entities!$AM$8,IF(ISNUMBER(CDS_Entities!$K$8),CDS_Entities!$K$8,0))))) | J24: =IF($B10="","",IF($A10=0,0,IF(ISNUMBER($J10),$J10,IF(ISNUMBER(CDS_Entities!$AO$8),CDS_Entities!$AO$8,IF(ISNUMBER(CDS_Entities!$L$8),CDS_Entities!$L$8,0))))) | K24: =IF($B10="","",IF($A10=0,0,IF(ISNUMBER($K10),$K10,IF(ISNUMBER(CDS_Entities!$AQ$8),CDS_Entities!$AQ$8,IF(ISNUMBER(CDS_Entities!$M$8),CDS_Entities!$M$8,0)))))
B25: =IF($B11="","",$B11) | E25: =IF($B11="","",IF($A11=0,"off",IF(ISNUMBER($E11),$E11,CDS_Entities!$F$9))) | F25: =IF($B11="","",IF($A11=0,0,IF(ISNUMBER($F11),$F11,IF(ISNUMBER(CDS_Entities!$AG$9),CDS_Entities!$AG$9,IF(ISNUMBER(CDS_Entities!$H$9),CDS_Entities!$H$9,0))))) | G25: =IF($B11="","",IF($A11=0,0,IF(ISNUMBER($G11),$G11,IF(ISNUMBER(CDS_Entities!$AI$9),CDS_Entities!$AI$9,IF(ISNUMBER(CDS_Entities!$I$9),CDS_Entities!$I$9,0))))) | H25: =IF($B11="","",IF($A11=0,0,IF(ISNUMBER($H11),$H11,IF(ISNUMBER(CDS_Entities!$AK$9),CDS_Entities!$AK$9,IF(ISNUMBER(CDS_Entities!$J$9),CDS_Entities!$J$9,0))))) | I25: =IF($B11="","",IF($A11=0,0,IF(ISNUMBER($I11),$I11,IF(ISNUMBER(CDS_Entities!$AM$9),CDS_Entities!$AM$9,IF(ISNUMBER(CDS_Entities!$K$9),CDS_Entities!$K$9,0))))) | J25: =IF($B11="","",IF($A11=0,0,IF(ISNUMBER($J11),$J11,IF(ISNUMBER(CDS_Entities!$AO$9),CDS_Entities!$AO$9,IF(ISNUMBER(CDS_Entities!$L$9),CDS_Entities!$L$9,0))))) | K25: =IF($B11="","",IF($A11=0,0,IF(ISNUMBER($K11),$K11,IF(ISNUMBER(CDS_Entities!$AQ$9),CDS_Entities!$AQ$9,IF(ISNUMBER(CDS_Entities!$M$9),CDS_Entities!$M$9,0)))))
B26: =IF($B12="","",$B12) | E26: =IF($B12="","",IF($A12=0,"off",IF(ISNUMBER($E12),$E12,CDS_Entities!$F$10))) | F26: =IF($B12="","",IF($A12=0,0,IF(ISNUMBER($F12),$F12,IF(ISNUMBER(CDS_Entities!$AG$10),CDS_Entities!$AG$10,IF(ISNUMBER(CDS_Entities!$H$10),CDS_Entities!$H$10,0))))) | G26: =IF($B12="","",IF($A12=0,0,IF(ISNUMBER($G12),$G12,IF(ISNUMBER(CDS_Entities!$AI$10),CDS_Entities!$AI$10,IF(ISNUMBER(CDS_Entities!$I$10),CDS_Entities!$I$10,0))))) | H26: =IF($B12="","",IF($A12=0,0,IF(ISNUMBER($H12),$H12,IF(ISNUMBER(CDS_Entities!$AK$10),CDS_Entities!$AK$10,IF(ISNUMBER(CDS_Entities!$J$10),CDS_Entities!$J$10,0))))) | I26: =IF($B12="","",IF($A12=0,0,IF(ISNUMBER($I12),$I12,IF(ISNUMBER(CDS_Entities!$AM$10),CDS_Entities!$AM$10,IF(ISNUMBER(CDS_Entities!$K$10),CDS_Entities!$K$10,0))))) | J26: =IF($B12="","",IF($A12=0,0,IF(ISNUMBER($J12),$J12,IF(ISNUMBER(CDS_Entities!$AO$10),CDS_Entities!$AO$10,IF(ISNUMBER(CDS_Entities!$L$10),CDS_Entities!$L$10,0))))) | K26: =IF($B12="","",IF($A12=0,0,IF(ISNUMBER($K12),$K12,IF(ISNUMBER(CDS_Entities!$AQ$10),CDS_Entities!$AQ$10,IF(ISNUMBER(CDS_Entities!$M$10),CDS_Entities!$M$10,0)))))
B27: =IF($B13="","",$B13) | E27: =IF($B13="","",IF($A13=0,"off",IF(ISNUMBER($E13),$E13,CDS_Entities!$F$11))) | F27: =IF($B13="","",IF($A13=0,0,IF(ISNUMBER($F13),$F13,IF(ISNUMBER(CDS_Entities!$AG$11),CDS_Entities!$AG$11,IF(ISNUMBER(CDS_Entities!$H$11),CDS_Entities!$H$11,0))))) | G27: =IF($B13="","",IF($A13=0,0,IF(ISNUMBER($G13),$G13,IF(ISNUMBER(CDS_Entities!$AI$11),CDS_Entities!$AI$11,IF(ISNUMBER(CDS_Entities!$I$11),CDS_Entities!$I$11,0))))) | H27: =IF($B13="","",IF($A13=0,0,IF(ISNUMBER($H13),$H13,IF(ISNUMBER(CDS_Entities!$AK$11),CDS_Entities!$AK$11,IF(ISNUMBER(CDS_Entities!$J$11),CDS_Entities!$J$11,0))))) | I27: =IF($B13="","",IF($A13=0,0,IF(ISNUMBER($I13),$I13,IF(ISNUMBER(CDS_Entities!$AM$11),CDS_Entities!$AM$11,IF(ISNUMBER(CDS_Entities!$K$11),CDS_Entities!$K$11,0))))) | J27: =IF($B13="","",IF($A13=0,0,IF(ISNUMBER($J13),$J13,IF(ISNUMBER(CDS_Entities!$AO$11),CDS_Entities!$AO$11,IF(ISNUMBER(CDS_Entities!$L$11),CDS_Entities!$L$11,0))))) | K27: =IF($B13="","",IF($A13=0,0,IF(ISNUMBER($K13),$K13,IF(ISNUMBER(CDS_Entities!$AQ$11),CDS_Entities!$AQ$11,IF(ISNUMBER(CDS_Entities!$M$11),CDS_Entities!$M$11,0)))))
B28: =IF($B14="","",$B14) | E28: =IF($B14="","",IF($A14=0,"off",IF(ISNUMBER($E14),$E14,CDS_Entities!$F$12))) | F28: =IF($B14="","",IF($A14=0,0,IF(ISNUMBER($F14),$F14,IF(ISNUMBER(CDS_Entities!$AG$12),CDS_Entities!$AG$12,IF(ISNUMBER(CDS_Entities!$H$12),CDS_Entities!$H$12,0))))) | G28: =IF($B14="","",IF($A14=0,0,IF(ISNUMBER($G14),$G14,IF(ISNUMBER(CDS_Entities!$AI$12),CDS_Entities!$AI$12,IF(ISNUMBER(CDS_Entities!$I$12),CDS_Entities!$I$12,0))))) | H28: =IF($B14="","",IF($A14=0,0,IF(ISNUMBER($H14),$H14,IF(ISNUMBER(CDS_Entities!$AK$12),CDS_Entities!$AK$12,IF(ISNUMBER(CDS_Entities!$J$12),CDS_Entities!$J$12,0))))) | I28: =IF($B14="","",IF($A14=0,0,IF(ISNUMBER($I14),$I14,IF(ISNUMBER(CDS_Entities!$AM$12),CDS_Entities!$AM$12,IF(ISNUMBER(CDS_Entities!$K$12),CDS_Entities!$K$12,0))))) | J28: =IF($B14="","",IF($A14=0,0,IF(ISNUMBER($J14),$J14,IF(ISNUMBER(CDS_Entities!$AO$12),CDS_Entities!$AO$12,IF(ISNUMBER(CDS_Entities!$L$12),CDS_Entities!$L$12,0))))) | K28: =IF($B14="","",IF($A14=0,0,IF(ISNUMBER($K14),$K14,IF(ISNUMBER(CDS_Entities!$AQ$12),CDS_Entities!$AQ$12,IF(ISNUMBER(CDS_Entities!$M$12),CDS_Entities!$M$12,0)))))
B29: =IF($B15="","",$B15) | E29: =IF($B15="","",IF($A15=0,"off",IF(ISNUMBER($E15),$E15,CDS_Entities!$F$13))) | F29: =IF($B15="","",IF($A15=0,0,IF(ISNUMBER($F15),$F15,IF(ISNUMBER(CDS_Entities!$AG$13),CDS_Entities!$AG$13,IF(ISNUMBER(CDS_Entities!$H$13),CDS_Entities!$H$13,0))))) | G29: =IF($B15="","",IF($A15=0,0,IF(ISNUMBER($G15),$G15,IF(ISNUMBER(CDS_Entities!$AI$13),CDS_Entities!$AI$13,IF(ISNUMBER(CDS_Entities!$I$13),CDS_Entities!$I$13,0))))) | H29: =IF($B15="","",IF($A15=0,0,IF(ISNUMBER($H15),$H15,IF(ISNUMBER(CDS_Entities!$AK$13),CDS_Entities!$AK$13,IF(ISNUMBER(CDS_Entities!$J$13),CDS_Entities!$J$13,0))))) | I29: =IF($B15="","",IF($A15=0,0,IF(ISNUMBER($I15),$I15,IF(ISNUMBER(CDS_Entities!$AM$13),CDS_Entities!$AM$13,IF(ISNUMBER(CDS_Entities!$K$13),CDS_Entities!$K$13,0))))) | J29: =IF($B15="","",IF($A15=0,0,IF(ISNUMBER($J15),$J15,IF(ISNUMBER(CDS_Entities!$AO$13),CDS_Entities!$AO$13,IF(ISNUMBER(CDS_Entities!$L$13),CDS_Entities!$L$13,0))))) | K29: =IF($B15="","",IF($A15=0,0,IF(ISNUMBER($K15),$K15,IF(ISNUMBER(CDS_Entities!$AQ$13),CDS_Entities!$AQ$13,IF(ISNUMBER(CDS_Entities!$M$13),CDS_Entities!$M$13,0)))))
B30: =IF($B16="","",$B16) | E30: =IF($B16="","",IF($A16=0,"off",IF(ISNUMBER($E16),$E16,CDS_Entities!$F$14))) | F30: =IF($B16="","",IF($A16=0,0,IF(ISNUMBER($F16),$F16,IF(ISNUMBER(CDS_Entities!$AG$14),CDS_Entities!$AG$14,IF(ISNUMBER(CDS_Entities!$H$14),CDS_Entities!$H$14,0))))) | G30: =IF($B16="","",IF($A16=0,0,IF(ISNUMBER($G16),$G16,IF(ISNUMBER(CDS_Entities!$AI$14),CDS_Entities!$AI$14,IF(ISNUMBER(CDS_Entities!$I$14),CDS_Entities!$I$14,0))))) | H30: =IF($B16="","",IF($A16=0,0,IF(ISNUMBER($H16),$H16,IF(ISNUMBER(CDS_Entities!$AK$14),CDS_Entities!$AK$14,IF(ISNUMBER(CDS_Entities!$J$14),CDS_Entities!$J$14,0))))) | I30: =IF($B16="","",IF($A16=0,0,IF(ISNUMBER($I16),$I16,IF(ISNUMBER(CDS_Entities!$AM$14),CDS_Entities!$AM$14,IF(ISNUMBER(CDS_Entities!$K$14),CDS_Entities!$K$14,0))))) | J30: =IF($B16="","",IF($A16=0,0,IF(ISNUMBER($J16),$J16,IF(ISNUMBER(CDS_Entities!$AO$14),CDS_Entities!$AO$14,IF(ISNUMBER(CDS_Entities!$L$14),CDS_Entities!$L$14,0))))) | K30: =IF($B16="","",IF($A16=0,0,IF(ISNUMBER($K16),$K16,IF(ISNUMBER(CDS_Entities!$AQ$14),CDS_Entities!$AQ$14,IF(ISNUMBER(CDS_Entities!$M$14),CDS_Entities!$M$14,0)))))

Sheet Curves
A1: Curves
A2: Discount curve is the pasted snapshot. Hazard and survival come from the strip.
A4: SOFR discount curve
A5: Date | B5: T | C5: DF | D5: Zero %
A6: ='Curve_Interface'!K9 | B6: =('Curve_Interface'!K9-VAL_DATE)/365 | C6: ='Curve_Interface'!L9 | D6: =IF(B6<=0,"",-LN(C6)/B6*100)
A7: ='Curve_Interface'!K10 | B7: =('Curve_Interface'!K10-VAL_DATE)/365 | C7: ='Curve_Interface'!L10 | D7: =IF(B7<=0,"",-LN(C7)/B7*100)
A8: ='Curve_Interface'!K11 | B8: =('Curve_Interface'!K11-VAL_DATE)/365 | C8: ='Curve_Interface'!L11 | D8: =IF(B8<=0,"",-LN(C8)/B8*100)
A9: ='Curve_Interface'!K12 | B9: =('Curve_Interface'!K12-VAL_DATE)/365 | C9: ='Curve_Interface'!L12 | D9: =IF(B9<=0,"",-LN(C9)/B9*100)
A10: ='Curve_Interface'!K13 | B10: =('Curve_Interface'!K13-VAL_DATE)/365 | C10: ='Curve_Interface'!L13 | D10: =IF(B10<=0,"",-LN(C10)/B10*100)
A11: ='Curve_Interface'!K14 | B11: =('Curve_Interface'!K14-VAL_DATE)/365 | C11: ='Curve_Interface'!L14 | D11: =IF(B11<=0,"",-LN(C11)/B11*100)
A12: ='Curve_Interface'!K15 | B12: =('Curve_Interface'!K15-VAL_DATE)/365 | C12: ='Curve_Interface'!L15 | D12: =IF(B12<=0,"",-LN(C12)/B12*100)
A13: ='Curve_Interface'!K16 | B13: =('Curve_Interface'!K16-VAL_DATE)/365 | C13: ='Curve_Interface'!L16 | D13: =IF(B13<=0,"",-LN(C13)/B13*100)
A14: ='Curve_Interface'!K17 | B14: =('Curve_Interface'!K17-VAL_DATE)/365 | C14: ='Curve_Interface'!L17 | D14: =IF(B14<=0,"",-LN(C14)/B14*100)
A15: ='Curve_Interface'!K18 | B15: =('Curve_Interface'!K18-VAL_DATE)/365 | C15: ='Curve_Interface'!L18 | D15: =IF(B15<=0,"",-LN(C15)/B15*100)
A16: ='Curve_Interface'!K19 | B16: =('Curve_Interface'!K19-VAL_DATE)/365 | C16: ='Curve_Interface'!L19 | D16: =IF(B16<=0,"",-LN(C16)/B16*100)
A17: ='Curve_Interface'!K20 | B17: =('Curve_Interface'!K20-VAL_DATE)/365 | C17: ='Curve_Interface'!L20 | D17: =IF(B17<=0,"",-LN(C17)/B17*100)
... A70: ='Curve_Interface'!K73 | B70: =('Curve_Interface'!K73-VAL_DATE)/365 | C70: ='Curve_Interface'!L73 | D70: =IF(B70<=0,"",-LN(C70)/B70*100)
A73: Hazard and survival
A74: Tenor | B74: Hazard % | C74: Survival Q | D74: Default prob 1-Q
A75: =Hazard_Bootstrap!A7 | B75: =Hazard_Bootstrap!D7*100 | C75: =Hazard_Bootstrap!E7 | D75: =Hazard_Bootstrap!F7
A76: =Hazard_Bootstrap!A8 | B76: =Hazard_Bootstrap!D8*100 | C76: =Hazard_Bootstrap!E8 | D76: =Hazard_Bootstrap!F8
A77: =Hazard_Bootstrap!A9 | B77: =Hazard_Bootstrap!D9*100 | C77: =Hazard_Bootstrap!E9 | D77: =Hazard_Bootstrap!F9
A78: =Hazard_Bootstrap!A10 | B78: =Hazard_Bootstrap!D10*100 | C78: =Hazard_Bootstrap!E10 | D78: =Hazard_Bootstrap!F10
A79: =Hazard_Bootstrap!A11 | B79: =Hazard_Bootstrap!D11*100 | C79: =Hazard_Bootstrap!E11 | D79: =Hazard_Bootstrap!F11
A80: =Hazard_Bootstrap!A12 | B80: =Hazard_Bootstrap!D12*100 | C80: =Hazard_Bootstrap!E12 | D80: =Hazard_Bootstrap!F12
A83: Spread term structure
A84: Tenor | B84: Market bp | C84: Model bp | D84: Diff bp | E84: Traded spread
A85: =Hazard_Bootstrap!A7 | B85: =Hazard_Bootstrap!C7 | C85: =Hazard_Bootstrap!I7 | D85: =Hazard_Bootstrap!J7 | E85: =CDS_Pricer!$B$15
A86: =Hazard_Bootstrap!A8 | B86: =Hazard_Bootstrap!C8 | C86: =Hazard_Bootstrap!I8 | D86: =Hazard_Bootstrap!J8 | E86: =CDS_Pricer!$B$15
A87: =Hazard_Bootstrap!A9 | B87: =Hazard_Bootstrap!C9 | C87: =Hazard_Bootstrap!I9 | D87: =Hazard_Bootstrap!J9 | E87: =CDS_Pricer!$B$15
A88: =Hazard_Bootstrap!A10 | B88: =Hazard_Bootstrap!C10 | C88: =Hazard_Bootstrap!I10 | D88: =Hazard_Bootstrap!J10 | E88: =CDS_Pricer!$B$15
A89: =Hazard_Bootstrap!A11 | B89: =Hazard_Bootstrap!C11 | C89: =Hazard_Bootstrap!I11 | D89: =Hazard_Bootstrap!J11 | E89: =CDS_Pricer!$B$15
A90: =Hazard_Bootstrap!A12 | B90: =Hazard_Bootstrap!C12 | C90: =Hazard_Bootstrap!I12 | D90: =Hazard_Bootstrap!J12 | E90: =CDS_Pricer!$B$15

Sheet Model_Notes
A1: Model notes: Bloomberg B-Model (CDSW)
A2: Equation numbers and page cites are the white paper's own. Scans in bloomberg/reference/cds_white_paper/.
A4: Pricing
A5: (3.1) | B5: Market Value = Protection Leg - Premium Leg, both discounted to pricing date T
A6: (3.2) | B6: Upfront = Market Value / D(T_s) + Accrued Interest
A7: (3.3) | B7: S = Protection Leg / (Premium Leg - Accrued Interest * D(T_s)) at C = 1bp
A8: (3.4) | B8: Coupons-in-Survival = A * C * SUM delta(T_i-1, T_i) p_s(T_i) D(T_i)
A9: (3.5) | B9: Accrued-on-Default = A * C * INT_T^TM delta(T_n(t), t) (-dp_s/dt) D(t) dt
A10: (3.6) | B10: Protection Leg = A (1-R) * INT_T^TM (-dp_s/dt) D(t) dt
A12: Conventions that the sheets depend on
A13: p.6 | B13: Accrual dates are IMM (3/20, 6/20, 9/20, 12/20). Payment dates roll to the next business day; the last accrual end date T_M does not roll.
A14: p.6 | B14: Coupon standardised to 100bp / 500bp for most names. ACT/360.
A15: p.6 | B15: Protection starts immediately, so the protection period is T_M - T + 1 days.
A16: p.7 | B16: Accrued interest includes the pricing date.
A17: p.7 | B17: T_s = settlement, typically 3 business days after pricing. The upfront is quoted there, so market value is compounded T to T_s.
A18: p.6 | B18: USD discounting is the SOFR RFR curve: ISDA moved to RFR curves and the B-Model follows.
A19: p.6 | B19: Recovery R is a model parameter, conventionally 40%, not an observable.
A21: Curve stripper (section 4, p.8)
A22: Sequential one-dimensional root-finding, not a joint fit. h_1 is solved on [0, T_M1] to match the first quote;
A23: each later h_i+1 is solved on (T_Mi, T_Mi+1] with all earlier hazards held fixed.
A24: Hazard is piecewise constant. h(t) >= 0 is a hard constraint - default is terminating, so survival cannot rise.
A25: The timeline is discretised finely enough that the forward discount rate and hazard are constant on a segment,
A26: and no segment is longer than a premium accrual period; (3.5) and (3.6) are then analytic on each segment.
A28: Strippability (p.9)
A29: With h_i+1 running 0 to infinity the achievable par spread at the next maturity is a bounded interval, and it
A30: narrows sharply once survival is already low. A quote outside that interval makes the calibration fail.
A31: The paper's reading: usually inconsistent data sources rather than genuine arbitrage. Common with inverted
A32: curves (S_i+1 < S_i, though mildly inverted curves are often still strippable) and distressed non-flat curves.
A33: Approximate lower bound, valid while cumulative default probability is low: S_i+1 >= S_i * T_i / T_i+1
A35: Strippability check on the live quotes
A36: Tenor | B36: T | C36: S (bp) | D36: bound S*T_prev/T | E36: ok?
A37: =Hazard_Bootstrap!A7 | B37: =CDS_Quotes!B7 | C37: =Hazard_Bootstrap!C7 | D37: - | E37: first pillar, unconstrained
A38: =Hazard_Bootstrap!A8 | B38: =CDS_Quotes!B8 | C38: =Hazard_Bootstrap!C8 | D38: =C37*B37/B38 | E38: =IF(C38>=D38,"ok","below bound — may not strip")
A39: =Hazard_Bootstrap!A9 | B39: =CDS_Quotes!B9 | C39: =Hazard_Bootstrap!C9 | D39: =C38*B38/B39 | E39: =IF(C39>=D39,"ok","below bound — may not strip")
A40: =Hazard_Bootstrap!A10 | B40: =CDS_Quotes!B10 | C40: =Hazard_Bootstrap!C10 | D40: =C39*B39/B40 | E40: =IF(C40>=D40,"ok","below bound — may not strip")
A41: =Hazard_Bootstrap!A11 | B41: =CDS_Quotes!B11 | C41: =Hazard_Bootstrap!C11 | D41: =C40*B40/B41 | E41: =IF(C41>=D41,"ok","below bound — may not strip")
A42: =Hazard_Bootstrap!A12 | B42: =CDS_Quotes!B12 | C42: =Hazard_Bootstrap!C12 | D42: =C41*B41/B42 | E42: =IF(C42>=D42,"ok","below bound — may not strip")
A44: A fail is the p.9 condition: a warning about the quotes, not the solver.
A45: Bound is approximate, valid while cumulative default probability is low.
A47: Limits
...

Sheet Root_Methods
A1: Root-finding methods on the hazard strip
A2: All methods solve the same f(h) = (1-R)*Prot(h) - S*(RPV01(h) - AI), B-Model (3.3). Same root; different cost.
A3: Baseline is the scheme, not the algorithm. Section 4 p.8 fixes piecewise-constant hazard solved maturity by maturity, each a 1-D root-find with earlier hazards fixed. It names no method. Hazard_Solver here is bisection.
A4: Needs CDSBrent.bas and CDSRootFinders.bas imported, saved as .xlsm.
A6: Method | B6: Family | C6: Order | D6: Needs | E6: Bracketed | F6: 5Y hazard | G6: its | H6: |f(root)| | I6: vs baseline | J6: Note
A7: BISECTION | B7: bracketing | C7: linear (halves) | D7: no | E7: yes, always | F7: =IFERROR(CDS_Root("BISECTION",Hazard_Solver!$D$136,Hazard_Solver!$F$136,Hazard_Solver!$B$137,Hazard_Solver!$D$137,Hazard_Solver!$F$137,CDS_Parameters!$B$26,Hazard_Solver!$F$139:$U$139,Hazard_Solver!$F$143:$U$143,Hazard_Solver!$F$141:$U$141,Hazard_Solver!$F$142:$U$142),"module not loaded") | G7: =IFERROR(CDS_RootIterations(),"") | H7: =IFERROR(ABS(CDS_Objective(F7,Hazard_Solver!$D$136,Hazard_Solver!$F$136,Hazard_Solver!$B$137,Hazard_Solver!$D$137,Hazard_Solver!$F$137,CDS_Parameters!$B$26,Hazard_Solver!$F$139:$U$139,Hazard_Solver!$F$143:$U$143,Hazard_Solver!$F$141:$U$141,Hazard_Solver!$F$142:$U$142)),"") | I7: =IF(ISNUMBER(F7),F7-Hazard_Solver!$B$175,"") | J7: The safe floor. Cannot fail once bracketed, but pays for it - ~52 steps to machine precision.
A8: FALSE POSITION | B8: bracketing | C8: super-linear | D8: no | E8: yes, always | F8: =IFERROR(CDS_Root("FALSE POSITION",Hazard_Solver!$D$136,Hazard_Solver!$F$136,Hazard_Solver!$B$137,Hazard_Solver!$D$137,Hazard_Solver!$F$137,CDS_Parameters!$B$26,Hazard_Solver!$F$139:$U$139,Hazard_Solver!$F$143:$U$143,Hazard_Solver!$F$141:$U$141,Hazard_Solver!$F$142:$U$142),"module not loaded") | G8: =IFERROR(CDS_RootIterations(),"") | H8: =IFERROR(ABS(CDS_Objective(F8,Hazard_Solver!$D$136,Hazard_Solver!$F$136,Hazard_Solver!$B$137,Hazard_Solver!$D$137,Hazard_Solver!$F$137,CDS_Parameters!$B$26,Hazard_Solver!$F$139:$U$139,Hazard_Solver!$F$143:$U$143,Hazard_Solver!$F$141:$U$141,Hazard_Solver!$F$142:$U$142)),"") | I8: =IF(ISNUMBER(F8),F8-Hazard_Solver!$B$175,"") | J8: Keeps a bracket like bisection but interpolates. Can stall when one end stays fixed.
A9: SECANT | B9: open | C9: ~1.618 | D9: no | E9: no | F9: =IFERROR(CDS_Root("SECANT",Hazard_Solver!$D$136,Hazard_Solver!$F$136,Hazard_Solver!$B$137,Hazard_Solver!$D$137,Hazard_Solver!$F$137,CDS_Parameters!$B$26,Hazard_Solver!$F$139:$U$139,Hazard_Solver!$F$143:$U$143,Hazard_Solver!$F$141:$U$141,Hazard_Solver!$F$142:$U$142),"module not loaded") | G9: =IFERROR(CDS_RootIterations(),"") | H9: =IFERROR(ABS(CDS_Objective(F9,Hazard_Solver!$D$136,Hazard_Solver!$F$136,Hazard_Solver!$B$137,Hazard_Solver!$D$137,Hazard_Solver!$F$137,CDS_Parameters!$B$26,Hazard_Solver!$F$139:$U$139,Hazard_Solver!$F$143:$U$143,Hazard_Solver!$F$141:$U$141,Hazard_Solver!$F$142:$U$142)),"") | I9: =IF(ISNUMBER(F9),F9-Hazard_Solver!$B$175,"") | J9: Newton without a derivative, using the secant of the last two points. No bracket, so it can leave the domain.
A10: NEWTON | B10: open | C10: 2 (quadratic) | D10: f' | E10: no | F10: =IFERROR(CDS_Root("NEWTON",Hazard_Solver!$D$136,Hazard_Solver!$F$136,Hazard_Solver!$B$137,Hazard_Solver!$D$137,Hazard_Solver!$F$137,CDS_Parameters!$B$26,Hazard_Solver!$F$139:$U$139,Hazard_Solver!$F$143:$U$143,Hazard_Solver!$F$141:$U$141,Hazard_Solver!$F$142:$U$142),"module not loaded") | G10: =IFERROR(CDS_RootIterations(),"") | H10: =IFERROR(ABS(CDS_Objective(F10,Hazard_Solver!$D$136,Hazard_Solver!$F$136,Hazard_Solver!$B$137,Hazard_Solver!$D$137,Hazard_Solver!$F$137,CDS_Parameters!$B$26,Hazard_Solver!$F$139:$U$139,Hazard_Solver!$F$143:$U$143,Hazard_Solver!$F$141:$U$141,Hazard_Solver!$F$142:$U$142)),"") | I10: =IF(ISNUMBER(F10),F10-Hazard_Solver!$B$175,"") | J10: Householder d=1. Derivative is analytic here - dQ/dh = -cum*Q - so no bumping.
A11: HALLEY | B11: open | C11: 3 (cubic) | D11: f', f'' | E11: no | F11: =IFERROR(CDS_Root("HALLEY",Hazard_Solver!$D$136,Hazard_Solver!$F$136,Hazard_Solver!$B$137,Hazard_Solver!$D$137,Hazard_Solver!$F$137,CDS_Parameters!$B$26,Hazard_Solver!$F$139:$U$139,Hazard_Solver!$F$143:$U$143,Hazard_Solver!$F$141:$U$141,Hazard_Solver!$F$142:$U$142),"module not loaded") | G11: =IFERROR(CDS_RootIterations(),"") | H11: =IFERROR(ABS(CDS_Objective(F11,Hazard_Solver!$D$136,Hazard_Solver!$F$136,Hazard_Solver!$B$137,Hazard_Solver!$D$137,Hazard_Solver!$F$137,CDS_Parameters!$B$26,Hazard_Solver!$F$139:$U$139,Hazard_Solver!$F$143:$U$143,Hazard_Solver!$F$141:$U$141,Hazard_Solver!$F$142:$U$142)),"") | I11: =IF(ISNUMBER(F11),F11-Hazard_Solver!$B$175,"") | J11: Householder d=2. Second derivative also analytic: d2Q/dh2 = cum^2*Q.
A12: HOUSEHOLDER | B12: open | C12: d+1 | D12: f' ... f^(d) | E12: no | F12: =IFERROR(CDS_Root("HOUSEHOLDER",Hazard_Solver!$D$136,Hazard_Solver!$F$136,Hazard_Solver!$B$137,Hazard_Solver!$D$137,Hazard_Solver!$F$137,CDS_Parameters!$B$26,Hazard_Solver!$F$139:$U$139,Hazard_Solver!$F$143:$U$143,Hazard_Solver!$F$141:$U$141,Hazard_Solver!$F$142:$U$142),"module not loaded") | G12: =IFERROR(CDS_RootIterations(),"") | H12: =IFERROR(ABS(CDS_Objective(F12,Hazard_Solver!$D$136,Hazard_Solver!$F$136,Hazard_Solver!$B$137,Hazard_Solver!$D$137,Hazard_Solver!$F$137,CDS_Parameters!$B$26,Hazard_Solver!$F$139:$U$139,Hazard_Solver!$F$143:$U$143,Hazard_Solver!$F$141:$U$141,Hazard_Solver!$F$142:$U$142)),"") | I12: =IF(ISNUMBER(F12),F12-Hazard_Solver!$B$175,"") | J12: General order d. d=1 reduces to Newton and d=2 to Halley, the M2 identity.
A13: RIDDERS | B13: bracketing hybrid | C13: hybrid | D13: no | E13: yes, always | F13: =IFERROR(CDS_Root("RIDDERS",Hazard_Solver!$D$136,Hazard_Solver!$F$136,Hazard_Solver!$B$137,Hazard_Solver!$D$137,Hazard_Solver!$F$137,CDS_Parameters!$B$26,Hazard_Solver!$F$139:$U$139,Hazard_Solver!$F$143:$U$143,Hazard_Solver!$F$141:$U$141,Hazard_Solver!$F$142:$U$142),"module not loaded") | G13: =IFERROR(CDS_RootIterations(),"") | H13: =IFERROR(ABS(CDS_Objective(F13,Hazard_Solver!$D$136,Hazard_Solver!$F$136,Hazard_Solver!$B$137,Hazard_Solver!$D$137,Hazard_Solver!$F$137,CDS_Parameters!$B$26,Hazard_Solver!$F$139:$U$139,Hazard_Solver!$F$143:$U$143,Hazard_Solver!$F$141:$U$141,Hazard_Solver!$F$142:$U$142)),"") | I13: =IF(ISNUMBER(F13),F13-Hazard_Solver!$B$175,"") | J13: Bisection plus exponential interpolation. Keeps the bracket and converges fast.
A14: BRENT | B14: bracketing hybrid | C14: hybrid | D14: no | E14: yes, always | F14: =IFERROR(CDS_Root("BRENT",Hazard_Solver!$D$136,Hazard_Solver!$F$136,Hazard_Solver!$B$137,Hazard_Solver!$D$137,Hazard_Solver!$F$137,CDS_Parameters!$B$26,Hazard_Solver!$F$139:$U$139,Hazard_Solver!$F$143:$U$143,Hazard_Solver!$F$141:$U$141,Hazard_Solver!$F$142:$U$142),"module not loaded") | G14: =IFERROR(CDS_RootIterations(),"") | H14: =IFERROR(ABS(CDS_Objective(F14,Hazard_Solver!$D$136,Hazard_Solver!$F$136,Hazard_Solver!$B$137,Hazard_Solver!$D$137,Hazard_Solver!$F$137,CDS_Parameters!$B$26,Hazard_Solver!$F$139:$U$139,Hazard_Solver!$F$143:$U$143,Hazard_Solver!$F$141:$U$141,Hazard_Solver!$F$142:$U$142)),"") | I14: =IF(ISNUMBER(F14),F14-Hazard_Solver!$B$175,"") | J14: IQI, falling back to secant, falling back to bisection. Bisection's guarantee at near-secant speed.
A16: Spread of the eight roots (max - min) | F16: =IF(COUNT(F7:F14)=0,"module not loaded",MAX(F7:F14)-MIN(F7:F14)) | G16: they solve the same equation, so this is the real check
A18: Measured on the 5Y objective (quarterly, R=40%, S=95bp), tolerance 1e-15
A19: Method | B19: iters | C19: |root - scipy.brentq| | D19: |f(root)|
A20: bisection | B20: 52 | C20: 5.0e-16 | D20: 1.3e-15
A21: false position | B21: 12 | C21: 2.4e-17 | D21: 6.9e-17
A22: secant | B22: 13 | C22: 3.5e-18 | D22: 1.4e-17
A23: Newton (d=1) | B23: 6 | C23: 6.9e-18 | D23: 1.4e-17
A24: Halley (d=2) | B24: 6 | C24: 3.5e-18 | D24: 1.4e-17
A25: Householder d=3 | B25: 6 | C25: 3.5e-18 | D25: 1.4e-17
A26: Ridders | B26: 5 | C26: 2.1e-17 | D26: 3.5e-17
A27: Brent | B27: 9 | C27: 1.4e-17 | D27: 1.4e-17
A29: Results
A30: All eight agree to ~1e-16. Method is a cost choice here, not an accuracy one.
A31: Bisection: 52 steps. Newton: 6. That is the cost of ignoring the shape of f.
A32: Halley and Householder d=3 do not beat Newton here: 6 iterations each. f is near-linear in h at the root,
A33: so the extra order is spent before tolerance is reached.
A34: Ridders is fastest at 5. But secant, Newton and Halley can all leave the domain on a bad start;
A35: bracketing methods cannot. The strip must never return h < 0 (p.8), so the guarantee outranks the speed.
A36: If nothing converges, suspect the quote. See the p.9 strippability check on Model_Notes.

Sheet Brent_vs_Bisection
A1: Brent (VBA) vs in-cell bisection
A2: Same objective (3.3), same inputs. Only the root-finder differs. Eight methods on Root_Methods.
A3: Import CDSBrent.bas (Alt+F11 > File > Import File), save as .xlsm. Until then col D reads 'module not loaded'.
A5: Tenor | B5: Market bp | C5: Bisection (30 steps) | D5: Brent (VBA) | E5: diff | F5: Brent its | G5: f at bisection | H5: f at Brent | I5: Model bp | J5: Err bp
A6: 1Y | B6: =Hazard_Solver!$B$7 | C6: =Hazard_Solver!$B$46 | D6: =IFERROR(CDS_Hazard(Hazard_Solver!$D$7,Hazard_Solver!$F$7,Hazard_Solver!$B$8,Hazard_Solver!$D$8,Hazard_Solver!$F$8,CDS_Parameters!$B$26,Hazard_Solver!$F$10:$U$10,Hazard_Solver!$F$14:$U$14,Hazard_Solver!$F$12:$U$12,Hazard_Solver!$F$13:$U$13),"module not loaded") | E6: =IF(ISNUMBER(D6),D6-C6,"") | F6: =IFERROR(CDS_LastIterations(),"") | G6: =IFERROR(CDS_Objective(C6,Hazard_Solver!$D$7,Hazard_Solver!$F$7,Hazard_Solver!$B$8,Hazard_Solver!$D$8,Hazard_Solver!$F$8,CDS_Parameters!$B$26,Hazard_Solver!$F$10:$U$10,Hazard_Solver!$F$14:$U$14,Hazard_Solver!$F$12:$U$12,Hazard_Solver!$F$13:$U$13),"") | H6: =IF(ISNUMBER(D6),IFERROR(CDS_Objective(D6,Hazard_Solver!$D$7,Hazard_Solver!$F$7,Hazard_Solver!$B$8,Hazard_Solver!$D$8,Hazard_Solver!$F$8,CDS_Parameters!$B$26,Hazard_Solver!$F$10:$U$10,Hazard_Solver!$F$14:$U$14,Hazard_Solver!$F$12:$U$12,Hazard_Solver!$F$13:$U$13),""),"") | I6: =IF(ISNUMBER(D6),IFERROR(CDS_ModelSpread(D6,Hazard_Solver!$D$7,Hazard_Solver!$F$7,Hazard_Solver!$B$8,Hazard_Solver!$D$8,Hazard_Solver!$F$8,CDS_Parameters!$B$26,Hazard_Solver!$F$10:$U$10,Hazard_Solver!$F$14:$U$14,Hazard_Solver!$F$12:$U$12,Hazard_Solver!$F$13:$U$13),""),"") | J6: =IF(ISNUMBER(I6),I6-B6,"")
A7: 2Y | B7: =Hazard_Solver!$B$50 | C7: =Hazard_Solver!$B$89 | D7: =IFERROR(CDS_Hazard(Hazard_Solver!$D$50,Hazard_Solver!$F$50,Hazard_Solver!$B$51,Hazard_Solver!$D$51,Hazard_Solver!$F$51,CDS_Parameters!$B$26,Hazard_Solver!$F$53:$U$53,Hazard_Solver!$F$57:$U$57,Hazard_Solver!$F$55:$U$55,Hazard_Solver!$F$56:$U$56),"module not loaded") | E7: =IF(ISNUMBER(D7),D7-C7,"") | F7: =IFERROR(CDS_LastIterations(),"") | G7: =IFERROR(CDS_Objective(C7,Hazard_Solver!$D$50,Hazard_Solver!$F$50,Hazard_Solver!$B$51,Hazard_Solver!$D$51,Hazard_Solver!$F$51,CDS_Parameters!$B$26,Hazard_Solver!$F$53:$U$53,Hazard_Solver!$F$57:$U$57,Hazard_Solver!$F$55:$U$55,Hazard_Solver!$F$56:$U$56),"") | H7: =IF(ISNUMBER(D7),IFERROR(CDS_Objective(D7,Hazard_Solver!$D$50,Hazard_Solver!$F$50,Hazard_Solver!$B$51,Hazard_Solver!$D$51,Hazard_Solver!$F$51,CDS_Parameters!$B$26,Hazard_Solver!$F$53:$U$53,Hazard_Solver!$F$57:$U$57,Hazard_Solver!$F$55:$U$55,Hazard_Solver!$F$56:$U$56),""),"") | I7: =IF(ISNUMBER(D7),IFERROR(CDS_ModelSpread(D7,Hazard_Solver!$D$50,Hazard_Solver!$F$50,Hazard_Solver!$B$51,Hazard_Solver!$D$51,Hazard_Solver!$F$51,CDS_Parameters!$B$26,Hazard_Solver!$F$53:$U$53,Hazard_Solver!$F$57:$U$57,Hazard_Solver!$F$55:$U$55,Hazard_Solver!$F$56:$U$56),""),"") | J7: =IF(ISNUMBER(I7),I7-B7,"")
A8: 3Y | B8: =Hazard_Solver!$B$93 | C8: =Hazard_Solver!$B$132 | D8: =IFERROR(CDS_Hazard(Hazard_Solver!$D$93,Hazard_Solver!$F$93,Hazard_Solver!$B$94,Hazard_Solver!$D$94,Hazard_Solver!$F$94,CDS_Parameters!$B$26,Hazard_Solver!$F$96:$U$96,Hazard_Solver!$F$100:$U$100,Hazard_Solver!$F$98:$U$98,Hazard_Solver!$F$99:$U$99),"module not loaded") | E8: =IF(ISNUMBER(D8),D8-C8,"") | F8: =IFERROR(CDS_LastIterations(),"") | G8: =IFERROR(CDS_Objective(C8,Hazard_Solver!$D$93,Hazard_Solver!$F$93,Hazard_Solver!$B$94,Hazard_Solver!$D$94,Hazard_Solver!$F$94,CDS_Parameters!$B$26,Hazard_Solver!$F$96:$U$96,Hazard_Solver!$F$100:$U$100,Hazard_Solver!$F$98:$U$98,Hazard_Solver!$F$99:$U$99),"") | H8: =IF(ISNUMBER(D8),IFERROR(CDS_Objective(D8,Hazard_Solver!$D$93,Hazard_Solver!$F$93,Hazard_Solver!$B$94,Hazard_Solver!$D$94,Hazard_Solver!$F$94,CDS_Parameters!$B$26,Hazard_Solver!$F$96:$U$96,Hazard_Solver!$F$100:$U$100,Hazard_Solver!$F$98:$U$98,Hazard_Solver!$F$99:$U$99),""),"") | I8: =IF(ISNUMBER(D8),IFERROR(CDS_ModelSpread(D8,Hazard_Solver!$D$93,Hazard_Solver!$F$93,Hazard_Solver!$B$94,Hazard_Solver!$D$94,Hazard_Solver!$F$94,CDS_Parameters!$B$26,Hazard_Solver!$F$96:$U$96,Hazard_Solver!$F$100:$U$100,Hazard_Solver!$F$98:$U$98,Hazard_Solver!$F$99:$U$99),""),"") | J8: =IF(ISNUMBER(I8),I8-B8,"")
A9: 5Y | B9: =Hazard_Solver!$B$136 | C9: =Hazard_Solver!$B$175 | D9: =IFERROR(CDS_Hazard(Hazard_Solver!$D$136,Hazard_Solver!$F$136,Hazard_Solver!$B$137,Hazard_Solver!$D$137,Hazard_Solver!$F$137,CDS_Parameters!$B$26,Hazard_Solver!$F$139:$U$139,Hazard_Solver!$F$143:$U$143,Hazard_Solver!$F$141:$U$141,Hazard_Solver!$F$142:$U$142),"module not loaded") | E9: =IF(ISNUMBER(D9),D9-C9,"") | F9: =IFERROR(CDS_LastIterations(),"") | G9: =IFERROR(CDS_Objective(C9,Hazard_Solver!$D$136,Hazard_Solver!$F$136,Hazard_Solver!$B$137,Hazard_Solver!$D$137,Hazard_Solver!$F$137,CDS_Parameters!$B$26,Hazard_Solver!$F$139:$U$139,Hazard_Solver!$F$143:$U$143,Hazard_Solver!$F$141:$U$141,Hazard_Solver!$F$142:$U$142),"") | H9: =IF(ISNUMBER(D9),IFERROR(CDS_Objective(D9,Hazard_Solver!$D$136,Hazard_Solver!$F$136,Hazard_Solver!$B$137,Hazard_Solver!$D$137,Hazard_Solver!$F$137,CDS_Parameters!$B$26,Hazard_Solver!$F$139:$U$139,Hazard_Solver!$F$143:$U$143,Hazard_Solver!$F$141:$U$141,Hazard_Solver!$F$142:$U$142),""),"") | I9: =IF(ISNUMBER(D9),IFERROR(CDS_ModelSpread(D9,Hazard_Solver!$D$136,Hazard_Solver!$F$136,Hazard_Solver!$B$137,Hazard_Solver!$D$137,Hazard_Solver!$F$137,CDS_Parameters!$B$26,Hazard_Solver!$F$139:$U$139,Hazard_Solver!$F$143:$U$143,Hazard_Solver!$F$141:$U$141,Hazard_Solver!$F$142:$U$142),""),"") | J9: =IF(ISNUMBER(I9),I9-B9,"")
A10: 7Y | B10: =Hazard_Solver!$B$179 | C10: =Hazard_Solver!$B$218 | D10: =IFERROR(CDS_Hazard(Hazard_Solver!$D$179,Hazard_Solver!$F$179,Hazard_Solver!$B$180,Hazard_Solver!$D$180,Hazard_Solver!$F$180,CDS_Parameters!$B$26,Hazard_Solver!$F$182:$U$182,Hazard_Solver!$F$186:$U$186,Hazard_Solver!$F$184:$U$184,Hazard_Solver!$F$185:$U$185),"module not loaded") | E10: =IF(ISNUMBER(D10),D10-C10,"") | F10: =IFERROR(CDS_LastIterations(),"") | G10: =IFERROR(CDS_Objective(C10,Hazard_Solver!$D$179,Hazard_Solver!$F$179,Hazard_Solver!$B$180,Hazard_Solver!$D$180,Hazard_Solver!$F$180,CDS_Parameters!$B$26,Hazard_Solver!$F$182:$U$182,Hazard_Solver!$F$186:$U$186,Hazard_Solver!$F$184:$U$184,Hazard_Solver!$F$185:$U$185),"") | H10: =IF(ISNUMBER(D10),IFERROR(CDS_Objective(D10,Hazard_Solver!$D$179,Hazard_Solver!$F$179,Hazard_Solver!$B$180,Hazard_Solver!$D$180,Hazard_Solver!$F$180,CDS_Parameters!$B$26,Hazard_Solver!$F$182:$U$182,Hazard_Solver!$F$186:$U$186,Hazard_Solver!$F$184:$U$184,Hazard_Solver!$F$185:$U$185),""),"") | I10: =IF(ISNUMBER(D10),IFERROR(CDS_ModelSpread(D10,Hazard_Solver!$D$179,Hazard_Solver!$F$179,Hazard_Solver!$B$180,Hazard_Solver!$D$180,Hazard_Solver!$F$180,CDS_Parameters!$B$26,Hazard_Solver!$F$182:$U$182,Hazard_Solver!$F$186:$U$186,Hazard_Solver!$F$184:$U$184,Hazard_Solver!$F$185:$U$185),""),"") | J10: =IF(ISNUMBER(I10),I10-B10,"")
A11: 10Y | B11: =Hazard_Solver!$B$222 | C11: =Hazard_Solver!$B$261 | D11: =IFERROR(CDS_Hazard(Hazard_Solver!$D$222,Hazard_Solver!$F$222,Hazard_Solver!$B$223,Hazard_Solver!$D$223,Hazard_Solver!$F$223,CDS_Parameters!$B$26,Hazard_Solver!$F$225:$U$225,Hazard_Solver!$F$229:$U$229,Hazard_Solver!$F$227:$U$227,Hazard_Solver!$F$228:$U$228),"module not loaded") | E11: =IF(ISNUMBER(D11),D11-C11,"") | F11: =IFERROR(CDS_LastIterations(),"") | G11: =IFERROR(CDS_Objective(C11,Hazard_Solver!$D$222,Hazard_Solver!$F$222,Hazard_Solver!$B$223,Hazard_Solver!$D$223,Hazard_Solver!$F$223,CDS_Parameters!$B$26,Hazard_Solver!$F$225:$U$225,Hazard_Solver!$F$229:$U$229,Hazard_Solver!$F$227:$U$227,Hazard_Solver!$F$228:$U$228),"") | H11: =IF(ISNUMBER(D11),IFERROR(CDS_Objective(D11,Hazard_Solver!$D$222,Hazard_Solver!$F$222,Hazard_Solver!$B$223,Hazard_Solver!$D$223,Hazard_Solver!$F$223,CDS_Parameters!$B$26,Hazard_Solver!$F$225:$U$225,Hazard_Solver!$F$229:$U$229,Hazard_Solver!$F$227:$U$227,Hazard_Solver!$F$228:$U$228),""),"") | I11: =IF(ISNUMBER(D11),IFERROR(CDS_ModelSpread(D11,Hazard_Solver!$D$222,Hazard_Solver!$F$222,Hazard_Solver!$B$223,Hazard_Solver!$D$223,Hazard_Solver!$F$223,CDS_Parameters!$B$26,Hazard_Solver!$F$225:$U$225,Hazard_Solver!$F$229:$U$229,Hazard_Solver!$F$227:$U$227,Hazard_Solver!$F$228:$U$228),""),"") | J11: =IF(ISNUMBER(I11),I11-B11,"")
A13: Max |diff| (hazard) | C13: =IF(COUNT(E6:E11)=0,"module not loaded",MAX(MAX(E6:E11),-MIN(E6:E11)))
A14: Max |Err| Brent (bp) | C14: =IF(COUNT(J6:J11)=0,"",MAX(MAX(J6:J11),-MIN(J6:J11)))
A17: WHAT BRENT ACTUALLY BUYS
B18: In-cell bisection | C18: Brent (VBA) | D18: Better
A19: Iterations | B19: 30, fixed | C19: 8-13, adaptive | D19: Brent
A20: Residual |f| at the root | B20: ~1e-9 | C20: ~1e-17 | D20: Brent, by ~8 orders
A21: Hazard agreement | B21: the two agree to ~1e-9 | D21: immaterial: 1e-9 of hazard is 1e-7 bp of spread
A22: Cells consumed | B22: ~3,600 on Hazard_Solver | C22: 6 function calls | D22: Brent, heavily
A23: Working visible | B23: yes, every halving is a row | C23: no, opaque call | D23: BISECTION
A24: File format | B24: .xlsx | C24: .xlsm + macro trust | D24: BISECTION
A25: Recalc | B25: native | C25: UDF, slower per call, no multithread | D25: bisection
A26: Fails on an unstrippable quote | B26: pins silently at a bracket end | C26: returns #NUM! | D26: Brent
A29: Verdict
A30: Brent wins on the numbers: 8-13 iterations to machine precision vs 30 fixed halvings, residual ~1e-17 vs ~1e-9.
A31: It would return ~3,600 cells and a faster recalc. It costs the visible working and forces .xlsm.
A32: Keeping bisection as the engine and Brent as the cross-check is the useful split: an independent implementation agreeing to 1e-9 is real evidence the strip is right.
A33: Functional gain worth taking: Brent returns #NUM! on an unbracketed quote. Bisection returns a bracket end that looks like an answer. See Model_Notes, p.9.

Sheet Curve_Interface
A1: Curve_Interface
A2: Shared discounting D(0,t). Curve grid in K:L is a dated snapshot from the SOFR bootstrap, pasted as values.
A4: Piecewise-flat instantaneous forward between pillars. Confirmed against S490 as Step Forward (Cont).
N5: Valuation date | O5: 46224
K6: Curve grid - LIVE LINK to the curve workbook | M6: source: [USD_SOFR_Curve_Bloomberg_Pricer.xlsx]Curve_Interface!K8 (anchor) + K10:L74 (65 pillars) | N6: drives every date on the CDS sheets
A7: Valuation: | B7: =VAL_DATE | C7: Spot: | D7: ='[USD_SOFR_Curve_Bloomberg_Pricer.xlsx]Curve_Interface'!$D$7 | E7: 1st CDS date: | F7: =IF(DATE(YEAR(VAL_DATE),CEILING(MONTH(VAL_DATE)/3,1)*3,20)>=VAL_DATE,DATE(YEAR(VAL_DATE),CEILING(MONTH(VAL_DATE)/3,1)*3,20),EDATE(DATE(YEAR(VAL_DATE),CEILING(MONTH(VAL_DATE)/3,1)*3,20),3)) | I7: Interpolation | J7: Step-function forward (flat fwd) | K7: Date | L7: DF
I8: VERIFIED default | J8: Step-function forward reproduces S490 (confirmed on screen: Step Forward (Cont)). Piecewise Linear (Simple) is 48x worse here. Only switch if the screen says so. | K8: ='[USD_SOFR_Curve_Bloomberg_Pricer.xlsx]Curve_Interface'!$K$8 | L8: ='[USD_SOFR_Curve_Bloomberg_Pricer.xlsx]Curve_Interface'!$L$8 | N8: LINK CHECK
A9: Coupon # | B9: Date | C9: Time from val (yrs) | D9: Prev SOFR pillar | E9: Next SOFR pillar | F9: Segment fwd (%) | G9: Interp DF D(0,t) | H9: Interp zero (%) | K9: ='[USD_SOFR_Curve_Bloomberg_Pricer.xlsx]Curve_Interface'!$K$10 | L9: ='[USD_SOFR_Curve_Bloomberg_Pricer.xlsx]Curve_Interface'!$L$10 | N9: pillars linked | O9: =COUNT($L$8:$L$73)
A10: 1 | B10: =EDATE($F$7,3*0) | C10: =(B10-VAL_DATE)/365 | D10: =INDEX($K$8:$K$73,MATCH(B10,$K$8:$K$73,1)) | E10: =INDEX($K$8:$K$73,MATCH(B10,$K$8:$K$73,1)+1) | F10: =-LN(INDEX($L$8:$L$73,MATCH(B10,$K$8:$K$73,1)+1)/INDEX($L$8:$L$73,MATCH(B10,$K$8:$K$73,1)))/((E10-D10)/365)*100 | G10: =IFERROR(IF($J$7="Piecewise Linear (Simple)",IF(((B10-VAL_DATE)/360)<=0,1,1/(1+(IF(MAX((10>0)*(D10-VAL_DATE)/360,0)<=0,IF(((E10-VAL_DATE)/360)<=0,0,(1/INDEX($L$8:$L$73,MATCH(B10,$K$8:$K$73,1)+1)-1)/((E10-VAL_DATE)/360)),IF(MAX((10>0)*(D10-VAL_DATE)/360,0)<=0,0,(1/INDEX($L$8:$L$73,MATCH(B10,$K$8:$K$73,1))-1)/MAX((10>0)*(D10-VAL_DATE)/360,0)))+(IF(((E10-VAL_DATE)/360)<=0,0,(1/INDEX($L$8:$L$73,MATCH(B10,$K$8:$K$73,1)+1)-1)/((E10-VAL_DATE)/360))-IF(MAX((10>0)*(D10-VAL_DATE)/360,0)<=0,IF(((E10-VAL_DATE)/360)<=0,0,(1/INDEX($L$8:$L$73,MATCH(B10,$K$8:$K$73,1)+1)-1)/((E10-VAL_DATE)/360)),IF(MAX((10>0)*(D10-VAL_DATE)/360,0)<=0,0,(1/INDEX($L$8:$L$73,MATCH(B10,$K$8:$K$73,1))-1)/MAX((10>0)*(D10-VAL_DATE)/360,0))))*IF(((E10-VAL_DATE)/360)-MAX((10>0)*(D10-VAL_DATE)/360,0)=0,0,(((B10-VAL_DATE)/360)-MAX((10>0)*(D10-VAL_DATE)/360,0))/(((E10-VAL_DATE)/360)-MAX((10>0)*(D10-VAL_DATE)/360,0))))*((B10-VAL_DATE)/360))),INDEX($L$8:$L$73,MATCH(B10,$K$8:$K$73,1))*EXP(-(F10/100)*(B10-D10)/365)),"") | H10: =-LN(G10)/C10*100 | I10: Method 1: DF=1/(1+r_s*t), r_s linear, ACT/360, flat outside the pillars. | K10: ='[USD_SOFR_Curve_Bloomberg_Pricer.xlsx]Curve_Interface'!$K$11 | L10: ='[USD_SOFR_Curve_Bloomberg_Pricer.xlsx]Curve_Interface'!$L$11 | N10: first date | O10: =IF(COUNT($K$8:$K$73)=0,"",MIN($K$8:$K$73))
A11: 2 | B11: =EDATE($F$7,3*1) | C11: =(B11-VAL_DATE)/365 | D11: =INDEX($K$8:$K$73,MATCH(B11,$K$8:$K$73,1)) | E11: =INDEX($K$8:$K$73,MATCH(B11,$K$8:$K$73,1)+1) | F11: =-LN(INDEX($L$8:$L$73,MATCH(B11,$K$8:$K$73,1)+1)/INDEX($L$8:$L$73,MATCH(B11,$K$8:$K$73,1)))/((E11-D11)/365)*100 | G11: =IFERROR(IF($J$7="Piecewise Linear (Simple)",IF(((B11-VAL_DATE)/360)<=0,1,1/(1+(IF(MAX((11>0)*(D11-VAL_DATE)/360,0)<=0,IF(((E11-VAL_DATE)/360)<=0,0,(1/INDEX($L$8:$L$73,MATCH(B11,$K$8:$K$73,1)+1)-1)/((E11-VAL_DATE)/360)),IF(MAX((11>0)*(D11-VAL_DATE)/360,0)<=0,0,(1/INDEX($L$8:$L$73,MATCH(B11,$K$8:$K$73,1))-1)/MAX((11>0)*(D11-VAL_DATE)/360,0)))+(IF(((E11-VAL_DATE)/360)<=0,0,(1/INDEX($L$8:$L$73,MATCH(B11,$K$8:$K$73,1)+1)-1)/((E11-VAL_DATE)/360))-IF(MAX((11>0)*(D11-VAL_DATE)/360,0)<=0,IF(((E11-VAL_DATE)/360)<=0,0,(1/INDEX($L$8:$L$73,MATCH(B11,$K$8:$K$73,1)+1)-1)/((E11-VAL_DATE)/360)),IF(MAX((11>0)*(D11-VAL_DATE)/360,0)<=0,0,(1/INDEX($L$8:$L$73,MATCH(B11,$K$8:$K$73,1))-1)/MAX((11>0)*(D11-VAL_DATE)/360,0))))*IF(((E11-VAL_DATE)/360)-MAX((11>0)*(D11-VAL_DATE)/360,0)=0,0,(((B11-VAL_DATE)/360)-MAX((11>0)*(D11-VAL_DATE)/360,0))/(((E11-VAL_DATE)/360)-MAX((11>0)*(D11-VAL_DATE)/360,0))))*((B11-VAL_DATE)/360))),INDEX($L$8:$L$73,MATCH(B11,$K$8:$K$73,1))*EXP(-(F11/100)*(B11-D11)/365)),"") | H11: =-LN(G11)/C11*100 | I11: Method 3: flat forward between pillars = log-linear in DF. | K11: ='[USD_SOFR_Curve_Bloomberg_Pricer.xlsx]Curve_Interface'!$K$12 | L11: ='[USD_SOFR_Curve_Bloomberg_Pricer.xlsx]Curve_Interface'!$L$12 | N11: last date | O11: =IF(COUNT($K$8:$K$73)=0,"",MAX($K$8:$K$73))
A12: 3 | B12: =EDATE($F$7,3*2) | C12: =(B12-VAL_DATE)/365 | D12: =INDEX($K$8:$K$73,MATCH(B12,$K$8:$K$73,1)) | E12: =INDEX($K$8:$K$73,MATCH(B12,$K$8:$K$73,1)+1) | F12: =-LN(INDEX($L$8:$L$73,MATCH(B12,$K$8:$K$73,1)+1)/INDEX($L$8:$L$73,MATCH(B12,$K$8:$K$73,1)))/((E12-D12)/365)*100 | G12: =IFERROR(IF($J$7="Piecewise Linear (Simple)",IF(((B12-VAL_DATE)/360)<=0,1,1/(1+(IF(MAX((12>0)*(D12-VAL_DATE)/360,0)<=0,IF(((E12-VAL_DATE)/360)<=0,0,(1/INDEX($L$8:$L$73,MATCH(B12,$K$8:$K$73,1)+1)-1)/((E12-VAL_DATE)/360)),IF(MAX((12>0)*(D12-VAL_DATE)/360,0)<=0,0,(1/INDEX($L$8:$L$73,MATCH(B12,$K$8:$K$73,1))-1)/MAX((12>0)*(D12-VAL_DATE)/360,0)))+(IF(((E12-VAL_DATE)/360)<=0,0,(1/INDEX($L$8:$L$73,MATCH(B12,$K$8:$K$73,1)+1)-1)/((E12-VAL_DATE)/360))-IF(MAX((12>0)*(D12-VAL_DATE)/360,0)<=0,IF(((E12-VAL_DATE)/360)<=0,0,(1/INDEX($L$8:$L$73,MATCH(B12,$K$8:$K$73,1)+1)-1)/((E12-VAL_DATE)/360)),IF(MAX((12>0)*(D12-VAL_DATE)/360,0)<=0,0,(1/INDEX($L$8:$L$73,MATCH(B12,$K$8:$K$73,1))-1)/MAX((12>0)*(D12-VAL_DATE)/360,0))))*IF(((E12-VAL_DATE)/360)-MAX((12>0)*(D12-VAL_DATE)/360,0)=0,0,(((B12-VAL_DATE)/360)-MAX((12>0)*(D12-VAL_DATE)/360,0))/(((E12-VAL_DATE)/360)-MAX((12>0)*(D12-VAL_DATE)/360,0))))*((B12-VAL_DATE)/360))),INDEX($L$8:$L$73,MATCH(B12,$K$8:$K$73,1))*EXP(-(F12/100)*(B12-D12)/365)),"") | H12: =-LN(G12)/C12*100 | I12: Identical at the pillars. They differ off-pillar, which is what CDS_Schedule looks up. ~0.07bp in a 2Y gap. | K12: ='[USD_SOFR_Curve_Bloomberg_Pricer.xlsx]Curve_Interface'!$K$13 | L12: ='[USD_SOFR_Curve_Bloomberg_Pricer.xlsx]Curve_Interface'!$L$13 | N12: anchor DF (want 1) | O12: =IF($L$8="","",$L$8)
A13: 4 | B13: =EDATE($F$7,3*3) | C13: =(B13-VAL_DATE)/365 | D13: =INDEX($K$8:$K$73,MATCH(B13,$K$8:$K$73,1)) | E13: =INDEX($K$8:$K$73,MATCH(B13,$K$8:$K$73,1)+1) | F13: =-LN(INDEX($L$8:$L$73,MATCH(B13,$K$8:$K$73,1)+1)/INDEX($L$8:$L$73,MATCH(B13,$K$8:$K$73,1)))/((E13-D13)/365)*100 | G13: =IFERROR(IF($J$7="Piecewise Linear (Simple)",IF(((B13-VAL_DATE)/360)<=0,1,1/(1+(IF(MAX((13>0)*(D13-VAL_DATE)/360,0)<=0,IF(((E13-VAL_DATE)/360)<=0,0,(1/INDEX($L$8:$L$73,MATCH(B13,$K$8:$K$73,1)+1)-1)/((E13-VAL_DATE)/360)),IF(MAX((13>0)*(D13-VAL_DATE)/360,0)<=0,0,(1/INDEX($L$8:$L$73,MATCH(B13,$K$8:$K$73,1))-1)/MAX((13>0)*(D13-VAL_DATE)/360,0)))+(IF(((E13-VAL_DATE)/360)<=0,0,(1/INDEX($L$8:$L$73,MATCH(B13,$K$8:$K$73,1)+1)-1)/((E13-VAL_DATE)/360))-IF(MAX((13>0)*(D13-VAL_DATE)/360,0)<=0,IF(((E13-VAL_DATE)/360)<=0,0,(1/INDEX($L$8:$L$73,MATCH(B13,$K$8:$K$73,1)+1)-1)/((E13-VAL_DATE)/360)),IF(MAX((13>0)*(D13-VAL_DATE)/360,0)<=0,0,(1/INDEX($L$8:$L$73,MATCH(B13,$K$8:$K$73,1))-1)/MAX((13>0)*(D13-VAL_DATE)/360,0))))*IF(((E13-VAL_DATE)/360)-MAX((13>0)*(D13-VAL_DATE)/360,0)=0,0,(((B13-VAL_DATE)/360)-MAX((13>0)*(D13-VAL_DATE)/360,0))/(((E13-VAL_DATE)/360)-MAX((13>0)*(D13-VAL_DATE)/360,0))))*((B13-VAL_DATE)/360))),INDEX($L$8:$L$73,MATCH(B13,$K$8:$K$73,1))*EXP(-(F13/100)*(B13-D13)/365)),"") | H13: =-LN(G13)/C13*100 | K13: ='[USD_SOFR_Curve_Bloomberg_Pricer.xlsx]Curve_Interface'!$K$14 | L13: ='[USD_SOFR_Curve_Bloomberg_Pricer.xlsx]Curve_Interface'!$L$14 | N13: first tenor date | O13: =IF($K$9="","",$K$9)
A14: 5 | B14: =EDATE($F$7,3*4) | C14: =(B14-VAL_DATE)/365 | D14: =INDEX($K$8:$K$73,MATCH(B14,$K$8:$K$73,1)) | E14: =INDEX($K$8:$K$73,MATCH(B14,$K$8:$K$73,1)+1) | F14: =-LN(INDEX($L$8:$L$73,MATCH(B14,$K$8:$K$73,1)+1)/INDEX($L$8:$L$73,MATCH(B14,$K$8:$K$73,1)))/((E14-D14)/365)*100 | G14: =IFERROR(IF($J$7="Piecewise Linear (Simple)",IF(((B14-VAL_DATE)/360)<=0,1,1/(1+(IF(MAX((14>0)*(D14-VAL_DATE)/360,0)<=0,IF(((E14-VAL_DATE)/360)<=0,0,(1/INDEX($L$8:$L$73,MATCH(B14,$K$8:$K$73,1)+1)-1)/((E14-VAL_DATE)/360)),IF(MAX((14>0)*(D14-VAL_DATE)/360,0)<=0,0,(1/INDEX($L$8:$L$73,MATCH(B14,$K$8:$K$73,1))-1)/MAX((14>0)*(D14-VAL_DATE)/360,0)))+(IF(((E14-VAL_DATE)/360)<=0,0,(1/INDEX($L$8:$L$73,MATCH(B14,$K$8:$K$73,1)+1)-1)/((E14-VAL_DATE)/360))-IF(MAX((14>0)*(D14-VAL_DATE)/360,0)<=0,IF(((E14-VAL_DATE)/360)<=0,0,(1/INDEX($L$8:$L$73,MATCH(B14,$K$8:$K$73,1)+1)-1)/((E14-VAL_DATE)/360)),IF(MAX((14>0)*(D14-VAL_DATE)/360,0)<=0,0,(1/INDEX($L$8:$L$73,MATCH(B14,$K$8:$K$73,1))-1)/MAX((14>0)*(D14-VAL_DATE)/360,0))))*IF(((E14-VAL_DATE)/360)-MAX((14>0)*(D14-VAL_DATE)/360,0)=0,0,(((B14-VAL_DATE)/360)-MAX((14>0)*(D14-VAL_DATE)/360,0))/(((E14-VAL_DATE)/360)-MAX((14>0)*(D14-VAL_DATE)/360,0))))*((B14-VAL_DATE)/360))),INDEX($L$8:$L$73,MATCH(B14,$K$8:$K$73,1))*EXP(-(F14/100)*(B14-D14)/365)),"") | H14: =-LN(G14)/C14*100 | K14: ='[USD_SOFR_Curve_Bloomberg_Pricer.xlsx]Curve_Interface'!$K$15 | L14: ='[USD_SOFR_Curve_Bloomberg_Pricer.xlsx]Curve_Interface'!$L$15 | N14: DF monotone? | O14: =IF(COUNT($L$8:$L$73)<2,"",IF(SUMPRODUCT(--($L$9:$L$73>$L$8:$L$72))=0,"ok","NOT DECREASING"))
A15: 6 | B15: =EDATE($F$7,3*5) | C15: =(B15-VAL_DATE)/365 | D15: =INDEX($K$8:$K$73,MATCH(B15,$K$8:$K$73,1)) | E15: =INDEX($K$8:$K$73,MATCH(B15,$K$8:$K$73,1)+1) | F15: =-LN(INDEX($L$8:$L$73,MATCH(B15,$K$8:$K$73,1)+1)/INDEX($L$8:$L$73,MATCH(B15,$K$8:$K$73,1)))/((E15-D15)/365)*100 | G15: =IFERROR(IF($J$7="Piecewise Linear (Simple)",IF(((B15-VAL_DATE)/360)<=0,1,1/(1+(IF(MAX((15>0)*(D15-VAL_DATE)/360,0)<=0,IF(((E15-VAL_DATE)/360)<=0,0,(1/INDEX($L$8:$L$73,MATCH(B15,$K$8:$K$73,1)+1)-1)/((E15-VAL_DATE)/360)),IF(MAX((15>0)*(D15-VAL_DATE)/360,0)<=0,0,(1/INDEX($L$8:$L$73,MATCH(B15,$K$8:$K$73,1))-1)/MAX((15>0)*(D15-VAL_DATE)/360,0)))+(IF(((E15-VAL_DATE)/360)<=0,0,(1/INDEX($L$8:$L$73,MATCH(B15,$K$8:$K$73,1)+1)-1)/((E15-VAL_DATE)/360))-IF(MAX((15>0)*(D15-VAL_DATE)/360,0)<=0,IF(((E15-VAL_DATE)/360)<=0,0,(1/INDEX($L$8:$L$73,MATCH(B15,$K$8:$K$73,1)+1)-1)/((E15-VAL_DATE)/360)),IF(MAX((15>0)*(D15-VAL_DATE)/360,0)<=0,0,(1/INDEX($L$8:$L$73,MATCH(B15,$K$8:$K$73,1))-1)/MAX((15>0)*(D15-VAL_DATE)/360,0))))*IF(((E15-VAL_DATE)/360)-MAX((15>0)*(D15-VAL_DATE)/360,0)=0,0,(((B15-VAL_DATE)/360)-MAX((15>0)*(D15-VAL_DATE)/360,0))/(((E15-VAL_DATE)/360)-MAX((15>0)*(D15-VAL_DATE)/360,0))))*((B15-VAL_DATE)/360))),INDEX($L$8:$L$73,MATCH(B15,$K$8:$K$73,1))*EXP(-(F15/100)*(B15-D15)/365)),"") | H15: =-LN(G15)/C15*100 | K15: ='[USD_SOFR_Curve_Bloomberg_Pricer.xlsx]Curve_Interface'!$K$16 | L15: ='[USD_SOFR_Curve_Bloomberg_Pricer.xlsx]Curve_Interface'!$L$16 | N15: =IF(O9=0,"LINK NOT RESOLVING - open USD_SOFR_Curve_Bloomberg_Pricer.xlsx",IF(ABS(O12-1)>0.000001,"ROW 8 IS NOT THE ANCHOR - check the offset",IF(O13-VAL_DATE>14,"FIRST TENOR LOOKS WRONG - expected about a week after the curve date",IF(O9<60,"FEWER PILLARS THAN EXPECTED - check the source range","link ok"))))
A16: 7 | B16: =EDATE($F$7,3*6) | C16: =(B16-VAL_DATE)/365 | D16: =INDEX($K$8:$K$73,MATCH(B16,$K$8:$K$73,1)) | E16: =INDEX($K$8:$K$73,MATCH(B16,$K$8:$K$73,1)+1) | F16: =-LN(INDEX($L$8:$L$73,MATCH(B16,$K$8:$K$73,1)+1)/INDEX($L$8:$L$73,MATCH(B16,$K$8:$K$73,1)))/((E16-D16)/365)*100 | G16: =IFERROR(IF($J$7="Piecewise Linear (Simple)",IF(((B16-VAL_DATE)/360)<=0,1,1/(1+(IF(MAX((16>0)*(D16-VAL_DATE)/360,0)<=0,IF(((E16-VAL_DATE)/360)<=0,0,(1/INDEX($L$8:$L$73,MATCH(B16,$K$8:$K$73,1)+1)-1)/((E16-VAL_DATE)/360)),IF(MAX((16>0)*(D16-VAL_DATE)/360,0)<=0,0,(1/INDEX($L$8:$L$73,MATCH(B16,$K$8:$K$73,1))-1)/MAX((16>0)*(D16-VAL_DATE)/360,0)))+(IF(((E16-VAL_DATE)/360)<=0,0,(1/INDEX($L$8:$L$73,MATCH(B16,$K$8:$K$73,1)+1)-1)/((E16-VAL_DATE)/360))-IF(MAX((16>0)*(D16-VAL_DATE)/360,0)<=0,IF(((E16-VAL_DATE)/360)<=0,0,(1/INDEX($L$8:$L$73,MATCH(B16,$K$8:$K$73,1)+1)-1)/((E16-VAL_DATE)/360)),IF(MAX((16>0)*(D16-VAL_DATE)/360,0)<=0,0,(1/INDEX($L$8:$L$73,MATCH(B16,$K$8:$K$73,1))-1)/MAX((16>0)*(D16-VAL_DATE)/360,0))))*IF(((E16-VAL_DATE)/360)-MAX((16>0)*(D16-VAL_DATE)/360,0)=0,0,(((B16-VAL_DATE)/360)-MAX((16>0)*(D16-VAL_DATE)/360,0))/(((E16-VAL_DATE)/360)-MAX((16>0)*(D16-VAL_DATE)/360,0))))*((B16-VAL_DATE)/360))),INDEX($L$8:$L$73,MATCH(B16,$K$8:$K$73,1))*EXP(-(F16/100)*(B16-D16)/365)),"") | H16: =-LN(G16)/C16*100 | K16: ='[USD_SOFR_Curve_Bloomberg_Pricer.xlsx]Curve_Interface'!$K$17 | L16: ='[USD_SOFR_Curve_Bloomberg_Pricer.xlsx]Curve_Interface'!$L$17 | N16: Live only while the curve workbook is OPEN. Closed, Excel serves the last cached values and the BDP pulls in the source do not refresh.
A17: 8 | B17: =EDATE($F$7,3*7) | C17: =(B17-VAL_DATE)/365 | D17: =INDEX($K$8:$K$73,MATCH(B17,$K$8:$K$73,1)) | E17: =INDEX($K$8:$K$73,MATCH(B17,$K$8:$K$73,1)+1) | F17: =-LN(INDEX($L$8:$L$73,MATCH(B17,$K$8:$K$73,1)+1)/INDEX($L$8:$L$73,MATCH(B17,$K$8:$K$73,1)))/((E17-D17)/365)*100 | G17: =IFERROR(IF($J$7="Piecewise Linear (Simple)",IF(((B17-VAL_DATE)/360)<=0,1,1/(1+(IF(MAX((17>0)*(D17-VAL_DATE)/360,0)<=0,IF(((E17-VAL_DATE)/360)<=0,0,(1/INDEX($L$8:$L$73,MATCH(B17,$K$8:$K$73,1)+1)-1)/((E17-VAL_DATE)/360)),IF(MAX((17>0)*(D17-VAL_DATE)/360,0)<=0,0,(1/INDEX($L$8:$L$73,MATCH(B17,$K$8:$K$73,1))-1)/MAX((17>0)*(D17-VAL_DATE)/360,0)))+(IF(((E17-VAL_DATE)/360)<=0,0,(1/INDEX($L$8:$L$73,MATCH(B17,$K$8:$K$73,1)+1)-1)/((E17-VAL_DATE)/360))-IF(MAX((17>0)*(D17-VAL_DATE)/360,0)<=0,IF(((E17-VAL_DATE)/360)<=0,0,(1/INDEX($L$8:$L$73,MATCH(B17,$K$8:$K$73,1)+1)-1)/((E17-VAL_DATE)/360)),IF(MAX((17>0)*(D17-VAL_DATE)/360,0)<=0,0,(1/INDEX($L$8:$L$73,MATCH(B17,$K$8:$K$73,1))-1)/MAX((17>0)*(D17-VAL_DATE)/360,0))))*IF(((E17-VAL_DATE)/360)-MAX((17>0)*(D17-VAL_DATE)/360,0)=0,0,(((B17-VAL_DATE)/360)-MAX((17>0)*(D17-VAL_DATE)/360,0))/(((E17-VAL_DATE)/360)-MAX((17>0)*(D17-VAL_DATE)/360,0))))*((B17-VAL_DATE)/360))),INDEX($L$8:$L$73,MATCH(B17,$K$8:$K$73,1))*EXP(-(F17/100)*(B17-D17)/365)),"") | H17: =-LN(G17)/C17*100 | K17: ='[USD_SOFR_Curve_Bloomberg_Pricer.xlsx]Curve_Interface'!$K$18 | L17: ='[USD_SOFR_Curve_Bloomberg_Pricer.xlsx]Curve_Interface'!$L$18 | N17: Live only while the curve workbook is OPEN. Closed, Excel serves the last cached values and the BDP pulls in the source do not refresh.
A18: 9 | B18: =EDATE($F$7,3*8) | C18: =(B18-VAL_DATE)/365 | D18: =INDEX($K$8:$K$73,MATCH(B18,$K$8:$K$73,1)) | E18: =INDEX($K$8:$K$73,MATCH(B18,$K$8:$K$73,1)+1) | F18: =-LN(INDEX($L$8:$L$73,MATCH(B18,$K$8:$K$73,1)+1)/INDEX($L$8:$L$73,MATCH(B18,$K$8:$K$73,1)))/((E18-D18)/365)*100 | G18: =IFERROR(IF($J$7="Piecewise Linear (Simple)",IF(((B18-VAL_DATE)/360)<=0,1,1/(1+(IF(MAX((18>0)*(D18-VAL_DATE)/360,0)<=0,IF(((E18-VAL_DATE)/360)<=0,0,(1/INDEX($L$8:$L$73,MATCH(B18,$K$8:$K$73,1)+1)-1)/((E18-VAL_DATE)/360)),IF(MAX((18>0)*(D18-VAL_DATE)/360,0)<=0,0,(1/INDEX($L$8:$L$73,MATCH(B18,$K$8:$K$73,1))-1)/MAX((18>0)*(D18-VAL_DATE)/360,0)))+(IF(((E18-VAL_DATE)/360)<=0,0,(1/INDEX($L$8:$L$73,MATCH(B18,$K$8:$K$73,1)+1)-1)/((E18-VAL_DATE)/360))-IF(MAX((18>0)*(D18-VAL_DATE)/360,0)<=0,IF(((E18-VAL_DATE)/360)<=0,0,(1/INDEX($L$8:$L$73,MATCH(B18,$K$8:$K$73,1)+1)-1)/((E18-VAL_DATE)/360)),IF(MAX((18>0)*(D18-VAL_DATE)/360,0)<=0,0,(1/INDEX($L$8:$L$73,MATCH(B18,$K$8:$K$73,1))-1)/MAX((18>0)*(D18-VAL_DATE)/360,0))))*IF(((E18-VAL_DATE)/360)-MAX((18>0)*(D18-VAL_DATE)/360,0)=0,0,(((B18-VAL_DATE)/360)-MAX((18>0)*(D18-VAL_DATE)/360,0))/(((E18-VAL_DATE)/360)-MAX((18>0)*(D18-VAL_DATE)/360,0))))*((B18-VAL_DATE)/360))),INDEX($L$8:$L$73,MATCH(B18,$K$8:$K$73,1))*EXP(-(F18/100)*(B18-D18)/365)),"") | H18: =-LN(G18)/C18*100 | K18: ='[USD_SOFR_Curve_Bloomberg_Pricer.xlsx]Curve_Interface'!$K$19 | L18: ='[USD_SOFR_Curve_Bloomberg_Pricer.xlsx]Curve_Interface'!$L$19 | N18: Data > Edit Links > Change Source if the file moves.
A19: 10 | B19: =EDATE($F$7,3*9) | C19: =(B19-VAL_DATE)/365 | D19: =INDEX($K$8:$K$73,MATCH(B19,$K$8:$K$73,1)) | E19: =INDEX($K$8:$K$73,MATCH(B19,$K$8:$K$73,1)+1) | F19: =-LN(INDEX($L$8:$L$73,MATCH(B19,$K$8:$K$73,1)+1)/INDEX($L$8:$L$73,MATCH(B19,$K$8:$K$73,1)))/((E19-D19)/365)*100 | G19: =IFERROR(IF($J$7="Piecewise Linear (Simple)",IF(((B19-VAL_DATE)/360)<=0,1,1/(1+(IF(MAX((19>0)*(D19-VAL_DATE)/360,0)<=0,IF(((E19-VAL_DATE)/360)<=0,0,(1/INDEX($L$8:$L$73,MATCH(B19,$K$8:$K$73,1)+1)-1)/((E19-VAL_DATE)/360)),IF(MAX((19>0)*(D19-VAL_DATE)/360,0)<=0,0,(1/INDEX($L$8:$L$73,MATCH(B19,$K$8:$K$73,1))-1)/MAX((19>0)*(D19-VAL_DATE)/360,0)))+(IF(((E19-VAL_DATE)/360)<=0,0,(1/INDEX($L$8:$L$73,MATCH(B19,$K$8:$K$73,1)+1)-1)/((E19-VAL_DATE)/360))-IF(MAX((19>0)*(D19-VAL_DATE)/360,0)<=0,IF(((E19-VAL_DATE)/360)<=0,0,(1/INDEX($L$8:$L$73,MATCH(B19,$K$8:$K$73,1)+1)-1)/((E19-VAL_DATE)/360)),IF(MAX((19>0)*(D19-VAL_DATE)/360,0)<=0,0,(1/INDEX($L$8:$L$73,MATCH(B19,$K$8:$K$73,1))-1)/MAX((19>0)*(D19-VAL_DATE)/360,0))))*IF(((E19-VAL_DATE)/360)-MAX((19>0)*(D19-VAL_DATE)/360,0)=0,0,(((B19-VAL_DATE)/360)-MAX((19>0)*(D19-VAL_DATE)/360,0))/(((E19-VAL_DATE)/360)-MAX((19>0)*(D19-VAL_DATE)/360,0))))*((B19-VAL_DATE)/360))),INDEX($L$8:$L$73,MATCH(B19,$K$8:$K$73,1))*EXP(-(F19/100)*(B19-D19)/365)),"") | H19: =-LN(G19)/C19*100 | K19: ='[USD_SOFR_Curve_Bloomberg_Pricer.xlsx]Curve_Interface'!$K$20 | L19: ='[USD_SOFR_Curve_Bloomberg_Pricer.xlsx]Curve_Interface'!$L$20
A20: 11 | B20: =EDATE($F$7,3*10) | C20: =(B20-VAL_DATE)/365 | D20: =INDEX($K$8:$K$73,MATCH(B20,$K$8:$K$73,1)) | E20: =INDEX($K$8:$K$73,MATCH(B20,$K$8:$K$73,1)+1) | F20: =-LN(INDEX($L$8:$L$73,MATCH(B20,$K$8:$K$73,1)+1)/INDEX($L$8:$L$73,MATCH(B20,$K$8:$K$73,1)))/((E20-D20)/365)*100 | G20: =IFERROR(IF($J$7="Piecewise Linear (Simple)",IF(((B20-VAL_DATE)/360)<=0,1,1/(1+(IF(MAX((20>0)*(D20-VAL_DATE)/360,0)<=0,IF(((E20-VAL_DATE)/360)<=0,0,(1/INDEX($L$8:$L$73,MATCH(B20,$K$8:$K$73,1)+1)-1)/((E20-VAL_DATE)/360)),IF(MAX((20>0)*(D20-VAL_DATE)/360,0)<=0,0,(1/INDEX($L$8:$L$73,MATCH(B20,$K$8:$K$73,1))-1)/MAX((20>0)*(D20-VAL_DATE)/360,0)))+(IF(((E20-VAL_DATE)/360)<=0,0,(1/INDEX($L$8:$L$73,MATCH(B20,$K$8:$K$73,1)+1)-1)/((E20-VAL_DATE)/360))-IF(MAX((20>0)*(D20-VAL_DATE)/360,0)<=0,IF(((E20-VAL_DATE)/360)<=0,0,(1/INDEX($L$8:$L$73,MATCH(B20,$K$8:$K$73,1)+1)-1)/((E20-VAL_DATE)/360)),IF(MAX((20>0)*(D20-VAL_DATE)/360,0)<=0,0,(1/INDEX($L$8:$L$73,MATCH(B20,$K$8:$K$73,1))-1)/MAX((20>0)*(D20-VAL_DATE)/360,0))))*IF(((E20-VAL_DATE)/360)-MAX((20>0)*(D20-VAL_DATE)/360,0)=0,0,(((B20-VAL_DATE)/360)-MAX((20>0)*(D20-VAL_DATE)/360,0))/(((E20-VAL_DATE)/360)-MAX((20>0)*(D20-VAL_DATE)/360,0))))*((B20-VAL_DATE)/360))),INDEX($L$8:$L$73,MATCH(B20,$K$8:$K$73,1))*EXP(-(F20/100)*(B20-D20)/365)),"") | H20: =-LN(G20)/C20*100 | K20: ='[USD_SOFR_Curve_Bloomberg_Pricer.xlsx]Curve_Interface'!$K$21 | L20: ='[USD_SOFR_Curve_Bloomberg_Pricer.xlsx]Curve_Interface'!$L$21
A21: 12 | B21: =EDATE($F$7,3*11) | C21: =(B21-VAL_DATE)/365 | D21: =INDEX($K$8:$K$73,MATCH(B21,$K$8:$K$73,1)) | E21: =INDEX($K$8:$K$73,MATCH(B21,$K$8:$K$73,1)+1) | F21: =-LN(INDEX($L$8:$L$73,MATCH(B21,$K$8:$K$73,1)+1)/INDEX($L$8:$L$73,MATCH(B21,$K$8:$K$73,1)))/((E21-D21)/365)*100 | G21: =IFERROR(IF($J$7="Piecewise Linear (Simple)",IF(((B21-VAL_DATE)/360)<=0,1,1/(1+(IF(MAX((21>0)*(D21-VAL_DATE)/360,0)<=0,IF(((E21-VAL_DATE)/360)<=0,0,(1/INDEX($L$8:$L$73,MATCH(B21,$K$8:$K$73,1)+1)-1)/((E21-VAL_DATE)/360)),IF(MAX((21>0)*(D21-VAL_DATE)/360,0)<=0,0,(1/INDEX($L$8:$L$73,MATCH(B21,$K$8:$K$73,1))-1)/MAX((21>0)*(D21-VAL_DATE)/360,0)))+(IF(((E21-VAL_DATE)/360)<=0,0,(1/INDEX($L$8:$L$73,MATCH(B21,$K$8:$K$73,1)+1)-1)/((E21-VAL_DATE)/360))-IF(MAX((21>0)*(D21-VAL_DATE)/360,0)<=0,IF(((E21-VAL_DATE)/360)<=0,0,(1/INDEX($L$8:$L$73,MATCH(B21,$K$8:$K$73,1)+1)-1)/((E21-VAL_DATE)/360)),IF(MAX((21>0)*(D21-VAL_DATE)/360,0)<=0,0,(1/INDEX($L$8:$L$73,MATCH(B21,$K$8:$K$73,1))-1)/MAX((21>0)*(D21-VAL_DATE)/360,0))))*IF(((E21-VAL_DATE)/360)-MAX((21>0)*(D21-VAL_DATE)/360,0)=0,0,(((B21-VAL_DATE)/360)-MAX((21>0)*(D21-VAL_DATE)/360,0))/(((E21-VAL_DATE)/360)-MAX((21>0)*(D21-VAL_DATE)/360,0))))*((B21-VAL_DATE)/360))),INDEX($L$8:$L$73,MATCH(B21,$K$8:$K$73,1))*EXP(-(F21/100)*(B21-D21)/365)),"") | H21: =-LN(G21)/C21*100 | K21: ='[USD_SOFR_Curve_Bloomberg_Pricer.xlsx]Curve_Interface'!$K$22 | L21: ='[USD_SOFR_Curve_Bloomberg_Pricer.xlsx]Curve_Interface'!$L$22
A22: 13 | B22: =EDATE($F$7,3*12) | C22: =(B22-VAL_DATE)/365 | D22: =INDEX($K$8:$K$73,MATCH(B22,$K$8:$K$73,1)) | E22: =INDEX($K$8:$K$73,MATCH(B22,$K$8:$K$73,1)+1) | F22: =-LN(INDEX($L$8:$L$73,MATCH(B22,$K$8:$K$73,1)+1)/INDEX($L$8:$L$73,MATCH(B22,$K$8:$K$73,1)))/((E22-D22)/365)*100 | G22: =IFERROR(IF($J$7="Piecewise Linear (Simple)",IF(((B22-VAL_DATE)/360)<=0,1,1/(1+(IF(MAX((22>0)*(D22-VAL_DATE)/360,0)<=0,IF(((E22-VAL_DATE)/360)<=0,0,(1/INDEX($L$8:$L$73,MATCH(B22,$K$8:$K$73,1)+1)-1)/((E22-VAL_DATE)/360)),IF(MAX((22>0)*(D22-VAL_DATE)/360,0)<=0,0,(1/INDEX($L$8:$L$73,MATCH(B22,$K$8:$K$73,1))-1)/MAX((22>0)*(D22-VAL_DATE)/360,0)))+(IF(((E22-VAL_DATE)/360)<=0,0,(1/INDEX($L$8:$L$73,MATCH(B22,$K$8:$K$73,1)+1)-1)/((E22-VAL_DATE)/360))-IF(MAX((22>0)*(D22-VAL_DATE)/360,0)<=0,IF(((E22-VAL_DATE)/360)<=0,0,(1/INDEX($L$8:$L$73,MATCH(B22,$K$8:$K$73,1)+1)-1)/((E22-VAL_DATE)/360)),IF(MAX((22>0)*(D22-VAL_DATE)/360,0)<=0,0,(1/INDEX($L$8:$L$73,MATCH(B22,$K$8:$K$73,1))-1)/MAX((22>0)*(D22-VAL_DATE)/360,0))))*IF(((E22-VAL_DATE)/360)-MAX((22>0)*(D22-VAL_DATE)/360,0)=0,0,(((B22-VAL_DATE)/360)-MAX((22>0)*(D22-VAL_DATE)/360,0))/(((E22-VAL_DATE)/360)-MAX((22>0)*(D22-VAL_DATE)/360,0))))*((B22-VAL_DATE)/360))),INDEX($L$8:$L$73,MATCH(B22,$K$8:$K$73,1))*EXP(-(F22/100)*(B22-D22)/365)),"") | H22: =-LN(G22)/C22*100 | K22: ='[USD_SOFR_Curve_Bloomberg_Pricer.xlsx]Curve_Interface'!$K$23 | L22: ='[USD_SOFR_Curve_Bloomberg_Pricer.xlsx]Curve_Interface'!$L$23
