Workbook

Sheet Quotes
A1: KRW IRS (Kevin grid, 8Y/9Y dropped)
A2: tau | B2: 0.25
A4: Tenor | B4: Coupon | C4: Year
A5: 3Mo | B5: 0.0291 | C5: 0.25
A6: 6Mo | B6: 0.03125 | C6: 0.5
A7: 9Mo | B7: 0.03315 | C7: 0.75
A8: 1Yr | B8: 0.034675 | C8: 1
A9: 2Yr | B9: 0.03825 | C9: 2
A10: 3Yr | B10: 0.03965 | C10: 3
A11: 4Yr | B11: 0.04029 | C11: 4
A12: 5Yr | B12: 0.040775 | C12: 5
A13: 7Yr | B13: 0.041425 | C13: 7
A14: 10Yr | B14: 0.042 | C14: 10
A15: 15Yr | B15: 0.041775 | C15: 15
A16: 20Yr | B16: 0.04075 | C16: 20
A17: 30Yr | B17: 0.03845 | C17: 30

Sheet Interpolation
A1: Year | B1: Swap % | C1: Helper
A2: 0.25 | B2: =INDEX(Quotes!$B$5:$B$17,C2)+(A2-INDEX(Quotes!$C$5:$C$17,C2))/(INDEX(Quotes!$C$5:$C$17,C2+1)-INDEX(Quotes!$C$5:$C$17,C2))*(INDEX(Quotes!$B$5:$B$17,C2+1)-INDEX(Quotes!$B$5:$B$17,C2)) | C2: =MIN(MATCH(A2,Quotes!$C$5:$C$17,1),12)
A3: 0.5 | B3: =INDEX(Quotes!$B$5:$B$17,C3)+(A3-INDEX(Quotes!$C$5:$C$17,C3))/(INDEX(Quotes!$C$5:$C$17,C3+1)-INDEX(Quotes!$C$5:$C$17,C3))*(INDEX(Quotes!$B$5:$B$17,C3+1)-INDEX(Quotes!$B$5:$B$17,C3)) | C3: =MIN(MATCH(A3,Quotes!$C$5:$C$17,1),12)
A4: 0.75 | B4: =INDEX(Quotes!$B$5:$B$17,C4)+(A4-INDEX(Quotes!$C$5:$C$17,C4))/(INDEX(Quotes!$C$5:$C$17,C4+1)-INDEX(Quotes!$C$5:$C$17,C4))*(INDEX(Quotes!$B$5:$B$17,C4+1)-INDEX(Quotes!$B$5:$B$17,C4)) | C4: =MIN(MATCH(A4,Quotes!$C$5:$C$17,1),12)
A5: 1 | B5: =INDEX(Quotes!$B$5:$B$17,C5)+(A5-INDEX(Quotes!$C$5:$C$17,C5))/(INDEX(Quotes!$C$5:$C$17,C5+1)-INDEX(Quotes!$C$5:$C$17,C5))*(INDEX(Quotes!$B$5:$B$17,C5+1)-INDEX(Quotes!$B$5:$B$17,C5)) | C5: =MIN(MATCH(A5,Quotes!$C$5:$C$17,1),12)
A6: 1.25 | B6: =INDEX(Quotes!$B$5:$B$17,C6)+(A6-INDEX(Quotes!$C$5:$C$17,C6))/(INDEX(Quotes!$C$5:$C$17,C6+1)-INDEX(Quotes!$C$5:$C$17,C6))*(INDEX(Quotes!$B$5:$B$17,C6+1)-INDEX(Quotes!$B$5:$B$17,C6)) | C6: =MIN(MATCH(A6,Quotes!$C$5:$C$17,1),12)
A7: 1.5 | B7: =INDEX(Quotes!$B$5:$B$17,C7)+(A7-INDEX(Quotes!$C$5:$C$17,C7))/(INDEX(Quotes!$C$5:$C$17,C7+1)-INDEX(Quotes!$C$5:$C$17,C7))*(INDEX(Quotes!$B$5:$B$17,C7+1)-INDEX(Quotes!$B$5:$B$17,C7)) | C7: =MIN(MATCH(A7,Quotes!$C$5:$C$17,1),12)
A8: 1.75 | B8: =INDEX(Quotes!$B$5:$B$17,C8)+(A8-INDEX(Quotes!$C$5:$C$17,C8))/(INDEX(Quotes!$C$5:$C$17,C8+1)-INDEX(Quotes!$C$5:$C$17,C8))*(INDEX(Quotes!$B$5:$B$17,C8+1)-INDEX(Quotes!$B$5:$B$17,C8)) | C8: =MIN(MATCH(A8,Quotes!$C$5:$C$17,1),12)
A9: 2 | B9: =INDEX(Quotes!$B$5:$B$17,C9)+(A9-INDEX(Quotes!$C$5:$C$17,C9))/(INDEX(Quotes!$C$5:$C$17,C9+1)-INDEX(Quotes!$C$5:$C$17,C9))*(INDEX(Quotes!$B$5:$B$17,C9+1)-INDEX(Quotes!$B$5:$B$17,C9)) | C9: =MIN(MATCH(A9,Quotes!$C$5:$C$17,1),12)
A10: 2.25 | B10: =INDEX(Quotes!$B$5:$B$17,C10)+(A10-INDEX(Quotes!$C$5:$C$17,C10))/(INDEX(Quotes!$C$5:$C$17,C10+1)-INDEX(Quotes!$C$5:$C$17,C10))*(INDEX(Quotes!$B$5:$B$17,C10+1)-INDEX(Quotes!$B$5:$B$17,C10)) | C10: =MIN(MATCH(A10,Quotes!$C$5:$C$17,1),12)
A11: 2.5 | B11: =INDEX(Quotes!$B$5:$B$17,C11)+(A11-INDEX(Quotes!$C$5:$C$17,C11))/(INDEX(Quotes!$C$5:$C$17,C11+1)-INDEX(Quotes!$C$5:$C$17,C11))*(INDEX(Quotes!$B$5:$B$17,C11+1)-INDEX(Quotes!$B$5:$B$17,C11)) | C11: =MIN(MATCH(A11,Quotes!$C$5:$C$17,1),12)
A12: 2.75 | B12: =INDEX(Quotes!$B$5:$B$17,C12)+(A12-INDEX(Quotes!$C$5:$C$17,C12))/(INDEX(Quotes!$C$5:$C$17,C12+1)-INDEX(Quotes!$C$5:$C$17,C12))*(INDEX(Quotes!$B$5:$B$17,C12+1)-INDEX(Quotes!$B$5:$B$17,C12)) | C12: =MIN(MATCH(A12,Quotes!$C$5:$C$17,1),12)
A13: 3 | B13: =INDEX(Quotes!$B$5:$B$17,C13)+(A13-INDEX(Quotes!$C$5:$C$17,C13))/(INDEX(Quotes!$C$5:$C$17,C13+1)-INDEX(Quotes!$C$5:$C$17,C13))*(INDEX(Quotes!$B$5:$B$17,C13+1)-INDEX(Quotes!$B$5:$B$17,C13)) | C13: =MIN(MATCH(A13,Quotes!$C$5:$C$17,1),12)
... A121: 30 | B121: =INDEX(Quotes!$B$5:$B$17,C121)+(A121-INDEX(Quotes!$C$5:$C$17,C121))/(INDEX(Quotes!$C$5:$C$17,C121+1)-INDEX(Quotes!$C$5:$C$17,C121))*(INDEX(Quotes!$B$5:$B$17,C121+1)-INDEX(Quotes!$B$5:$B$17,C121)) | C121: =MIN(MATCH(A121,Quotes!$C$5:$C$17,1),12)

Sheet Bootstrap
A2: Year | B2: Swap % | C2: DF | D2: Zero % | E2: Future %
A3: =Interpolation!A2 | B3: =Interpolation!B2 | C3: =1/(1+B3*Quotes!$B$2) | D3: =(1/C3-1)/A3 | E3: =(1/C3-1)/Quotes!$B$2
A4: =Interpolation!A3 | B4: =Interpolation!B3 | C4: =(1-B4*Quotes!$B$2*SUM($C$3:C3))/(1+B4*Quotes!$B$2) | D4: =(1/C4-1)/A4 | E4: =(C3/C4-1)/Quotes!$B$2
A5: =Interpolation!A4 | B5: =Interpolation!B4 | C5: =(1-B5*Quotes!$B$2*SUM($C$3:C4))/(1+B5*Quotes!$B$2) | D5: =(1/C5-1)/A5 | E5: =(C4/C5-1)/Quotes!$B$2
A6: =Interpolation!A5 | B6: =Interpolation!B5 | C6: =(1-B6*Quotes!$B$2*SUM($C$3:C5))/(1+B6*Quotes!$B$2) | D6: =(1/C6-1)/A6 | E6: =(C5/C6-1)/Quotes!$B$2
A7: =Interpolation!A6 | B7: =Interpolation!B6 | C7: =(1-B7*Quotes!$B$2*SUM($C$3:C6))/(1+B7*Quotes!$B$2) | D7: =(1/C7-1)/A7 | E7: =(C6/C7-1)/Quotes!$B$2
A8: =Interpolation!A7 | B8: =Interpolation!B7 | C8: =(1-B8*Quotes!$B$2*SUM($C$3:C7))/(1+B8*Quotes!$B$2) | D8: =(1/C8-1)/A8 | E8: =(C7/C8-1)/Quotes!$B$2
A9: =Interpolation!A8 | B9: =Interpolation!B8 | C9: =(1-B9*Quotes!$B$2*SUM($C$3:C8))/(1+B9*Quotes!$B$2) | D9: =(1/C9-1)/A9 | E9: =(C8/C9-1)/Quotes!$B$2
A10: =Interpolation!A9 | B10: =Interpolation!B9 | C10: =(1-B10*Quotes!$B$2*SUM($C$3:C9))/(1+B10*Quotes!$B$2) | D10: =(1/C10-1)/A10 | E10: =(C9/C10-1)/Quotes!$B$2
A11: =Interpolation!A10 | B11: =Interpolation!B10 | C11: =(1-B11*Quotes!$B$2*SUM($C$3:C10))/(1+B11*Quotes!$B$2) | D11: =(1/C11-1)/A11 | E11: =(C10/C11-1)/Quotes!$B$2
A12: =Interpolation!A11 | B12: =Interpolation!B11 | C12: =(1-B12*Quotes!$B$2*SUM($C$3:C11))/(1+B12*Quotes!$B$2) | D12: =(1/C12-1)/A12 | E12: =(C11/C12-1)/Quotes!$B$2
A13: =Interpolation!A12 | B13: =Interpolation!B12 | C13: =(1-B13*Quotes!$B$2*SUM($C$3:C12))/(1+B13*Quotes!$B$2) | D13: =(1/C13-1)/A13 | E13: =(C12/C13-1)/Quotes!$B$2
A14: =Interpolation!A13 | B14: =Interpolation!B13 | C14: =(1-B14*Quotes!$B$2*SUM($C$3:C13))/(1+B14*Quotes!$B$2) | D14: =(1/C14-1)/A14 | E14: =(C13/C14-1)/Quotes!$B$2
A15: =Interpolation!A14 | B15: =Interpolation!B14 | C15: =(1-B15*Quotes!$B$2*SUM($C$3:C14))/(1+B15*Quotes!$B$2) | D15: =(1/C15-1)/A15 | E15: =(C14/C15-1)/Quotes!$B$2
... A122: =Interpolation!A121 | B122: =Interpolation!B121 | C122: =(1-B122*Quotes!$B$2*SUM($C$3:C121))/(1+B122*Quotes!$B$2) | D122: =(1/C122-1)/A122 | E122: =(C121/C122-1)/Quotes!$B$2

Sheet Amort-Set-up
A1: Amortising IRS
A5: Start | B5: =DATE(2026,7,27)
A11: Solved par | B11: =SUMPRODUCT($E$20:$E$59,$F$20:$F$59,$D$20:$D$59)/SUMPRODUCT($E$20:$E$59,$D$20:$D$59)
A12: Trade fixed rate | B12: =B11
A15: Fixed leg PV | B15: =SUM($J$20:$J$59)
A16: Float leg PV | B16: =SUM($K$20:$K$59)
A17: NPV | B17: =B15-B16
A19: Period | B19: Start | C19: End | D19: DF | E19: Notional | F19: Forward % | G19: Fixed CF | H19: Float CF | J19: PV fixed | K19: PV float
A20: 1 | B20: =EDATE($B$5,3*0) | C20: =EDATE($B$5,3*1) | D20: =Bootstrap!C3 | E20: 10000000000 | F20: =Bootstrap!E3 | G20: =E20*$B$12*Quotes!$B$2 | H20: =E20*F20*Quotes!$B$2 | J20: =G20*D20 | K20: =H20*D20
A21: 2 | B21: =EDATE($B$5,3*1) | C21: =EDATE($B$5,3*2) | D21: =Bootstrap!C4 | E21: 10000000000 | F21: =Bootstrap!E4 | G21: =E21*$B$12*Quotes!$B$2 | H21: =E21*F21*Quotes!$B$2 | J21: =G21*D21 | K21: =H21*D21
A22: 3 | B22: =EDATE($B$5,3*2) | C22: =EDATE($B$5,3*3) | D22: =Bootstrap!C5 | E22: 10000000000 | F22: =Bootstrap!E5 | G22: =E22*$B$12*Quotes!$B$2 | H22: =E22*F22*Quotes!$B$2 | J22: =G22*D22 | K22: =H22*D22
A23: 4 | B23: =EDATE($B$5,3*3) | C23: =EDATE($B$5,3*4) | D23: =Bootstrap!C6 | E23: 10000000000 | F23: =Bootstrap!E6 | G23: =E23*$B$12*Quotes!$B$2 | H23: =E23*F23*Quotes!$B$2 | J23: =G23*D23 | K23: =H23*D23
A24: 5 | B24: =EDATE($B$5,3*4) | C24: =EDATE($B$5,3*5) | D24: =Bootstrap!C7 | E24: 30000000000 | F24: =Bootstrap!E7 | G24: =E24*$B$12*Quotes!$B$2 | H24: =E24*F24*Quotes!$B$2 | J24: =G24*D24 | K24: =H24*D24
A25: 6 | B25: =EDATE($B$5,3*5) | C25: =EDATE($B$5,3*6) | D25: =Bootstrap!C8 | E25: 30000000000 | F25: =Bootstrap!E8 | G25: =E25*$B$12*Quotes!$B$2 | H25: =E25*F25*Quotes!$B$2 | J25: =G25*D25 | K25: =H25*D25
A26: 7 | B26: =EDATE($B$5,3*6) | C26: =EDATE($B$5,3*7) | D26: =Bootstrap!C9 | E26: 30000000000 | F26: =Bootstrap!E9 | G26: =E26*$B$12*Quotes!$B$2 | H26: =E26*F26*Quotes!$B$2 | J26: =G26*D26 | K26: =H26*D26
A27: 8 | B27: =EDATE($B$5,3*7) | C27: =EDATE($B$5,3*8) | D27: =Bootstrap!C10 | E27: 30000000000 | F27: =Bootstrap!E10 | G27: =E27*$B$12*Quotes!$B$2 | H27: =E27*F27*Quotes!$B$2 | J27: =G27*D27 | K27: =H27*D27
A28: 9 | B28: =EDATE($B$5,3*8) | C28: =EDATE($B$5,3*9) | D28: =Bootstrap!C11 | E28: 60000000000 | F28: =Bootstrap!E11 | G28: =E28*$B$12*Quotes!$B$2 | H28: =E28*F28*Quotes!$B$2 | J28: =G28*D28 | K28: =H28*D28
A29: 10 | B29: =EDATE($B$5,3*9) | C29: =EDATE($B$5,3*10) | D29: =Bootstrap!C12 | E29: 60000000000 | F29: =Bootstrap!E12 | G29: =E29*$B$12*Quotes!$B$2 | H29: =E29*F29*Quotes!$B$2 | J29: =G29*D29 | K29: =H29*D29
A30: 11 | B30: =EDATE($B$5,3*10) | C30: =EDATE($B$5,3*11) | D30: =Bootstrap!C13 | E30: 60000000000 | F30: =Bootstrap!E13 | G30: =E30*$B$12*Quotes!$B$2 | H30: =E30*F30*Quotes!$B$2 | J30: =G30*D30 | K30: =H30*D30
A31: 12 | B31: =EDATE($B$5,3*11) | C31: =EDATE($B$5,3*12) | D31: =Bootstrap!C14 | E31: 60000000000 | F31: =Bootstrap!E14 | G31: =E31*$B$12*Quotes!$B$2 | H31: =E31*F31*Quotes!$B$2 | J31: =G31*D31 | K31: =H31*D31
A32: 13 | B32: =EDATE($B$5,3*12) | C32: =EDATE($B$5,3*13) | D32: =Bootstrap!C15 | E32: 100000000000 | F32: =Bootstrap!E15 | G32: =E32*$B$12*Quotes!$B$2 | H32: =E32*F32*Quotes!$B$2 | J32: =G32*D32 | K32: =H32*D32
A33: 14 | B33: =EDATE($B$5,3*13) | C33: =EDATE($B$5,3*14) | D33: =Bootstrap!C16 | E33: 100000000000 | F33: =Bootstrap!E16 | G33: =E33*$B$12*Quotes!$B$2 | H33: =E33*F33*Quotes!$B$2 | J33: =G33*D33 | K33: =H33*D33
A34: 15 | B34: =EDATE($B$5,3*14) | C34: =EDATE($B$5,3*15) | D34: =Bootstrap!C17 | E34: 100000000000 | F34: =Bootstrap!E17 | G34: =E34*$B$12*Quotes!$B$2 | H34: =E34*F34*Quotes!$B$2 | J34: =G34*D34 | K34: =H34*D34
A35: 16 | B35: =EDATE($B$5,3*15) | C35: =EDATE($B$5,3*16) | D35: =Bootstrap!C18 | E35: 100000000000 | F35: =Bootstrap!E18 | G35: =E35*$B$12*Quotes!$B$2 | H35: =E35*F35*Quotes!$B$2 | J35: =G35*D35 | K35: =H35*D35
A36: 17 | B36: =EDATE($B$5,3*16) | C36: =EDATE($B$5,3*17) | D36: =Bootstrap!C19 | E36: 80000000000 | F36: =Bootstrap!E19 | G36: =E36*$B$12*Quotes!$B$2 | H36: =E36*F36*Quotes!$B$2 | J36: =G36*D36 | K36: =H36*D36
A37: 18 | B37: =EDATE($B$5,3*17) | C37: =EDATE($B$5,3*18) | D37: =Bootstrap!C20 | E37: 80000000000 | F37: =Bootstrap!E20 | G37: =E37*$B$12*Quotes!$B$2 | H37: =E37*F37*Quotes!$B$2 | J37: =G37*D37 | K37: =H37*D37
A38: 19 | B38: =EDATE($B$5,3*18) | C38: =EDATE($B$5,3*19) | D38: =Bootstrap!C21 | E38: 80000000000 | F38: =Bootstrap!E21 | G38: =E38*$B$12*Quotes!$B$2 | H38: =E38*F38*Quotes!$B$2 | J38: =G38*D38 | K38: =H38*D38
A39: 20 | B39: =EDATE($B$5,3*19) | C39: =EDATE($B$5,3*20) | D39: =Bootstrap!C22 | E39: 80000000000 | F39: =Bootstrap!E22 | G39: =E39*$B$12*Quotes!$B$2 | H39: =E39*F39*Quotes!$B$2 | J39: =G39*D39 | K39: =H39*D39
A40: 21 | B40: =EDATE($B$5,3*20) | C40: =EDATE($B$5,3*21) | D40: =Bootstrap!C23 | E40: 60000000000 | F40: =Bootstrap!E23 | G40: =E40*$B$12*Quotes!$B$2 | H40: =E40*F40*Quotes!$B$2 | J40: =G40*D40 | K40: =H40*D40
A41: 22 | B41: =EDATE($B$5,3*21) | C41: =EDATE($B$5,3*22) | D41: =Bootstrap!C24 | E41: 60000000000 | F41: =Bootstrap!E24 | G41: =E41*$B$12*Quotes!$B$2 | H41: =E41*F41*Quotes!$B$2 | J41: =G41*D41 | K41: =H41*D41
A42: 23 | B42: =EDATE($B$5,3*22) | C42: =EDATE($B$5,3*23) | D42: =Bootstrap!C25 | E42: 60000000000 | F42: =Bootstrap!E25 | G42: =E42*$B$12*Quotes!$B$2 | H42: =E42*F42*Quotes!$B$2 | J42: =G42*D42 | K42: =H42*D42
A43: 24 | B43: =EDATE($B$5,3*23) | C43: =EDATE($B$5,3*24) | D43: =Bootstrap!C26 | E43: 60000000000 | F43: =Bootstrap!E26 | G43: =E43*$B$12*Quotes!$B$2 | H43: =E43*F43*Quotes!$B$2 | J43: =G43*D43 | K43: =H43*D43
A44: 25 | B44: =EDATE($B$5,3*24) | C44: =EDATE($B$5,3*25) | D44: =Bootstrap!C27 | E44: 50000000000 | F44: =Bootstrap!E27 | G44: =E44*$B$12*Quotes!$B$2 | H44: =E44*F44*Quotes!$B$2 | J44: =G44*D44 | K44: =H44*D44
A45: 26 | B45: =EDATE($B$5,3*25) | C45: =EDATE($B$5,3*26) | D45: =Bootstrap!C28 | E45: 50000000000 | F45: =Bootstrap!E28 | G45: =E45*$B$12*Quotes!$B$2 | H45: =E45*F45*Quotes!$B$2 | J45: =G45*D45 | K45: =H45*D45
A46: 27 | B46: =EDATE($B$5,3*26) | C46: =EDATE($B$5,3*27) | D46: =Bootstrap!C29 | E46: 50000000000 | F46: =Bootstrap!E29 | G46: =E46*$B$12*Quotes!$B$2 | H46: =E46*F46*Quotes!$B$2 | J46: =G46*D46 | K46: =H46*D46
A47: 28 | B47: =EDATE($B$5,3*27) | C47: =EDATE($B$5,3*28) | D47: =Bootstrap!C30 | E47: 50000000000 | F47: =Bootstrap!E30 | G47: =E47*$B$12*Quotes!$B$2 | H47: =E47*F47*Quotes!$B$2 | J47: =G47*D47 | K47: =H47*D47
A48: 29 | B48: =EDATE($B$5,3*28) | C48: =EDATE($B$5,3*29) | D48: =Bootstrap!C31 | E48: 50000000000 | F48: =Bootstrap!E31 | G48: =E48*$B$12*Quotes!$B$2 | H48: =E48*F48*Quotes!$B$2 | J48: =G48*D48 | K48: =H48*D48
A49: 30 | B49: =EDATE($B$5,3*29) | C49: =EDATE($B$5,3*30) | D49: =Bootstrap!C32 | E49: 50000000000 | F49: =Bootstrap!E32 | G49: =E49*$B$12*Quotes!$B$2 | H49: =E49*F49*Quotes!$B$2 | J49: =G49*D49 | K49: =H49*D49
A50: 31 | B50: =EDATE($B$5,3*30) | C50: =EDATE($B$5,3*31) | D50: =Bootstrap!C33 | E50: 50000000000 | F50: =Bootstrap!E33 | G50: =E50*$B$12*Quotes!$B$2 | H50: =E50*F50*Quotes!$B$2 | J50: =G50*D50 | K50: =H50*D50
A51: 32 | B51: =EDATE($B$5,3*31) | C51: =EDATE($B$5,3*32) | D51: =Bootstrap!C34 | E51: 50000000000 | F51: =Bootstrap!E34 | G51: =E51*$B$12*Quotes!$B$2 | H51: =E51*F51*Quotes!$B$2 | J51: =G51*D51 | K51: =H51*D51
...

Sheet KRD
A1: Bucketed key-rate delta (Kevin grid)
D3: ='Amort-Set-up'!$B$12
E4: =Quotes!$B$2
A6: Tenor | B6: Year | C6: Base
A7: =Quotes!A5 | B7: =Quotes!C5 | C7: =Quotes!B5 | D7: =$C7 | E7: =$C7+0.0001 | F7: =$C7 | G7: =$C7 | H7: =$C7 | I7: =$C7 | J7: =$C7 | K7: =$C7 | L7: =$C7 | M7: =$C7 | N7: =$C7
A8: =Quotes!A6 | B8: =Quotes!C6 | C8: =Quotes!B6 | D8: =$C8 | E8: =$C8 | F8: =$C8+0.0001 | G8: =$C8 | H8: =$C8 | I8: =$C8 | J8: =$C8 | K8: =$C8 | L8: =$C8 | M8: =$C8 | N8: =$C8
A9: =Quotes!A7 | B9: =Quotes!C7 | C9: =Quotes!B7 | D9: =$C9 | E9: =$C9 | F9: =$C9 | G9: =$C9+0.0001 | H9: =$C9 | I9: =$C9 | J9: =$C9 | K9: =$C9 | L9: =$C9 | M9: =$C9 | N9: =$C9
A10: =Quotes!A8 | B10: =Quotes!C8 | C10: =Quotes!B8 | D10: =$C10 | E10: =$C10 | F10: =$C10 | G10: =$C10 | H10: =$C10+0.0001 | I10: =$C10 | J10: =$C10 | K10: =$C10 | L10: =$C10 | M10: =$C10 | N10: =$C10
A11: =Quotes!A9 | B11: =Quotes!C9 | C11: =Quotes!B9 | D11: =$C11 | E11: =$C11 | F11: =$C11 | G11: =$C11 | H11: =$C11 | I11: =$C11+0.0001 | J11: =$C11 | K11: =$C11 | L11: =$C11 | M11: =$C11 | N11: =$C11
A12: =Quotes!A10 | B12: =Quotes!C10 | C12: =Quotes!B10 | D12: =$C12 | E12: =$C12 | F12: =$C12 | G12: =$C12 | H12: =$C12 | I12: =$C12 | J12: =$C12+0.0001 | K12: =$C12 | L12: =$C12 | M12: =$C12 | N12: =$C12
A13: =Quotes!A11 | B13: =Quotes!C11 | C13: =Quotes!B11 | D13: =$C13 | E13: =$C13 | F13: =$C13 | G13: =$C13 | H13: =$C13 | I13: =$C13 | J13: =$C13 | K13: =$C13+0.0001 | L13: =$C13 | M13: =$C13 | N13: =$C13
A14: =Quotes!A12 | B14: =Quotes!C12 | C14: =Quotes!B12 | D14: =$C14 | E14: =$C14 | F14: =$C14 | G14: =$C14 | H14: =$C14 | I14: =$C14 | J14: =$C14 | K14: =$C14 | L14: =$C14+0.0001 | M14: =$C14 | N14: =$C14
A15: =Quotes!A13 | B15: =Quotes!C13 | C15: =Quotes!B13 | D15: =$C15 | E15: =$C15 | F15: =$C15 | G15: =$C15 | H15: =$C15 | I15: =$C15 | J15: =$C15 | K15: =$C15 | L15: =$C15 | M15: =$C15+0.0001 | N15: =$C15
A16: =Quotes!A14 | B16: =Quotes!C14 | C16: =Quotes!B14 | D16: =$C16 | E16: =$C16 | F16: =$C16 | G16: =$C16 | H16: =$C16 | I16: =$C16 | J16: =$C16 | K16: =$C16 | ... M16: =$C16 | N16: =$C16+0.0001
A17: =Quotes!A15 | B17: =Quotes!C15 | C17: =Quotes!B15 | D17: =$C17 | E17: =$C17 | F17: =$C17 | G17: =$C17 | H17: =$C17 | I17: =$C17 | J17: =$C17 | K17: =$C17 | ... N17: =$C17
A18: =Quotes!A16 | B18: =Quotes!C16 | C18: =Quotes!B16 | D18: =$C18 | E18: =$C18 | F18: =$C18 | G18: =$C18 | H18: =$C18 | I18: =$C18 | J18: =$C18 | K18: =$C18 | ... N18: =$C18
A19: =Quotes!A17 | B19: =Quotes!C17 | C19: =Quotes!B17 | D19: =$C19 | E19: =$C19 | F19: =$C19 | G19: =$C19 | H19: =$C19 | I19: =$C19 | J19: =$C19 | K19: =$C19 | ... N19: =$C19
A24: Qtr | B24: Year | C24: m | D24: w | E24: Notional | F24: 1 | G24: 2 | H24: 3 | I24: 4 | J24: 5 | K24: 6 | L24: 7 | M24: 8 | N24: 9 | O24: 10 | P24: 11 | R24: 1 | S24: 1 | T24: 1 | U24: 1 | V24: 1 | W24: 1 | X24: 1 | Y24: 1 | Z24: 1 | AA24: 1 | AB24: 1
A25: 1 | B25: =A25*0.25 | C25: =MIN(MATCH(B25,$B$7:$B$19,1),12) | D25: =(B25-INDEX($B$7:$B$19,C25))/(INDEX($B$7:$B$19,C25+1)-INDEX($B$7:$B$19,C25)) | E25: ='Amort-Set-up'!E20 | F25: =INDEX($D$7:$N$19,$C25,F$24)+$D25*(INDEX($D$7:$N$19,$C25+1,F$24)-INDEX($D$7:$N$19,$C25,F$24)) | G25: =INDEX($D$7:$N$19,$C25,G$24)+$D25*(INDEX($D$7:$N$19,$C25+1,G$24)-INDEX($D$7:$N$19,$C25,G$24)) | H25: =INDEX($D$7:$N$19,$C25,H$24)+$D25*(INDEX($D$7:$N$19,$C25+1,H$24)-INDEX($D$7:$N$19,$C25,H$24)) | I25: =INDEX($D$7:$N$19,$C25,I$24)+$D25*(INDEX($D$7:$N$19,$C25+1,I$24)-INDEX($D$7:$N$19,$C25,I$24)) | J25: =INDEX($D$7:$N$19,$C25,J$24)+$D25*(INDEX($D$7:$N$19,$C25+1,J$24)-INDEX($D$7:$N$19,$C25,J$24)) | K25: =INDEX($D$7:$N$19,$C25,K$24)+$D25*(INDEX($D$7:$N$19,$C25+1,K$24)-INDEX($D$7:$N$19,$C25,K$24)) | L25: =INDEX($D$7:$N$19,$C25,L$24)+$D25*(INDEX($D$7:$N$19,$C25+1,L$24)-INDEX($D$7:$N$19,$C25,L$24)) | M25: =INDEX($D$7:$N$19,$C25,M$24)+$D25*(INDEX($D$7:$N$19,$C25+1,M$24)-INDEX($D$7:$N$19,$C25,M$24)) | ... P25: =INDEX($D$7:$N$19,$C25,P$24)+$D25*(INDEX($D$7:$N$19,$C25+1,P$24)-INDEX($D$7:$N$19,$C25,P$24)) | R25: =1/(1+F25*$E$4) | S25: =1/(1+G25*$E$4) | T25: =1/(1+H25*$E$4) | U25: =1/(1+I25*$E$4) | V25: =1/(1+J25*$E$4) | W25: =1/(1+K25*$E$4) | X25: =1/(1+L25*$E$4) | Y25: =1/(1+M25*$E$4) | ... AB25: =1/(1+P25*$E$4)
A26: 2 | B26: =A26*0.25 | C26: =MIN(MATCH(B26,$B$7:$B$19,1),12) | D26: =(B26-INDEX($B$7:$B$19,C26))/(INDEX($B$7:$B$19,C26+1)-INDEX($B$7:$B$19,C26)) | E26: ='Amort-Set-up'!E21 | F26: =INDEX($D$7:$N$19,$C26,F$24)+$D26*(INDEX($D$7:$N$19,$C26+1,F$24)-INDEX($D$7:$N$19,$C26,F$24)) | G26: =INDEX($D$7:$N$19,$C26,G$24)+$D26*(INDEX($D$7:$N$19,$C26+1,G$24)-INDEX($D$7:$N$19,$C26,G$24)) | H26: =INDEX($D$7:$N$19,$C26,H$24)+$D26*(INDEX($D$7:$N$19,$C26+1,H$24)-INDEX($D$7:$N$19,$C26,H$24)) | I26: =INDEX($D$7:$N$19,$C26,I$24)+$D26*(INDEX($D$7:$N$19,$C26+1,I$24)-INDEX($D$7:$N$19,$C26,I$24)) | J26: =INDEX($D$7:$N$19,$C26,J$24)+$D26*(INDEX($D$7:$N$19,$C26+1,J$24)-INDEX($D$7:$N$19,$C26,J$24)) | K26: =INDEX($D$7:$N$19,$C26,K$24)+$D26*(INDEX($D$7:$N$19,$C26+1,K$24)-INDEX($D$7:$N$19,$C26,K$24)) | L26: =INDEX($D$7:$N$19,$C26,L$24)+$D26*(INDEX($D$7:$N$19,$C26+1,L$24)-INDEX($D$7:$N$19,$C26,L$24)) | M26: =INDEX($D$7:$N$19,$C26,M$24)+$D26*(INDEX($D$7:$N$19,$C26+1,M$24)-INDEX($D$7:$N$19,$C26,M$24)) | ... P26: =INDEX($D$7:$N$19,$C26,P$24)+$D26*(INDEX($D$7:$N$19,$C26+1,P$24)-INDEX($D$7:$N$19,$C26,P$24)) | R26: =(1-F26*$E$4*SUM(R$25:R25))/(1+F26*$E$4) | S26: =(1-G26*$E$4*SUM(S$25:S25))/(1+G26*$E$4) | T26: =(1-H26*$E$4*SUM(T$25:T25))/(1+H26*$E$4) | U26: =(1-I26*$E$4*SUM(U$25:U25))/(1+I26*$E$4) | V26: =(1-J26*$E$4*SUM(V$25:V25))/(1+J26*$E$4) | W26: =(1-K26*$E$4*SUM(W$25:W25))/(1+K26*$E$4) | X26: =(1-L26*$E$4*SUM(X$25:X25))/(1+L26*$E$4) | Y26: =(1-M26*$E$4*SUM(Y$25:Y25))/(1+M26*$E$4) | ... AB26: =(1-P26*$E$4*SUM(AB$25:AB25))/(1+P26*$E$4)
A27: 3 | B27: =A27*0.25 | C27: =MIN(MATCH(B27,$B$7:$B$19,1),12) | D27: =(B27-INDEX($B$7:$B$19,C27))/(INDEX($B$7:$B$19,C27+1)-INDEX($B$7:$B$19,C27)) | E27: ='Amort-Set-up'!E22 | F27: =INDEX($D$7:$N$19,$C27,F$24)+$D27*(INDEX($D$7:$N$19,$C27+1,F$24)-INDEX($D$7:$N$19,$C27,F$24)) | G27: =INDEX($D$7:$N$19,$C27,G$24)+$D27*(INDEX($D$7:$N$19,$C27+1,G$24)-INDEX($D$7:$N$19,$C27,G$24)) | H27: =INDEX($D$7:$N$19,$C27,H$24)+$D27*(INDEX($D$7:$N$19,$C27+1,H$24)-INDEX($D$7:$N$19,$C27,H$24)) | I27: =INDEX($D$7:$N$19,$C27,I$24)+$D27*(INDEX($D$7:$N$19,$C27+1,I$24)-INDEX($D$7:$N$19,$C27,I$24)) | J27: =INDEX($D$7:$N$19,$C27,J$24)+$D27*(INDEX($D$7:$N$19,$C27+1,J$24)-INDEX($D$7:$N$19,$C27,J$24)) | K27: =INDEX($D$7:$N$19,$C27,K$24)+$D27*(INDEX($D$7:$N$19,$C27+1,K$24)-INDEX($D$7:$N$19,$C27,K$24)) | L27: =INDEX($D$7:$N$19,$C27,L$24)+$D27*(INDEX($D$7:$N$19,$C27+1,L$24)-INDEX($D$7:$N$19,$C27,L$24)) | M27: =INDEX($D$7:$N$19,$C27,M$24)+$D27*(INDEX($D$7:$N$19,$C27+1,M$24)-INDEX($D$7:$N$19,$C27,M$24)) | ... P27: =INDEX($D$7:$N$19,$C27,P$24)+$D27*(INDEX($D$7:$N$19,$C27+1,P$24)-INDEX($D$7:$N$19,$C27,P$24)) | R27: =(1-F27*$E$4*SUM(R$25:R26))/(1+F27*$E$4) | S27: =(1-G27*$E$4*SUM(S$25:S26))/(1+G27*$E$4) | T27: =(1-H27*$E$4*SUM(T$25:T26))/(1+H27*$E$4) | U27: =(1-I27*$E$4*SUM(U$25:U26))/(1+I27*$E$4) | V27: =(1-J27*$E$4*SUM(V$25:V26))/(1+J27*$E$4) | W27: =(1-K27*$E$4*SUM(W$25:W26))/(1+K27*$E$4) | X27: =(1-L27*$E$4*SUM(X$25:X26))/(1+L27*$E$4) | Y27: =(1-M27*$E$4*SUM(Y$25:Y26))/(1+M27*$E$4) | ... AB27: =(1-P27*$E$4*SUM(AB$25:AB26))/(1+P27*$E$4)
A28: 4 | B28: =A28*0.25 | C28: =MIN(MATCH(B28,$B$7:$B$19,1),12) | D28: =(B28-INDEX($B$7:$B$19,C28))/(INDEX($B$7:$B$19,C28+1)-INDEX($B$7:$B$19,C28)) | E28: ='Amort-Set-up'!E23 | F28: =INDEX($D$7:$N$19,$C28,F$24)+$D28*(INDEX($D$7:$N$19,$C28+1,F$24)-INDEX($D$7:$N$19,$C28,F$24)) | G28: =INDEX($D$7:$N$19,$C28,G$24)+$D28*(INDEX($D$7:$N$19,$C28+1,G$24)-INDEX($D$7:$N$19,$C28,G$24)) | H28: =INDEX($D$7:$N$19,$C28,H$24)+$D28*(INDEX($D$7:$N$19,$C28+1,H$24)-INDEX($D$7:$N$19,$C28,H$24)) | I28: =INDEX($D$7:$N$19,$C28,I$24)+$D28*(INDEX($D$7:$N$19,$C28+1,I$24)-INDEX($D$7:$N$19,$C28,I$24)) | J28: =INDEX($D$7:$N$19,$C28,J$24)+$D28*(INDEX($D$7:$N$19,$C28+1,J$24)-INDEX($D$7:$N$19,$C28,J$24)) | K28: =INDEX($D$7:$N$19,$C28,K$24)+$D28*(INDEX($D$7:$N$19,$C28+1,K$24)-INDEX($D$7:$N$19,$C28,K$24)) | L28: =INDEX($D$7:$N$19,$C28,L$24)+$D28*(INDEX($D$7:$N$19,$C28+1,L$24)-INDEX($D$7:$N$19,$C28,L$24)) | M28: =INDEX($D$7:$N$19,$C28,M$24)+$D28*(INDEX($D$7:$N$19,$C28+1,M$24)-INDEX($D$7:$N$19,$C28,M$24)) | ... P28: =INDEX($D$7:$N$19,$C28,P$24)+$D28*(INDEX($D$7:$N$19,$C28+1,P$24)-INDEX($D$7:$N$19,$C28,P$24)) | R28: =(1-F28*$E$4*SUM(R$25:R27))/(1+F28*$E$4) | S28: =(1-G28*$E$4*SUM(S$25:S27))/(1+G28*$E$4) | T28: =(1-H28*$E$4*SUM(T$25:T27))/(1+H28*$E$4) | U28: =(1-I28*$E$4*SUM(U$25:U27))/(1+I28*$E$4) | V28: =(1-J28*$E$4*SUM(V$25:V27))/(1+J28*$E$4) | W28: =(1-K28*$E$4*SUM(W$25:W27))/(1+K28*$E$4) | X28: =(1-L28*$E$4*SUM(X$25:X27))/(1+L28*$E$4) | Y28: =(1-M28*$E$4*SUM(Y$25:Y27))/(1+M28*$E$4) | ... AB28: =(1-P28*$E$4*SUM(AB$25:AB27))/(1+P28*$E$4)
A29: 5 | B29: =A29*0.25 | C29: =MIN(MATCH(B29,$B$7:$B$19,1),12) | D29: =(B29-INDEX($B$7:$B$19,C29))/(INDEX($B$7:$B$19,C29+1)-INDEX($B$7:$B$19,C29)) | E29: ='Amort-Set-up'!E24 | F29: =INDEX($D$7:$N$19,$C29,F$24)+$D29*(INDEX($D$7:$N$19,$C29+1,F$24)-INDEX($D$7:$N$19,$C29,F$24)) | G29: =INDEX($D$7:$N$19,$C29,G$24)+$D29*(INDEX($D$7:$N$19,$C29+1,G$24)-INDEX($D$7:$N$19,$C29,G$24)) | H29: =INDEX($D$7:$N$19,$C29,H$24)+$D29*(INDEX($D$7:$N$19,$C29+1,H$24)-INDEX($D$7:$N$19,$C29,H$24)) | I29: =INDEX($D$7:$N$19,$C29,I$24)+$D29*(INDEX($D$7:$N$19,$C29+1,I$24)-INDEX($D$7:$N$19,$C29,I$24)) | J29: =INDEX($D$7:$N$19,$C29,J$24)+$D29*(INDEX($D$7:$N$19,$C29+1,J$24)-INDEX($D$7:$N$19,$C29,J$24)) | K29: =INDEX($D$7:$N$19,$C29,K$24)+$D29*(INDEX($D$7:$N$19,$C29+1,K$24)-INDEX($D$7:$N$19,$C29,K$24)) | L29: =INDEX($D$7:$N$19,$C29,L$24)+$D29*(INDEX($D$7:$N$19,$C29+1,L$24)-INDEX($D$7:$N$19,$C29,L$24)) | M29: =INDEX($D$7:$N$19,$C29,M$24)+$D29*(INDEX($D$7:$N$19,$C29+1,M$24)-INDEX($D$7:$N$19,$C29,M$24)) | ... P29: =INDEX($D$7:$N$19,$C29,P$24)+$D29*(INDEX($D$7:$N$19,$C29+1,P$24)-INDEX($D$7:$N$19,$C29,P$24)) | R29: =(1-F29*$E$4*SUM(R$25:R28))/(1+F29*$E$4) | S29: =(1-G29*$E$4*SUM(S$25:S28))/(1+G29*$E$4) | T29: =(1-H29*$E$4*SUM(T$25:T28))/(1+H29*$E$4) | U29: =(1-I29*$E$4*SUM(U$25:U28))/(1+I29*$E$4) | V29: =(1-J29*$E$4*SUM(V$25:V28))/(1+J29*$E$4) | W29: =(1-K29*$E$4*SUM(W$25:W28))/(1+K29*$E$4) | X29: =(1-L29*$E$4*SUM(X$25:X28))/(1+L29*$E$4) | Y29: =(1-M29*$E$4*SUM(Y$25:Y28))/(1+M29*$E$4) | ... AB29: =(1-P29*$E$4*SUM(AB$25:AB28))/(1+P29*$E$4)
A30: 6 | B30: =A30*0.25 | C30: =MIN(MATCH(B30,$B$7:$B$19,1),12) | D30: =(B30-INDEX($B$7:$B$19,C30))/(INDEX($B$7:$B$19,C30+1)-INDEX($B$7:$B$19,C30)) | E30: ='Amort-Set-up'!E25 | F30: =INDEX($D$7:$N$19,$C30,F$24)+$D30*(INDEX($D$7:$N$19,$C30+1,F$24)-INDEX($D$7:$N$19,$C30,F$24)) | G30: =INDEX($D$7:$N$19,$C30,G$24)+$D30*(INDEX($D$7:$N$19,$C30+1,G$24)-INDEX($D$7:$N$19,$C30,G$24)) | H30: =INDEX($D$7:$N$19,$C30,H$24)+$D30*(INDEX($D$7:$N$19,$C30+1,H$24)-INDEX($D$7:$N$19,$C30,H$24)) | I30: =INDEX($D$7:$N$19,$C30,I$24)+$D30*(INDEX($D$7:$N$19,$C30+1,I$24)-INDEX($D$7:$N$19,$C30,I$24)) | J30: =INDEX($D$7:$N$19,$C30,J$24)+$D30*(INDEX($D$7:$N$19,$C30+1,J$24)-INDEX($D$7:$N$19,$C30,J$24)) | K30: =INDEX($D$7:$N$19,$C30,K$24)+$D30*(INDEX($D$7:$N$19,$C30+1,K$24)-INDEX($D$7:$N$19,$C30,K$24)) | L30: =INDEX($D$7:$N$19,$C30,L$24)+$D30*(INDEX($D$7:$N$19,$C30+1,L$24)-INDEX($D$7:$N$19,$C30,L$24)) | M30: =INDEX($D$7:$N$19,$C30,M$24)+$D30*(INDEX($D$7:$N$19,$C30+1,M$24)-INDEX($D$7:$N$19,$C30,M$24)) | ... P30: =INDEX($D$7:$N$19,$C30,P$24)+$D30*(INDEX($D$7:$N$19,$C30+1,P$24)-INDEX($D$7:$N$19,$C30,P$24)) | R30: =(1-F30*$E$4*SUM(R$25:R29))/(1+F30*$E$4) | S30: =(1-G30*$E$4*SUM(S$25:S29))/(1+G30*$E$4) | T30: =(1-H30*$E$4*SUM(T$25:T29))/(1+H30*$E$4) | U30: =(1-I30*$E$4*SUM(U$25:U29))/(1+I30*$E$4) | V30: =(1-J30*$E$4*SUM(V$25:V29))/(1+J30*$E$4) | W30: =(1-K30*$E$4*SUM(W$25:W29))/(1+K30*$E$4) | X30: =(1-L30*$E$4*SUM(X$25:X29))/(1+L30*$E$4) | Y30: =(1-M30*$E$4*SUM(Y$25:Y29))/(1+M30*$E$4) | ... AB30: =(1-P30*$E$4*SUM(AB$25:AB29))/(1+P30*$E$4)
A31: 7 | B31: =A31*0.25 | C31: =MIN(MATCH(B31,$B$7:$B$19,1),12) | D31: =(B31-INDEX($B$7:$B$19,C31))/(INDEX($B$7:$B$19,C31+1)-INDEX($B$7:$B$19,C31)) | E31: ='Amort-Set-up'!E26 | F31: =INDEX($D$7:$N$19,$C31,F$24)+$D31*(INDEX($D$7:$N$19,$C31+1,F$24)-INDEX($D$7:$N$19,$C31,F$24)) | G31: =INDEX($D$7:$N$19,$C31,G$24)+$D31*(INDEX($D$7:$N$19,$C31+1,G$24)-INDEX($D$7:$N$19,$C31,G$24)) | H31: =INDEX($D$7:$N$19,$C31,H$24)+$D31*(INDEX($D$7:$N$19,$C31+1,H$24)-INDEX($D$7:$N$19,$C31,H$24)) | I31: =INDEX($D$7:$N$19,$C31,I$24)+$D31*(INDEX($D$7:$N$19,$C31+1,I$24)-INDEX($D$7:$N$19,$C31,I$24)) | J31: =INDEX($D$7:$N$19,$C31,J$24)+$D31*(INDEX($D$7:$N$19,$C31+1,J$24)-INDEX($D$7:$N$19,$C31,J$24)) | K31: =INDEX($D$7:$N$19,$C31,K$24)+$D31*(INDEX($D$7:$N$19,$C31+1,K$24)-INDEX($D$7:$N$19,$C31,K$24)) | L31: =INDEX($D$7:$N$19,$C31,L$24)+$D31*(INDEX($D$7:$N$19,$C31+1,L$24)-INDEX($D$7:$N$19,$C31,L$24)) | M31: =INDEX($D$7:$N$19,$C31,M$24)+$D31*(INDEX($D$7:$N$19,$C31+1,M$24)-INDEX($D$7:$N$19,$C31,M$24)) | ... P31: =INDEX($D$7:$N$19,$C31,P$24)+$D31*(INDEX($D$7:$N$19,$C31+1,P$24)-INDEX($D$7:$N$19,$C31,P$24)) | R31: =(1-F31*$E$4*SUM(R$25:R30))/(1+F31*$E$4) | S31: =(1-G31*$E$4*SUM(S$25:S30))/(1+G31*$E$4) | T31: =(1-H31*$E$4*SUM(T$25:T30))/(1+H31*$E$4) | U31: =(1-I31*$E$4*SUM(U$25:U30))/(1+I31*$E$4) | V31: =(1-J31*$E$4*SUM(V$25:V30))/(1+J31*$E$4) | W31: =(1-K31*$E$4*SUM(W$25:W30))/(1+K31*$E$4) | X31: =(1-L31*$E$4*SUM(X$25:X30))/(1+L31*$E$4) | Y31: =(1-M31*$E$4*SUM(Y$25:Y30))/(1+M31*$E$4) | ... AB31: =(1-P31*$E$4*SUM(AB$25:AB30))/(1+P31*$E$4)
A32: 8 | B32: =A32*0.25 | C32: =MIN(MATCH(B32,$B$7:$B$19,1),12) | D32: =(B32-INDEX($B$7:$B$19,C32))/(INDEX($B$7:$B$19,C32+1)-INDEX($B$7:$B$19,C32)) | E32: ='Amort-Set-up'!E27 | F32: =INDEX($D$7:$N$19,$C32,F$24)+$D32*(INDEX($D$7:$N$19,$C32+1,F$24)-INDEX($D$7:$N$19,$C32,F$24)) | G32: =INDEX($D$7:$N$19,$C32,G$24)+$D32*(INDEX($D$7:$N$19,$C32+1,G$24)-INDEX($D$7:$N$19,$C32,G$24)) | H32: =INDEX($D$7:$N$19,$C32,H$24)+$D32*(INDEX($D$7:$N$19,$C32+1,H$24)-INDEX($D$7:$N$19,$C32,H$24)) | I32: =INDEX($D$7:$N$19,$C32,I$24)+$D32*(INDEX($D$7:$N$19,$C32+1,I$24)-INDEX($D$7:$N$19,$C32,I$24)) | J32: =INDEX($D$7:$N$19,$C32,J$24)+$D32*(INDEX($D$7:$N$19,$C32+1,J$24)-INDEX($D$7:$N$19,$C32,J$24)) | K32: =INDEX($D$7:$N$19,$C32,K$24)+$D32*(INDEX($D$7:$N$19,$C32+1,K$24)-INDEX($D$7:$N$19,$C32,K$24)) | L32: =INDEX($D$7:$N$19,$C32,L$24)+$D32*(INDEX($D$7:$N$19,$C32+1,L$24)-INDEX($D$7:$N$19,$C32,L$24)) | M32: =INDEX($D$7:$N$19,$C32,M$24)+$D32*(INDEX($D$7:$N$19,$C32+1,M$24)-INDEX($D$7:$N$19,$C32,M$24)) | ... P32: =INDEX($D$7:$N$19,$C32,P$24)+$D32*(INDEX($D$7:$N$19,$C32+1,P$24)-INDEX($D$7:$N$19,$C32,P$24)) | R32: =(1-F32*$E$4*SUM(R$25:R31))/(1+F32*$E$4) | S32: =(1-G32*$E$4*SUM(S$25:S31))/(1+G32*$E$4) | T32: =(1-H32*$E$4*SUM(T$25:T31))/(1+H32*$E$4) | U32: =(1-I32*$E$4*SUM(U$25:U31))/(1+I32*$E$4) | V32: =(1-J32*$E$4*SUM(V$25:V31))/(1+J32*$E$4) | W32: =(1-K32*$E$4*SUM(W$25:W31))/(1+K32*$E$4) | X32: =(1-L32*$E$4*SUM(X$25:X31))/(1+L32*$E$4) | Y32: =(1-M32*$E$4*SUM(Y$25:Y31))/(1+M32*$E$4) | ... AB32: =(1-P32*$E$4*SUM(AB$25:AB31))/(1+P32*$E$4)
A33: 9 | B33: =A33*0.25 | C33: =MIN(MATCH(B33,$B$7:$B$19,1),12) | D33: =(B33-INDEX($B$7:$B$19,C33))/(INDEX($B$7:$B$19,C33+1)-INDEX($B$7:$B$19,C33)) | E33: ='Amort-Set-up'!E28 | F33: =INDEX($D$7:$N$19,$C33,F$24)+$D33*(INDEX($D$7:$N$19,$C33+1,F$24)-INDEX($D$7:$N$19,$C33,F$24)) | G33: =INDEX($D$7:$N$19,$C33,G$24)+$D33*(INDEX($D$7:$N$19,$C33+1,G$24)-INDEX($D$7:$N$19,$C33,G$24)) | H33: =INDEX($D$7:$N$19,$C33,H$24)+$D33*(INDEX($D$7:$N$19,$C33+1,H$24)-INDEX($D$7:$N$19,$C33,H$24)) | I33: =INDEX($D$7:$N$19,$C33,I$24)+$D33*(INDEX($D$7:$N$19,$C33+1,I$24)-INDEX($D$7:$N$19,$C33,I$24)) | J33: =INDEX($D$7:$N$19,$C33,J$24)+$D33*(INDEX($D$7:$N$19,$C33+1,J$24)-INDEX($D$7:$N$19,$C33,J$24)) | K33: =INDEX($D$7:$N$19,$C33,K$24)+$D33*(INDEX($D$7:$N$19,$C33+1,K$24)-INDEX($D$7:$N$19,$C33,K$24)) | L33: =INDEX($D$7:$N$19,$C33,L$24)+$D33*(INDEX($D$7:$N$19,$C33+1,L$24)-INDEX($D$7:$N$19,$C33,L$24)) | M33: =INDEX($D$7:$N$19,$C33,M$24)+$D33*(INDEX($D$7:$N$19,$C33+1,M$24)-INDEX($D$7:$N$19,$C33,M$24)) | ... P33: =INDEX($D$7:$N$19,$C33,P$24)+$D33*(INDEX($D$7:$N$19,$C33+1,P$24)-INDEX($D$7:$N$19,$C33,P$24)) | R33: =(1-F33*$E$4*SUM(R$25:R32))/(1+F33*$E$4) | S33: =(1-G33*$E$4*SUM(S$25:S32))/(1+G33*$E$4) | T33: =(1-H33*$E$4*SUM(T$25:T32))/(1+H33*$E$4) | U33: =(1-I33*$E$4*SUM(U$25:U32))/(1+I33*$E$4) | V33: =(1-J33*$E$4*SUM(V$25:V32))/(1+J33*$E$4) | W33: =(1-K33*$E$4*SUM(W$25:W32))/(1+K33*$E$4) | X33: =(1-L33*$E$4*SUM(X$25:X32))/(1+L33*$E$4) | Y33: =(1-M33*$E$4*SUM(Y$25:Y32))/(1+M33*$E$4) | ... AB33: =(1-P33*$E$4*SUM(AB$25:AB32))/(1+P33*$E$4)
A34: 10 | B34: =A34*0.25 | C34: =MIN(MATCH(B34,$B$7:$B$19,1),12) | D34: =(B34-INDEX($B$7:$B$19,C34))/(INDEX($B$7:$B$19,C34+1)-INDEX($B$7:$B$19,C34)) | E34: ='Amort-Set-up'!E29 | F34: =INDEX($D$7:$N$19,$C34,F$24)+$D34*(INDEX($D$7:$N$19,$C34+1,F$24)-INDEX($D$7:$N$19,$C34,F$24)) | G34: =INDEX($D$7:$N$19,$C34,G$24)+$D34*(INDEX($D$7:$N$19,$C34+1,G$24)-INDEX($D$7:$N$19,$C34,G$24)) | H34: =INDEX($D$7:$N$19,$C34,H$24)+$D34*(INDEX($D$7:$N$19,$C34+1,H$24)-INDEX($D$7:$N$19,$C34,H$24)) | I34: =INDEX($D$7:$N$19,$C34,I$24)+$D34*(INDEX($D$7:$N$19,$C34+1,I$24)-INDEX($D$7:$N$19,$C34,I$24)) | J34: =INDEX($D$7:$N$19,$C34,J$24)+$D34*(INDEX($D$7:$N$19,$C34+1,J$24)-INDEX($D$7:$N$19,$C34,J$24)) | K34: =INDEX($D$7:$N$19,$C34,K$24)+$D34*(INDEX($D$7:$N$19,$C34+1,K$24)-INDEX($D$7:$N$19,$C34,K$24)) | L34: =INDEX($D$7:$N$19,$C34,L$24)+$D34*(INDEX($D$7:$N$19,$C34+1,L$24)-INDEX($D$7:$N$19,$C34,L$24)) | M34: =INDEX($D$7:$N$19,$C34,M$24)+$D34*(INDEX($D$7:$N$19,$C34+1,M$24)-INDEX($D$7:$N$19,$C34,M$24)) | ... P34: =INDEX($D$7:$N$19,$C34,P$24)+$D34*(INDEX($D$7:$N$19,$C34+1,P$24)-INDEX($D$7:$N$19,$C34,P$24)) | R34: =(1-F34*$E$4*SUM(R$25:R33))/(1+F34*$E$4) | S34: =(1-G34*$E$4*SUM(S$25:S33))/(1+G34*$E$4) | T34: =(1-H34*$E$4*SUM(T$25:T33))/(1+H34*$E$4) | U34: =(1-I34*$E$4*SUM(U$25:U33))/(1+I34*$E$4) | V34: =(1-J34*$E$4*SUM(V$25:V33))/(1+J34*$E$4) | W34: =(1-K34*$E$4*SUM(W$25:W33))/(1+K34*$E$4) | X34: =(1-L34*$E$4*SUM(X$25:X33))/(1+L34*$E$4) | Y34: =(1-M34*$E$4*SUM(Y$25:Y33))/(1+M34*$E$4) | ... AB34: =(1-P34*$E$4*SUM(AB$25:AB33))/(1+P34*$E$4)
A35: 11 | B35: =A35*0.25 | C35: =MIN(MATCH(B35,$B$7:$B$19,1),12) | D35: =(B35-INDEX($B$7:$B$19,C35))/(INDEX($B$7:$B$19,C35+1)-INDEX($B$7:$B$19,C35)) | E35: ='Amort-Set-up'!E30 | F35: =INDEX($D$7:$N$19,$C35,F$24)+$D35*(INDEX($D$7:$N$19,$C35+1,F$24)-INDEX($D$7:$N$19,$C35,F$24)) | G35: =INDEX($D$7:$N$19,$C35,G$24)+$D35*(INDEX($D$7:$N$19,$C35+1,G$24)-INDEX($D$7:$N$19,$C35,G$24)) | H35: =INDEX($D$7:$N$19,$C35,H$24)+$D35*(INDEX($D$7:$N$19,$C35+1,H$24)-INDEX($D$7:$N$19,$C35,H$24)) | I35: =INDEX($D$7:$N$19,$C35,I$24)+$D35*(INDEX($D$7:$N$19,$C35+1,I$24)-INDEX($D$7:$N$19,$C35,I$24)) | J35: =INDEX($D$7:$N$19,$C35,J$24)+$D35*(INDEX($D$7:$N$19,$C35+1,J$24)-INDEX($D$7:$N$19,$C35,J$24)) | K35: =INDEX($D$7:$N$19,$C35,K$24)+$D35*(INDEX($D$7:$N$19,$C35+1,K$24)-INDEX($D$7:$N$19,$C35,K$24)) | L35: =INDEX($D$7:$N$19,$C35,L$24)+$D35*(INDEX($D$7:$N$19,$C35+1,L$24)-INDEX($D$7:$N$19,$C35,L$24)) | M35: =INDEX($D$7:$N$19,$C35,M$24)+$D35*(INDEX($D$7:$N$19,$C35+1,M$24)-INDEX($D$7:$N$19,$C35,M$24)) | ... P35: =INDEX($D$7:$N$19,$C35,P$24)+$D35*(INDEX($D$7:$N$19,$C35+1,P$24)-INDEX($D$7:$N$19,$C35,P$24)) | R35: =(1-F35*$E$4*SUM(R$25:R34))/(1+F35*$E$4) | S35: =(1-G35*$E$4*SUM(S$25:S34))/(1+G35*$E$4) | T35: =(1-H35*$E$4*SUM(T$25:T34))/(1+H35*$E$4) | U35: =(1-I35*$E$4*SUM(U$25:U34))/(1+I35*$E$4) | V35: =(1-J35*$E$4*SUM(V$25:V34))/(1+J35*$E$4) | W35: =(1-K35*$E$4*SUM(W$25:W34))/(1+K35*$E$4) | X35: =(1-L35*$E$4*SUM(X$25:X34))/(1+L35*$E$4) | Y35: =(1-M35*$E$4*SUM(Y$25:Y34))/(1+M35*$E$4) | ... AB35: =(1-P35*$E$4*SUM(AB$25:AB34))/(1+P35*$E$4)
A36: 12 | B36: =A36*0.25 | C36: =MIN(MATCH(B36,$B$7:$B$19,1),12) | D36: =(B36-INDEX($B$7:$B$19,C36))/(INDEX($B$7:$B$19,C36+1)-INDEX($B$7:$B$19,C36)) | E36: ='Amort-Set-up'!E31 | F36: =INDEX($D$7:$N$19,$C36,F$24)+$D36*(INDEX($D$7:$N$19,$C36+1,F$24)-INDEX($D$7:$N$19,$C36,F$24)) | G36: =INDEX($D$7:$N$19,$C36,G$24)+$D36*(INDEX($D$7:$N$19,$C36+1,G$24)-INDEX($D$7:$N$19,$C36,G$24)) | H36: =INDEX($D$7:$N$19,$C36,H$24)+$D36*(INDEX($D$7:$N$19,$C36+1,H$24)-INDEX($D$7:$N$19,$C36,H$24)) | I36: =INDEX($D$7:$N$19,$C36,I$24)+$D36*(INDEX($D$7:$N$19,$C36+1,I$24)-INDEX($D$7:$N$19,$C36,I$24)) | J36: =INDEX($D$7:$N$19,$C36,J$24)+$D36*(INDEX($D$7:$N$19,$C36+1,J$24)-INDEX($D$7:$N$19,$C36,J$24)) | K36: =INDEX($D$7:$N$19,$C36,K$24)+$D36*(INDEX($D$7:$N$19,$C36+1,K$24)-INDEX($D$7:$N$19,$C36,K$24)) | L36: =INDEX($D$7:$N$19,$C36,L$24)+$D36*(INDEX($D$7:$N$19,$C36+1,L$24)-INDEX($D$7:$N$19,$C36,L$24)) | M36: =INDEX($D$7:$N$19,$C36,M$24)+$D36*(INDEX($D$7:$N$19,$C36+1,M$24)-INDEX($D$7:$N$19,$C36,M$24)) | ... P36: =INDEX($D$7:$N$19,$C36,P$24)+$D36*(INDEX($D$7:$N$19,$C36+1,P$24)-INDEX($D$7:$N$19,$C36,P$24)) | R36: =(1-F36*$E$4*SUM(R$25:R35))/(1+F36*$E$4) | S36: =(1-G36*$E$4*SUM(S$25:S35))/(1+G36*$E$4) | T36: =(1-H36*$E$4*SUM(T$25:T35))/(1+H36*$E$4) | U36: =(1-I36*$E$4*SUM(U$25:U35))/(1+I36*$E$4) | V36: =(1-J36*$E$4*SUM(V$25:V35))/(1+J36*$E$4) | W36: =(1-K36*$E$4*SUM(W$25:W35))/(1+K36*$E$4) | X36: =(1-L36*$E$4*SUM(X$25:X35))/(1+L36*$E$4) | Y36: =(1-M36*$E$4*SUM(Y$25:Y35))/(1+M36*$E$4) | ... AB36: =(1-P36*$E$4*SUM(AB$25:AB35))/(1+P36*$E$4)
A37: 13 | B37: =A37*0.25 | C37: =MIN(MATCH(B37,$B$7:$B$19,1),12) | D37: =(B37-INDEX($B$7:$B$19,C37))/(INDEX($B$7:$B$19,C37+1)-INDEX($B$7:$B$19,C37)) | E37: ='Amort-Set-up'!E32 | F37: =INDEX($D$7:$N$19,$C37,F$24)+$D37*(INDEX($D$7:$N$19,$C37+1,F$24)-INDEX($D$7:$N$19,$C37,F$24)) | G37: =INDEX($D$7:$N$19,$C37,G$24)+$D37*(INDEX($D$7:$N$19,$C37+1,G$24)-INDEX($D$7:$N$19,$C37,G$24)) | H37: =INDEX($D$7:$N$19,$C37,H$24)+$D37*(INDEX($D$7:$N$19,$C37+1,H$24)-INDEX($D$7:$N$19,$C37,H$24)) | I37: =INDEX($D$7:$N$19,$C37,I$24)+$D37*(INDEX($D$7:$N$19,$C37+1,I$24)-INDEX($D$7:$N$19,$C37,I$24)) | J37: =INDEX($D$7:$N$19,$C37,J$24)+$D37*(INDEX($D$7:$N$19,$C37+1,J$24)-INDEX($D$7:$N$19,$C37,J$24)) | K37: =INDEX($D$7:$N$19,$C37,K$24)+$D37*(INDEX($D$7:$N$19,$C37+1,K$24)-INDEX($D$7:$N$19,$C37,K$24)) | L37: =INDEX($D$7:$N$19,$C37,L$24)+$D37*(INDEX($D$7:$N$19,$C37+1,L$24)-INDEX($D$7:$N$19,$C37,L$24)) | M37: =INDEX($D$7:$N$19,$C37,M$24)+$D37*(INDEX($D$7:$N$19,$C37+1,M$24)-INDEX($D$7:$N$19,$C37,M$24)) | ... P37: =INDEX($D$7:$N$19,$C37,P$24)+$D37*(INDEX($D$7:$N$19,$C37+1,P$24)-INDEX($D$7:$N$19,$C37,P$24)) | R37: =(1-F37*$E$4*SUM(R$25:R36))/(1+F37*$E$4) | S37: =(1-G37*$E$4*SUM(S$25:S36))/(1+G37*$E$4) | T37: =(1-H37*$E$4*SUM(T$25:T36))/(1+H37*$E$4) | U37: =(1-I37*$E$4*SUM(U$25:U36))/(1+I37*$E$4) | V37: =(1-J37*$E$4*SUM(V$25:V36))/(1+J37*$E$4) | W37: =(1-K37*$E$4*SUM(W$25:W36))/(1+K37*$E$4) | X37: =(1-L37*$E$4*SUM(X$25:X36))/(1+L37*$E$4) | Y37: =(1-M37*$E$4*SUM(Y$25:Y36))/(1+M37*$E$4) | ... AB37: =(1-P37*$E$4*SUM(AB$25:AB36))/(1+P37*$E$4)
... A64: 40 | B64: =A64*0.25 | C64: =MIN(MATCH(B64,$B$7:$B$19,1),12) | D64: =(B64-INDEX($B$7:$B$19,C64))/(INDEX($B$7:$B$19,C64+1)-INDEX($B$7:$B$19,C64)) | E64: ='Amort-Set-up'!E59 | F64: =INDEX($D$7:$N$19,$C64,F$24)+$D64*(INDEX($D$7:$N$19,$C64+1,F$24)-INDEX($D$7:$N$19,$C64,F$24)) | G64: =INDEX($D$7:$N$19,$C64,G$24)+$D64*(INDEX($D$7:$N$19,$C64+1,G$24)-INDEX($D$7:$N$19,$C64,G$24)) | H64: =INDEX($D$7:$N$19,$C64,H$24)+$D64*(INDEX($D$7:$N$19,$C64+1,H$24)-INDEX($D$7:$N$19,$C64,H$24)) | I64: =INDEX($D$7:$N$19,$C64,I$24)+$D64*(INDEX($D$7:$N$19,$C64+1,I$24)-INDEX($D$7:$N$19,$C64,I$24)) | J64: =INDEX($D$7:$N$19,$C64,J$24)+$D64*(INDEX($D$7:$N$19,$C64+1,J$24)-INDEX($D$7:$N$19,$C64,J$24)) | K64: =INDEX($D$7:$N$19,$C64,K$24)+$D64*(INDEX($D$7:$N$19,$C64+1,K$24)-INDEX($D$7:$N$19,$C64,K$24)) | L64: =INDEX($D$7:$N$19,$C64,L$24)+$D64*(INDEX($D$7:$N$19,$C64+1,L$24)-INDEX($D$7:$N$19,$C64,L$24)) | M64: =INDEX($D$7:$N$19,$C64,M$24)+$D64*(INDEX($D$7:$N$19,$C64+1,M$24)-INDEX($D$7:$N$19,$C64,M$24)) | ... P64: =INDEX($D$7:$N$19,$C64,P$24)+$D64*(INDEX($D$7:$N$19,$C64+1,P$24)-INDEX($D$7:$N$19,$C64,P$24)) | R64: =(1-F64*$E$4*SUM(R$25:R63))/(1+F64*$E$4) | S64: =(1-G64*$E$4*SUM(S$25:S63))/(1+G64*$E$4) | T64: =(1-H64*$E$4*SUM(T$25:T63))/(1+H64*$E$4) | U64: =(1-I64*$E$4*SUM(U$25:U63))/(1+I64*$E$4) | V64: =(1-J64*$E$4*SUM(V$25:V63))/(1+J64*$E$4) | W64: =(1-K64*$E$4*SUM(W$25:W63))/(1+K64*$E$4) | X64: =(1-L64*$E$4*SUM(X$25:X63))/(1+L64*$E$4) | Y64: =(1-M64*$E$4*SUM(Y$25:Y63))/(1+M64*$E$4) | ... AB64: =(1-P64*$E$4*SUM(AB$25:AB63))/(1+P64*$E$4)
A66: Fixed PV | R66: =$D$3*$E$4*SUMPRODUCT($E$25:$E$64,R$25:R$64) | S66: =$D$3*$E$4*SUMPRODUCT($E$25:$E$64,S$25:S$64) | T66: =$D$3*$E$4*SUMPRODUCT($E$25:$E$64,T$25:T$64) | U66: =$D$3*$E$4*SUMPRODUCT($E$25:$E$64,U$25:U$64) | V66: =$D$3*$E$4*SUMPRODUCT($E$25:$E$64,V$25:V$64) | W66: =$D$3*$E$4*SUMPRODUCT($E$25:$E$64,W$25:W$64) | X66: =$D$3*$E$4*SUMPRODUCT($E$25:$E$64,X$25:X$64) | Y66: =$D$3*$E$4*SUMPRODUCT($E$25:$E$64,Y$25:Y$64) | ... AB66: =$D$3*$E$4*SUMPRODUCT($E$25:$E$64,AB$25:AB$64)
A67: Float PV | R67: =SUMPRODUCT($E$25:$E$64,R$24:R$63-R$25:R$64) | S67: =SUMPRODUCT($E$25:$E$64,S$24:S$63-S$25:S$64) | T67: =SUMPRODUCT($E$25:$E$64,T$24:T$63-T$25:T$64) | U67: =SUMPRODUCT($E$25:$E$64,U$24:U$63-U$25:U$64) | V67: =SUMPRODUCT($E$25:$E$64,V$24:V$63-V$25:V$64) | W67: =SUMPRODUCT($E$25:$E$64,W$24:W$63-W$25:W$64) | X67: =SUMPRODUCT($E$25:$E$64,X$24:X$63-X$25:X$64) | Y67: =SUMPRODUCT($E$25:$E$64,Y$24:Y$63-Y$25:Y$64) | ... AB67: =SUMPRODUCT($E$25:$E$64,AB$24:AB$63-AB$25:AB$64)
A68: NPV | R68: =R66-R67 | S68: =S66-S67 | T68: =T66-T67 | U68: =U66-U67 | V68: =V66-V67 | W68: =W66-W67 | X68: =X66-X67 | Y68: =Y66-Y67 | ... AB68: =AB66-AB67
A69: DELTA | R69: =R68-$R68 | S69: =S68-$R68 | T69: =T68-$R68 | U69: =U68-$R68 | V69: =V68-$R68 | W69: =W68-$R68 | X69: =X68-$R68 | Y69: =Y68-$R68 | ... AB69: =AB68-$R68
S70: =$A7 | T70: =$A8 | U70: =$A9 | V70: =$A10 | W70: =$A11 | X70: =$A12 | Y70: =$A13 | Z70: =$A14 | AA70: =$A15 | AB70: =$A16

Sheet KRD reformed
A1: Delta — 1bp per tenor
A2: KRW IRS loan hedge, 10Y. Each row = change in NPV for +1bp on that tenor. Live off the KRD delta row — reprices when the notionals or curve change.
A4: Tenor | B4: dv01
A5: 2D | B5: 0 | D5: 2D–2M: no curve node below 3M / no swap sensitivity → 0
A6: 1W | B6: 0 | D6: 12Y–30Y: past the 10Y maturity → 0
A7: 1M | B7: 0 | D7: 8Y/9Y risk sits in the 7Y and 10Y buckets (dropped as nodes)
A8: 2M | B8: 0
A9: 3M | B9: =KRD!S$69
A10: 6M | B10: =KRD!T$69
A11: 9M | B11: =KRD!U$69
A12: 1Y | B12: =KRD!V$69
A13: 2Y | B13: =KRD!W$69
A14: 3Y | B14: =KRD!X$69
A15: 4Y | B15: =KRD!Y$69
A16: 5Y | B16: =KRD!Z$69
A17: 7Y | B17: =KRD!AA$69
A18: 10Y | B18: =KRD!AB$69
A19: 12Y | B19: 0
A20: 15Y | B20: 0
A21: 20Y | B21: 0
A22: 25Y | B22: 0
A23: 30Y | B23: 0
A24: TOTAL | B24: =SUM(B5:B23)
