Workbook

Sheet Quotes
A1: KWR IRS
A2: tau (time gap) | B2: 0.25 | D2: curve date | E2: 46226
A4: Tenors | B4: Coupon | C4: Year
A5: 3Mo | B5: 0.0291 | C5: 0.25
A6: 6Mo | B6: 0.03125 | C6: 0.5
A7: 9Mo | B7: 0.03315 | C7: 0.75
A8: 1Yr | B8: 0.034675 | C8: 1
A9: 2Yr | B9: 0.03825 | C9: 2
A10: 3Yr | B10: 0.03965 | C10: 3
A11: 4Yr | B11: 0.04029 | C11: 4
A12: 5Yr | B12: 0.040775 | C12: 5
A13: 7Yr | B13: 0.041425 | C13: 7
A14: 8Yr | B14: 0.04165 | C14: 8
A15: 9Yr | B15: 0.04185 | C15: 9
A16: 10Yr | B16: 0.042 | C16: 10
... A19: 30Yr | B19: 0.03845 | C19: 30

Sheet Interpolation
B1: Interpolate between | C1: these two
A2: Year | B2: lo tenor yr | C2: hi tenor yr | D2: weight | E2: Swap Rate % (interpolating between) | F2: source | G2: Helper
A3: 0.25 | B3: =INDEX(Quotes!$C$5:$C$19,$G3) | C3: =INDEX(Quotes!$C$5:$C$19,MIN($G3+1,15)) | D3: =IF($C3=$B3,0,($A3-$B3)/($C3-$B3)) | E3: =INDEX(Quotes!$B$5:$B$19,$G3)+$D3*(INDEX(Quotes!$B$5:$B$19,MIN($G3+1,15))-INDEX(Quotes!$B$5:$B$19,$G3)) | F3: =IF(COUNTIF(Quotes!$C$5:$C$19,$A3)>0,"quote","interp") | G3: =MATCH($A3,Quotes!$C$5:$C$19,1)
A4: 0.5 | B4: =INDEX(Quotes!$C$5:$C$19,$G4) | C4: =INDEX(Quotes!$C$5:$C$19,MIN($G4+1,15)) | D4: =IF($C4=$B4,0,($A4-$B4)/($C4-$B4)) | E4: =INDEX(Quotes!$B$5:$B$19,$G4)+$D4*(INDEX(Quotes!$B$5:$B$19,MIN($G4+1,15))-INDEX(Quotes!$B$5:$B$19,$G4)) | F4: =IF(COUNTIF(Quotes!$C$5:$C$19,$A4)>0,"quote","interp") | G4: =MATCH($A4,Quotes!$C$5:$C$19,1)
A5: 0.75 | B5: =INDEX(Quotes!$C$5:$C$19,$G5) | C5: =INDEX(Quotes!$C$5:$C$19,MIN($G5+1,15)) | D5: =IF($C5=$B5,0,($A5-$B5)/($C5-$B5)) | E5: =INDEX(Quotes!$B$5:$B$19,$G5)+$D5*(INDEX(Quotes!$B$5:$B$19,MIN($G5+1,15))-INDEX(Quotes!$B$5:$B$19,$G5)) | F5: =IF(COUNTIF(Quotes!$C$5:$C$19,$A5)>0,"quote","interp") | G5: =MATCH($A5,Quotes!$C$5:$C$19,1)
A6: 1 | B6: =INDEX(Quotes!$C$5:$C$19,$G6) | C6: =INDEX(Quotes!$C$5:$C$19,MIN($G6+1,15)) | D6: =IF($C6=$B6,0,($A6-$B6)/($C6-$B6)) | E6: =INDEX(Quotes!$B$5:$B$19,$G6)+$D6*(INDEX(Quotes!$B$5:$B$19,MIN($G6+1,15))-INDEX(Quotes!$B$5:$B$19,$G6)) | F6: =IF(COUNTIF(Quotes!$C$5:$C$19,$A6)>0,"quote","interp") | G6: =MATCH($A6,Quotes!$C$5:$C$19,1)
A7: 1.25 | B7: =INDEX(Quotes!$C$5:$C$19,$G7) | C7: =INDEX(Quotes!$C$5:$C$19,MIN($G7+1,15)) | D7: =IF($C7=$B7,0,($A7-$B7)/($C7-$B7)) | E7: =INDEX(Quotes!$B$5:$B$19,$G7)+$D7*(INDEX(Quotes!$B$5:$B$19,MIN($G7+1,15))-INDEX(Quotes!$B$5:$B$19,$G7)) | F7: =IF(COUNTIF(Quotes!$C$5:$C$19,$A7)>0,"quote","interp") | G7: =MATCH($A7,Quotes!$C$5:$C$19,1)
A8: 1.5 | B8: =INDEX(Quotes!$C$5:$C$19,$G8) | C8: =INDEX(Quotes!$C$5:$C$19,MIN($G8+1,15)) | D8: =IF($C8=$B8,0,($A8-$B8)/($C8-$B8)) | E8: =INDEX(Quotes!$B$5:$B$19,$G8)+$D8*(INDEX(Quotes!$B$5:$B$19,MIN($G8+1,15))-INDEX(Quotes!$B$5:$B$19,$G8)) | F8: =IF(COUNTIF(Quotes!$C$5:$C$19,$A8)>0,"quote","interp") | G8: =MATCH($A8,Quotes!$C$5:$C$19,1)
A9: 1.75 | B9: =INDEX(Quotes!$C$5:$C$19,$G9) | C9: =INDEX(Quotes!$C$5:$C$19,MIN($G9+1,15)) | D9: =IF($C9=$B9,0,($A9-$B9)/($C9-$B9)) | E9: =INDEX(Quotes!$B$5:$B$19,$G9)+$D9*(INDEX(Quotes!$B$5:$B$19,MIN($G9+1,15))-INDEX(Quotes!$B$5:$B$19,$G9)) | F9: =IF(COUNTIF(Quotes!$C$5:$C$19,$A9)>0,"quote","interp") | G9: =MATCH($A9,Quotes!$C$5:$C$19,1)
A10: 2 | B10: =INDEX(Quotes!$C$5:$C$19,$G10) | C10: =INDEX(Quotes!$C$5:$C$19,MIN($G10+1,15)) | D10: =IF($C10=$B10,0,($A10-$B10)/($C10-$B10)) | E10: =INDEX(Quotes!$B$5:$B$19,$G10)+$D10*(INDEX(Quotes!$B$5:$B$19,MIN($G10+1,15))-INDEX(Quotes!$B$5:$B$19,$G10)) | F10: =IF(COUNTIF(Quotes!$C$5:$C$19,$A10)>0,"quote","interp") | G10: =MATCH($A10,Quotes!$C$5:$C$19,1)
A11: 2.25 | B11: =INDEX(Quotes!$C$5:$C$19,$G11) | C11: =INDEX(Quotes!$C$5:$C$19,MIN($G11+1,15)) | D11: =IF($C11=$B11,0,($A11-$B11)/($C11-$B11)) | E11: =INDEX(Quotes!$B$5:$B$19,$G11)+$D11*(INDEX(Quotes!$B$5:$B$19,MIN($G11+1,15))-INDEX(Quotes!$B$5:$B$19,$G11)) | F11: =IF(COUNTIF(Quotes!$C$5:$C$19,$A11)>0,"quote","interp") | G11: =MATCH($A11,Quotes!$C$5:$C$19,1)
A12: 2.5 | B12: =INDEX(Quotes!$C$5:$C$19,$G12) | C12: =INDEX(Quotes!$C$5:$C$19,MIN($G12+1,15)) | D12: =IF($C12=$B12,0,($A12-$B12)/($C12-$B12)) | E12: =INDEX(Quotes!$B$5:$B$19,$G12)+$D12*(INDEX(Quotes!$B$5:$B$19,MIN($G12+1,15))-INDEX(Quotes!$B$5:$B$19,$G12)) | F12: =IF(COUNTIF(Quotes!$C$5:$C$19,$A12)>0,"quote","interp") | G12: =MATCH($A12,Quotes!$C$5:$C$19,1)
A13: 2.75 | B13: =INDEX(Quotes!$C$5:$C$19,$G13) | C13: =INDEX(Quotes!$C$5:$C$19,MIN($G13+1,15)) | D13: =IF($C13=$B13,0,($A13-$B13)/($C13-$B13)) | E13: =INDEX(Quotes!$B$5:$B$19,$G13)+$D13*(INDEX(Quotes!$B$5:$B$19,MIN($G13+1,15))-INDEX(Quotes!$B$5:$B$19,$G13)) | F13: =IF(COUNTIF(Quotes!$C$5:$C$19,$A13)>0,"quote","interp") | G13: =MATCH($A13,Quotes!$C$5:$C$19,1)
A14: 3 | B14: =INDEX(Quotes!$C$5:$C$19,$G14) | C14: =INDEX(Quotes!$C$5:$C$19,MIN($G14+1,15)) | D14: =IF($C14=$B14,0,($A14-$B14)/($C14-$B14)) | E14: =INDEX(Quotes!$B$5:$B$19,$G14)+$D14*(INDEX(Quotes!$B$5:$B$19,MIN($G14+1,15))-INDEX(Quotes!$B$5:$B$19,$G14)) | F14: =IF(COUNTIF(Quotes!$C$5:$C$19,$A14)>0,"quote","interp") | G14: =MATCH($A14,Quotes!$C$5:$C$19,1)
... A122: 30 | B122: =INDEX(Quotes!$C$5:$C$19,$G122) | C122: =INDEX(Quotes!$C$5:$C$19,MIN($G122+1,15)) | D122: =IF($C122=$B122,0,($A122-$B122)/($C122-$B122)) | E122: =INDEX(Quotes!$B$5:$B$19,$G122)+$D122*(INDEX(Quotes!$B$5:$B$19,MIN($G122+1,15))-INDEX(Quotes!$B$5:$B$19,$G122)) | F122: =IF(COUNTIF(Quotes!$C$5:$C$19,$A122)>0,"quote","interp") | G122: =MATCH($A122,Quotes!$C$5:$C$19,1)

Sheet Bootstrap
A2: Date | B2: Year | C2: Swap % | D2: DF | E2: Zero % | F2: Future %
A3: =EDATE(Quotes!$E$2,3*1) | B3: =Interpolation!A3 | C3: =Interpolation!E3 | D3: =1/(1+C3*Quotes!$B$2) | E3: =(1/D3-1)/B3 | F3: =(1/D3-1)/Quotes!$B$2
A4: =EDATE(Quotes!$E$2,3*2) | B4: =Interpolation!A4 | C4: =Interpolation!E4 | D4: =(1-C4*Quotes!$B$2*SUM($D$3:D3))/(1+C4*Quotes!$B$2) | E4: =(1/D4-1)/B4 | F4: =(D3/D4-1)/Quotes!$B$2
A5: =EDATE(Quotes!$E$2,3*3) | B5: =Interpolation!A5 | C5: =Interpolation!E5 | D5: =(1-C5*Quotes!$B$2*SUM($D$3:D4))/(1+C5*Quotes!$B$2) | E5: =(1/D5-1)/B5 | F5: =(D4/D5-1)/Quotes!$B$2
A6: =EDATE(Quotes!$E$2,3*4) | B6: =Interpolation!A6 | C6: =Interpolation!E6 | D6: =(1-C6*Quotes!$B$2*SUM($D$3:D5))/(1+C6*Quotes!$B$2) | E6: =(1/D6-1)/B6 | F6: =(D5/D6-1)/Quotes!$B$2
A7: =EDATE(Quotes!$E$2,3*5) | B7: =Interpolation!A7 | C7: =Interpolation!E7 | D7: =(1-C7*Quotes!$B$2*SUM($D$3:D6))/(1+C7*Quotes!$B$2) | E7: =(1/D7-1)/B7 | F7: =(D6/D7-1)/Quotes!$B$2
A8: =EDATE(Quotes!$E$2,3*6) | B8: =Interpolation!A8 | C8: =Interpolation!E8 | D8: =(1-C8*Quotes!$B$2*SUM($D$3:D7))/(1+C8*Quotes!$B$2) | E8: =(1/D8-1)/B8 | F8: =(D7/D8-1)/Quotes!$B$2
A9: =EDATE(Quotes!$E$2,3*7) | B9: =Interpolation!A9 | C9: =Interpolation!E9 | D9: =(1-C9*Quotes!$B$2*SUM($D$3:D8))/(1+C9*Quotes!$B$2) | E9: =(1/D9-1)/B9 | F9: =(D8/D9-1)/Quotes!$B$2
A10: =EDATE(Quotes!$E$2,3*8) | B10: =Interpolation!A10 | C10: =Interpolation!E10 | D10: =(1-C10*Quotes!$B$2*SUM($D$3:D9))/(1+C10*Quotes!$B$2) | E10: =(1/D10-1)/B10 | F10: =(D9/D10-1)/Quotes!$B$2
A11: =EDATE(Quotes!$E$2,3*9) | B11: =Interpolation!A11 | C11: =Interpolation!E11 | D11: =(1-C11*Quotes!$B$2*SUM($D$3:D10))/(1+C11*Quotes!$B$2) | E11: =(1/D11-1)/B11 | F11: =(D10/D11-1)/Quotes!$B$2
A12: =EDATE(Quotes!$E$2,3*10) | B12: =Interpolation!A12 | C12: =Interpolation!E12 | D12: =(1-C12*Quotes!$B$2*SUM($D$3:D11))/(1+C12*Quotes!$B$2) | E12: =(1/D12-1)/B12 | F12: =(D11/D12-1)/Quotes!$B$2
A13: =EDATE(Quotes!$E$2,3*11) | B13: =Interpolation!A13 | C13: =Interpolation!E13 | D13: =(1-C13*Quotes!$B$2*SUM($D$3:D12))/(1+C13*Quotes!$B$2) | E13: =(1/D13-1)/B13 | F13: =(D12/D13-1)/Quotes!$B$2
A14: =EDATE(Quotes!$E$2,3*12) | B14: =Interpolation!A14 | C14: =Interpolation!E14 | D14: =(1-C14*Quotes!$B$2*SUM($D$3:D13))/(1+C14*Quotes!$B$2) | E14: =(1/D14-1)/B14 | F14: =(D13/D14-1)/Quotes!$B$2
A15: =EDATE(Quotes!$E$2,3*13) | B15: =Interpolation!A15 | C15: =Interpolation!E15 | D15: =(1-C15*Quotes!$B$2*SUM($D$3:D14))/(1+C15*Quotes!$B$2) | E15: =(1/D15-1)/B15 | F15: =(D14/D15-1)/Quotes!$B$2
A16: =EDATE(Quotes!$E$2,3*14) | B16: =Interpolation!A16 | C16: =Interpolation!E16 | D16: =(1-C16*Quotes!$B$2*SUM($D$3:D15))/(1+C16*Quotes!$B$2) | E16: =(1/D16-1)/B16 | F16: =(D15/D16-1)/Quotes!$B$2
A17: =EDATE(Quotes!$E$2,3*15) | B17: =Interpolation!A17 | C17: =Interpolation!E17 | D17: =(1-C17*Quotes!$B$2*SUM($D$3:D16))/(1+C17*Quotes!$B$2) | E17: =(1/D17-1)/B17 | F17: =(D16/D17-1)/Quotes!$B$2
A18: =EDATE(Quotes!$E$2,3*16) | B18: =Interpolation!A18 | C18: =Interpolation!E18 | D18: =(1-C18*Quotes!$B$2*SUM($D$3:D17))/(1+C18*Quotes!$B$2) | E18: =(1/D18-1)/B18 | F18: =(D17/D18-1)/Quotes!$B$2
A19: =EDATE(Quotes!$E$2,3*17) | B19: =Interpolation!A19 | C19: =Interpolation!E19 | D19: =(1-C19*Quotes!$B$2*SUM($D$3:D18))/(1+C19*Quotes!$B$2) | E19: =(1/D19-1)/B19 | F19: =(D18/D19-1)/Quotes!$B$2
A20: =EDATE(Quotes!$E$2,3*18) | B20: =Interpolation!A20 | C20: =Interpolation!E20 | D20: =(1-C20*Quotes!$B$2*SUM($D$3:D19))/(1+C20*Quotes!$B$2) | E20: =(1/D20-1)/B20 | F20: =(D19/D20-1)/Quotes!$B$2
A21: =EDATE(Quotes!$E$2,3*19) | B21: =Interpolation!A21 | C21: =Interpolation!E21 | D21: =(1-C21*Quotes!$B$2*SUM($D$3:D20))/(1+C21*Quotes!$B$2) | E21: =(1/D21-1)/B21 | F21: =(D20/D21-1)/Quotes!$B$2
A22: =EDATE(Quotes!$E$2,3*20) | B22: =Interpolation!A22 | C22: =Interpolation!E22 | D22: =(1-C22*Quotes!$B$2*SUM($D$3:D21))/(1+C22*Quotes!$B$2) | E22: =(1/D22-1)/B22 | F22: =(D21/D22-1)/Quotes!$B$2
A23: =EDATE(Quotes!$E$2,3*21) | B23: =Interpolation!A23 | C23: =Interpolation!E23 | D23: =(1-C23*Quotes!$B$2*SUM($D$3:D22))/(1+C23*Quotes!$B$2) | E23: =(1/D23-1)/B23 | F23: =(D22/D23-1)/Quotes!$B$2
A24: =EDATE(Quotes!$E$2,3*22) | B24: =Interpolation!A24 | C24: =Interpolation!E24 | D24: =(1-C24*Quotes!$B$2*SUM($D$3:D23))/(1+C24*Quotes!$B$2) | E24: =(1/D24-1)/B24 | F24: =(D23/D24-1)/Quotes!$B$2
A25: =EDATE(Quotes!$E$2,3*23) | B25: =Interpolation!A25 | C25: =Interpolation!E25 | D25: =(1-C25*Quotes!$B$2*SUM($D$3:D24))/(1+C25*Quotes!$B$2) | E25: =(1/D25-1)/B25 | F25: =(D24/D25-1)/Quotes!$B$2
A26: =EDATE(Quotes!$E$2,3*24) | B26: =Interpolation!A26 | C26: =Interpolation!E26 | D26: =(1-C26*Quotes!$B$2*SUM($D$3:D25))/(1+C26*Quotes!$B$2) | E26: =(1/D26-1)/B26 | F26: =(D25/D26-1)/Quotes!$B$2
A27: =EDATE(Quotes!$E$2,3*25) | B27: =Interpolation!A27 | C27: =Interpolation!E27 | D27: =(1-C27*Quotes!$B$2*SUM($D$3:D26))/(1+C27*Quotes!$B$2) | E27: =(1/D27-1)/B27 | F27: =(D26/D27-1)/Quotes!$B$2
A28: =EDATE(Quotes!$E$2,3*26) | B28: =Interpolation!A28 | C28: =Interpolation!E28 | D28: =(1-C28*Quotes!$B$2*SUM($D$3:D27))/(1+C28*Quotes!$B$2) | E28: =(1/D28-1)/B28 | F28: =(D27/D28-1)/Quotes!$B$2
A29: =EDATE(Quotes!$E$2,3*27) | B29: =Interpolation!A29 | C29: =Interpolation!E29 | D29: =(1-C29*Quotes!$B$2*SUM($D$3:D28))/(1+C29*Quotes!$B$2) | E29: =(1/D29-1)/B29 | F29: =(D28/D29-1)/Quotes!$B$2
A30: =EDATE(Quotes!$E$2,3*28) | B30: =Interpolation!A30 | C30: =Interpolation!E30 | D30: =(1-C30*Quotes!$B$2*SUM($D$3:D29))/(1+C30*Quotes!$B$2) | E30: =(1/D30-1)/B30 | F30: =(D29/D30-1)/Quotes!$B$2
A31: =EDATE(Quotes!$E$2,3*29) | B31: =Interpolation!A31 | C31: =Interpolation!E31 | D31: =(1-C31*Quotes!$B$2*SUM($D$3:D30))/(1+C31*Quotes!$B$2) | E31: =(1/D31-1)/B31 | F31: =(D30/D31-1)/Quotes!$B$2
A32: =EDATE(Quotes!$E$2,3*30) | B32: =Interpolation!A32 | C32: =Interpolation!E32 | D32: =(1-C32*Quotes!$B$2*SUM($D$3:D31))/(1+C32*Quotes!$B$2) | E32: =(1/D32-1)/B32 | F32: =(D31/D32-1)/Quotes!$B$2
A33: =EDATE(Quotes!$E$2,3*31) | B33: =Interpolation!A33 | C33: =Interpolation!E33 | D33: =(1-C33*Quotes!$B$2*SUM($D$3:D32))/(1+C33*Quotes!$B$2) | E33: =(1/D33-1)/B33 | F33: =(D32/D33-1)/Quotes!$B$2
A34: =EDATE(Quotes!$E$2,3*32) | B34: =Interpolation!A34 | C34: =Interpolation!E34 | D34: =(1-C34*Quotes!$B$2*SUM($D$3:D33))/(1+C34*Quotes!$B$2) | E34: =(1/D34-1)/B34 | F34: =(D33/D34-1)/Quotes!$B$2
A35: =EDATE(Quotes!$E$2,3*33) | B35: =Interpolation!A35 | C35: =Interpolation!E35 | D35: =(1-C35*Quotes!$B$2*SUM($D$3:D34))/(1+C35*Quotes!$B$2) | E35: =(1/D35-1)/B35 | F35: =(D34/D35-1)/Quotes!$B$2
A36: =EDATE(Quotes!$E$2,3*34) | B36: =Interpolation!A36 | C36: =Interpolation!E36 | D36: =(1-C36*Quotes!$B$2*SUM($D$3:D35))/(1+C36*Quotes!$B$2) | E36: =(1/D36-1)/B36 | F36: =(D35/D36-1)/Quotes!$B$2
A37: =EDATE(Quotes!$E$2,3*35) | B37: =Interpolation!A37 | C37: =Interpolation!E37 | D37: =(1-C37*Quotes!$B$2*SUM($D$3:D36))/(1+C37*Quotes!$B$2) | E37: =(1/D37-1)/B37 | F37: =(D36/D37-1)/Quotes!$B$2
A38: =EDATE(Quotes!$E$2,3*36) | B38: =Interpolation!A38 | C38: =Interpolation!E38 | D38: =(1-C38*Quotes!$B$2*SUM($D$3:D37))/(1+C38*Quotes!$B$2) | E38: =(1/D38-1)/B38 | F38: =(D37/D38-1)/Quotes!$B$2
A39: =EDATE(Quotes!$E$2,3*37) | B39: =Interpolation!A39 | C39: =Interpolation!E39 | D39: =(1-C39*Quotes!$B$2*SUM($D$3:D38))/(1+C39*Quotes!$B$2) | E39: =(1/D39-1)/B39 | F39: =(D38/D39-1)/Quotes!$B$2
A40: =EDATE(Quotes!$E$2,3*38) | B40: =Interpolation!A40 | C40: =Interpolation!E40 | D40: =(1-C40*Quotes!$B$2*SUM($D$3:D39))/(1+C40*Quotes!$B$2) | E40: =(1/D40-1)/B40 | F40: =(D39/D40-1)/Quotes!$B$2
A41: =EDATE(Quotes!$E$2,3*39) | B41: =Interpolation!A41 | C41: =Interpolation!E41 | D41: =(1-C41*Quotes!$B$2*SUM($D$3:D40))/(1+C41*Quotes!$B$2) | E41: =(1/D41-1)/B41 | F41: =(D40/D41-1)/Quotes!$B$2
...
