Workbook
Name VAL_DATE: Instructions!$B$9
Name HIST_START: Instructions!$B$10
Name HIST_END: Instructions!$B$11
Name PX_SRC: Instructions!$B$12
Name SOFR_TKR: Instructions!$B$13
Name S490_TKR: Instructions!$B$14
Name BOOT_MODE: Bootstrap!$G$4
Name BOOT_DFSPOT: Bootstrap!$D$4
Name BOOT_DATES: Bootstrap!$B$8:$B$72
Name BOOT_S: Bootstrap!$E$8:$E$72
Name BOOT_TAU0: Bootstrap!$D$8:$D$72
Name BOOT_TAUC: Bootstrap!$F$8:$F$72
Name BOOT_ANN: Bootstrap!$G$8:$G$72
Name BOOT_DF: Bootstrap!$H$8:$H$72
Name BOOT_T: Bootstrap!$C$8:$C$72
Name BOOT_ZERO: Bootstrap!$J$8:$J$72

Sheet Instructions
A1: USD SOFR Curve — Bloomberg Data Template
A2: Modern replication of the Lehman (2002) USD single-curve build: fixing + SR3/SR1 futures + SOFR OIS
A4: This workbook is a live Bloomberg template. Open it in Excel on a machine with the Bloomberg Add-in (BLPAPI) connected; the BDP / BDH / BDS formulas then populate automatically. Off-terminal (or in any non-Bloomberg viewer) the Bloomberg cells show #NAME? or blanks — that is expected, not a defect. Set the parameters below first; every date-driven pull references them.
A7: PARAMETERS (edit the yellow cells)
A8: Parameter | B8: Value | C8: Named ref | D8: Notes
A9: Valuation date | B9: =IF(Bootstrap!$G$4="Test 1",Testing!$D$5,IF(Bootstrap!$G$4="Test 2",Testing!$D$55,IF(Bootstrap!$G$4="Test 3",Testing!$D$105,DATE(2026,7,21)))) | C9: VAL_DATE | D9: Follows the active test case's curve date; otherwise the pinned capture date 07/21/2026. A test case must move the WHOLE workbook to its snapshot, or the bootstrap builds on one date and the targets come from another.
A10: Historical start | B10: 01/01/2018 | C10: HIST_START | D10: Start of BDH history windows.
A11: Historical end | B11: 07/20/2026 | C11: HIST_END | D11: End of BDH history windows.
A12: Price source | B12: BGN | C12: PX_SRC | D12: Bloomberg pricing source suffix used across every OIS ticker (BGN = Bloomberg Generic). Keep one source across all maturities.
A13: Overnight SOFR ticker | B13: SOFRRATE Index | C13: SOFR_TKR | D13: Published overnight SOFR fixing (NY Fed).
A14: Bloomberg SOFR curve | B14: YCSW0490 Index | C14: S490_TKR | D14: Bloomberg curve S490 (USD SOFR) — validation benchmark only.
A16: LEHMAN 2002 → MODERN USD CURVE MAPPING
A17: Lehman 2002 instrument | C17: Modern equivalent | E17: Bloomberg source
A18: LIBOR deposits | C18: SOFR fixing / short OIS | E18: SOFRRATE Index; USOSFR1Z..USOSFRF
A19: Eurodollar futures | C19: 3M SOFR futures (SR3) | E19: SFRA Comdty (CT chain)
A20: (1M money market) | C20: 1M SOFR futures (SR1) | E20: SERA Comdty (CT chain)
A21: LIBOR swaps | C21: SOFR OIS swaps | E21: USOSFR2..USOSFR50 BGN Curncy
A22: Dealer curve | C22: Bloomberg S490 (validation) | E22: YCSW0490 Index
A24: BOOTSTRAP METHODOLOGY — one discount curve, three liquid segments
A25: Short end (o/n – ~1Y) | B25: SOFR fixing + short OIS (1W,1M,3M,6M) anchor P(0,T) at the front — the modern LIBOR-deposit segment.
A26: Mid (~3M – ~5Y) | B26: SR3 3M-SOFR futures; implied rate = 100 − price, each covering one 3M IMM reference quarter — the modern Eurodollar-futures segment.
A27: Long end (~2Y – 50Y) | B27: SOFR OIS par swaps (mid = (bid+ask)/2) where deep liquidity lives — the modern LIBOR-swap segment.
A28: Bootstrap order | B28: Left → right: each instrument solves for the next discount-factor pillar given everything already solved to its left (sequential 1-D root find).
A30: Three differences vs. Lehman 2002 (where 'modern' is not a literal copy):
A31: • Single-curve: the SOFR curve both projects forwards AND discounts. Lehman 2002 was also single-curve (LIBOR did both), so a SOFR OIS build is CLOSER to the paper than a modern LIBOR build would be.
A32: • Compounding: SOFR is an overnight rate compounded daily in arrears over each period; LIBOR was a term rate set once. The OIS/futures legs carry a daily-compounding calc LIBOR did not need.
A33: • Futures convexity: SR3 (like Eurodollar) futures need a small convexity adjustment before the implied rate enters the curve. A first pass can omit it and report the bias against the S490 benchmark.
A35: TABS IN THIS WORKBOOK
A36: Charts | B36: Curve visuals — zero curve, discount factors, and V1-vs-V2 forward comparison.
A37: 1. SOFR_Fixings | B37: Overnight SOFR fixing — current (BDP) + daily history (BDH).
A38: 2. SOFR_Futures | B38: SR3 (3M) and SR1 (1M) SOFR futures chains + fields + implied rate = 100 − price.
A39: 3. SOFR_OIS_Quotes | B39: Full USOSFR OIS strip (1W–50Y): bid / ask / last + mid. Bootstrap-set flagged.
A40: 4. Bootstrap | B40: Purely-OIS bootstrap. The production curve — Swap_Pricer, Curve_Interface, and CDS all use it.
A41: Bootstrap - the single production SOFR curve, purely from OIS quotes. (The former Bootstrap_Lehman futures variant has been removed.) | B41: Lehman methodology: short OIS + SR3 futures (1Y–5Y) + OIS swaps. Compare col H vs the OIS Bootstrap.
A42: Curve_Interface | B42: Shared D(0,t): interpolates the SOFR curve to ANY date (quarterly CDS dates demo). Used by Swap_Pricer + CDS.
A43: CDS_Parameters | B43: Credit assumptions: recovery, notional, coupon, direction (recovery is an INPUT).
A44: CDS_Quotes | B44: Single-name CDS par spreads (BDP ticker, or manual demo). One entity, one seniority.
A45: CDS_Schedule | B45: Quarterly premium/default schedule to 10Y; DF from the SOFR curve, survival from hazards.
A46: Hazard_Bootstrap | B46: Piecewise-constant hazard curve; s/(1-R) default, Goal-Seek the error to 0 for exact fit.
A47: CDS_Pricer | B47: Prices a CDS off both curves: protection − premium, par spread, upfront, CS01.
...

Sheet Method
A1: USD SOFR curve and CDS module - build method
A2: Order of construction. Each step names the sheet that does the work.
A4: STEP 1 | B4: Pull the OIS strip | C4: SOFR_OIS_Quotes
C5: 32 tickers, USOSFR1Z to USOSFR50, source BGN (Instructions!B12).
C6: E/F = BDP PX_BID / PX_ASK. H = (bid+ask)/2. Curve Side = Mid, matching S490.
C7: H falls back to J (frozen S490 mids) when BDP is unavailable, so the curve always builds.
C8: N:S reconciles the BDP pull against a Bloomberg curve export.
A10: STEP 2 | B10: Dates and settlement | C10: Bootstrap col B
C11: Spot = VAL_DATE + 2 business days. Maturities = spot anniversaries.
C12: Modified following, weekends only, no holiday calendar.
C13: Bloomberg rolls 07/23/2033 to 07/25/2033; plain EDATE does not.
C14: Settle Date = curve date on the S490 screen, so DF(settle) = 1. No spot-lag stub.
A16: STEP 3 | B16: Short end, 1W to 1Y | C16: Bootstrap rows 8-22
C17: Single-payment OIS. DF = 1 / (1 + S * tau)
C18: tau = ACT/360 measured from VAL_DATE, not from spot.
A20: STEP 4 | B20: Long end, 18M to 50Y | C20: Bootstrap rows 23-72
C21: Annual coupons. DF = (1 - S*A) / (1 + S*tau)
C22: A = sum of tau_i * DF_i over prior annual coupon dates (col G).
C23: 18M is off the annual grid: uses the annuity through 1Y and contributes nothing
C24: onward, so I23 = 0 and the 2Y accrual runs from 1Y.
A26: STEP 5 | B26: Gap years | C26: Bootstrap, interpolated rows
C27: 11Y, 13-14Y, 16-19Y, 21-24Y, 26-29Y, 31-39Y, 41-49Y are not quoted.
C28: Log-linear in DF between surrounding pillars = step-function forward.
C29: Confirmed on the S490 screen: Interpolation = Step Forward (Cont).
C30: Tested against the guide's method 1 (piecewise linear simple): 48x worse here.
A32: STEP 6 | B32: Long pillar solver | C32: Curve_Solver (hidden)
C33: Gap DFs feed the annuity of the pillar they interpolate from, which is circular.
C34: Each quoted pillar 12Y+ is bisection-solved so the par identity holds with its
C35: gap points inside the annuity.
C36: Par check: Bootstrap col R, residuals ~1e-13.
A38: STEP 7 | B38: Zero rates | C38: Bootstrap col J
C39: z = -ln(DF) / t, ACT/365 from VAL_DATE, continuously compounded.
A41: STEP 8 | B41: Validate against S490 | C41: Bloomberg_S490_Validation, Bootstrap T:W
C42: Col L = S490 zero curve, hard-coded from the 07/21/26 capture.
C43: Result: 32/32 pillars, max |dz| 0.397bp, max |dDF| 1.88e-05, 0.08bp from 2Y.
C44: Residual is simple interest vs Bloomberg's daily-compounded short OIS.
C45: It is not fitted out: every curve input is a pulled quote.
A47: STEP 9 | B47: Curve interface | C47: Curve_Interface
C48: Exposes D(0,t) for any date. Interpolation selector at J7.
C49: CDS_Schedule and Swap_Pricer each hold their own inline copy of the
...

Sheet Conventions
A1: Conventions
A2: OIS quote conventions (DES/FLDS) for representative tenors — record before you bootstrap
A4: Convention attribute | B4: BDP field (verify via FLDS) | C4: USOSFRC (3M) | D4: USOSFR1 (1Y) | E4: USOSFR5 (5Y) | F4: USOSFR30 (30Y)
A5: Currency | B5: CRNCY | C5: =IFERROR(BDP("USOSFRC BGN Curncy","CRNCY"),"ERROR PLZ FIX") | D5: =IFERROR(BDP("USOSFR1 BGN Curncy","CRNCY"),"ERROR PLZ FIX") | E5: =IFERROR(BDP("USOSFR5 BGN Curncy","CRNCY"),"ERROR PLZ FIX") | F5: =IFERROR(BDP("USOSFR30 BGN Curncy","CRNCY"),"ERROR PLZ FIX")
A6: Reference index | B6: — DES/SWPM manual — | C6: — DES/SWPM — | D6: — DES/SWPM — | E6: — DES/SWPM — | F6: — DES/SWPM —
A7: Spot / settlement lag | B7: — DES/SWPM manual — | C7: — DES/SWPM — | D7: — DES/SWPM — | E7: — DES/SWPM — | F7: — DES/SWPM —
A8: Effective date rule | B8: — DES/SWPM manual — | C8: — DES/SWPM — | D8: — DES/SWPM — | E8: — DES/SWPM — | F8: — DES/SWPM —
A9: Maturity date rule | B9: — DES/SWPM manual — | C9: — DES/SWPM — | D9: — DES/SWPM — | E9: — DES/SWPM — | F9: — DES/SWPM —
A10: Business-day calendar | B10: CALENDAR_CODE | C10: =IFERROR(BDP("USOSFRC BGN Curncy","CALENDAR_CODE"),"ERROR PLZ FIX") | D10: =IFERROR(BDP("USOSFR1 BGN Curncy","CALENDAR_CODE"),"ERROR PLZ FIX") | E10: =IFERROR(BDP("USOSFR5 BGN Curncy","CALENDAR_CODE"),"ERROR PLZ FIX") | F10: =IFERROR(BDP("USOSFR30 BGN Curncy","CALENDAR_CODE"),"ERROR PLZ FIX")
A11: Business-day convention | B11: — DES/SWPM manual — | C11: — DES/SWPM — | D11: — DES/SWPM — | E11: — DES/SWPM — | F11: — DES/SWPM —
A12: Fixed-leg day count | B12: DAY_CNT_DES | C12: =IFERROR(BDP("USOSFRC BGN Curncy","DAY_CNT_DES"),"ERROR PLZ FIX") | D12: =IFERROR(BDP("USOSFR1 BGN Curncy","DAY_CNT_DES"),"ERROR PLZ FIX") | E12: =IFERROR(BDP("USOSFR5 BGN Curncy","DAY_CNT_DES"),"ERROR PLZ FIX") | F12: =IFERROR(BDP("USOSFR30 BGN Curncy","DAY_CNT_DES"),"ERROR PLZ FIX")
A13: Fixed-leg pay frequency | B13: — DES/SWPM manual — | C13: — DES/SWPM — | D13: — DES/SWPM — | E13: — DES/SWPM — | F13: — DES/SWPM —
A14: Floating-leg day count | B14: — DES/SWPM manual — | C14: — DES/SWPM — | D14: — DES/SWPM — | E14: — DES/SWPM — | F14: — DES/SWPM —
A15: Floating-leg pay frequency | B15: — DES/SWPM manual — | C15: — DES/SWPM — | D15: — DES/SWPM — | E15: — DES/SWPM — | F15: — DES/SWPM —
A16: SOFR compounding method | B16: — DES/SWPM manual — | C16: — DES/SWPM — | D16: — DES/SWPM — | E16: — DES/SWPM — | F16: — DES/SWPM —
A17: Payment lag | B17: — DES/SWPM manual — | C17: — DES/SWPM — | D17: — DES/SWPM — | E17: — DES/SWPM — | F17: — DES/SWPM —
A18: Observation shift / lookback | B18: — DES/SWPM manual — | C18: — DES/SWPM — | D18: — DES/SWPM — | E18: — DES/SWPM — | F18: — DES/SWPM —
A19: End-of-month treatment | B19: — DES/SWPM manual — | C19: — DES/SWPM — | D19: — DES/SWPM — | E19: — DES/SWPM — | F19: — DES/SWPM —
A21: USD SOFR OIS — MARKET-STANDARD CONVENTIONS (confirm per-trade in DES)
A22: Reference index | B22: USD-SOFR (compounded in arrears)
A23: Spot / settlement lag | B23: T+2 US business days
A24: Effective date rule | B24: Spot (T+2), modified following
A25: Maturity date rule | B25: Effective + tenor, modified following
A26: Business-day convention | B26: Modified Following
A27: Fixed-leg day count | B27: ACT/360
A28: Fixed-leg pay frequency | B28: Annual (single payment if tenor ≤ 1Y)
A29: Floating-leg day count | B29: ACT/360
A30: Floating-leg pay frequency | B30: Annual (single payment if tenor ≤ 1Y)
A31: SOFR compounding method | B31: Daily compounded, ACT/360
A32: Payment lag | B32: 2 US business days
A33: Observation shift / lookback | B33: None (payment-delay convention, 2 bd)
A34: End-of-month treatment | B34: EOM applies
A36: SWPM <GO>: build a representative SOFR OIS for 1Y, 5Y and 30Y and export the cashflow schedule — that gives an authoritative set of pay/accrual dates to test your own date generation against. Rows marked '— DES/SWPM —' are leg-level conventions that a rate-quote ticker does not carry; read them from DES <GO> on an actual swap (the market-standard defaults above are the expected values). Where a BDP cell shows 'N/A — use FLDS', open FLDS <GO> to find the enabled field.

Sheet SOFR_Fixings
A1: SOFR_Fixings
A2: Overnight SOFR fixing (SOFRRATE Index) — the curve's shortest anchor point
A4: CURRENT FIXING
A5: Ticker | B5: Field | C5: Value (%) | D5: As of | E5: O/N stub (%)
A6: =SOFR_TKR | B6: PX_LAST | C6: =IFERROR(BDP(SOFR_TKR,"PX_LAST")+0,E6) | D6: =IFERROR(BDP(SOFR_TKR,"LAST_UPDATE_DT"),"ERROR PLZ FIX") | E6: 3.59 | F6: O/N fixing. Informational only since Step 3 sets DF(settle)=1. Live BDP overrides this cell.
A9: DAILY HISTORY
A10: The BDH array below spills down two columns (Date, PX_LAST) from the anchor cell A12. It uses the HIST_START / HIST_END parameters on the Instructions tab.
A11: Date | B11: SOFR PX_LAST (%)
A12: =IFERROR(BDH(SOFR_TKR,"PX_LAST",TEXT(HIST_START,"mm/dd/yyyy"),TEXT(HIST_END,"mm/dd/yyyy")),"ERROR PLZ FIX")

Sheet SOFR_OIS_Quotes
A1: SOFR_OIS_Quotes | J1: REAL MARKET DATA - S490 USD SOFR, Step Forward (Cont), Settle 07/21/26, Curve Side Mid | N1: RECONCILIATION vs the Bloomberg curve export
A2: USD fixed-vs-SOFR OIS strip (USOSFR…, BGN) — 1W to 50Y. Maturity & years are derived live from the tenor. | J2: S490 screen mids, frozen 07/21/26. Used only when BDP fails. | N2: Paste export bid/ask in N:O. Q/R/S = BDP minus export, bp. Mixed signs of a few tenths = ticked apart. Consistent shift = wrong source/field. | T2: =IF(Bootstrap!$G$4="Fixed (S490 07/21/26)","FIXED - BDP ignored, curve on the 07/21/26 capture","LIVE - BDP mid, falling back to the capture if unavailable")
A3: Spot (T+2): | B3: =WORKDAY(VAL_DATE,2) | C3: Maturity & Tenor(yrs) recompute from the tenor label + spot. | T3: Column H is the mid actually used. T is always the raw BDP mid, so the live-vs-fixed gap stays visible in either mode.
A4: Ticker root | B4: Tenor | C4: Maturity date | D4: Tenor (yrs) | E4: PX_BID | F4: PX_ASK | G4: PX_LAST | H4: Mid = (Bid+Ask)/2 | I4: In bootstrap set | J4: Manual MID (%) <- S490_Snapshot | K4: Source | M4: Dates modified-following, weekends only. Matches S490. | N4: Export Bid (paste) | O4: Export Ask (paste) | P4: Export Mid | Q4: d Bid (bp) | R4: d Ask (bp) | S4: d Mid (bp) | T4: Live mid (BDP only) | U4: d live - fixed (bp)
A5: USOSFR1Z | B5: 1W | C5: =IF(MONTH((IF(RIGHT(B5,1)="W",$B$3+7*VALUE(LEFT(B5,LEN(B5)-1)),IF(RIGHT(B5,1)="M",EDATE($B$3,VALUE(LEFT(B5,LEN(B5)-1))),EDATE($B$3,12*VALUE(LEFT(B5,LEN(B5)-1)))))+IF(WEEKDAY(IF(RIGHT(B5,1)="W",$B$3+7*VALUE(LEFT(B5,LEN(B5)-1)),IF(RIGHT(B5,1)="M",EDATE($B$3,VALUE(LEFT(B5,LEN(B5)-1))),EDATE($B$3,12*VALUE(LEFT(B5,LEN(B5)-1))))),2)=6,2,IF(WEEKDAY(IF(RIGHT(B5,1)="W",$B$3+7*VALUE(LEFT(B5,LEN(B5)-1)),IF(RIGHT(B5,1)="M",EDATE($B$3,VALUE(LEFT(B5,LEN(B5)-1))),EDATE($B$3,12*VALUE(LEFT(B5,LEN(B5)-1))))),2)=7,1,0))))<>MONTH(IF(RIGHT(B5,1)="W",$B$3+7*VALUE(LEFT(B5,LEN(B5)-1)),IF(RIGHT(B5,1)="M",EDATE($B$3,VALUE(LEFT(B5,LEN(B5)-1))),EDATE($B$3,12*VALUE(LEFT(B5,LEN(B5)-1)))))),(IF(RIGHT(B5,1)="W",$B$3+7*VALUE(LEFT(B5,LEN(B5)-1)),IF(RIGHT(B5,1)="M",EDATE($B$3,VALUE(LEFT(B5,LEN(B5)-1))),EDATE($B$3,12*VALUE(LEFT(B5,LEN(B5)-1)))))-IF(WEEKDAY(IF(RIGHT(B5,1)="W",$B$3+7*VALUE(LEFT(B5,LEN(B5)-1)),IF(RIGHT(B5,1)="M",EDATE($B$3,VALUE(LEFT(B5,LEN(B5)-1))),EDATE($B$3,12*VALUE(LEFT(B5,LEN(B5)-1))))),2)=6,1,IF(WEEKDAY(IF(RIGHT(B5,1)="W",$B$3+7*VALUE(LEFT(B5,LEN(B5)-1)),IF(RIGHT(B5,1)="M",EDATE($B$3,VALUE(LEFT(B5,LEN(B5)-1))),EDATE($B$3,12*VALUE(LEFT(B5,LEN(B5)-1))))),2)=7,2,0))),(IF(RIGHT(B5,1)="W",$B$3+7*VALUE(LEFT(B5,LEN(B5)-1)),IF(RIGHT(B5,1)="M",EDATE($B$3,VALUE(LEFT(B5,LEN(B5)-1))),EDATE($B$3,12*VALUE(LEFT(B5,LEN(B5)-1)))))+IF(WEEKDAY(IF(RIGHT(B5,1)="W",$B$3+7*VALUE(LEFT(B5,LEN(B5)-1)),IF(RIGHT(B5,1)="M",EDATE($B$3,VALUE(LEFT(B5,LEN(B5)-1))),EDATE($B$3,12*VALUE(LEFT(B5,LEN(B5)-1))))),2)=6,2,IF(WEEKDAY(IF(RIGHT(B5,1)="W",$B$3+7*VALUE(LEFT(B5,LEN(B5)-1)),IF(RIGHT(B5,1)="M",EDATE($B$3,VALUE(LEFT(B5,LEN(B5)-1))),EDATE($B$3,12*VALUE(LEFT(B5,LEN(B5)-1))))),2)=7,1,0)))) | D5: =(C5-$B$3)/365 | E5: =IFERROR(BDP(A5&" "&PX_SRC&" Curncy","PX_BID"),"ERROR PLZ FIX") | F5: =IFERROR(BDP(A5&" "&PX_SRC&" Curncy","PX_ASK"),"ERROR PLZ FIX") | G5: =IFERROR(BDP(A5&" "&PX_SRC&" Curncy","PX_LAST"),"ERROR PLZ FIX") | H5: =IFERROR(IF(Bootstrap!$G$4="Test 1",INDEX(Testing!$B$8:$B$47,MATCH(C5,Testing!$F$8:$F$47,0)),IF(Bootstrap!$G$4="Test 2",INDEX(Testing!$B$58:$B$97,MATCH(C5,Testing!$F$58:$F$97,0)),IF(Bootstrap!$G$4="Test 3",INDEX(Testing!$B$108:$B$147,MATCH(C5,Testing!$F$108:$F$147,0)),IF(Bootstrap!$G$4="Fixed (S490 07/21/26)",J5,IF(ISNUMBER(T5),T5,J5))))),J5) | I5: Y | J5: =IFERROR(INDEX(S490_Snapshot!$C$7:$C$38,MATCH(B5,S490_Snapshot!$B$7:$B$38,0)),"") | K5: S490_Snapshot | P5: =IF(COUNT(N5:O5)=2,(N5+O5)/2,"") | Q5: =IF(AND(ISNUMBER(N5),ISNUMBER(E5)),(E5-N5)*100,"") | R5: =IF(AND(ISNUMBER(O5),ISNUMBER(F5)),(F5-O5)*100,"") | S5: =IF(AND(ISNUMBER(P5),ISNUMBER(H5)),(H5-P5)*100,"") | T5: =IFERROR((E5+F5)/2,IFERROR(G5+0,"")) | U5: =IF(OR(T5="",NOT(ISNUMBER(J5))),"",(T5-J5)*100)
A6: USOSFR2Z | B6: 2W | C6: =IF(MONTH((IF(RIGHT(B6,1)="W",$B$3+7*VALUE(LEFT(B6,LEN(B6)-1)),IF(RIGHT(B6,1)="M",EDATE($B$3,VALUE(LEFT(B6,LEN(B6)-1))),EDATE($B$3,12*VALUE(LEFT(B6,LEN(B6)-1)))))+IF(WEEKDAY(IF(RIGHT(B6,1)="W",$B$3+7*VALUE(LEFT(B6,LEN(B6)-1)),IF(RIGHT(B6,1)="M",EDATE($B$3,VALUE(LEFT(B6,LEN(B6)-1))),EDATE($B$3,12*VALUE(LEFT(B6,LEN(B6)-1))))),2)=6,2,IF(WEEKDAY(IF(RIGHT(B6,1)="W",$B$3+7*VALUE(LEFT(B6,LEN(B6)-1)),IF(RIGHT(B6,1)="M",EDATE($B$3,VALUE(LEFT(B6,LEN(B6)-1))),EDATE($B$3,12*VALUE(LEFT(B6,LEN(B6)-1))))),2)=7,1,0))))<>MONTH(IF(RIGHT(B6,1)="W",$B$3+7*VALUE(LEFT(B6,LEN(B6)-1)),IF(RIGHT(B6,1)="M",EDATE($B$3,VALUE(LEFT(B6,LEN(B6)-1))),EDATE($B$3,12*VALUE(LEFT(B6,LEN(B6)-1)))))),(IF(RIGHT(B6,1)="W",$B$3+7*VALUE(LEFT(B6,LEN(B6)-1)),IF(RIGHT(B6,1)="M",EDATE($B$3,VALUE(LEFT(B6,LEN(B6)-1))),EDATE($B$3,12*VALUE(LEFT(B6,LEN(B6)-1)))))-IF(WEEKDAY(IF(RIGHT(B6,1)="W",$B$3+7*VALUE(LEFT(B6,LEN(B6)-1)),IF(RIGHT(B6,1)="M",EDATE($B$3,VALUE(LEFT(B6,LEN(B6)-1))),EDATE($B$3,12*VALUE(LEFT(B6,LEN(B6)-1))))),2)=6,1,IF(WEEKDAY(IF(RIGHT(B6,1)="W",$B$3+7*VALUE(LEFT(B6,LEN(B6)-1)),IF(RIGHT(B6,1)="M",EDATE($B$3,VALUE(LEFT(B6,LEN(B6)-1))),EDATE($B$3,12*VALUE(LEFT(B6,LEN(B6)-1))))),2)=7,2,0))),(IF(RIGHT(B6,1)="W",$B$3+7*VALUE(LEFT(B6,LEN(B6)-1)),IF(RIGHT(B6,1)="M",EDATE($B$3,VALUE(LEFT(B6,LEN(B6)-1))),EDATE($B$3,12*VALUE(LEFT(B6,LEN(B6)-1)))))+IF(WEEKDAY(IF(RIGHT(B6,1)="W",$B$3+7*VALUE(LEFT(B6,LEN(B6)-1)),IF(RIGHT(B6,1)="M",EDATE($B$3,VALUE(LEFT(B6,LEN(B6)-1))),EDATE($B$3,12*VALUE(LEFT(B6,LEN(B6)-1))))),2)=6,2,IF(WEEKDAY(IF(RIGHT(B6,1)="W",$B$3+7*VALUE(LEFT(B6,LEN(B6)-1)),IF(RIGHT(B6,1)="M",EDATE($B$3,VALUE(LEFT(B6,LEN(B6)-1))),EDATE($B$3,12*VALUE(LEFT(B6,LEN(B6)-1))))),2)=7,1,0)))) | D6: =(C6-$B$3)/365 | E6: =IFERROR(BDP(A6&" "&PX_SRC&" Curncy","PX_BID"),"ERROR PLZ FIX") | F6: =IFERROR(BDP(A6&" "&PX_SRC&" Curncy","PX_ASK"),"ERROR PLZ FIX") | G6: =IFERROR(BDP(A6&" "&PX_SRC&" Curncy","PX_LAST"),"ERROR PLZ FIX") | H6: =IFERROR(IF(Bootstrap!$G$4="Test 1",INDEX(Testing!$B$8:$B$47,MATCH(C6,Testing!$F$8:$F$47,0)),IF(Bootstrap!$G$4="Test 2",INDEX(Testing!$B$58:$B$97,MATCH(C6,Testing!$F$58:$F$97,0)),IF(Bootstrap!$G$4="Test 3",INDEX(Testing!$B$108:$B$147,MATCH(C6,Testing!$F$108:$F$147,0)),IF(Bootstrap!$G$4="Fixed (S490 07/21/26)",J6,IF(ISNUMBER(T6),T6,J6))))),J6) | J6: =IFERROR(INDEX(S490_Snapshot!$C$7:$C$38,MATCH(B6,S490_Snapshot!$B$7:$B$38,0)),"") | K6: S490_Snapshot | P6: =IF(COUNT(N6:O6)=2,(N6+O6)/2,"") | Q6: =IF(AND(ISNUMBER(N6),ISNUMBER(E6)),(E6-N6)*100,"") | R6: =IF(AND(ISNUMBER(O6),ISNUMBER(F6)),(F6-O6)*100,"") | S6: =IF(AND(ISNUMBER(P6),ISNUMBER(H6)),(H6-P6)*100,"") | T6: =IFERROR((E6+F6)/2,IFERROR(G6+0,"")) | U6: =IF(OR(T6="",NOT(ISNUMBER(J6))),"",(T6-J6)*100)
A7: USOSFR3Z | B7: 3W | C7: =IF(MONTH((IF(RIGHT(B7,1)="W",$B$3+7*VALUE(LEFT(B7,LEN(B7)-1)),IF(RIGHT(B7,1)="M",EDATE($B$3,VALUE(LEFT(B7,LEN(B7)-1))),EDATE($B$3,12*VALUE(LEFT(B7,LEN(B7)-1)))))+IF(WEEKDAY(IF(RIGHT(B7,1)="W",$B$3+7*VALUE(LEFT(B7,LEN(B7)-1)),IF(RIGHT(B7,1)="M",EDATE($B$3,VALUE(LEFT(B7,LEN(B7)-1))),EDATE($B$3,12*VALUE(LEFT(B7,LEN(B7)-1))))),2)=6,2,IF(WEEKDAY(IF(RIGHT(B7,1)="W",$B$3+7*VALUE(LEFT(B7,LEN(B7)-1)),IF(RIGHT(B7,1)="M",EDATE($B$3,VALUE(LEFT(B7,LEN(B7)-1))),EDATE($B$3,12*VALUE(LEFT(B7,LEN(B7)-1))))),2)=7,1,0))))<>MONTH(IF(RIGHT(B7,1)="W",$B$3+7*VALUE(LEFT(B7,LEN(B7)-1)),IF(RIGHT(B7,1)="M",EDATE($B$3,VALUE(LEFT(B7,LEN(B7)-1))),EDATE($B$3,12*VALUE(LEFT(B7,LEN(B7)-1)))))),(IF(RIGHT(B7,1)="W",$B$3+7*VALUE(LEFT(B7,LEN(B7)-1)),IF(RIGHT(B7,1)="M",EDATE($B$3,VALUE(LEFT(B7,LEN(B7)-1))),EDATE($B$3,12*VALUE(LEFT(B7,LEN(B7)-1)))))-IF(WEEKDAY(IF(RIGHT(B7,1)="W",$B$3+7*VALUE(LEFT(B7,LEN(B7)-1)),IF(RIGHT(B7,1)="M",EDATE($B$3,VALUE(LEFT(B7,LEN(B7)-1))),EDATE($B$3,12*VALUE(LEFT(B7,LEN(B7)-1))))),2)=6,1,IF(WEEKDAY(IF(RIGHT(B7,1)="W",$B$3+7*VALUE(LEFT(B7,LEN(B7)-1)),IF(RIGHT(B7,1)="M",EDATE($B$3,VALUE(LEFT(B7,LEN(B7)-1))),EDATE($B$3,12*VALUE(LEFT(B7,LEN(B7)-1))))),2)=7,2,0))),(IF(RIGHT(B7,1)="W",$B$3+7*VALUE(LEFT(B7,LEN(B7)-1)),IF(RIGHT(B7,1)="M",EDATE($B$3,VALUE(LEFT(B7,LEN(B7)-1))),EDATE($B$3,12*VALUE(LEFT(B7,LEN(B7)-1)))))+IF(WEEKDAY(IF(RIGHT(B7,1)="W",$B$3+7*VALUE(LEFT(B7,LEN(B7)-1)),IF(RIGHT(B7,1)="M",EDATE($B$3,VALUE(LEFT(B7,LEN(B7)-1))),EDATE($B$3,12*VALUE(LEFT(B7,LEN(B7)-1))))),2)=6,2,IF(WEEKDAY(IF(RIGHT(B7,1)="W",$B$3+7*VALUE(LEFT(B7,LEN(B7)-1)),IF(RIGHT(B7,1)="M",EDATE($B$3,VALUE(LEFT(B7,LEN(B7)-1))),EDATE($B$3,12*VALUE(LEFT(B7,LEN(B7)-1))))),2)=7,1,0)))) | D7: =(C7-$B$3)/365 | E7: =IFERROR(BDP(A7&" "&PX_SRC&" Curncy","PX_BID"),"ERROR PLZ FIX") | F7: =IFERROR(BDP(A7&" "&PX_SRC&" Curncy","PX_ASK"),"ERROR PLZ FIX") | G7: =IFERROR(BDP(A7&" "&PX_SRC&" Curncy","PX_LAST"),"ERROR PLZ FIX") | H7: =IFERROR(IF(Bootstrap!$G$4="Test 1",INDEX(Testing!$B$8:$B$47,MATCH(C7,Testing!$F$8:$F$47,0)),IF(Bootstrap!$G$4="Test 2",INDEX(Testing!$B$58:$B$97,MATCH(C7,Testing!$F$58:$F$97,0)),IF(Bootstrap!$G$4="Test 3",INDEX(Testing!$B$108:$B$147,MATCH(C7,Testing!$F$108:$F$147,0)),IF(Bootstrap!$G$4="Fixed (S490 07/21/26)",J7,IF(ISNUMBER(T7),T7,J7))))),J7) | J7: =IFERROR(INDEX(S490_Snapshot!$C$7:$C$38,MATCH(B7,S490_Snapshot!$B$7:$B$38,0)),"") | K7: S490_Snapshot | P7: =IF(COUNT(N7:O7)=2,(N7+O7)/2,"") | Q7: =IF(AND(ISNUMBER(N7),ISNUMBER(E7)),(E7-N7)*100,"") | R7: =IF(AND(ISNUMBER(O7),ISNUMBER(F7)),(F7-O7)*100,"") | S7: =IF(AND(ISNUMBER(P7),ISNUMBER(H7)),(H7-P7)*100,"") | T7: =IFERROR((E7+F7)/2,IFERROR(G7+0,"")) | U7: =IF(OR(T7="",NOT(ISNUMBER(J7))),"",(T7-J7)*100)
A8: USOSFRA | B8: 1M | C8: =IF(MONTH((IF(RIGHT(B8,1)="W",$B$3+7*VALUE(LEFT(B8,LEN(B8)-1)),IF(RIGHT(B8,1)="M",EDATE($B$3,VALUE(LEFT(B8,LEN(B8)-1))),EDATE($B$3,12*VALUE(LEFT(B8,LEN(B8)-1)))))+IF(WEEKDAY(IF(RIGHT(B8,1)="W",$B$3+7*VALUE(LEFT(B8,LEN(B8)-1)),IF(RIGHT(B8,1)="M",EDATE($B$3,VALUE(LEFT(B8,LEN(B8)-1))),EDATE($B$3,12*VALUE(LEFT(B8,LEN(B8)-1))))),2)=6,2,IF(WEEKDAY(IF(RIGHT(B8,1)="W",$B$3+7*VALUE(LEFT(B8,LEN(B8)-1)),IF(RIGHT(B8,1)="M",EDATE($B$3,VALUE(LEFT(B8,LEN(B8)-1))),EDATE($B$3,12*VALUE(LEFT(B8,LEN(B8)-1))))),2)=7,1,0))))<>MONTH(IF(RIGHT(B8,1)="W",$B$3+7*VALUE(LEFT(B8,LEN(B8)-1)),IF(RIGHT(B8,1)="M",EDATE($B$3,VALUE(LEFT(B8,LEN(B8)-1))),EDATE($B$3,12*VALUE(LEFT(B8,LEN(B8)-1)))))),(IF(RIGHT(B8,1)="W",$B$3+7*VALUE(LEFT(B8,LEN(B8)-1)),IF(RIGHT(B8,1)="M",EDATE($B$3,VALUE(LEFT(B8,LEN(B8)-1))),EDATE($B$3,12*VALUE(LEFT(B8,LEN(B8)-1)))))-IF(WEEKDAY(IF(RIGHT(B8,1)="W",$B$3+7*VALUE(LEFT(B8,LEN(B8)-1)),IF(RIGHT(B8,1)="M",EDATE($B$3,VALUE(LEFT(B8,LEN(B8)-1))),EDATE($B$3,12*VALUE(LEFT(B8,LEN(B8)-1))))),2)=6,1,IF(WEEKDAY(IF(RIGHT(B8,1)="W",$B$3+7*VALUE(LEFT(B8,LEN(B8)-1)),IF(RIGHT(B8,1)="M",EDATE($B$3,VALUE(LEFT(B8,LEN(B8)-1))),EDATE($B$3,12*VALUE(LEFT(B8,LEN(B8)-1))))),2)=7,2,0))),(IF(RIGHT(B8,1)="W",$B$3+7*VALUE(LEFT(B8,LEN(B8)-1)),IF(RIGHT(B8,1)="M",EDATE($B$3,VALUE(LEFT(B8,LEN(B8)-1))),EDATE($B$3,12*VALUE(LEFT(B8,LEN(B8)-1)))))+IF(WEEKDAY(IF(RIGHT(B8,1)="W",$B$3+7*VALUE(LEFT(B8,LEN(B8)-1)),IF(RIGHT(B8,1)="M",EDATE($B$3,VALUE(LEFT(B8,LEN(B8)-1))),EDATE($B$3,12*VALUE(LEFT(B8,LEN(B8)-1))))),2)=6,2,IF(WEEKDAY(IF(RIGHT(B8,1)="W",$B$3+7*VALUE(LEFT(B8,LEN(B8)-1)),IF(RIGHT(B8,1)="M",EDATE($B$3,VALUE(LEFT(B8,LEN(B8)-1))),EDATE($B$3,12*VALUE(LEFT(B8,LEN(B8)-1))))),2)=7,1,0)))) | D8: =(C8-$B$3)/365 | E8: =IFERROR(BDP(A8&" "&PX_SRC&" Curncy","PX_BID"),"ERROR PLZ FIX") | F8: =IFERROR(BDP(A8&" "&PX_SRC&" Curncy","PX_ASK"),"ERROR PLZ FIX") | G8: =IFERROR(BDP(A8&" "&PX_SRC&" Curncy","PX_LAST"),"ERROR PLZ FIX") | H8: =IFERROR(IF(Bootstrap!$G$4="Test 1",INDEX(Testing!$B$8:$B$47,MATCH(C8,Testing!$F$8:$F$47,0)),IF(Bootstrap!$G$4="Test 2",INDEX(Testing!$B$58:$B$97,MATCH(C8,Testing!$F$58:$F$97,0)),IF(Bootstrap!$G$4="Test 3",INDEX(Testing!$B$108:$B$147,MATCH(C8,Testing!$F$108:$F$147,0)),IF(Bootstrap!$G$4="Fixed (S490 07/21/26)",J8,IF(ISNUMBER(T8),T8,J8))))),J8) | I8: Y | J8: =IFERROR(INDEX(S490_Snapshot!$C$7:$C$38,MATCH(B8,S490_Snapshot!$B$7:$B$38,0)),"") | K8: S490_Snapshot | P8: =IF(COUNT(N8:O8)=2,(N8+O8)/2,"") | Q8: =IF(AND(ISNUMBER(N8),ISNUMBER(E8)),(E8-N8)*100,"") | R8: =IF(AND(ISNUMBER(O8),ISNUMBER(F8)),(F8-O8)*100,"") | S8: =IF(AND(ISNUMBER(P8),ISNUMBER(H8)),(H8-P8)*100,"") | T8: =IFERROR((E8+F8)/2,IFERROR(G8+0,"")) | U8: =IF(OR(T8="",NOT(ISNUMBER(J8))),"",(T8-J8)*100)
A9: USOSFRB | B9: 2M | C9: =IF(MONTH((IF(RIGHT(B9,1)="W",$B$3+7*VALUE(LEFT(B9,LEN(B9)-1)),IF(RIGHT(B9,1)="M",EDATE($B$3,VALUE(LEFT(B9,LEN(B9)-1))),EDATE($B$3,12*VALUE(LEFT(B9,LEN(B9)-1)))))+IF(WEEKDAY(IF(RIGHT(B9,1)="W",$B$3+7*VALUE(LEFT(B9,LEN(B9)-1)),IF(RIGHT(B9,1)="M",EDATE($B$3,VALUE(LEFT(B9,LEN(B9)-1))),EDATE($B$3,12*VALUE(LEFT(B9,LEN(B9)-1))))),2)=6,2,IF(WEEKDAY(IF(RIGHT(B9,1)="W",$B$3+7*VALUE(LEFT(B9,LEN(B9)-1)),IF(RIGHT(B9,1)="M",EDATE($B$3,VALUE(LEFT(B9,LEN(B9)-1))),EDATE($B$3,12*VALUE(LEFT(B9,LEN(B9)-1))))),2)=7,1,0))))<>MONTH(IF(RIGHT(B9,1)="W",$B$3+7*VALUE(LEFT(B9,LEN(B9)-1)),IF(RIGHT(B9,1)="M",EDATE($B$3,VALUE(LEFT(B9,LEN(B9)-1))),EDATE($B$3,12*VALUE(LEFT(B9,LEN(B9)-1)))))),(IF(RIGHT(B9,1)="W",$B$3+7*VALUE(LEFT(B9,LEN(B9)-1)),IF(RIGHT(B9,1)="M",EDATE($B$3,VALUE(LEFT(B9,LEN(B9)-1))),EDATE($B$3,12*VALUE(LEFT(B9,LEN(B9)-1)))))-IF(WEEKDAY(IF(RIGHT(B9,1)="W",$B$3+7*VALUE(LEFT(B9,LEN(B9)-1)),IF(RIGHT(B9,1)="M",EDATE($B$3,VALUE(LEFT(B9,LEN(B9)-1))),EDATE($B$3,12*VALUE(LEFT(B9,LEN(B9)-1))))),2)=6,1,IF(WEEKDAY(IF(RIGHT(B9,1)="W",$B$3+7*VALUE(LEFT(B9,LEN(B9)-1)),IF(RIGHT(B9,1)="M",EDATE($B$3,VALUE(LEFT(B9,LEN(B9)-1))),EDATE($B$3,12*VALUE(LEFT(B9,LEN(B9)-1))))),2)=7,2,0))),(IF(RIGHT(B9,1)="W",$B$3+7*VALUE(LEFT(B9,LEN(B9)-1)),IF(RIGHT(B9,1)="M",EDATE($B$3,VALUE(LEFT(B9,LEN(B9)-1))),EDATE($B$3,12*VALUE(LEFT(B9,LEN(B9)-1)))))+IF(WEEKDAY(IF(RIGHT(B9,1)="W",$B$3+7*VALUE(LEFT(B9,LEN(B9)-1)),IF(RIGHT(B9,1)="M",EDATE($B$3,VALUE(LEFT(B9,LEN(B9)-1))),EDATE($B$3,12*VALUE(LEFT(B9,LEN(B9)-1))))),2)=6,2,IF(WEEKDAY(IF(RIGHT(B9,1)="W",$B$3+7*VALUE(LEFT(B9,LEN(B9)-1)),IF(RIGHT(B9,1)="M",EDATE($B$3,VALUE(LEFT(B9,LEN(B9)-1))),EDATE($B$3,12*VALUE(LEFT(B9,LEN(B9)-1))))),2)=7,1,0)))) | D9: =(C9-$B$3)/365 | E9: =IFERROR(BDP(A9&" "&PX_SRC&" Curncy","PX_BID"),"ERROR PLZ FIX") | F9: =IFERROR(BDP(A9&" "&PX_SRC&" Curncy","PX_ASK"),"ERROR PLZ FIX") | G9: =IFERROR(BDP(A9&" "&PX_SRC&" Curncy","PX_LAST"),"ERROR PLZ FIX") | H9: =IFERROR(IF(Bootstrap!$G$4="Test 1",INDEX(Testing!$B$8:$B$47,MATCH(C9,Testing!$F$8:$F$47,0)),IF(Bootstrap!$G$4="Test 2",INDEX(Testing!$B$58:$B$97,MATCH(C9,Testing!$F$58:$F$97,0)),IF(Bootstrap!$G$4="Test 3",INDEX(Testing!$B$108:$B$147,MATCH(C9,Testing!$F$108:$F$147,0)),IF(Bootstrap!$G$4="Fixed (S490 07/21/26)",J9,IF(ISNUMBER(T9),T9,J9))))),J9) | J9: =IFERROR(INDEX(S490_Snapshot!$C$7:$C$38,MATCH(B9,S490_Snapshot!$B$7:$B$38,0)),"") | K9: S490_Snapshot | P9: =IF(COUNT(N9:O9)=2,(N9+O9)/2,"") | Q9: =IF(AND(ISNUMBER(N9),ISNUMBER(E9)),(E9-N9)*100,"") | R9: =IF(AND(ISNUMBER(O9),ISNUMBER(F9)),(F9-O9)*100,"") | S9: =IF(AND(ISNUMBER(P9),ISNUMBER(H9)),(H9-P9)*100,"") | T9: =IFERROR((E9+F9)/2,IFERROR(G9+0,"")) | U9: =IF(OR(T9="",NOT(ISNUMBER(J9))),"",(T9-J9)*100)
A10: USOSFRC | B10: 3M | C10: =IF(MONTH((IF(RIGHT(B10,1)="W",$B$3+7*VALUE(LEFT(B10,LEN(B10)-1)),IF(RIGHT(B10,1)="M",EDATE($B$3,VALUE(LEFT(B10,LEN(B10)-1))),EDATE($B$3,12*VALUE(LEFT(B10,LEN(B10)-1)))))+IF(WEEKDAY(IF(RIGHT(B10,1)="W",$B$3+7*VALUE(LEFT(B10,LEN(B10)-1)),IF(RIGHT(B10,1)="M",EDATE($B$3,VALUE(LEFT(B10,LEN(B10)-1))),EDATE($B$3,12*VALUE(LEFT(B10,LEN(B10)-1))))),2)=6,2,IF(WEEKDAY(IF(RIGHT(B10,1)="W",$B$3+7*VALUE(LEFT(B10,LEN(B10)-1)),IF(RIGHT(B10,1)="M",EDATE($B$3,VALUE(LEFT(B10,LEN(B10)-1))),EDATE($B$3,12*VALUE(LEFT(B10,LEN(B10)-1))))),2)=7,1,0))))<>MONTH(IF(RIGHT(B10,1)="W",$B$3+7*VALUE(LEFT(B10,LEN(B10)-1)),IF(RIGHT(B10,1)="M",EDATE($B$3,VALUE(LEFT(B10,LEN(B10)-1))),EDATE($B$3,12*VALUE(LEFT(B10,LEN(B10)-1)))))),(IF(RIGHT(B10,1)="W",$B$3+7*VALUE(LEFT(B10,LEN(B10)-1)),IF(RIGHT(B10,1)="M",EDATE($B$3,VALUE(LEFT(B10,LEN(B10)-1))),EDATE($B$3,12*VALUE(LEFT(B10,LEN(B10)-1)))))-IF(WEEKDAY(IF(RIGHT(B10,1)="W",$B$3+7*VALUE(LEFT(B10,LEN(B10)-1)),IF(RIGHT(B10,1)="M",EDATE($B$3,VALUE(LEFT(B10,LEN(B10)-1))),EDATE($B$3,12*VALUE(LEFT(B10,LEN(B10)-1))))),2)=6,1,IF(WEEKDAY(IF(RIGHT(B10,1)="W",$B$3+7*VALUE(LEFT(B10,LEN(B10)-1)),IF(RIGHT(B10,1)="M",EDATE($B$3,VALUE(LEFT(B10,LEN(B10)-1))),EDATE($B$3,12*VALUE(LEFT(B10,LEN(B10)-1))))),2)=7,2,0))),(IF(RIGHT(B10,1)="W",$B$3+7*VALUE(LEFT(B10,LEN(B10)-1)),IF(RIGHT(B10,1)="M",EDATE($B$3,VALUE(LEFT(B10,LEN(B10)-1))),EDATE($B$3,12*VALUE(LEFT(B10,LEN(B10)-1)))))+IF(WEEKDAY(IF(RIGHT(B10,1)="W",$B$3+7*VALUE(LEFT(B10,LEN(B10)-1)),IF(RIGHT(B10,1)="M",EDATE($B$3,VALUE(LEFT(B10,LEN(B10)-1))),EDATE($B$3,12*VALUE(LEFT(B10,LEN(B10)-1))))),2)=6,2,IF(WEEKDAY(IF(RIGHT(B10,1)="W",$B$3+7*VALUE(LEFT(B10,LEN(B10)-1)),IF(RIGHT(B10,1)="M",EDATE($B$3,VALUE(LEFT(B10,LEN(B10)-1))),EDATE($B$3,12*VALUE(LEFT(B10,LEN(B10)-1))))),2)=7,1,0)))) | D10: =(C10-$B$3)/365 | E10: =IFERROR(BDP(A10&" "&PX_SRC&" Curncy","PX_BID"),"ERROR PLZ FIX") | F10: =IFERROR(BDP(A10&" "&PX_SRC&" Curncy","PX_ASK"),"ERROR PLZ FIX") | G10: =IFERROR(BDP(A10&" "&PX_SRC&" Curncy","PX_LAST"),"ERROR PLZ FIX") | H10: =IFERROR(IF(Bootstrap!$G$4="Test 1",INDEX(Testing!$B$8:$B$47,MATCH(C10,Testing!$F$8:$F$47,0)),IF(Bootstrap!$G$4="Test 2",INDEX(Testing!$B$58:$B$97,MATCH(C10,Testing!$F$58:$F$97,0)),IF(Bootstrap!$G$4="Test 3",INDEX(Testing!$B$108:$B$147,MATCH(C10,Testing!$F$108:$F$147,0)),IF(Bootstrap!$G$4="Fixed (S490 07/21/26)",J10,IF(ISNUMBER(T10),T10,J10))))),J10) | I10: Y | J10: =IFERROR(INDEX(S490_Snapshot!$C$7:$C$38,MATCH(B10,S490_Snapshot!$B$7:$B$38,0)),"") | K10: S490_Snapshot | P10: =IF(COUNT(N10:O10)=2,(N10+O10)/2,"") | Q10: =IF(AND(ISNUMBER(N10),ISNUMBER(E10)),(E10-N10)*100,"") | R10: =IF(AND(ISNUMBER(O10),ISNUMBER(F10)),(F10-O10)*100,"") | S10: =IF(AND(ISNUMBER(P10),ISNUMBER(H10)),(H10-P10)*100,"") | T10: =IFERROR((E10+F10)/2,IFERROR(G10+0,"")) | U10: =IF(OR(T10="",NOT(ISNUMBER(J10))),"",(T10-J10)*100)
A11: USOSFRD | B11: 4M | C11: =IF(MONTH((IF(RIGHT(B11,1)="W",$B$3+7*VALUE(LEFT(B11,LEN(B11)-1)),IF(RIGHT(B11,1)="M",EDATE($B$3,VALUE(LEFT(B11,LEN(B11)-1))),EDATE($B$3,12*VALUE(LEFT(B11,LEN(B11)-1)))))+IF(WEEKDAY(IF(RIGHT(B11,1)="W",$B$3+7*VALUE(LEFT(B11,LEN(B11)-1)),IF(RIGHT(B11,1)="M",EDATE($B$3,VALUE(LEFT(B11,LEN(B11)-1))),EDATE($B$3,12*VALUE(LEFT(B11,LEN(B11)-1))))),2)=6,2,IF(WEEKDAY(IF(RIGHT(B11,1)="W",$B$3+7*VALUE(LEFT(B11,LEN(B11)-1)),IF(RIGHT(B11,1)="M",EDATE($B$3,VALUE(LEFT(B11,LEN(B11)-1))),EDATE($B$3,12*VALUE(LEFT(B11,LEN(B11)-1))))),2)=7,1,0))))<>MONTH(IF(RIGHT(B11,1)="W",$B$3+7*VALUE(LEFT(B11,LEN(B11)-1)),IF(RIGHT(B11,1)="M",EDATE($B$3,VALUE(LEFT(B11,LEN(B11)-1))),EDATE($B$3,12*VALUE(LEFT(B11,LEN(B11)-1)))))),(IF(RIGHT(B11,1)="W",$B$3+7*VALUE(LEFT(B11,LEN(B11)-1)),IF(RIGHT(B11,1)="M",EDATE($B$3,VALUE(LEFT(B11,LEN(B11)-1))),EDATE($B$3,12*VALUE(LEFT(B11,LEN(B11)-1)))))-IF(WEEKDAY(IF(RIGHT(B11,1)="W",$B$3+7*VALUE(LEFT(B11,LEN(B11)-1)),IF(RIGHT(B11,1)="M",EDATE($B$3,VALUE(LEFT(B11,LEN(B11)-1))),EDATE($B$3,12*VALUE(LEFT(B11,LEN(B11)-1))))),2)=6,1,IF(WEEKDAY(IF(RIGHT(B11,1)="W",$B$3+7*VALUE(LEFT(B11,LEN(B11)-1)),IF(RIGHT(B11,1)="M",EDATE($B$3,VALUE(LEFT(B11,LEN(B11)-1))),EDATE($B$3,12*VALUE(LEFT(B11,LEN(B11)-1))))),2)=7,2,0))),(IF(RIGHT(B11,1)="W",$B$3+7*VALUE(LEFT(B11,LEN(B11)-1)),IF(RIGHT(B11,1)="M",EDATE($B$3,VALUE(LEFT(B11,LEN(B11)-1))),EDATE($B$3,12*VALUE(LEFT(B11,LEN(B11)-1)))))+IF(WEEKDAY(IF(RIGHT(B11,1)="W",$B$3+7*VALUE(LEFT(B11,LEN(B11)-1)),IF(RIGHT(B11,1)="M",EDATE($B$3,VALUE(LEFT(B11,LEN(B11)-1))),EDATE($B$3,12*VALUE(LEFT(B11,LEN(B11)-1))))),2)=6,2,IF(WEEKDAY(IF(RIGHT(B11,1)="W",$B$3+7*VALUE(LEFT(B11,LEN(B11)-1)),IF(RIGHT(B11,1)="M",EDATE($B$3,VALUE(LEFT(B11,LEN(B11)-1))),EDATE($B$3,12*VALUE(LEFT(B11,LEN(B11)-1))))),2)=7,1,0)))) | D11: =(C11-$B$3)/365 | E11: =IFERROR(BDP(A11&" "&PX_SRC&" Curncy","PX_BID"),"ERROR PLZ FIX") | F11: =IFERROR(BDP(A11&" "&PX_SRC&" Curncy","PX_ASK"),"ERROR PLZ FIX") | G11: =IFERROR(BDP(A11&" "&PX_SRC&" Curncy","PX_LAST"),"ERROR PLZ FIX") | H11: =IFERROR(IF(Bootstrap!$G$4="Test 1",INDEX(Testing!$B$8:$B$47,MATCH(C11,Testing!$F$8:$F$47,0)),IF(Bootstrap!$G$4="Test 2",INDEX(Testing!$B$58:$B$97,MATCH(C11,Testing!$F$58:$F$97,0)),IF(Bootstrap!$G$4="Test 3",INDEX(Testing!$B$108:$B$147,MATCH(C11,Testing!$F$108:$F$147,0)),IF(Bootstrap!$G$4="Fixed (S490 07/21/26)",J11,IF(ISNUMBER(T11),T11,J11))))),J11) | J11: =IFERROR(INDEX(S490_Snapshot!$C$7:$C$38,MATCH(B11,S490_Snapshot!$B$7:$B$38,0)),"") | K11: S490_Snapshot | P11: =IF(COUNT(N11:O11)=2,(N11+O11)/2,"") | Q11: =IF(AND(ISNUMBER(N11),ISNUMBER(E11)),(E11-N11)*100,"") | R11: =IF(AND(ISNUMBER(O11),ISNUMBER(F11)),(F11-O11)*100,"") | S11: =IF(AND(ISNUMBER(P11),ISNUMBER(H11)),(H11-P11)*100,"") | T11: =IFERROR((E11+F11)/2,IFERROR(G11+0,"")) | U11: =IF(OR(T11="",NOT(ISNUMBER(J11))),"",(T11-J11)*100)
A12: USOSFRE | B12: 5M | C12: =IF(MONTH((IF(RIGHT(B12,1)="W",$B$3+7*VALUE(LEFT(B12,LEN(B12)-1)),IF(RIGHT(B12,1)="M",EDATE($B$3,VALUE(LEFT(B12,LEN(B12)-1))),EDATE($B$3,12*VALUE(LEFT(B12,LEN(B12)-1)))))+IF(WEEKDAY(IF(RIGHT(B12,1)="W",$B$3+7*VALUE(LEFT(B12,LEN(B12)-1)),IF(RIGHT(B12,1)="M",EDATE($B$3,VALUE(LEFT(B12,LEN(B12)-1))),EDATE($B$3,12*VALUE(LEFT(B12,LEN(B12)-1))))),2)=6,2,IF(WEEKDAY(IF(RIGHT(B12,1)="W",$B$3+7*VALUE(LEFT(B12,LEN(B12)-1)),IF(RIGHT(B12,1)="M",EDATE($B$3,VALUE(LEFT(B12,LEN(B12)-1))),EDATE($B$3,12*VALUE(LEFT(B12,LEN(B12)-1))))),2)=7,1,0))))<>MONTH(IF(RIGHT(B12,1)="W",$B$3+7*VALUE(LEFT(B12,LEN(B12)-1)),IF(RIGHT(B12,1)="M",EDATE($B$3,VALUE(LEFT(B12,LEN(B12)-1))),EDATE($B$3,12*VALUE(LEFT(B12,LEN(B12)-1)))))),(IF(RIGHT(B12,1)="W",$B$3+7*VALUE(LEFT(B12,LEN(B12)-1)),IF(RIGHT(B12,1)="M",EDATE($B$3,VALUE(LEFT(B12,LEN(B12)-1))),EDATE($B$3,12*VALUE(LEFT(B12,LEN(B12)-1)))))-IF(WEEKDAY(IF(RIGHT(B12,1)="W",$B$3+7*VALUE(LEFT(B12,LEN(B12)-1)),IF(RIGHT(B12,1)="M",EDATE($B$3,VALUE(LEFT(B12,LEN(B12)-1))),EDATE($B$3,12*VALUE(LEFT(B12,LEN(B12)-1))))),2)=6,1,IF(WEEKDAY(IF(RIGHT(B12,1)="W",$B$3+7*VALUE(LEFT(B12,LEN(B12)-1)),IF(RIGHT(B12,1)="M",EDATE($B$3,VALUE(LEFT(B12,LEN(B12)-1))),EDATE($B$3,12*VALUE(LEFT(B12,LEN(B12)-1))))),2)=7,2,0))),(IF(RIGHT(B12,1)="W",$B$3+7*VALUE(LEFT(B12,LEN(B12)-1)),IF(RIGHT(B12,1)="M",EDATE($B$3,VALUE(LEFT(B12,LEN(B12)-1))),EDATE($B$3,12*VALUE(LEFT(B12,LEN(B12)-1)))))+IF(WEEKDAY(IF(RIGHT(B12,1)="W",$B$3+7*VALUE(LEFT(B12,LEN(B12)-1)),IF(RIGHT(B12,1)="M",EDATE($B$3,VALUE(LEFT(B12,LEN(B12)-1))),EDATE($B$3,12*VALUE(LEFT(B12,LEN(B12)-1))))),2)=6,2,IF(WEEKDAY(IF(RIGHT(B12,1)="W",$B$3+7*VALUE(LEFT(B12,LEN(B12)-1)),IF(RIGHT(B12,1)="M",EDATE($B$3,VALUE(LEFT(B12,LEN(B12)-1))),EDATE($B$3,12*VALUE(LEFT(B12,LEN(B12)-1))))),2)=7,1,0)))) | D12: =(C12-$B$3)/365 | E12: =IFERROR(BDP(A12&" "&PX_SRC&" Curncy","PX_BID"),"ERROR PLZ FIX") | F12: =IFERROR(BDP(A12&" "&PX_SRC&" Curncy","PX_ASK"),"ERROR PLZ FIX") | G12: =IFERROR(BDP(A12&" "&PX_SRC&" Curncy","PX_LAST"),"ERROR PLZ FIX") | H12: =IFERROR(IF(Bootstrap!$G$4="Test 1",INDEX(Testing!$B$8:$B$47,MATCH(C12,Testing!$F$8:$F$47,0)),IF(Bootstrap!$G$4="Test 2",INDEX(Testing!$B$58:$B$97,MATCH(C12,Testing!$F$58:$F$97,0)),IF(Bootstrap!$G$4="Test 3",INDEX(Testing!$B$108:$B$147,MATCH(C12,Testing!$F$108:$F$147,0)),IF(Bootstrap!$G$4="Fixed (S490 07/21/26)",J12,IF(ISNUMBER(T12),T12,J12))))),J12) | J12: =IFERROR(INDEX(S490_Snapshot!$C$7:$C$38,MATCH(B12,S490_Snapshot!$B$7:$B$38,0)),"") | K12: S490_Snapshot | P12: =IF(COUNT(N12:O12)=2,(N12+O12)/2,"") | Q12: =IF(AND(ISNUMBER(N12),ISNUMBER(E12)),(E12-N12)*100,"") | R12: =IF(AND(ISNUMBER(O12),ISNUMBER(F12)),(F12-O12)*100,"") | S12: =IF(AND(ISNUMBER(P12),ISNUMBER(H12)),(H12-P12)*100,"") | T12: =IFERROR((E12+F12)/2,IFERROR(G12+0,"")) | U12: =IF(OR(T12="",NOT(ISNUMBER(J12))),"",(T12-J12)*100)
A13: USOSFRF | B13: 6M | C13: =IF(MONTH((IF(RIGHT(B13,1)="W",$B$3+7*VALUE(LEFT(B13,LEN(B13)-1)),IF(RIGHT(B13,1)="M",EDATE($B$3,VALUE(LEFT(B13,LEN(B13)-1))),EDATE($B$3,12*VALUE(LEFT(B13,LEN(B13)-1)))))+IF(WEEKDAY(IF(RIGHT(B13,1)="W",$B$3+7*VALUE(LEFT(B13,LEN(B13)-1)),IF(RIGHT(B13,1)="M",EDATE($B$3,VALUE(LEFT(B13,LEN(B13)-1))),EDATE($B$3,12*VALUE(LEFT(B13,LEN(B13)-1))))),2)=6,2,IF(WEEKDAY(IF(RIGHT(B13,1)="W",$B$3+7*VALUE(LEFT(B13,LEN(B13)-1)),IF(RIGHT(B13,1)="M",EDATE($B$3,VALUE(LEFT(B13,LEN(B13)-1))),EDATE($B$3,12*VALUE(LEFT(B13,LEN(B13)-1))))),2)=7,1,0))))<>MONTH(IF(RIGHT(B13,1)="W",$B$3+7*VALUE(LEFT(B13,LEN(B13)-1)),IF(RIGHT(B13,1)="M",EDATE($B$3,VALUE(LEFT(B13,LEN(B13)-1))),EDATE($B$3,12*VALUE(LEFT(B13,LEN(B13)-1)))))),(IF(RIGHT(B13,1)="W",$B$3+7*VALUE(LEFT(B13,LEN(B13)-1)),IF(RIGHT(B13,1)="M",EDATE($B$3,VALUE(LEFT(B13,LEN(B13)-1))),EDATE($B$3,12*VALUE(LEFT(B13,LEN(B13)-1)))))-IF(WEEKDAY(IF(RIGHT(B13,1)="W",$B$3+7*VALUE(LEFT(B13,LEN(B13)-1)),IF(RIGHT(B13,1)="M",EDATE($B$3,VALUE(LEFT(B13,LEN(B13)-1))),EDATE($B$3,12*VALUE(LEFT(B13,LEN(B13)-1))))),2)=6,1,IF(WEEKDAY(IF(RIGHT(B13,1)="W",$B$3+7*VALUE(LEFT(B13,LEN(B13)-1)),IF(RIGHT(B13,1)="M",EDATE($B$3,VALUE(LEFT(B13,LEN(B13)-1))),EDATE($B$3,12*VALUE(LEFT(B13,LEN(B13)-1))))),2)=7,2,0))),(IF(RIGHT(B13,1)="W",$B$3+7*VALUE(LEFT(B13,LEN(B13)-1)),IF(RIGHT(B13,1)="M",EDATE($B$3,VALUE(LEFT(B13,LEN(B13)-1))),EDATE($B$3,12*VALUE(LEFT(B13,LEN(B13)-1)))))+IF(WEEKDAY(IF(RIGHT(B13,1)="W",$B$3+7*VALUE(LEFT(B13,LEN(B13)-1)),IF(RIGHT(B13,1)="M",EDATE($B$3,VALUE(LEFT(B13,LEN(B13)-1))),EDATE($B$3,12*VALUE(LEFT(B13,LEN(B13)-1))))),2)=6,2,IF(WEEKDAY(IF(RIGHT(B13,1)="W",$B$3+7*VALUE(LEFT(B13,LEN(B13)-1)),IF(RIGHT(B13,1)="M",EDATE($B$3,VALUE(LEFT(B13,LEN(B13)-1))),EDATE($B$3,12*VALUE(LEFT(B13,LEN(B13)-1))))),2)=7,1,0)))) | D13: =(C13-$B$3)/365 | E13: =IFERROR(BDP(A13&" "&PX_SRC&" Curncy","PX_BID"),"ERROR PLZ FIX") | F13: =IFERROR(BDP(A13&" "&PX_SRC&" Curncy","PX_ASK"),"ERROR PLZ FIX") | G13: =IFERROR(BDP(A13&" "&PX_SRC&" Curncy","PX_LAST"),"ERROR PLZ FIX") | H13: =IFERROR(IF(Bootstrap!$G$4="Test 1",INDEX(Testing!$B$8:$B$47,MATCH(C13,Testing!$F$8:$F$47,0)),IF(Bootstrap!$G$4="Test 2",INDEX(Testing!$B$58:$B$97,MATCH(C13,Testing!$F$58:$F$97,0)),IF(Bootstrap!$G$4="Test 3",INDEX(Testing!$B$108:$B$147,MATCH(C13,Testing!$F$108:$F$147,0)),IF(Bootstrap!$G$4="Fixed (S490 07/21/26)",J13,IF(ISNUMBER(T13),T13,J13))))),J13) | I13: Y | J13: =IFERROR(INDEX(S490_Snapshot!$C$7:$C$38,MATCH(B13,S490_Snapshot!$B$7:$B$38,0)),"") | K13: S490_Snapshot | P13: =IF(COUNT(N13:O13)=2,(N13+O13)/2,"") | Q13: =IF(AND(ISNUMBER(N13),ISNUMBER(E13)),(E13-N13)*100,"") | R13: =IF(AND(ISNUMBER(O13),ISNUMBER(F13)),(F13-O13)*100,"") | S13: =IF(AND(ISNUMBER(P13),ISNUMBER(H13)),(H13-P13)*100,"") | T13: =IFERROR((E13+F13)/2,IFERROR(G13+0,"")) | U13: =IF(OR(T13="",NOT(ISNUMBER(J13))),"",(T13-J13)*100)
A14: USOSFRG | B14: 7M | C14: =IF(MONTH((IF(RIGHT(B14,1)="W",$B$3+7*VALUE(LEFT(B14,LEN(B14)-1)),IF(RIGHT(B14,1)="M",EDATE($B$3,VALUE(LEFT(B14,LEN(B14)-1))),EDATE($B$3,12*VALUE(LEFT(B14,LEN(B14)-1)))))+IF(WEEKDAY(IF(RIGHT(B14,1)="W",$B$3+7*VALUE(LEFT(B14,LEN(B14)-1)),IF(RIGHT(B14,1)="M",EDATE($B$3,VALUE(LEFT(B14,LEN(B14)-1))),EDATE($B$3,12*VALUE(LEFT(B14,LEN(B14)-1))))),2)=6,2,IF(WEEKDAY(IF(RIGHT(B14,1)="W",$B$3+7*VALUE(LEFT(B14,LEN(B14)-1)),IF(RIGHT(B14,1)="M",EDATE($B$3,VALUE(LEFT(B14,LEN(B14)-1))),EDATE($B$3,12*VALUE(LEFT(B14,LEN(B14)-1))))),2)=7,1,0))))<>MONTH(IF(RIGHT(B14,1)="W",$B$3+7*VALUE(LEFT(B14,LEN(B14)-1)),IF(RIGHT(B14,1)="M",EDATE($B$3,VALUE(LEFT(B14,LEN(B14)-1))),EDATE($B$3,12*VALUE(LEFT(B14,LEN(B14)-1)))))),(IF(RIGHT(B14,1)="W",$B$3+7*VALUE(LEFT(B14,LEN(B14)-1)),IF(RIGHT(B14,1)="M",EDATE($B$3,VALUE(LEFT(B14,LEN(B14)-1))),EDATE($B$3,12*VALUE(LEFT(B14,LEN(B14)-1)))))-IF(WEEKDAY(IF(RIGHT(B14,1)="W",$B$3+7*VALUE(LEFT(B14,LEN(B14)-1)),IF(RIGHT(B14,1)="M",EDATE($B$3,VALUE(LEFT(B14,LEN(B14)-1))),EDATE($B$3,12*VALUE(LEFT(B14,LEN(B14)-1))))),2)=6,1,IF(WEEKDAY(IF(RIGHT(B14,1)="W",$B$3+7*VALUE(LEFT(B14,LEN(B14)-1)),IF(RIGHT(B14,1)="M",EDATE($B$3,VALUE(LEFT(B14,LEN(B14)-1))),EDATE($B$3,12*VALUE(LEFT(B14,LEN(B14)-1))))),2)=7,2,0))),(IF(RIGHT(B14,1)="W",$B$3+7*VALUE(LEFT(B14,LEN(B14)-1)),IF(RIGHT(B14,1)="M",EDATE($B$3,VALUE(LEFT(B14,LEN(B14)-1))),EDATE($B$3,12*VALUE(LEFT(B14,LEN(B14)-1)))))+IF(WEEKDAY(IF(RIGHT(B14,1)="W",$B$3+7*VALUE(LEFT(B14,LEN(B14)-1)),IF(RIGHT(B14,1)="M",EDATE($B$3,VALUE(LEFT(B14,LEN(B14)-1))),EDATE($B$3,12*VALUE(LEFT(B14,LEN(B14)-1))))),2)=6,2,IF(WEEKDAY(IF(RIGHT(B14,1)="W",$B$3+7*VALUE(LEFT(B14,LEN(B14)-1)),IF(RIGHT(B14,1)="M",EDATE($B$3,VALUE(LEFT(B14,LEN(B14)-1))),EDATE($B$3,12*VALUE(LEFT(B14,LEN(B14)-1))))),2)=7,1,0)))) | D14: =(C14-$B$3)/365 | E14: =IFERROR(BDP(A14&" "&PX_SRC&" Curncy","PX_BID"),"ERROR PLZ FIX") | F14: =IFERROR(BDP(A14&" "&PX_SRC&" Curncy","PX_ASK"),"ERROR PLZ FIX") | G14: =IFERROR(BDP(A14&" "&PX_SRC&" Curncy","PX_LAST"),"ERROR PLZ FIX") | H14: =IFERROR(IF(Bootstrap!$G$4="Test 1",INDEX(Testing!$B$8:$B$47,MATCH(C14,Testing!$F$8:$F$47,0)),IF(Bootstrap!$G$4="Test 2",INDEX(Testing!$B$58:$B$97,MATCH(C14,Testing!$F$58:$F$97,0)),IF(Bootstrap!$G$4="Test 3",INDEX(Testing!$B$108:$B$147,MATCH(C14,Testing!$F$108:$F$147,0)),IF(Bootstrap!$G$4="Fixed (S490 07/21/26)",J14,IF(ISNUMBER(T14),T14,J14))))),J14) | J14: =IFERROR(INDEX(S490_Snapshot!$C$7:$C$38,MATCH(B14,S490_Snapshot!$B$7:$B$38,0)),"") | K14: S490_Snapshot | P14: =IF(COUNT(N14:O14)=2,(N14+O14)/2,"") | Q14: =IF(AND(ISNUMBER(N14),ISNUMBER(E14)),(E14-N14)*100,"") | R14: =IF(AND(ISNUMBER(O14),ISNUMBER(F14)),(F14-O14)*100,"") | S14: =IF(AND(ISNUMBER(P14),ISNUMBER(H14)),(H14-P14)*100,"") | T14: =IFERROR((E14+F14)/2,IFERROR(G14+0,"")) | U14: =IF(OR(T14="",NOT(ISNUMBER(J14))),"",(T14-J14)*100)
A15: USOSFRH | B15: 8M | C15: =IF(MONTH((IF(RIGHT(B15,1)="W",$B$3+7*VALUE(LEFT(B15,LEN(B15)-1)),IF(RIGHT(B15,1)="M",EDATE($B$3,VALUE(LEFT(B15,LEN(B15)-1))),EDATE($B$3,12*VALUE(LEFT(B15,LEN(B15)-1)))))+IF(WEEKDAY(IF(RIGHT(B15,1)="W",$B$3+7*VALUE(LEFT(B15,LEN(B15)-1)),IF(RIGHT(B15,1)="M",EDATE($B$3,VALUE(LEFT(B15,LEN(B15)-1))),EDATE($B$3,12*VALUE(LEFT(B15,LEN(B15)-1))))),2)=6,2,IF(WEEKDAY(IF(RIGHT(B15,1)="W",$B$3+7*VALUE(LEFT(B15,LEN(B15)-1)),IF(RIGHT(B15,1)="M",EDATE($B$3,VALUE(LEFT(B15,LEN(B15)-1))),EDATE($B$3,12*VALUE(LEFT(B15,LEN(B15)-1))))),2)=7,1,0))))<>MONTH(IF(RIGHT(B15,1)="W",$B$3+7*VALUE(LEFT(B15,LEN(B15)-1)),IF(RIGHT(B15,1)="M",EDATE($B$3,VALUE(LEFT(B15,LEN(B15)-1))),EDATE($B$3,12*VALUE(LEFT(B15,LEN(B15)-1)))))),(IF(RIGHT(B15,1)="W",$B$3+7*VALUE(LEFT(B15,LEN(B15)-1)),IF(RIGHT(B15,1)="M",EDATE($B$3,VALUE(LEFT(B15,LEN(B15)-1))),EDATE($B$3,12*VALUE(LEFT(B15,LEN(B15)-1)))))-IF(WEEKDAY(IF(RIGHT(B15,1)="W",$B$3+7*VALUE(LEFT(B15,LEN(B15)-1)),IF(RIGHT(B15,1)="M",EDATE($B$3,VALUE(LEFT(B15,LEN(B15)-1))),EDATE($B$3,12*VALUE(LEFT(B15,LEN(B15)-1))))),2)=6,1,IF(WEEKDAY(IF(RIGHT(B15,1)="W",$B$3+7*VALUE(LEFT(B15,LEN(B15)-1)),IF(RIGHT(B15,1)="M",EDATE($B$3,VALUE(LEFT(B15,LEN(B15)-1))),EDATE($B$3,12*VALUE(LEFT(B15,LEN(B15)-1))))),2)=7,2,0))),(IF(RIGHT(B15,1)="W",$B$3+7*VALUE(LEFT(B15,LEN(B15)-1)),IF(RIGHT(B15,1)="M",EDATE($B$3,VALUE(LEFT(B15,LEN(B15)-1))),EDATE($B$3,12*VALUE(LEFT(B15,LEN(B15)-1)))))+IF(WEEKDAY(IF(RIGHT(B15,1)="W",$B$3+7*VALUE(LEFT(B15,LEN(B15)-1)),IF(RIGHT(B15,1)="M",EDATE($B$3,VALUE(LEFT(B15,LEN(B15)-1))),EDATE($B$3,12*VALUE(LEFT(B15,LEN(B15)-1))))),2)=6,2,IF(WEEKDAY(IF(RIGHT(B15,1)="W",$B$3+7*VALUE(LEFT(B15,LEN(B15)-1)),IF(RIGHT(B15,1)="M",EDATE($B$3,VALUE(LEFT(B15,LEN(B15)-1))),EDATE($B$3,12*VALUE(LEFT(B15,LEN(B15)-1))))),2)=7,1,0)))) | D15: =(C15-$B$3)/365 | E15: =IFERROR(BDP(A15&" "&PX_SRC&" Curncy","PX_BID"),"ERROR PLZ FIX") | F15: =IFERROR(BDP(A15&" "&PX_SRC&" Curncy","PX_ASK"),"ERROR PLZ FIX") | G15: =IFERROR(BDP(A15&" "&PX_SRC&" Curncy","PX_LAST"),"ERROR PLZ FIX") | H15: =IFERROR(IF(Bootstrap!$G$4="Test 1",INDEX(Testing!$B$8:$B$47,MATCH(C15,Testing!$F$8:$F$47,0)),IF(Bootstrap!$G$4="Test 2",INDEX(Testing!$B$58:$B$97,MATCH(C15,Testing!$F$58:$F$97,0)),IF(Bootstrap!$G$4="Test 3",INDEX(Testing!$B$108:$B$147,MATCH(C15,Testing!$F$108:$F$147,0)),IF(Bootstrap!$G$4="Fixed (S490 07/21/26)",J15,IF(ISNUMBER(T15),T15,J15))))),J15) | J15: =IFERROR(INDEX(S490_Snapshot!$C$7:$C$38,MATCH(B15,S490_Snapshot!$B$7:$B$38,0)),"") | K15: S490_Snapshot | P15: =IF(COUNT(N15:O15)=2,(N15+O15)/2,"") | Q15: =IF(AND(ISNUMBER(N15),ISNUMBER(E15)),(E15-N15)*100,"") | R15: =IF(AND(ISNUMBER(O15),ISNUMBER(F15)),(F15-O15)*100,"") | S15: =IF(AND(ISNUMBER(P15),ISNUMBER(H15)),(H15-P15)*100,"") | T15: =IFERROR((E15+F15)/2,IFERROR(G15+0,"")) | U15: =IF(OR(T15="",NOT(ISNUMBER(J15))),"",(T15-J15)*100)
A16: USOSFRI | B16: 9M | C16: =IF(MONTH((IF(RIGHT(B16,1)="W",$B$3+7*VALUE(LEFT(B16,LEN(B16)-1)),IF(RIGHT(B16,1)="M",EDATE($B$3,VALUE(LEFT(B16,LEN(B16)-1))),EDATE($B$3,12*VALUE(LEFT(B16,LEN(B16)-1)))))+IF(WEEKDAY(IF(RIGHT(B16,1)="W",$B$3+7*VALUE(LEFT(B16,LEN(B16)-1)),IF(RIGHT(B16,1)="M",EDATE($B$3,VALUE(LEFT(B16,LEN(B16)-1))),EDATE($B$3,12*VALUE(LEFT(B16,LEN(B16)-1))))),2)=6,2,IF(WEEKDAY(IF(RIGHT(B16,1)="W",$B$3+7*VALUE(LEFT(B16,LEN(B16)-1)),IF(RIGHT(B16,1)="M",EDATE($B$3,VALUE(LEFT(B16,LEN(B16)-1))),EDATE($B$3,12*VALUE(LEFT(B16,LEN(B16)-1))))),2)=7,1,0))))<>MONTH(IF(RIGHT(B16,1)="W",$B$3+7*VALUE(LEFT(B16,LEN(B16)-1)),IF(RIGHT(B16,1)="M",EDATE($B$3,VALUE(LEFT(B16,LEN(B16)-1))),EDATE($B$3,12*VALUE(LEFT(B16,LEN(B16)-1)))))),(IF(RIGHT(B16,1)="W",$B$3+7*VALUE(LEFT(B16,LEN(B16)-1)),IF(RIGHT(B16,1)="M",EDATE($B$3,VALUE(LEFT(B16,LEN(B16)-1))),EDATE($B$3,12*VALUE(LEFT(B16,LEN(B16)-1)))))-IF(WEEKDAY(IF(RIGHT(B16,1)="W",$B$3+7*VALUE(LEFT(B16,LEN(B16)-1)),IF(RIGHT(B16,1)="M",EDATE($B$3,VALUE(LEFT(B16,LEN(B16)-1))),EDATE($B$3,12*VALUE(LEFT(B16,LEN(B16)-1))))),2)=6,1,IF(WEEKDAY(IF(RIGHT(B16,1)="W",$B$3+7*VALUE(LEFT(B16,LEN(B16)-1)),IF(RIGHT(B16,1)="M",EDATE($B$3,VALUE(LEFT(B16,LEN(B16)-1))),EDATE($B$3,12*VALUE(LEFT(B16,LEN(B16)-1))))),2)=7,2,0))),(IF(RIGHT(B16,1)="W",$B$3+7*VALUE(LEFT(B16,LEN(B16)-1)),IF(RIGHT(B16,1)="M",EDATE($B$3,VALUE(LEFT(B16,LEN(B16)-1))),EDATE($B$3,12*VALUE(LEFT(B16,LEN(B16)-1)))))+IF(WEEKDAY(IF(RIGHT(B16,1)="W",$B$3+7*VALUE(LEFT(B16,LEN(B16)-1)),IF(RIGHT(B16,1)="M",EDATE($B$3,VALUE(LEFT(B16,LEN(B16)-1))),EDATE($B$3,12*VALUE(LEFT(B16,LEN(B16)-1))))),2)=6,2,IF(WEEKDAY(IF(RIGHT(B16,1)="W",$B$3+7*VALUE(LEFT(B16,LEN(B16)-1)),IF(RIGHT(B16,1)="M",EDATE($B$3,VALUE(LEFT(B16,LEN(B16)-1))),EDATE($B$3,12*VALUE(LEFT(B16,LEN(B16)-1))))),2)=7,1,0)))) | D16: =(C16-$B$3)/365 | E16: =IFERROR(BDP(A16&" "&PX_SRC&" Curncy","PX_BID"),"ERROR PLZ FIX") | F16: =IFERROR(BDP(A16&" "&PX_SRC&" Curncy","PX_ASK"),"ERROR PLZ FIX") | G16: =IFERROR(BDP(A16&" "&PX_SRC&" Curncy","PX_LAST"),"ERROR PLZ FIX") | H16: =IFERROR(IF(Bootstrap!$G$4="Test 1",INDEX(Testing!$B$8:$B$47,MATCH(C16,Testing!$F$8:$F$47,0)),IF(Bootstrap!$G$4="Test 2",INDEX(Testing!$B$58:$B$97,MATCH(C16,Testing!$F$58:$F$97,0)),IF(Bootstrap!$G$4="Test 3",INDEX(Testing!$B$108:$B$147,MATCH(C16,Testing!$F$108:$F$147,0)),IF(Bootstrap!$G$4="Fixed (S490 07/21/26)",J16,IF(ISNUMBER(T16),T16,J16))))),J16) | J16: =IFERROR(INDEX(S490_Snapshot!$C$7:$C$38,MATCH(B16,S490_Snapshot!$B$7:$B$38,0)),"") | K16: S490_Snapshot | P16: =IF(COUNT(N16:O16)=2,(N16+O16)/2,"") | Q16: =IF(AND(ISNUMBER(N16),ISNUMBER(E16)),(E16-N16)*100,"") | R16: =IF(AND(ISNUMBER(O16),ISNUMBER(F16)),(F16-O16)*100,"") | S16: =IF(AND(ISNUMBER(P16),ISNUMBER(H16)),(H16-P16)*100,"") | T16: =IFERROR((E16+F16)/2,IFERROR(G16+0,"")) | U16: =IF(OR(T16="",NOT(ISNUMBER(J16))),"",(T16-J16)*100)
A17: USOSFRJ | B17: 10M | C17: =IF(MONTH((IF(RIGHT(B17,1)="W",$B$3+7*VALUE(LEFT(B17,LEN(B17)-1)),IF(RIGHT(B17,1)="M",EDATE($B$3,VALUE(LEFT(B17,LEN(B17)-1))),EDATE($B$3,12*VALUE(LEFT(B17,LEN(B17)-1)))))+IF(WEEKDAY(IF(RIGHT(B17,1)="W",$B$3+7*VALUE(LEFT(B17,LEN(B17)-1)),IF(RIGHT(B17,1)="M",EDATE($B$3,VALUE(LEFT(B17,LEN(B17)-1))),EDATE($B$3,12*VALUE(LEFT(B17,LEN(B17)-1))))),2)=6,2,IF(WEEKDAY(IF(RIGHT(B17,1)="W",$B$3+7*VALUE(LEFT(B17,LEN(B17)-1)),IF(RIGHT(B17,1)="M",EDATE($B$3,VALUE(LEFT(B17,LEN(B17)-1))),EDATE($B$3,12*VALUE(LEFT(B17,LEN(B17)-1))))),2)=7,1,0))))<>MONTH(IF(RIGHT(B17,1)="W",$B$3+7*VALUE(LEFT(B17,LEN(B17)-1)),IF(RIGHT(B17,1)="M",EDATE($B$3,VALUE(LEFT(B17,LEN(B17)-1))),EDATE($B$3,12*VALUE(LEFT(B17,LEN(B17)-1)))))),(IF(RIGHT(B17,1)="W",$B$3+7*VALUE(LEFT(B17,LEN(B17)-1)),IF(RIGHT(B17,1)="M",EDATE($B$3,VALUE(LEFT(B17,LEN(B17)-1))),EDATE($B$3,12*VALUE(LEFT(B17,LEN(B17)-1)))))-IF(WEEKDAY(IF(RIGHT(B17,1)="W",$B$3+7*VALUE(LEFT(B17,LEN(B17)-1)),IF(RIGHT(B17,1)="M",EDATE($B$3,VALUE(LEFT(B17,LEN(B17)-1))),EDATE($B$3,12*VALUE(LEFT(B17,LEN(B17)-1))))),2)=6,1,IF(WEEKDAY(IF(RIGHT(B17,1)="W",$B$3+7*VALUE(LEFT(B17,LEN(B17)-1)),IF(RIGHT(B17,1)="M",EDATE($B$3,VALUE(LEFT(B17,LEN(B17)-1))),EDATE($B$3,12*VALUE(LEFT(B17,LEN(B17)-1))))),2)=7,2,0))),(IF(RIGHT(B17,1)="W",$B$3+7*VALUE(LEFT(B17,LEN(B17)-1)),IF(RIGHT(B17,1)="M",EDATE($B$3,VALUE(LEFT(B17,LEN(B17)-1))),EDATE($B$3,12*VALUE(LEFT(B17,LEN(B17)-1)))))+IF(WEEKDAY(IF(RIGHT(B17,1)="W",$B$3+7*VALUE(LEFT(B17,LEN(B17)-1)),IF(RIGHT(B17,1)="M",EDATE($B$3,VALUE(LEFT(B17,LEN(B17)-1))),EDATE($B$3,12*VALUE(LEFT(B17,LEN(B17)-1))))),2)=6,2,IF(WEEKDAY(IF(RIGHT(B17,1)="W",$B$3+7*VALUE(LEFT(B17,LEN(B17)-1)),IF(RIGHT(B17,1)="M",EDATE($B$3,VALUE(LEFT(B17,LEN(B17)-1))),EDATE($B$3,12*VALUE(LEFT(B17,LEN(B17)-1))))),2)=7,1,0)))) | D17: =(C17-$B$3)/365 | E17: =IFERROR(BDP(A17&" "&PX_SRC&" Curncy","PX_BID"),"ERROR PLZ FIX") | F17: =IFERROR(BDP(A17&" "&PX_SRC&" Curncy","PX_ASK"),"ERROR PLZ FIX") | G17: =IFERROR(BDP(A17&" "&PX_SRC&" Curncy","PX_LAST"),"ERROR PLZ FIX") | H17: =IFERROR(IF(Bootstrap!$G$4="Test 1",INDEX(Testing!$B$8:$B$47,MATCH(C17,Testing!$F$8:$F$47,0)),IF(Bootstrap!$G$4="Test 2",INDEX(Testing!$B$58:$B$97,MATCH(C17,Testing!$F$58:$F$97,0)),IF(Bootstrap!$G$4="Test 3",INDEX(Testing!$B$108:$B$147,MATCH(C17,Testing!$F$108:$F$147,0)),IF(Bootstrap!$G$4="Fixed (S490 07/21/26)",J17,IF(ISNUMBER(T17),T17,J17))))),J17) | J17: =IFERROR(INDEX(S490_Snapshot!$C$7:$C$38,MATCH(B17,S490_Snapshot!$B$7:$B$38,0)),"") | K17: S490_Snapshot | P17: =IF(COUNT(N17:O17)=2,(N17+O17)/2,"") | Q17: =IF(AND(ISNUMBER(N17),ISNUMBER(E17)),(E17-N17)*100,"") | R17: =IF(AND(ISNUMBER(O17),ISNUMBER(F17)),(F17-O17)*100,"") | S17: =IF(AND(ISNUMBER(P17),ISNUMBER(H17)),(H17-P17)*100,"") | T17: =IFERROR((E17+F17)/2,IFERROR(G17+0,"")) | U17: =IF(OR(T17="",NOT(ISNUMBER(J17))),"",(T17-J17)*100)
A18: USOSFRK | B18: 11M | C18: =IF(MONTH((IF(RIGHT(B18,1)="W",$B$3+7*VALUE(LEFT(B18,LEN(B18)-1)),IF(RIGHT(B18,1)="M",EDATE($B$3,VALUE(LEFT(B18,LEN(B18)-1))),EDATE($B$3,12*VALUE(LEFT(B18,LEN(B18)-1)))))+IF(WEEKDAY(IF(RIGHT(B18,1)="W",$B$3+7*VALUE(LEFT(B18,LEN(B18)-1)),IF(RIGHT(B18,1)="M",EDATE($B$3,VALUE(LEFT(B18,LEN(B18)-1))),EDATE($B$3,12*VALUE(LEFT(B18,LEN(B18)-1))))),2)=6,2,IF(WEEKDAY(IF(RIGHT(B18,1)="W",$B$3+7*VALUE(LEFT(B18,LEN(B18)-1)),IF(RIGHT(B18,1)="M",EDATE($B$3,VALUE(LEFT(B18,LEN(B18)-1))),EDATE($B$3,12*VALUE(LEFT(B18,LEN(B18)-1))))),2)=7,1,0))))<>MONTH(IF(RIGHT(B18,1)="W",$B$3+7*VALUE(LEFT(B18,LEN(B18)-1)),IF(RIGHT(B18,1)="M",EDATE($B$3,VALUE(LEFT(B18,LEN(B18)-1))),EDATE($B$3,12*VALUE(LEFT(B18,LEN(B18)-1)))))),(IF(RIGHT(B18,1)="W",$B$3+7*VALUE(LEFT(B18,LEN(B18)-1)),IF(RIGHT(B18,1)="M",EDATE($B$3,VALUE(LEFT(B18,LEN(B18)-1))),EDATE($B$3,12*VALUE(LEFT(B18,LEN(B18)-1)))))-IF(WEEKDAY(IF(RIGHT(B18,1)="W",$B$3+7*VALUE(LEFT(B18,LEN(B18)-1)),IF(RIGHT(B18,1)="M",EDATE($B$3,VALUE(LEFT(B18,LEN(B18)-1))),EDATE($B$3,12*VALUE(LEFT(B18,LEN(B18)-1))))),2)=6,1,IF(WEEKDAY(IF(RIGHT(B18,1)="W",$B$3+7*VALUE(LEFT(B18,LEN(B18)-1)),IF(RIGHT(B18,1)="M",EDATE($B$3,VALUE(LEFT(B18,LEN(B18)-1))),EDATE($B$3,12*VALUE(LEFT(B18,LEN(B18)-1))))),2)=7,2,0))),(IF(RIGHT(B18,1)="W",$B$3+7*VALUE(LEFT(B18,LEN(B18)-1)),IF(RIGHT(B18,1)="M",EDATE($B$3,VALUE(LEFT(B18,LEN(B18)-1))),EDATE($B$3,12*VALUE(LEFT(B18,LEN(B18)-1)))))+IF(WEEKDAY(IF(RIGHT(B18,1)="W",$B$3+7*VALUE(LEFT(B18,LEN(B18)-1)),IF(RIGHT(B18,1)="M",EDATE($B$3,VALUE(LEFT(B18,LEN(B18)-1))),EDATE($B$3,12*VALUE(LEFT(B18,LEN(B18)-1))))),2)=6,2,IF(WEEKDAY(IF(RIGHT(B18,1)="W",$B$3+7*VALUE(LEFT(B18,LEN(B18)-1)),IF(RIGHT(B18,1)="M",EDATE($B$3,VALUE(LEFT(B18,LEN(B18)-1))),EDATE($B$3,12*VALUE(LEFT(B18,LEN(B18)-1))))),2)=7,1,0)))) | D18: =(C18-$B$3)/365 | E18: =IFERROR(BDP(A18&" "&PX_SRC&" Curncy","PX_BID"),"ERROR PLZ FIX") | F18: =IFERROR(BDP(A18&" "&PX_SRC&" Curncy","PX_ASK"),"ERROR PLZ FIX") | G18: =IFERROR(BDP(A18&" "&PX_SRC&" Curncy","PX_LAST"),"ERROR PLZ FIX") | H18: =IFERROR(IF(Bootstrap!$G$4="Test 1",INDEX(Testing!$B$8:$B$47,MATCH(C18,Testing!$F$8:$F$47,0)),IF(Bootstrap!$G$4="Test 2",INDEX(Testing!$B$58:$B$97,MATCH(C18,Testing!$F$58:$F$97,0)),IF(Bootstrap!$G$4="Test 3",INDEX(Testing!$B$108:$B$147,MATCH(C18,Testing!$F$108:$F$147,0)),IF(Bootstrap!$G$4="Fixed (S490 07/21/26)",J18,IF(ISNUMBER(T18),T18,J18))))),J18) | J18: =IFERROR(INDEX(S490_Snapshot!$C$7:$C$38,MATCH(B18,S490_Snapshot!$B$7:$B$38,0)),"") | K18: S490_Snapshot | P18: =IF(COUNT(N18:O18)=2,(N18+O18)/2,"") | Q18: =IF(AND(ISNUMBER(N18),ISNUMBER(E18)),(E18-N18)*100,"") | R18: =IF(AND(ISNUMBER(O18),ISNUMBER(F18)),(F18-O18)*100,"") | S18: =IF(AND(ISNUMBER(P18),ISNUMBER(H18)),(H18-P18)*100,"") | T18: =IFERROR((E18+F18)/2,IFERROR(G18+0,"")) | U18: =IF(OR(T18="",NOT(ISNUMBER(J18))),"",(T18-J18)*100)
A19: USOSFR1 | B19: 1Y | C19: =IF(MONTH((IF(RIGHT(B19,1)="W",$B$3+7*VALUE(LEFT(B19,LEN(B19)-1)),IF(RIGHT(B19,1)="M",EDATE($B$3,VALUE(LEFT(B19,LEN(B19)-1))),EDATE($B$3,12*VALUE(LEFT(B19,LEN(B19)-1)))))+IF(WEEKDAY(IF(RIGHT(B19,1)="W",$B$3+7*VALUE(LEFT(B19,LEN(B19)-1)),IF(RIGHT(B19,1)="M",EDATE($B$3,VALUE(LEFT(B19,LEN(B19)-1))),EDATE($B$3,12*VALUE(LEFT(B19,LEN(B19)-1))))),2)=6,2,IF(WEEKDAY(IF(RIGHT(B19,1)="W",$B$3+7*VALUE(LEFT(B19,LEN(B19)-1)),IF(RIGHT(B19,1)="M",EDATE($B$3,VALUE(LEFT(B19,LEN(B19)-1))),EDATE($B$3,12*VALUE(LEFT(B19,LEN(B19)-1))))),2)=7,1,0))))<>MONTH(IF(RIGHT(B19,1)="W",$B$3+7*VALUE(LEFT(B19,LEN(B19)-1)),IF(RIGHT(B19,1)="M",EDATE($B$3,VALUE(LEFT(B19,LEN(B19)-1))),EDATE($B$3,12*VALUE(LEFT(B19,LEN(B19)-1)))))),(IF(RIGHT(B19,1)="W",$B$3+7*VALUE(LEFT(B19,LEN(B19)-1)),IF(RIGHT(B19,1)="M",EDATE($B$3,VALUE(LEFT(B19,LEN(B19)-1))),EDATE($B$3,12*VALUE(LEFT(B19,LEN(B19)-1)))))-IF(WEEKDAY(IF(RIGHT(B19,1)="W",$B$3+7*VALUE(LEFT(B19,LEN(B19)-1)),IF(RIGHT(B19,1)="M",EDATE($B$3,VALUE(LEFT(B19,LEN(B19)-1))),EDATE($B$3,12*VALUE(LEFT(B19,LEN(B19)-1))))),2)=6,1,IF(WEEKDAY(IF(RIGHT(B19,1)="W",$B$3+7*VALUE(LEFT(B19,LEN(B19)-1)),IF(RIGHT(B19,1)="M",EDATE($B$3,VALUE(LEFT(B19,LEN(B19)-1))),EDATE($B$3,12*VALUE(LEFT(B19,LEN(B19)-1))))),2)=7,2,0))),(IF(RIGHT(B19,1)="W",$B$3+7*VALUE(LEFT(B19,LEN(B19)-1)),IF(RIGHT(B19,1)="M",EDATE($B$3,VALUE(LEFT(B19,LEN(B19)-1))),EDATE($B$3,12*VALUE(LEFT(B19,LEN(B19)-1)))))+IF(WEEKDAY(IF(RIGHT(B19,1)="W",$B$3+7*VALUE(LEFT(B19,LEN(B19)-1)),IF(RIGHT(B19,1)="M",EDATE($B$3,VALUE(LEFT(B19,LEN(B19)-1))),EDATE($B$3,12*VALUE(LEFT(B19,LEN(B19)-1))))),2)=6,2,IF(WEEKDAY(IF(RIGHT(B19,1)="W",$B$3+7*VALUE(LEFT(B19,LEN(B19)-1)),IF(RIGHT(B19,1)="M",EDATE($B$3,VALUE(LEFT(B19,LEN(B19)-1))),EDATE($B$3,12*VALUE(LEFT(B19,LEN(B19)-1))))),2)=7,1,0)))) | D19: =(C19-$B$3)/365 | E19: =IFERROR(BDP(A19&" "&PX_SRC&" Curncy","PX_BID"),"ERROR PLZ FIX") | F19: =IFERROR(BDP(A19&" "&PX_SRC&" Curncy","PX_ASK"),"ERROR PLZ FIX") | G19: =IFERROR(BDP(A19&" "&PX_SRC&" Curncy","PX_LAST"),"ERROR PLZ FIX") | H19: =IFERROR(IF(Bootstrap!$G$4="Test 1",INDEX(Testing!$B$8:$B$47,MATCH(C19,Testing!$F$8:$F$47,0)),IF(Bootstrap!$G$4="Test 2",INDEX(Testing!$B$58:$B$97,MATCH(C19,Testing!$F$58:$F$97,0)),IF(Bootstrap!$G$4="Test 3",INDEX(Testing!$B$108:$B$147,MATCH(C19,Testing!$F$108:$F$147,0)),IF(Bootstrap!$G$4="Fixed (S490 07/21/26)",J19,IF(ISNUMBER(T19),T19,J19))))),J19) | J19: =IFERROR(INDEX(S490_Snapshot!$C$7:$C$38,MATCH(B19,S490_Snapshot!$B$7:$B$38,0)),"") | K19: S490_Snapshot | P19: =IF(COUNT(N19:O19)=2,(N19+O19)/2,"") | Q19: =IF(AND(ISNUMBER(N19),ISNUMBER(E19)),(E19-N19)*100,"") | R19: =IF(AND(ISNUMBER(O19),ISNUMBER(F19)),(F19-O19)*100,"") | S19: =IF(AND(ISNUMBER(P19),ISNUMBER(H19)),(H19-P19)*100,"") | T19: =IFERROR((E19+F19)/2,IFERROR(G19+0,"")) | U19: =IF(OR(T19="",NOT(ISNUMBER(J19))),"",(T19-J19)*100)
A20: Col H is the mid in use. Test cases match on the derived MATURITY DATE, not the tenor label - a capture writing 12M where this sheet writes 1Y still lines up. | B20: 18M | C20: =IF(MONTH((IF(RIGHT(B20,1)="W",$B$3+7*VALUE(LEFT(B20,LEN(B20)-1)),IF(RIGHT(B20,1)="M",EDATE($B$3,VALUE(LEFT(B20,LEN(B20)-1))),EDATE($B$3,12*VALUE(LEFT(B20,LEN(B20)-1)))))+IF(WEEKDAY(IF(RIGHT(B20,1)="W",$B$3+7*VALUE(LEFT(B20,LEN(B20)-1)),IF(RIGHT(B20,1)="M",EDATE($B$3,VALUE(LEFT(B20,LEN(B20)-1))),EDATE($B$3,12*VALUE(LEFT(B20,LEN(B20)-1))))),2)=6,2,IF(WEEKDAY(IF(RIGHT(B20,1)="W",$B$3+7*VALUE(LEFT(B20,LEN(B20)-1)),IF(RIGHT(B20,1)="M",EDATE($B$3,VALUE(LEFT(B20,LEN(B20)-1))),EDATE($B$3,12*VALUE(LEFT(B20,LEN(B20)-1))))),2)=7,1,0))))<>MONTH(IF(RIGHT(B20,1)="W",$B$3+7*VALUE(LEFT(B20,LEN(B20)-1)),IF(RIGHT(B20,1)="M",EDATE($B$3,VALUE(LEFT(B20,LEN(B20)-1))),EDATE($B$3,12*VALUE(LEFT(B20,LEN(B20)-1)))))),(IF(RIGHT(B20,1)="W",$B$3+7*VALUE(LEFT(B20,LEN(B20)-1)),IF(RIGHT(B20,1)="M",EDATE($B$3,VALUE(LEFT(B20,LEN(B20)-1))),EDATE($B$3,12*VALUE(LEFT(B20,LEN(B20)-1)))))-IF(WEEKDAY(IF(RIGHT(B20,1)="W",$B$3+7*VALUE(LEFT(B20,LEN(B20)-1)),IF(RIGHT(B20,1)="M",EDATE($B$3,VALUE(LEFT(B20,LEN(B20)-1))),EDATE($B$3,12*VALUE(LEFT(B20,LEN(B20)-1))))),2)=6,1,IF(WEEKDAY(IF(RIGHT(B20,1)="W",$B$3+7*VALUE(LEFT(B20,LEN(B20)-1)),IF(RIGHT(B20,1)="M",EDATE($B$3,VALUE(LEFT(B20,LEN(B20)-1))),EDATE($B$3,12*VALUE(LEFT(B20,LEN(B20)-1))))),2)=7,2,0))),(IF(RIGHT(B20,1)="W",$B$3+7*VALUE(LEFT(B20,LEN(B20)-1)),IF(RIGHT(B20,1)="M",EDATE($B$3,VALUE(LEFT(B20,LEN(B20)-1))),EDATE($B$3,12*VALUE(LEFT(B20,LEN(B20)-1)))))+IF(WEEKDAY(IF(RIGHT(B20,1)="W",$B$3+7*VALUE(LEFT(B20,LEN(B20)-1)),IF(RIGHT(B20,1)="M",EDATE($B$3,VALUE(LEFT(B20,LEN(B20)-1))),EDATE($B$3,12*VALUE(LEFT(B20,LEN(B20)-1))))),2)=6,2,IF(WEEKDAY(IF(RIGHT(B20,1)="W",$B$3+7*VALUE(LEFT(B20,LEN(B20)-1)),IF(RIGHT(B20,1)="M",EDATE($B$3,VALUE(LEFT(B20,LEN(B20)-1))),EDATE($B$3,12*VALUE(LEFT(B20,LEN(B20)-1))))),2)=7,1,0)))) | D20: =(C20-$B$3)/365 | E20: =IFERROR(BDP(A20&" "&PX_SRC&" Curncy","PX_BID"),"ERROR PLZ FIX") | F20: =IFERROR(BDP(A20&" "&PX_SRC&" Curncy","PX_ASK"),"ERROR PLZ FIX") | G20: =IFERROR(BDP(A20&" "&PX_SRC&" Curncy","PX_LAST"),"ERROR PLZ FIX") | H20: =IFERROR(IF(Bootstrap!$G$4="Test 1",INDEX(Testing!$B$8:$B$47,MATCH(C20,Testing!$F$8:$F$47,0)),IF(Bootstrap!$G$4="Test 2",INDEX(Testing!$B$58:$B$97,MATCH(C20,Testing!$F$58:$F$97,0)),IF(Bootstrap!$G$4="Test 3",INDEX(Testing!$B$108:$B$147,MATCH(C20,Testing!$F$108:$F$147,0)),IF(Bootstrap!$G$4="Fixed (S490 07/21/26)",J20,IF(ISNUMBER(T20),T20,J20))))),J20) | J20: =IFERROR(INDEX(S490_Snapshot!$C$7:$C$38,MATCH(B20,S490_Snapshot!$B$7:$B$38,0)),"") | K20: S490_Snapshot | P20: =IF(COUNT(N20:O20)=2,(N20+O20)/2,"") | Q20: =IF(AND(ISNUMBER(N20),ISNUMBER(E20)),(E20-N20)*100,"") | R20: =IF(AND(ISNUMBER(O20),ISNUMBER(F20)),(F20-O20)*100,"") | S20: =IF(AND(ISNUMBER(P20),ISNUMBER(H20)),(H20-P20)*100,"") | T20: =IFERROR((E20+F20)/2,IFERROR(G20+0,"")) | U20: =IF(OR(T20="",NOT(ISNUMBER(J20))),"",(T20-J20)*100)
