Workbook
Name VAL_DATE: Instructions!$B$9
Name HIST_START: Instructions!$B$10
Name HIST_END: Instructions!$B$11
Name PX_SRC: Instructions!$B$12
Name SOFR_TKR: Instructions!$B$13
Name S490_TKR: Instructions!$B$14

Sheet Instructions
A1: USD SOFR Curve — Bloomberg Data Template
A2: Modern replication of the Lehman (2002) USD single-curve build: fixing + SR3/SR1 futures + SOFR OIS
A4: This workbook is a live Bloomberg template. Open it in Excel on a machine with the Bloomberg Add-in (BLPAPI) connected; the BDP / BDH / BDS formulas then populate automatically. Off-terminal (or in any non-Bloomberg viewer) the Bloomberg cells show #NAME? or blanks — that is expected, not a defect. Set the parameters below first; every date-driven pull references them.
A7: PARAMETERS (edit the yellow cells)
A8: Parameter | B8: Value | C8: Named ref | D8: Notes
A9: Valuation date | B9: =TODAY() | C9: VAL_DATE | D9: Curve reference / spot date. Live pulls (BDP) are as-of now; set this to your snapshot date.
A10: Historical start | B10: 01/01/2018 | C10: HIST_START | D10: Start of BDH history windows.
A11: Historical end | B11: 07/20/2026 | C11: HIST_END | D11: End of BDH history windows.
A12: Price source | B12: BGN | C12: PX_SRC | D12: Bloomberg pricing source suffix used across every OIS ticker (BGN = Bloomberg Generic). Keep one source across all maturities.
A13: Overnight SOFR ticker | B13: SOFRRATE Index | C13: SOFR_TKR | D13: Published overnight SOFR fixing (NY Fed).
A14: Bloomberg SOFR curve | B14: YCSW0490 Index | C14: S490_TKR | D14: Bloomberg curve S490 (USD SOFR) — validation benchmark only.
A16: LEHMAN 2002 → MODERN USD CURVE MAPPING
A17: Lehman 2002 instrument | C17: Modern equivalent | E17: Bloomberg source
A18: LIBOR deposits | C18: SOFR fixing / short OIS | E18: SOFRRATE Index; USOSFR1Z..USOSFRF
A19: Eurodollar futures | C19: 3M SOFR futures (SR3) | E19: SFRA Comdty (CT chain)
A20: (1M money market) | C20: 1M SOFR futures (SR1) | E20: SERA Comdty (CT chain)
A21: LIBOR swaps | C21: SOFR OIS swaps | E21: USOSFR2..USOSFR50 BGN Curncy
A22: Dealer curve | C22: Bloomberg S490 (validation) | E22: YCSW0490 Index
A24: BOOTSTRAP METHODOLOGY — one discount curve, three liquid segments
A25: Short end (o/n – ~1Y) | B25: SOFR fixing + short OIS (1W,1M,3M,6M) anchor P(0,T) at the front — the modern LIBOR-deposit segment.
A26: Mid (~3M – ~5Y) | B26: SR3 3M-SOFR futures; implied rate = 100 − price, each covering one 3M IMM reference quarter — the modern Eurodollar-futures segment.
A27: Long end (~2Y – 50Y) | B27: SOFR OIS par swaps (mid = (bid+ask)/2) where deep liquidity lives — the modern LIBOR-swap segment.
A28: Bootstrap order | B28: Left → right: each instrument solves for the next discount-factor pillar given everything already solved to its left (sequential 1-D root find).
A30: Three differences vs. Lehman 2002 (where 'modern' is not a literal copy):
A31: • Single-curve: the SOFR curve both projects forwards AND discounts. Lehman 2002 was also single-curve (LIBOR did both), so a SOFR OIS build is CLOSER to the paper than a modern LIBOR build would be.
A32: • Compounding: SOFR is an overnight rate compounded daily in arrears over each period; LIBOR was a term rate set once. The OIS/futures legs carry a daily-compounding calc LIBOR did not need.
A33: • Futures convexity: SR3 (like Eurodollar) futures need a small convexity adjustment before the implied rate enters the curve. A first pass can omit it and report the bias against the S490 benchmark.
A35: TABS IN THIS WORKBOOK
A36: Charts | B36: Curve visuals — zero curve, discount factors, and V1-vs-V2 forward comparison.
A37: 1. SOFR_Fixings | B37: Overnight SOFR fixing — current (BDP) + daily history (BDH).
A38: 2. SOFR_Futures | B38: SR3 (3M) and SR1 (1M) SOFR futures chains + fields + implied rate = 100 − price.
A39: 3. SOFR_OIS_Quotes | B39: Full USOSFR OIS strip (1W–50Y): bid / ask / last + mid. Bootstrap-set flagged.
A40: 4. Bootstrap | B40: Live single-curve OIS bootstrap → discount factors, zero & forward rates, S490 Δz check.
A41: Curve_Interface | B41: Shared D(0,t): interpolates the SOFR curve to ANY date (quarterly CDS dates demo). Used by Swap_Pricer + CDS.
A42: CDS_Parameters | B42: Credit assumptions: recovery, notional, coupon, direction (recovery is an INPUT).
A43: CDS_Quotes | B43: Single-name CDS par spreads (BDP ticker, or manual demo). One entity, one seniority.
A44: CDS_Schedule | B44: Quarterly premium/default schedule to 10Y; DF from the SOFR curve, survival from hazards.
A45: Hazard_Bootstrap | B45: Piecewise-constant hazard curve; s/(1-R) default, Goal-Seek the error to 0 for exact fit.
A46: CDS_Pricer | B46: Prices a CDS off both curves: protection − premium, par spread, upfront, CS01.
A47: CDS_Validation | B47: Survival/hazard sanity checks + the s ≈ (1-R)·lambda approximation.
...

Sheet Charts
A1: Curve visuals
A2: Charts read live from the Bootstrap and Fwd_Interp tabs — they populate once Bloomberg fills the data. Bootstrap columns: T (C), Discount factor (H), Zero (J); Fwd_Interp: T (B), flat fwd V1 (F), quadratic V2 (K).

Sheet SOFR_Fixings
A1: SOFR_Fixings
A2: Overnight SOFR fixing (SOFRRATE Index) — the curve's shortest anchor point
A4: CURRENT FIXING
A5: Ticker | B5: Field | C5: Value (%) | D5: As of
A6: =SOFR_TKR | B6: PX_LAST | C6: =IFERROR(BDP(SOFR_TKR,"PX_LAST"),"ERROR PLZ FIX") | D6: =IFERROR(BDP(SOFR_TKR,"LAST_UPDATE_DT"),"ERROR PLZ FIX")
A9: DAILY HISTORY
A10: The BDH array below spills down two columns (Date, PX_LAST) from the anchor cell A12. It uses the HIST_START / HIST_END parameters on the Instructions tab.
A11: Date | B11: SOFR PX_LAST (%)
A12: =IFERROR(BDH(SOFR_TKR,"PX_LAST",TEXT(HIST_START,"mm/dd/yyyy"),TEXT(HIST_END,"mm/dd/yyyy")),"ERROR PLZ FIX")

Sheet SOFR_Futures
A1: SOFR_Futures
A2: SR3 (3M) and SR1 (1M) SOFR futures — modern replacement for the Eurodollar-futures strip
A4: SR3 — THREE-MONTH SOFR FUTURES (SFRA Comdty · CME SR3) — first 20 quarterly contracts
A5: Column A cell below holds =BDS("SFRA Comdty","FUT_CHAIN") and SPILLS the active contract tickers down. Field columns reference each row's contract in column A. Adjust the row count to the liquid strip (check VOLUME / OPEN_INT).
A6: Contract (from CT chain) | B6: SECURITY_DES | C6: PX_LAST | D6: PX_BID | E6: PX_ASK | F6: Implied rate % (100−Last) | G6: FUT_MONTH_YR | H6: Ref. start (FUT_DLV_DT_FIRST) | I6: LAST_TRADEABLE_DT | J6: VOLUME | K6: OPEN_INT
A7: =BDS("SFRA Comdty","FUT_CHAIN") | B7: =IFERROR(BDP($A7,"SECURITY_DES"),"ERROR PLZ FIX") | C7: =IFERROR(BDP($A7,"PX_LAST"),"ERROR PLZ FIX") | D7: =IFERROR(BDP($A7,"PX_BID"),"ERROR PLZ FIX") | E7: =IFERROR(BDP($A7,"PX_ASK"),"ERROR PLZ FIX") | F7: =IFERROR(100-C7,"ERROR PLZ FIX") | G7: =IFERROR(BDP($A7,"FUT_MONTH_YR"),"ERROR PLZ FIX") | H7: =IFERROR(BDP($A7,"FUT_DLV_DT_FIRST"),"ERROR PLZ FIX") | I7: =IFERROR(BDP($A7,"LAST_TRADEABLE_DT"),"ERROR PLZ FIX") | J7: =IFERROR(BDP($A7,"VOLUME"),"ERROR PLZ FIX") | K7: =IFERROR(BDP($A7,"OPEN_INT"),"ERROR PLZ FIX")
B8: =IFERROR(BDP($A8,"SECURITY_DES"),"ERROR PLZ FIX") | C8: =IFERROR(BDP($A8,"PX_LAST"),"ERROR PLZ FIX") | D8: =IFERROR(BDP($A8,"PX_BID"),"ERROR PLZ FIX") | E8: =IFERROR(BDP($A8,"PX_ASK"),"ERROR PLZ FIX") | F8: =IFERROR(100-C8,"ERROR PLZ FIX") | G8: =IFERROR(BDP($A8,"FUT_MONTH_YR"),"ERROR PLZ FIX") | H8: =IFERROR(BDP($A8,"FUT_DLV_DT_FIRST"),"ERROR PLZ FIX") | I8: =IFERROR(BDP($A8,"LAST_TRADEABLE_DT"),"ERROR PLZ FIX") | J8: =IFERROR(BDP($A8,"VOLUME"),"ERROR PLZ FIX") | K8: =IFERROR(BDP($A8,"OPEN_INT"),"ERROR PLZ FIX")
B9: =IFERROR(BDP($A9,"SECURITY_DES"),"ERROR PLZ FIX") | C9: =IFERROR(BDP($A9,"PX_LAST"),"ERROR PLZ FIX") | D9: =IFERROR(BDP($A9,"PX_BID"),"ERROR PLZ FIX") | E9: =IFERROR(BDP($A9,"PX_ASK"),"ERROR PLZ FIX") | F9: =IFERROR(100-C9,"ERROR PLZ FIX") | G9: =IFERROR(BDP($A9,"FUT_MONTH_YR"),"ERROR PLZ FIX") | H9: =IFERROR(BDP($A9,"FUT_DLV_DT_FIRST"),"ERROR PLZ FIX") | I9: =IFERROR(BDP($A9,"LAST_TRADEABLE_DT"),"ERROR PLZ FIX") | J9: =IFERROR(BDP($A9,"VOLUME"),"ERROR PLZ FIX") | K9: =IFERROR(BDP($A9,"OPEN_INT"),"ERROR PLZ FIX")
B10: =IFERROR(BDP($A10,"SECURITY_DES"),"ERROR PLZ FIX") | C10: =IFERROR(BDP($A10,"PX_LAST"),"ERROR PLZ FIX") | D10: =IFERROR(BDP($A10,"PX_BID"),"ERROR PLZ FIX") | E10: =IFERROR(BDP($A10,"PX_ASK"),"ERROR PLZ FIX") | F10: =IFERROR(100-C10,"ERROR PLZ FIX") | G10: =IFERROR(BDP($A10,"FUT_MONTH_YR"),"ERROR PLZ FIX") | H10: =IFERROR(BDP($A10,"FUT_DLV_DT_FIRST"),"ERROR PLZ FIX") | I10: =IFERROR(BDP($A10,"LAST_TRADEABLE_DT"),"ERROR PLZ FIX") | J10: =IFERROR(BDP($A10,"VOLUME"),"ERROR PLZ FIX") | K10: =IFERROR(BDP($A10,"OPEN_INT"),"ERROR PLZ FIX")
B11: =IFERROR(BDP($A11,"SECURITY_DES"),"ERROR PLZ FIX") | C11: =IFERROR(BDP($A11,"PX_LAST"),"ERROR PLZ FIX") | D11: =IFERROR(BDP($A11,"PX_BID"),"ERROR PLZ FIX") | E11: =IFERROR(BDP($A11,"PX_ASK"),"ERROR PLZ FIX") | F11: =IFERROR(100-C11,"ERROR PLZ FIX") | G11: =IFERROR(BDP($A11,"FUT_MONTH_YR"),"ERROR PLZ FIX") | H11: =IFERROR(BDP($A11,"FUT_DLV_DT_FIRST"),"ERROR PLZ FIX") | I11: =IFERROR(BDP($A11,"LAST_TRADEABLE_DT"),"ERROR PLZ FIX") | J11: =IFERROR(BDP($A11,"VOLUME"),"ERROR PLZ FIX") | K11: =IFERROR(BDP($A11,"OPEN_INT"),"ERROR PLZ FIX")
B12: =IFERROR(BDP($A12,"SECURITY_DES"),"ERROR PLZ FIX") | C12: =IFERROR(BDP($A12,"PX_LAST"),"ERROR PLZ FIX") | D12: =IFERROR(BDP($A12,"PX_BID"),"ERROR PLZ FIX") | E12: =IFERROR(BDP($A12,"PX_ASK"),"ERROR PLZ FIX") | F12: =IFERROR(100-C12,"ERROR PLZ FIX") | G12: =IFERROR(BDP($A12,"FUT_MONTH_YR"),"ERROR PLZ FIX") | H12: =IFERROR(BDP($A12,"FUT_DLV_DT_FIRST"),"ERROR PLZ FIX") | I12: =IFERROR(BDP($A12,"LAST_TRADEABLE_DT"),"ERROR PLZ FIX") | J12: =IFERROR(BDP($A12,"VOLUME"),"ERROR PLZ FIX") | K12: =IFERROR(BDP($A12,"OPEN_INT"),"ERROR PLZ FIX")
B13: =IFERROR(BDP($A13,"SECURITY_DES"),"ERROR PLZ FIX") | C13: =IFERROR(BDP($A13,"PX_LAST"),"ERROR PLZ FIX") | D13: =IFERROR(BDP($A13,"PX_BID"),"ERROR PLZ FIX") | E13: =IFERROR(BDP($A13,"PX_ASK"),"ERROR PLZ FIX") | F13: =IFERROR(100-C13,"ERROR PLZ FIX") | G13: =IFERROR(BDP($A13,"FUT_MONTH_YR"),"ERROR PLZ FIX") | H13: =IFERROR(BDP($A13,"FUT_DLV_DT_FIRST"),"ERROR PLZ FIX") | I13: =IFERROR(BDP($A13,"LAST_TRADEABLE_DT"),"ERROR PLZ FIX") | J13: =IFERROR(BDP($A13,"VOLUME"),"ERROR PLZ FIX") | K13: =IFERROR(BDP($A13,"OPEN_INT"),"ERROR PLZ FIX")
B14: =IFERROR(BDP($A14,"SECURITY_DES"),"ERROR PLZ FIX") | C14: =IFERROR(BDP($A14,"PX_LAST"),"ERROR PLZ FIX") | D14: =IFERROR(BDP($A14,"PX_BID"),"ERROR PLZ FIX") | E14: =IFERROR(BDP($A14,"PX_ASK"),"ERROR PLZ FIX") | F14: =IFERROR(100-C14,"ERROR PLZ FIX") | G14: =IFERROR(BDP($A14,"FUT_MONTH_YR"),"ERROR PLZ FIX") | H14: =IFERROR(BDP($A14,"FUT_DLV_DT_FIRST"),"ERROR PLZ FIX") | I14: =IFERROR(BDP($A14,"LAST_TRADEABLE_DT"),"ERROR PLZ FIX") | J14: =IFERROR(BDP($A14,"VOLUME"),"ERROR PLZ FIX") | K14: =IFERROR(BDP($A14,"OPEN_INT"),"ERROR PLZ FIX")
B15: =IFERROR(BDP($A15,"SECURITY_DES"),"ERROR PLZ FIX") | C15: =IFERROR(BDP($A15,"PX_LAST"),"ERROR PLZ FIX") | D15: =IFERROR(BDP($A15,"PX_BID"),"ERROR PLZ FIX") | E15: =IFERROR(BDP($A15,"PX_ASK"),"ERROR PLZ FIX") | F15: =IFERROR(100-C15,"ERROR PLZ FIX") | G15: =IFERROR(BDP($A15,"FUT_MONTH_YR"),"ERROR PLZ FIX") | H15: =IFERROR(BDP($A15,"FUT_DLV_DT_FIRST"),"ERROR PLZ FIX") | I15: =IFERROR(BDP($A15,"LAST_TRADEABLE_DT"),"ERROR PLZ FIX") | J15: =IFERROR(BDP($A15,"VOLUME"),"ERROR PLZ FIX") | K15: =IFERROR(BDP($A15,"OPEN_INT"),"ERROR PLZ FIX")
B16: =IFERROR(BDP($A16,"SECURITY_DES"),"ERROR PLZ FIX") | C16: =IFERROR(BDP($A16,"PX_LAST"),"ERROR PLZ FIX") | D16: =IFERROR(BDP($A16,"PX_BID"),"ERROR PLZ FIX") | E16: =IFERROR(BDP($A16,"PX_ASK"),"ERROR PLZ FIX") | F16: =IFERROR(100-C16,"ERROR PLZ FIX") | G16: =IFERROR(BDP($A16,"FUT_MONTH_YR"),"ERROR PLZ FIX") | H16: =IFERROR(BDP($A16,"FUT_DLV_DT_FIRST"),"ERROR PLZ FIX") | I16: =IFERROR(BDP($A16,"LAST_TRADEABLE_DT"),"ERROR PLZ FIX") | J16: =IFERROR(BDP($A16,"VOLUME"),"ERROR PLZ FIX") | K16: =IFERROR(BDP($A16,"OPEN_INT"),"ERROR PLZ FIX")
B17: =IFERROR(BDP($A17,"SECURITY_DES"),"ERROR PLZ FIX") | C17: =IFERROR(BDP($A17,"PX_LAST"),"ERROR PLZ FIX") | D17: =IFERROR(BDP($A17,"PX_BID"),"ERROR PLZ FIX") | E17: =IFERROR(BDP($A17,"PX_ASK"),"ERROR PLZ FIX") | F17: =IFERROR(100-C17,"ERROR PLZ FIX") | G17: =IFERROR(BDP($A17,"FUT_MONTH_YR"),"ERROR PLZ FIX") | H17: =IFERROR(BDP($A17,"FUT_DLV_DT_FIRST"),"ERROR PLZ FIX") | I17: =IFERROR(BDP($A17,"LAST_TRADEABLE_DT"),"ERROR PLZ FIX") | J17: =IFERROR(BDP($A17,"VOLUME"),"ERROR PLZ FIX") | K17: =IFERROR(BDP($A17,"OPEN_INT"),"ERROR PLZ FIX")
B18: =IFERROR(BDP($A18,"SECURITY_DES"),"ERROR PLZ FIX") | C18: =IFERROR(BDP($A18,"PX_LAST"),"ERROR PLZ FIX") | D18: =IFERROR(BDP($A18,"PX_BID"),"ERROR PLZ FIX") | E18: =IFERROR(BDP($A18,"PX_ASK"),"ERROR PLZ FIX") | F18: =IFERROR(100-C18,"ERROR PLZ FIX") | G18: =IFERROR(BDP($A18,"FUT_MONTH_YR"),"ERROR PLZ FIX") | H18: =IFERROR(BDP($A18,"FUT_DLV_DT_FIRST"),"ERROR PLZ FIX") | I18: =IFERROR(BDP($A18,"LAST_TRADEABLE_DT"),"ERROR PLZ FIX") | J18: =IFERROR(BDP($A18,"VOLUME"),"ERROR PLZ FIX") | K18: =IFERROR(BDP($A18,"OPEN_INT"),"ERROR PLZ FIX")
B19: =IFERROR(BDP($A19,"SECURITY_DES"),"ERROR PLZ FIX") | C19: =IFERROR(BDP($A19,"PX_LAST"),"ERROR PLZ FIX") | D19: =IFERROR(BDP($A19,"PX_BID"),"ERROR PLZ FIX") | E19: =IFERROR(BDP($A19,"PX_ASK"),"ERROR PLZ FIX") | F19: =IFERROR(100-C19,"ERROR PLZ FIX") | G19: =IFERROR(BDP($A19,"FUT_MONTH_YR"),"ERROR PLZ FIX") | H19: =IFERROR(BDP($A19,"FUT_DLV_DT_FIRST"),"ERROR PLZ FIX") | I19: =IFERROR(BDP($A19,"LAST_TRADEABLE_DT"),"ERROR PLZ FIX") | J19: =IFERROR(BDP($A19,"VOLUME"),"ERROR PLZ FIX") | K19: =IFERROR(BDP($A19,"OPEN_INT"),"ERROR PLZ FIX")
... B26: =IFERROR(BDP($A26,"SECURITY_DES"),"ERROR PLZ FIX") | C26: =IFERROR(BDP($A26,"PX_LAST"),"ERROR PLZ FIX") | D26: =IFERROR(BDP($A26,"PX_BID"),"ERROR PLZ FIX") | E26: =IFERROR(BDP($A26,"PX_ASK"),"ERROR PLZ FIX") | F26: =IFERROR(100-C26,"ERROR PLZ FIX") | G26: =IFERROR(BDP($A26,"FUT_MONTH_YR"),"ERROR PLZ FIX") | H26: =IFERROR(BDP($A26,"FUT_DLV_DT_FIRST"),"ERROR PLZ FIX") | I26: =IFERROR(BDP($A26,"LAST_TRADEABLE_DT"),"ERROR PLZ FIX") | J26: =IFERROR(BDP($A26,"VOLUME"),"ERROR PLZ FIX") | K26: =IFERROR(BDP($A26,"OPEN_INT"),"ERROR PLZ FIX")
A29: SR1 — ONE-MONTH SOFR FUTURES (SERA Comdty · CME SR1) — first 13 monthly contracts
A30: Column A cell below holds =BDS("SERA Comdty","FUT_CHAIN") and SPILLS the active contract tickers down. Field columns reference each row's contract in column A. Adjust the row count to the liquid strip (check VOLUME / OPEN_INT).
A31: Contract (from CT chain) | B31: SECURITY_DES | C31: PX_LAST | D31: PX_BID | E31: PX_ASK | F31: Implied rate % (100−Last) | G31: FUT_MONTH_YR | H31: Ref. start (FUT_DLV_DT_FIRST) | I31: LAST_TRADEABLE_DT | J31: VOLUME | K31: OPEN_INT
A32: =BDS("SERA Comdty","FUT_CHAIN") | B32: =IFERROR(BDP($A32,"SECURITY_DES"),"ERROR PLZ FIX") | C32: =IFERROR(BDP($A32,"PX_LAST"),"ERROR PLZ FIX") | D32: =IFERROR(BDP($A32,"PX_BID"),"ERROR PLZ FIX") | E32: =IFERROR(BDP($A32,"PX_ASK"),"ERROR PLZ FIX") | F32: =IFERROR(100-C32,"ERROR PLZ FIX") | G32: =IFERROR(BDP($A32,"FUT_MONTH_YR"),"ERROR PLZ FIX") | H32: =IFERROR(BDP($A32,"FUT_DLV_DT_FIRST"),"ERROR PLZ FIX") | I32: =IFERROR(BDP($A32,"LAST_TRADEABLE_DT"),"ERROR PLZ FIX") | J32: =IFERROR(BDP($A32,"VOLUME"),"ERROR PLZ FIX") | K32: =IFERROR(BDP($A32,"OPEN_INT"),"ERROR PLZ FIX")
B33: =IFERROR(BDP($A33,"SECURITY_DES"),"ERROR PLZ FIX") | C33: =IFERROR(BDP($A33,"PX_LAST"),"ERROR PLZ FIX") | D33: =IFERROR(BDP($A33,"PX_BID"),"ERROR PLZ FIX") | E33: =IFERROR(BDP($A33,"PX_ASK"),"ERROR PLZ FIX") | F33: =IFERROR(100-C33,"ERROR PLZ FIX") | G33: =IFERROR(BDP($A33,"FUT_MONTH_YR"),"ERROR PLZ FIX") | H33: =IFERROR(BDP($A33,"FUT_DLV_DT_FIRST"),"ERROR PLZ FIX") | I33: =IFERROR(BDP($A33,"LAST_TRADEABLE_DT"),"ERROR PLZ FIX") | J33: =IFERROR(BDP($A33,"VOLUME"),"ERROR PLZ FIX") | K33: =IFERROR(BDP($A33,"OPEN_INT"),"ERROR PLZ FIX")
B34: =IFERROR(BDP($A34,"SECURITY_DES"),"ERROR PLZ FIX") | C34: =IFERROR(BDP($A34,"PX_LAST"),"ERROR PLZ FIX") | D34: =IFERROR(BDP($A34,"PX_BID"),"ERROR PLZ FIX") | E34: =IFERROR(BDP($A34,"PX_ASK"),"ERROR PLZ FIX") | F34: =IFERROR(100-C34,"ERROR PLZ FIX") | G34: =IFERROR(BDP($A34,"FUT_MONTH_YR"),"ERROR PLZ FIX") | H34: =IFERROR(BDP($A34,"FUT_DLV_DT_FIRST"),"ERROR PLZ FIX") | I34: =IFERROR(BDP($A34,"LAST_TRADEABLE_DT"),"ERROR PLZ FIX") | J34: =IFERROR(BDP($A34,"VOLUME"),"ERROR PLZ FIX") | K34: =IFERROR(BDP($A34,"OPEN_INT"),"ERROR PLZ FIX")
B35: =IFERROR(BDP($A35,"SECURITY_DES"),"ERROR PLZ FIX") | C35: =IFERROR(BDP($A35,"PX_LAST"),"ERROR PLZ FIX") | D35: =IFERROR(BDP($A35,"PX_BID"),"ERROR PLZ FIX") | E35: =IFERROR(BDP($A35,"PX_ASK"),"ERROR PLZ FIX") | F35: =IFERROR(100-C35,"ERROR PLZ FIX") | G35: =IFERROR(BDP($A35,"FUT_MONTH_YR"),"ERROR PLZ FIX") | H35: =IFERROR(BDP($A35,"FUT_DLV_DT_FIRST"),"ERROR PLZ FIX") | I35: =IFERROR(BDP($A35,"LAST_TRADEABLE_DT"),"ERROR PLZ FIX") | J35: =IFERROR(BDP($A35,"VOLUME"),"ERROR PLZ FIX") | K35: =IFERROR(BDP($A35,"OPEN_INT"),"ERROR PLZ FIX")
B36: =IFERROR(BDP($A36,"SECURITY_DES"),"ERROR PLZ FIX") | C36: =IFERROR(BDP($A36,"PX_LAST"),"ERROR PLZ FIX") | D36: =IFERROR(BDP($A36,"PX_BID"),"ERROR PLZ FIX") | E36: =IFERROR(BDP($A36,"PX_ASK"),"ERROR PLZ FIX") | F36: =IFERROR(100-C36,"ERROR PLZ FIX") | G36: =IFERROR(BDP($A36,"FUT_MONTH_YR"),"ERROR PLZ FIX") | H36: =IFERROR(BDP($A36,"FUT_DLV_DT_FIRST"),"ERROR PLZ FIX") | I36: =IFERROR(BDP($A36,"LAST_TRADEABLE_DT"),"ERROR PLZ FIX") | J36: =IFERROR(BDP($A36,"VOLUME"),"ERROR PLZ FIX") | K36: =IFERROR(BDP($A36,"OPEN_INT"),"ERROR PLZ FIX")
B37: =IFERROR(BDP($A37,"SECURITY_DES"),"ERROR PLZ FIX") | C37: =IFERROR(BDP($A37,"PX_LAST"),"ERROR PLZ FIX") | D37: =IFERROR(BDP($A37,"PX_BID"),"ERROR PLZ FIX") | E37: =IFERROR(BDP($A37,"PX_ASK"),"ERROR PLZ FIX") | F37: =IFERROR(100-C37,"ERROR PLZ FIX") | G37: =IFERROR(BDP($A37,"FUT_MONTH_YR"),"ERROR PLZ FIX") | H37: =IFERROR(BDP($A37,"FUT_DLV_DT_FIRST"),"ERROR PLZ FIX") | I37: =IFERROR(BDP($A37,"LAST_TRADEABLE_DT"),"ERROR PLZ FIX") | J37: =IFERROR(BDP($A37,"VOLUME"),"ERROR PLZ FIX") | K37: =IFERROR(BDP($A37,"OPEN_INT"),"ERROR PLZ FIX")
B38: =IFERROR(BDP($A38,"SECURITY_DES"),"ERROR PLZ FIX") | C38: =IFERROR(BDP($A38,"PX_LAST"),"ERROR PLZ FIX") | D38: =IFERROR(BDP($A38,"PX_BID"),"ERROR PLZ FIX") | E38: =IFERROR(BDP($A38,"PX_ASK"),"ERROR PLZ FIX") | F38: =IFERROR(100-C38,"ERROR PLZ FIX") | G38: =IFERROR(BDP($A38,"FUT_MONTH_YR"),"ERROR PLZ FIX") | H38: =IFERROR(BDP($A38,"FUT_DLV_DT_FIRST"),"ERROR PLZ FIX") | I38: =IFERROR(BDP($A38,"LAST_TRADEABLE_DT"),"ERROR PLZ FIX") | J38: =IFERROR(BDP($A38,"VOLUME"),"ERROR PLZ FIX") | K38: =IFERROR(BDP($A38,"OPEN_INT"),"ERROR PLZ FIX")
B39: =IFERROR(BDP($A39,"SECURITY_DES"),"ERROR PLZ FIX") | C39: =IFERROR(BDP($A39,"PX_LAST"),"ERROR PLZ FIX") | D39: =IFERROR(BDP($A39,"PX_BID"),"ERROR PLZ FIX") | E39: =IFERROR(BDP($A39,"PX_ASK"),"ERROR PLZ FIX") | F39: =IFERROR(100-C39,"ERROR PLZ FIX") | G39: =IFERROR(BDP($A39,"FUT_MONTH_YR"),"ERROR PLZ FIX") | H39: =IFERROR(BDP($A39,"FUT_DLV_DT_FIRST"),"ERROR PLZ FIX") | I39: =IFERROR(BDP($A39,"LAST_TRADEABLE_DT"),"ERROR PLZ FIX") | J39: =IFERROR(BDP($A39,"VOLUME"),"ERROR PLZ FIX") | K39: =IFERROR(BDP($A39,"OPEN_INT"),"ERROR PLZ FIX")
B40: =IFERROR(BDP($A40,"SECURITY_DES"),"ERROR PLZ FIX") | C40: =IFERROR(BDP($A40,"PX_LAST"),"ERROR PLZ FIX") | D40: =IFERROR(BDP($A40,"PX_BID"),"ERROR PLZ FIX") | E40: =IFERROR(BDP($A40,"PX_ASK"),"ERROR PLZ FIX") | F40: =IFERROR(100-C40,"ERROR PLZ FIX") | G40: =IFERROR(BDP($A40,"FUT_MONTH_YR"),"ERROR PLZ FIX") | H40: =IFERROR(BDP($A40,"FUT_DLV_DT_FIRST"),"ERROR PLZ FIX") | I40: =IFERROR(BDP($A40,"LAST_TRADEABLE_DT"),"ERROR PLZ FIX") | J40: =IFERROR(BDP($A40,"VOLUME"),"ERROR PLZ FIX") | K40: =IFERROR(BDP($A40,"OPEN_INT"),"ERROR PLZ FIX")
B41: =IFERROR(BDP($A41,"SECURITY_DES"),"ERROR PLZ FIX") | C41: =IFERROR(BDP($A41,"PX_LAST"),"ERROR PLZ FIX") | D41: =IFERROR(BDP($A41,"PX_BID"),"ERROR PLZ FIX") | E41: =IFERROR(BDP($A41,"PX_ASK"),"ERROR PLZ FIX") | F41: =IFERROR(100-C41,"ERROR PLZ FIX") | G41: =IFERROR(BDP($A41,"FUT_MONTH_YR"),"ERROR PLZ FIX") | H41: =IFERROR(BDP($A41,"FUT_DLV_DT_FIRST"),"ERROR PLZ FIX") | I41: =IFERROR(BDP($A41,"LAST_TRADEABLE_DT"),"ERROR PLZ FIX") | J41: =IFERROR(BDP($A41,"VOLUME"),"ERROR PLZ FIX") | K41: =IFERROR(BDP($A41,"OPEN_INT"),"ERROR PLZ FIX")
B42: =IFERROR(BDP($A42,"SECURITY_DES"),"ERROR PLZ FIX") | C42: =IFERROR(BDP($A42,"PX_LAST"),"ERROR PLZ FIX") | D42: =IFERROR(BDP($A42,"PX_BID"),"ERROR PLZ FIX") | E42: =IFERROR(BDP($A42,"PX_ASK"),"ERROR PLZ FIX") | F42: =IFERROR(100-C42,"ERROR PLZ FIX") | G42: =IFERROR(BDP($A42,"FUT_MONTH_YR"),"ERROR PLZ FIX") | H42: =IFERROR(BDP($A42,"FUT_DLV_DT_FIRST"),"ERROR PLZ FIX") | I42: =IFERROR(BDP($A42,"LAST_TRADEABLE_DT"),"ERROR PLZ FIX") | J42: =IFERROR(BDP($A42,"VOLUME"),"ERROR PLZ FIX") | K42: =IFERROR(BDP($A42,"OPEN_INT"),"ERROR PLZ FIX")
B43: =IFERROR(BDP($A43,"SECURITY_DES"),"ERROR PLZ FIX") | C43: =IFERROR(BDP($A43,"PX_LAST"),"ERROR PLZ FIX") | D43: =IFERROR(BDP($A43,"PX_BID"),"ERROR PLZ FIX") | E43: =IFERROR(BDP($A43,"PX_ASK"),"ERROR PLZ FIX") | F43: =IFERROR(100-C43,"ERROR PLZ FIX") | G43: =IFERROR(BDP($A43,"FUT_MONTH_YR"),"ERROR PLZ FIX") | H43: =IFERROR(BDP($A43,"FUT_DLV_DT_FIRST"),"ERROR PLZ FIX") | I43: =IFERROR(BDP($A43,"LAST_TRADEABLE_DT"),"ERROR PLZ FIX") | J43: =IFERROR(BDP($A43,"VOLUME"),"ERROR PLZ FIX") | K43: =IFERROR(BDP($A43,"OPEN_INT"),"ERROR PLZ FIX")
B44: =IFERROR(BDP($A44,"SECURITY_DES"),"ERROR PLZ FIX") | C44: =IFERROR(BDP($A44,"PX_LAST"),"ERROR PLZ FIX") | D44: =IFERROR(BDP($A44,"PX_BID"),"ERROR PLZ FIX") | E44: =IFERROR(BDP($A44,"PX_ASK"),"ERROR PLZ FIX") | F44: =IFERROR(100-C44,"ERROR PLZ FIX") | G44: =IFERROR(BDP($A44,"FUT_MONTH_YR"),"ERROR PLZ FIX") | H44: =IFERROR(BDP($A44,"FUT_DLV_DT_FIRST"),"ERROR PLZ FIX") | I44: =IFERROR(BDP($A44,"LAST_TRADEABLE_DT"),"ERROR PLZ FIX") | J44: =IFERROR(BDP($A44,"VOLUME"),"ERROR PLZ FIX") | K44: =IFERROR(BDP($A44,"OPEN_INT"),"ERROR PLZ FIX")

Sheet SOFR_OIS_Quotes
A1: SOFR_OIS_Quotes
A2: USD fixed-vs-SOFR OIS strip (USOSFR…, BGN) — 1W to 50Y. Maturity & years are derived live from the tenor.
A3: Spot (T+2): | B3: =WORKDAY(VAL_DATE,2) | C3: Maturity & Tenor(yrs) recompute from the tenor label + spot.
A4: Ticker root | B4: Tenor | C4: Maturity date | D4: Tenor (yrs) | E4: PX_BID | F4: PX_ASK | G4: PX_LAST | H4: Mid = (Bid+Ask)/2 | I4: In bootstrap set
A5: USOSFR1Z | B5: 1W | C5: =IF(RIGHT(B5,1)="W",$B$3+7*VALUE(LEFT(B5,LEN(B5)-1)),IF(RIGHT(B5,1)="M",EDATE($B$3,VALUE(LEFT(B5,LEN(B5)-1))),EDATE($B$3,12*VALUE(LEFT(B5,LEN(B5)-1))))) | D5: =(C5-$B$3)/365 | E5: =IFERROR(BDP(A5&" "&PX_SRC&" Curncy","PX_BID"),"ERROR PLZ FIX") | F5: =IFERROR(BDP(A5&" "&PX_SRC&" Curncy","PX_ASK"),"ERROR PLZ FIX") | G5: =IFERROR(BDP(A5&" "&PX_SRC&" Curncy","PX_LAST"),"ERROR PLZ FIX") | H5: =IFERROR((E5+F5)/2,IFERROR(G5,"ERROR PLZ FIX")) | I5: Y
A6: USOSFR2Z | B6: 2W | C6: =IF(RIGHT(B6,1)="W",$B$3+7*VALUE(LEFT(B6,LEN(B6)-1)),IF(RIGHT(B6,1)="M",EDATE($B$3,VALUE(LEFT(B6,LEN(B6)-1))),EDATE($B$3,12*VALUE(LEFT(B6,LEN(B6)-1))))) | D6: =(C6-$B$3)/365 | E6: =IFERROR(BDP(A6&" "&PX_SRC&" Curncy","PX_BID"),"ERROR PLZ FIX") | F6: =IFERROR(BDP(A6&" "&PX_SRC&" Curncy","PX_ASK"),"ERROR PLZ FIX") | G6: =IFERROR(BDP(A6&" "&PX_SRC&" Curncy","PX_LAST"),"ERROR PLZ FIX") | H6: =IFERROR((E6+F6)/2,IFERROR(G6,"ERROR PLZ FIX"))
A7: USOSFR3Z | B7: 3W | C7: =IF(RIGHT(B7,1)="W",$B$3+7*VALUE(LEFT(B7,LEN(B7)-1)),IF(RIGHT(B7,1)="M",EDATE($B$3,VALUE(LEFT(B7,LEN(B7)-1))),EDATE($B$3,12*VALUE(LEFT(B7,LEN(B7)-1))))) | D7: =(C7-$B$3)/365 | E7: =IFERROR(BDP(A7&" "&PX_SRC&" Curncy","PX_BID"),"ERROR PLZ FIX") | F7: =IFERROR(BDP(A7&" "&PX_SRC&" Curncy","PX_ASK"),"ERROR PLZ FIX") | G7: =IFERROR(BDP(A7&" "&PX_SRC&" Curncy","PX_LAST"),"ERROR PLZ FIX") | H7: =IFERROR((E7+F7)/2,IFERROR(G7,"ERROR PLZ FIX"))
A8: USOSFRA | B8: 1M | C8: =IF(RIGHT(B8,1)="W",$B$3+7*VALUE(LEFT(B8,LEN(B8)-1)),IF(RIGHT(B8,1)="M",EDATE($B$3,VALUE(LEFT(B8,LEN(B8)-1))),EDATE($B$3,12*VALUE(LEFT(B8,LEN(B8)-1))))) | D8: =(C8-$B$3)/365 | E8: =IFERROR(BDP(A8&" "&PX_SRC&" Curncy","PX_BID"),"ERROR PLZ FIX") | F8: =IFERROR(BDP(A8&" "&PX_SRC&" Curncy","PX_ASK"),"ERROR PLZ FIX") | G8: =IFERROR(BDP(A8&" "&PX_SRC&" Curncy","PX_LAST"),"ERROR PLZ FIX") | H8: =IFERROR((E8+F8)/2,IFERROR(G8,"ERROR PLZ FIX")) | I8: Y
A9: USOSFRB | B9: 2M | C9: =IF(RIGHT(B9,1)="W",$B$3+7*VALUE(LEFT(B9,LEN(B9)-1)),IF(RIGHT(B9,1)="M",EDATE($B$3,VALUE(LEFT(B9,LEN(B9)-1))),EDATE($B$3,12*VALUE(LEFT(B9,LEN(B9)-1))))) | D9: =(C9-$B$3)/365 | E9: =IFERROR(BDP(A9&" "&PX_SRC&" Curncy","PX_BID"),"ERROR PLZ FIX") | F9: =IFERROR(BDP(A9&" "&PX_SRC&" Curncy","PX_ASK"),"ERROR PLZ FIX") | G9: =IFERROR(BDP(A9&" "&PX_SRC&" Curncy","PX_LAST"),"ERROR PLZ FIX") | H9: =IFERROR((E9+F9)/2,IFERROR(G9,"ERROR PLZ FIX"))
A10: USOSFRC | B10: 3M | C10: =IF(RIGHT(B10,1)="W",$B$3+7*VALUE(LEFT(B10,LEN(B10)-1)),IF(RIGHT(B10,1)="M",EDATE($B$3,VALUE(LEFT(B10,LEN(B10)-1))),EDATE($B$3,12*VALUE(LEFT(B10,LEN(B10)-1))))) | D10: =(C10-$B$3)/365 | E10: =IFERROR(BDP(A10&" "&PX_SRC&" Curncy","PX_BID"),"ERROR PLZ FIX") | F10: =IFERROR(BDP(A10&" "&PX_SRC&" Curncy","PX_ASK"),"ERROR PLZ FIX") | G10: =IFERROR(BDP(A10&" "&PX_SRC&" Curncy","PX_LAST"),"ERROR PLZ FIX") | H10: =IFERROR((E10+F10)/2,IFERROR(G10,"ERROR PLZ FIX")) | I10: Y
A11: USOSFRD | B11: 4M | C11: =IF(RIGHT(B11,1)="W",$B$3+7*VALUE(LEFT(B11,LEN(B11)-1)),IF(RIGHT(B11,1)="M",EDATE($B$3,VALUE(LEFT(B11,LEN(B11)-1))),EDATE($B$3,12*VALUE(LEFT(B11,LEN(B11)-1))))) | D11: =(C11-$B$3)/365 | E11: =IFERROR(BDP(A11&" "&PX_SRC&" Curncy","PX_BID"),"ERROR PLZ FIX") | F11: =IFERROR(BDP(A11&" "&PX_SRC&" Curncy","PX_ASK"),"ERROR PLZ FIX") | G11: =IFERROR(BDP(A11&" "&PX_SRC&" Curncy","PX_LAST"),"ERROR PLZ FIX") | H11: =IFERROR((E11+F11)/2,IFERROR(G11,"ERROR PLZ FIX"))
A12: USOSFRE | B12: 5M | C12: =IF(RIGHT(B12,1)="W",$B$3+7*VALUE(LEFT(B12,LEN(B12)-1)),IF(RIGHT(B12,1)="M",EDATE($B$3,VALUE(LEFT(B12,LEN(B12)-1))),EDATE($B$3,12*VALUE(LEFT(B12,LEN(B12)-1))))) | D12: =(C12-$B$3)/365 | E12: =IFERROR(BDP(A12&" "&PX_SRC&" Curncy","PX_BID"),"ERROR PLZ FIX") | F12: =IFERROR(BDP(A12&" "&PX_SRC&" Curncy","PX_ASK"),"ERROR PLZ FIX") | G12: =IFERROR(BDP(A12&" "&PX_SRC&" Curncy","PX_LAST"),"ERROR PLZ FIX") | H12: =IFERROR((E12+F12)/2,IFERROR(G12,"ERROR PLZ FIX"))
A13: USOSFRF | B13: 6M | C13: =IF(RIGHT(B13,1)="W",$B$3+7*VALUE(LEFT(B13,LEN(B13)-1)),IF(RIGHT(B13,1)="M",EDATE($B$3,VALUE(LEFT(B13,LEN(B13)-1))),EDATE($B$3,12*VALUE(LEFT(B13,LEN(B13)-1))))) | D13: =(C13-$B$3)/365 | E13: =IFERROR(BDP(A13&" "&PX_SRC&" Curncy","PX_BID"),"ERROR PLZ FIX") | F13: =IFERROR(BDP(A13&" "&PX_SRC&" Curncy","PX_ASK"),"ERROR PLZ FIX") | G13: =IFERROR(BDP(A13&" "&PX_SRC&" Curncy","PX_LAST"),"ERROR PLZ FIX") | H13: =IFERROR((E13+F13)/2,IFERROR(G13,"ERROR PLZ FIX")) | I13: Y
A14: USOSFRG | B14: 7M | C14: =IF(RIGHT(B14,1)="W",$B$3+7*VALUE(LEFT(B14,LEN(B14)-1)),IF(RIGHT(B14,1)="M",EDATE($B$3,VALUE(LEFT(B14,LEN(B14)-1))),EDATE($B$3,12*VALUE(LEFT(B14,LEN(B14)-1))))) | D14: =(C14-$B$3)/365 | E14: =IFERROR(BDP(A14&" "&PX_SRC&" Curncy","PX_BID"),"ERROR PLZ FIX") | F14: =IFERROR(BDP(A14&" "&PX_SRC&" Curncy","PX_ASK"),"ERROR PLZ FIX") | G14: =IFERROR(BDP(A14&" "&PX_SRC&" Curncy","PX_LAST"),"ERROR PLZ FIX") | H14: =IFERROR((E14+F14)/2,IFERROR(G14,"ERROR PLZ FIX"))
A15: USOSFRH | B15: 8M | C15: =IF(RIGHT(B15,1)="W",$B$3+7*VALUE(LEFT(B15,LEN(B15)-1)),IF(RIGHT(B15,1)="M",EDATE($B$3,VALUE(LEFT(B15,LEN(B15)-1))),EDATE($B$3,12*VALUE(LEFT(B15,LEN(B15)-1))))) | D15: =(C15-$B$3)/365 | E15: =IFERROR(BDP(A15&" "&PX_SRC&" Curncy","PX_BID"),"ERROR PLZ FIX") | F15: =IFERROR(BDP(A15&" "&PX_SRC&" Curncy","PX_ASK"),"ERROR PLZ FIX") | G15: =IFERROR(BDP(A15&" "&PX_SRC&" Curncy","PX_LAST"),"ERROR PLZ FIX") | H15: =IFERROR((E15+F15)/2,IFERROR(G15,"ERROR PLZ FIX"))
A16: USOSFRI | B16: 9M | C16: =IF(RIGHT(B16,1)="W",$B$3+7*VALUE(LEFT(B16,LEN(B16)-1)),IF(RIGHT(B16,1)="M",EDATE($B$3,VALUE(LEFT(B16,LEN(B16)-1))),EDATE($B$3,12*VALUE(LEFT(B16,LEN(B16)-1))))) | D16: =(C16-$B$3)/365 | E16: =IFERROR(BDP(A16&" "&PX_SRC&" Curncy","PX_BID"),"ERROR PLZ FIX") | F16: =IFERROR(BDP(A16&" "&PX_SRC&" Curncy","PX_ASK"),"ERROR PLZ FIX") | G16: =IFERROR(BDP(A16&" "&PX_SRC&" Curncy","PX_LAST"),"ERROR PLZ FIX") | H16: =IFERROR((E16+F16)/2,IFERROR(G16,"ERROR PLZ FIX"))
A17: USOSFRJ | B17: 10M | C17: =IF(RIGHT(B17,1)="W",$B$3+7*VALUE(LEFT(B17,LEN(B17)-1)),IF(RIGHT(B17,1)="M",EDATE($B$3,VALUE(LEFT(B17,LEN(B17)-1))),EDATE($B$3,12*VALUE(LEFT(B17,LEN(B17)-1))))) | D17: =(C17-$B$3)/365 | E17: =IFERROR(BDP(A17&" "&PX_SRC&" Curncy","PX_BID"),"ERROR PLZ FIX") | F17: =IFERROR(BDP(A17&" "&PX_SRC&" Curncy","PX_ASK"),"ERROR PLZ FIX") | G17: =IFERROR(BDP(A17&" "&PX_SRC&" Curncy","PX_LAST"),"ERROR PLZ FIX") | H17: =IFERROR((E17+F17)/2,IFERROR(G17,"ERROR PLZ FIX"))
A18: USOSFRK | B18: 11M | C18: =IF(RIGHT(B18,1)="W",$B$3+7*VALUE(LEFT(B18,LEN(B18)-1)),IF(RIGHT(B18,1)="M",EDATE($B$3,VALUE(LEFT(B18,LEN(B18)-1))),EDATE($B$3,12*VALUE(LEFT(B18,LEN(B18)-1))))) | D18: =(C18-$B$3)/365 | E18: =IFERROR(BDP(A18&" "&PX_SRC&" Curncy","PX_BID"),"ERROR PLZ FIX") | F18: =IFERROR(BDP(A18&" "&PX_SRC&" Curncy","PX_ASK"),"ERROR PLZ FIX") | G18: =IFERROR(BDP(A18&" "&PX_SRC&" Curncy","PX_LAST"),"ERROR PLZ FIX") | H18: =IFERROR((E18+F18)/2,IFERROR(G18,"ERROR PLZ FIX"))
A19: USOSFR1 | B19: 1Y | C19: =IF(RIGHT(B19,1)="W",$B$3+7*VALUE(LEFT(B19,LEN(B19)-1)),IF(RIGHT(B19,1)="M",EDATE($B$3,VALUE(LEFT(B19,LEN(B19)-1))),EDATE($B$3,12*VALUE(LEFT(B19,LEN(B19)-1))))) | D19: =(C19-$B$3)/365 | E19: =IFERROR(BDP(A19&" "&PX_SRC&" Curncy","PX_BID"),"ERROR PLZ FIX") | F19: =IFERROR(BDP(A19&" "&PX_SRC&" Curncy","PX_ASK"),"ERROR PLZ FIX") | G19: =IFERROR(BDP(A19&" "&PX_SRC&" Curncy","PX_LAST"),"ERROR PLZ FIX") | H19: =IFERROR((E19+F19)/2,IFERROR(G19,"ERROR PLZ FIX"))
A20: USOSFR1F | B20: 18M | C20: =IF(RIGHT(B20,1)="W",$B$3+7*VALUE(LEFT(B20,LEN(B20)-1)),IF(RIGHT(B20,1)="M",EDATE($B$3,VALUE(LEFT(B20,LEN(B20)-1))),EDATE($B$3,12*VALUE(LEFT(B20,LEN(B20)-1))))) | D20: =(C20-$B$3)/365 | E20: =IFERROR(BDP(A20&" "&PX_SRC&" Curncy","PX_BID"),"ERROR PLZ FIX") | F20: =IFERROR(BDP(A20&" "&PX_SRC&" Curncy","PX_ASK"),"ERROR PLZ FIX") | G20: =IFERROR(BDP(A20&" "&PX_SRC&" Curncy","PX_LAST"),"ERROR PLZ FIX") | H20: =IFERROR((E20+F20)/2,IFERROR(G20,"ERROR PLZ FIX"))
A21: USOSFR2 | B21: 2Y | C21: =IF(RIGHT(B21,1)="W",$B$3+7*VALUE(LEFT(B21,LEN(B21)-1)),IF(RIGHT(B21,1)="M",EDATE($B$3,VALUE(LEFT(B21,LEN(B21)-1))),EDATE($B$3,12*VALUE(LEFT(B21,LEN(B21)-1))))) | D21: =(C21-$B$3)/365 | E21: =IFERROR(BDP(A21&" "&PX_SRC&" Curncy","PX_BID"),"ERROR PLZ FIX") | F21: =IFERROR(BDP(A21&" "&PX_SRC&" Curncy","PX_ASK"),"ERROR PLZ FIX") | G21: =IFERROR(BDP(A21&" "&PX_SRC&" Curncy","PX_LAST"),"ERROR PLZ FIX") | H21: =IFERROR((E21+F21)/2,IFERROR(G21,"ERROR PLZ FIX"))
A22: USOSFR3 | B22: 3Y | C22: =IF(RIGHT(B22,1)="W",$B$3+7*VALUE(LEFT(B22,LEN(B22)-1)),IF(RIGHT(B22,1)="M",EDATE($B$3,VALUE(LEFT(B22,LEN(B22)-1))),EDATE($B$3,12*VALUE(LEFT(B22,LEN(B22)-1))))) | D22: =(C22-$B$3)/365 | E22: =IFERROR(BDP(A22&" "&PX_SRC&" Curncy","PX_BID"),"ERROR PLZ FIX") | F22: =IFERROR(BDP(A22&" "&PX_SRC&" Curncy","PX_ASK"),"ERROR PLZ FIX") | G22: =IFERROR(BDP(A22&" "&PX_SRC&" Curncy","PX_LAST"),"ERROR PLZ FIX") | H22: =IFERROR((E22+F22)/2,IFERROR(G22,"ERROR PLZ FIX"))
A23: USOSFR4 | B23: 4Y | C23: =IF(RIGHT(B23,1)="W",$B$3+7*VALUE(LEFT(B23,LEN(B23)-1)),IF(RIGHT(B23,1)="M",EDATE($B$3,VALUE(LEFT(B23,LEN(B23)-1))),EDATE($B$3,12*VALUE(LEFT(B23,LEN(B23)-1))))) | D23: =(C23-$B$3)/365 | E23: =IFERROR(BDP(A23&" "&PX_SRC&" Curncy","PX_BID"),"ERROR PLZ FIX") | F23: =IFERROR(BDP(A23&" "&PX_SRC&" Curncy","PX_ASK"),"ERROR PLZ FIX") | G23: =IFERROR(BDP(A23&" "&PX_SRC&" Curncy","PX_LAST"),"ERROR PLZ FIX") | H23: =IFERROR((E23+F23)/2,IFERROR(G23,"ERROR PLZ FIX"))
A24: USOSFR5 | B24: 5Y | C24: =IF(RIGHT(B24,1)="W",$B$3+7*VALUE(LEFT(B24,LEN(B24)-1)),IF(RIGHT(B24,1)="M",EDATE($B$3,VALUE(LEFT(B24,LEN(B24)-1))),EDATE($B$3,12*VALUE(LEFT(B24,LEN(B24)-1))))) | D24: =(C24-$B$3)/365 | E24: =IFERROR(BDP(A24&" "&PX_SRC&" Curncy","PX_BID"),"ERROR PLZ FIX") | F24: =IFERROR(BDP(A24&" "&PX_SRC&" Curncy","PX_ASK"),"ERROR PLZ FIX") | G24: =IFERROR(BDP(A24&" "&PX_SRC&" Curncy","PX_LAST"),"ERROR PLZ FIX") | H24: =IFERROR((E24+F24)/2,IFERROR(G24,"ERROR PLZ FIX")) | I24: Y
A25: USOSFR6 | B25: 6Y | C25: =IF(RIGHT(B25,1)="W",$B$3+7*VALUE(LEFT(B25,LEN(B25)-1)),IF(RIGHT(B25,1)="M",EDATE($B$3,VALUE(LEFT(B25,LEN(B25)-1))),EDATE($B$3,12*VALUE(LEFT(B25,LEN(B25)-1))))) | D25: =(C25-$B$3)/365 | E25: =IFERROR(BDP(A25&" "&PX_SRC&" Curncy","PX_BID"),"ERROR PLZ FIX") | F25: =IFERROR(BDP(A25&" "&PX_SRC&" Curncy","PX_ASK"),"ERROR PLZ FIX") | G25: =IFERROR(BDP(A25&" "&PX_SRC&" Curncy","PX_LAST"),"ERROR PLZ FIX") | H25: =IFERROR((E25+F25)/2,IFERROR(G25,"ERROR PLZ FIX")) | I25: Y
A26: USOSFR7 | B26: 7Y | C26: =IF(RIGHT(B26,1)="W",$B$3+7*VALUE(LEFT(B26,LEN(B26)-1)),IF(RIGHT(B26,1)="M",EDATE($B$3,VALUE(LEFT(B26,LEN(B26)-1))),EDATE($B$3,12*VALUE(LEFT(B26,LEN(B26)-1))))) | D26: =(C26-$B$3)/365 | E26: =IFERROR(BDP(A26&" "&PX_SRC&" Curncy","PX_BID"),"ERROR PLZ FIX") | F26: =IFERROR(BDP(A26&" "&PX_SRC&" Curncy","PX_ASK"),"ERROR PLZ FIX") | G26: =IFERROR(BDP(A26&" "&PX_SRC&" Curncy","PX_LAST"),"ERROR PLZ FIX") | H26: =IFERROR((E26+F26)/2,IFERROR(G26,"ERROR PLZ FIX")) | I26: Y
A27: USOSFR8 | B27: 8Y | C27: =IF(RIGHT(B27,1)="W",$B$3+7*VALUE(LEFT(B27,LEN(B27)-1)),IF(RIGHT(B27,1)="M",EDATE($B$3,VALUE(LEFT(B27,LEN(B27)-1))),EDATE($B$3,12*VALUE(LEFT(B27,LEN(B27)-1))))) | D27: =(C27-$B$3)/365 | E27: =IFERROR(BDP(A27&" "&PX_SRC&" Curncy","PX_BID"),"ERROR PLZ FIX") | F27: =IFERROR(BDP(A27&" "&PX_SRC&" Curncy","PX_ASK"),"ERROR PLZ FIX") | G27: =IFERROR(BDP(A27&" "&PX_SRC&" Curncy","PX_LAST"),"ERROR PLZ FIX") | H27: =IFERROR((E27+F27)/2,IFERROR(G27,"ERROR PLZ FIX")) | I27: Y
A28: USOSFR9 | B28: 9Y | C28: =IF(RIGHT(B28,1)="W",$B$3+7*VALUE(LEFT(B28,LEN(B28)-1)),IF(RIGHT(B28,1)="M",EDATE($B$3,VALUE(LEFT(B28,LEN(B28)-1))),EDATE($B$3,12*VALUE(LEFT(B28,LEN(B28)-1))))) | D28: =(C28-$B$3)/365 | E28: =IFERROR(BDP(A28&" "&PX_SRC&" Curncy","PX_BID"),"ERROR PLZ FIX") | F28: =IFERROR(BDP(A28&" "&PX_SRC&" Curncy","PX_ASK"),"ERROR PLZ FIX") | G28: =IFERROR(BDP(A28&" "&PX_SRC&" Curncy","PX_LAST"),"ERROR PLZ FIX") | H28: =IFERROR((E28+F28)/2,IFERROR(G28,"ERROR PLZ FIX")) | I28: Y
A29: USOSFR10 | B29: 10Y | C29: =IF(RIGHT(B29,1)="W",$B$3+7*VALUE(LEFT(B29,LEN(B29)-1)),IF(RIGHT(B29,1)="M",EDATE($B$3,VALUE(LEFT(B29,LEN(B29)-1))),EDATE($B$3,12*VALUE(LEFT(B29,LEN(B29)-1))))) | D29: =(C29-$B$3)/365 | E29: =IFERROR(BDP(A29&" "&PX_SRC&" Curncy","PX_BID"),"ERROR PLZ FIX") | F29: =IFERROR(BDP(A29&" "&PX_SRC&" Curncy","PX_ASK"),"ERROR PLZ FIX") | G29: =IFERROR(BDP(A29&" "&PX_SRC&" Curncy","PX_LAST"),"ERROR PLZ FIX") | H29: =IFERROR((E29+F29)/2,IFERROR(G29,"ERROR PLZ FIX")) | I29: Y
A30: USOSFR12 | B30: 12Y | C30: =IF(RIGHT(B30,1)="W",$B$3+7*VALUE(LEFT(B30,LEN(B30)-1)),IF(RIGHT(B30,1)="M",EDATE($B$3,VALUE(LEFT(B30,LEN(B30)-1))),EDATE($B$3,12*VALUE(LEFT(B30,LEN(B30)-1))))) | D30: =(C30-$B$3)/365 | E30: =IFERROR(BDP(A30&" "&PX_SRC&" Curncy","PX_BID"),"ERROR PLZ FIX") | F30: =IFERROR(BDP(A30&" "&PX_SRC&" Curncy","PX_ASK"),"ERROR PLZ FIX") | G30: =IFERROR(BDP(A30&" "&PX_SRC&" Curncy","PX_LAST"),"ERROR PLZ FIX") | H30: =IFERROR((E30+F30)/2,IFERROR(G30,"ERROR PLZ FIX")) | I30: Y
A31: USOSFR15 | B31: 15Y | C31: =IF(RIGHT(B31,1)="W",$B$3+7*VALUE(LEFT(B31,LEN(B31)-1)),IF(RIGHT(B31,1)="M",EDATE($B$3,VALUE(LEFT(B31,LEN(B31)-1))),EDATE($B$3,12*VALUE(LEFT(B31,LEN(B31)-1))))) | D31: =(C31-$B$3)/365 | E31: =IFERROR(BDP(A31&" "&PX_SRC&" Curncy","PX_BID"),"ERROR PLZ FIX") | F31: =IFERROR(BDP(A31&" "&PX_SRC&" Curncy","PX_ASK"),"ERROR PLZ FIX") | G31: =IFERROR(BDP(A31&" "&PX_SRC&" Curncy","PX_LAST"),"ERROR PLZ FIX") | H31: =IFERROR((E31+F31)/2,IFERROR(G31,"ERROR PLZ FIX")) | I31: Y
A32: USOSFR20 | B32: 20Y | C32: =IF(RIGHT(B32,1)="W",$B$3+7*VALUE(LEFT(B32,LEN(B32)-1)),IF(RIGHT(B32,1)="M",EDATE($B$3,VALUE(LEFT(B32,LEN(B32)-1))),EDATE($B$3,12*VALUE(LEFT(B32,LEN(B32)-1))))) | D32: =(C32-$B$3)/365 | E32: =IFERROR(BDP(A32&" "&PX_SRC&" Curncy","PX_BID"),"ERROR PLZ FIX") | F32: =IFERROR(BDP(A32&" "&PX_SRC&" Curncy","PX_ASK"),"ERROR PLZ FIX") | G32: =IFERROR(BDP(A32&" "&PX_SRC&" Curncy","PX_LAST"),"ERROR PLZ FIX") | H32: =IFERROR((E32+F32)/2,IFERROR(G32,"ERROR PLZ FIX")) | I32: Y
A33: USOSFR25 | B33: 25Y | C33: =IF(RIGHT(B33,1)="W",$B$3+7*VALUE(LEFT(B33,LEN(B33)-1)),IF(RIGHT(B33,1)="M",EDATE($B$3,VALUE(LEFT(B33,LEN(B33)-1))),EDATE($B$3,12*VALUE(LEFT(B33,LEN(B33)-1))))) | D33: =(C33-$B$3)/365 | E33: =IFERROR(BDP(A33&" "&PX_SRC&" Curncy","PX_BID"),"ERROR PLZ FIX") | F33: =IFERROR(BDP(A33&" "&PX_SRC&" Curncy","PX_ASK"),"ERROR PLZ FIX") | G33: =IFERROR(BDP(A33&" "&PX_SRC&" Curncy","PX_LAST"),"ERROR PLZ FIX") | H33: =IFERROR((E33+F33)/2,IFERROR(G33,"ERROR PLZ FIX")) | I33: Y
A34: USOSFR30 | B34: 30Y | C34: =IF(RIGHT(B34,1)="W",$B$3+7*VALUE(LEFT(B34,LEN(B34)-1)),IF(RIGHT(B34,1)="M",EDATE($B$3,VALUE(LEFT(B34,LEN(B34)-1))),EDATE($B$3,12*VALUE(LEFT(B34,LEN(B34)-1))))) | D34: =(C34-$B$3)/365 | E34: =IFERROR(BDP(A34&" "&PX_SRC&" Curncy","PX_BID"),"ERROR PLZ FIX") | F34: =IFERROR(BDP(A34&" "&PX_SRC&" Curncy","PX_ASK"),"ERROR PLZ FIX") | G34: =IFERROR(BDP(A34&" "&PX_SRC&" Curncy","PX_LAST"),"ERROR PLZ FIX") | H34: =IFERROR((E34+F34)/2,IFERROR(G34,"ERROR PLZ FIX")) | I34: Y
A35: USOSFR40 | B35: 40Y | C35: =IF(RIGHT(B35,1)="W",$B$3+7*VALUE(LEFT(B35,LEN(B35)-1)),IF(RIGHT(B35,1)="M",EDATE($B$3,VALUE(LEFT(B35,LEN(B35)-1))),EDATE($B$3,12*VALUE(LEFT(B35,LEN(B35)-1))))) | D35: =(C35-$B$3)/365 | E35: =IFERROR(BDP(A35&" "&PX_SRC&" Curncy","PX_BID"),"ERROR PLZ FIX") | F35: =IFERROR(BDP(A35&" "&PX_SRC&" Curncy","PX_ASK"),"ERROR PLZ FIX") | G35: =IFERROR(BDP(A35&" "&PX_SRC&" Curncy","PX_LAST"),"ERROR PLZ FIX") | H35: =IFERROR((E35+F35)/2,IFERROR(G35,"ERROR PLZ FIX")) | I35: Y
A36: USOSFR50 | B36: 50Y | C36: =IF(RIGHT(B36,1)="W",$B$3+7*VALUE(LEFT(B36,LEN(B36)-1)),IF(RIGHT(B36,1)="M",EDATE($B$3,VALUE(LEFT(B36,LEN(B36)-1))),EDATE($B$3,12*VALUE(LEFT(B36,LEN(B36)-1))))) | D36: =(C36-$B$3)/365 | E36: =IFERROR(BDP(A36&" "&PX_SRC&" Curncy","PX_BID"),"ERROR PLZ FIX") | F36: =IFERROR(BDP(A36&" "&PX_SRC&" Curncy","PX_ASK"),"ERROR PLZ FIX") | G36: =IFERROR(BDP(A36&" "&PX_SRC&" Curncy","PX_LAST"),"ERROR PLZ FIX") | H36: =IFERROR((E36+F36)/2,IFERROR(G36,"ERROR PLZ FIX")) | I36: Y
A38: Maturity date and Tenor (yrs) are live formulas parsed from the tenor label (e.g. "18M" → EDATE(spot,18)) — change the tenor or the valuation date and they update. "In bootstrap set" = Y marks the recommended restricted calibration set (front 1W,1M,3M,6M; long end 5Y–50Y); the 3M–5Y gap is filled by SR3 futures on the SOFR_Futures tab.

Sheet Bootstrap
A1: Bootstrap
A2: Three-segment USD curve (Zhou 2002): short OIS (≤1Y) · SR3 futures (1Y–5Y) · OIS swaps (5Y–50Y)
A4: Spot (T+2): | B4: =WORKDAY(VAL_DATE,2)
A5: SHORT (o/n–1Y): single-payment SOFR OIS, DF = 1/(1+S·tau0). MIDDLE (1Y–5Y): the DF at 18M/2Y/3Y/4Y/5Y is interpolated off the SR3 futures chain (helper block cols O–W), which discounts each contract's forward rate forward from the OIS 1Y DF — so 18M/2Y…5Y here are driven by FUTURES, not the OIS pars (col E is shown only for reference). If the SR3 chain is unavailable the middle DFs FALL BACK to the OIS bootstrap so the curve never breaks — col N shows which is live per pillar. LONG (5Y–50Y): annual SOFR OIS swaps, DF = (1−S·A_prior)/(1+S·taucoupon), annuity (col I) built from the short + middle DFs. Cutovers at 1Y and 5Y mean nothing overlaps. Paste S490 zeros into column L for the Δz check. | O5: sigma (bp/yr): | P5: 100 | Q5: futures convexity CA = 0.5·sigma^2·t1·t2 (col T, bp)
O6: MIDDLE SEGMENT — SR3 futures chain (1Y→5Y) | Y6: Mid interp grid
A7: Tenor | B7: Maturity date | C7: T (yrs) | D7: tau0 spot→mat | E7: Par rate S (%) | F7: tau coupon | G7: Annuity A(prior) | H7: Discount factor | I7: Ann.add tau·DF | J7: Zero rate (%) cont. | K7: Fwd rate (%) | L7: S490 zero (%) [paste] | M7: Δ vs S490 (bp) | N7: DF source | O7: Contract | P7: Fut start | Q7: Fut end | R7: tau eff (post-1Y) | S7: Implied % | T7: Convexity bp | U7: Fwd | V7: DF before | W7: DF after | Y7: Date | Z7: DF
A8: 1W | B8: =$B$4+7 | C8: =(B8-$B$4)/365 | D8: =(B8-$B$4)/360 | E8: ='SOFR_OIS_Quotes'!$H5 | G8: 0 | H8: =1/(1+(E8/100)*D8) | I8: 0 | J8: =-LN(H8)/C8*100 | K8: =(1/H8-1)/D8*100 | M8: =IF(L8="","",(J8-L8)*100) | N8: short OIS | O8: ='SOFR_Futures'!A7 | P8: ='SOFR_Futures'!H7 | Q8: ='SOFR_Futures'!H8 | R8: =MAX(0,(Q8-MAX(P8,$B$22))/360) | S8: ='SOFR_Futures'!F7 | T8: =0.5*$P$5^2*((P8-$B$4)/365)*((Q8-$B$4)/365)/10000 | U8: =(S8-T8/100)/100 | V8: =$H$22 | W8: =V8/(1+U8*R8) | Y8: =$B$22 | Z8: =$H$22
A9: 2W | B9: =$B$4+14 | C9: =(B9-$B$4)/365 | D9: =(B9-$B$4)/360 | E9: ='SOFR_OIS_Quotes'!$H6 | G9: =SUM($I$8:I8) | H9: =1/(1+(E9/100)*D9) | I9: 0 | J9: =-LN(H9)/C9*100 | K9: =(H8/H9-1)/((B9-B8)/360)*100 | M9: =IF(L9="","",(J9-L9)*100) | N9: short OIS | O9: ='SOFR_Futures'!A8 | P9: ='SOFR_Futures'!H8 | Q9: ='SOFR_Futures'!H9 | R9: =MAX(0,(Q9-MAX(P9,$B$22))/360) | S9: ='SOFR_Futures'!F8 | T9: =0.5*$P$5^2*((P9-$B$4)/365)*((Q9-$B$4)/365)/10000 | U9: =(S9-T9/100)/100 | V9: =W8 | W9: =V9/(1+U9*R9) | Y9: =MAX(Q8,$B$22) | Z9: =W8
A10: 3W | B10: =$B$4+21 | C10: =(B10-$B$4)/365 | D10: =(B10-$B$4)/360 | E10: ='SOFR_OIS_Quotes'!$H7 | G10: =SUM($I$8:I9) | H10: =1/(1+(E10/100)*D10) | I10: 0 | J10: =-LN(H10)/C10*100 | K10: =(H9/H10-1)/((B10-B9)/360)*100 | M10: =IF(L10="","",(J10-L10)*100) | N10: short OIS | O10: ='SOFR_Futures'!A9 | P10: ='SOFR_Futures'!H9 | Q10: ='SOFR_Futures'!H10 | R10: =MAX(0,(Q10-MAX(P10,$B$22))/360) | S10: ='SOFR_Futures'!F9 | T10: =0.5*$P$5^2*((P10-$B$4)/365)*((Q10-$B$4)/365)/10000 | U10: =(S10-T10/100)/100 | V10: =W9 | W10: =V10/(1+U10*R10) | Y10: =MAX(Q9,$B$22) | Z10: =W9
A11: 1M | B11: =EDATE($B$4,1) | C11: =(B11-$B$4)/365 | D11: =(B11-$B$4)/360 | E11: ='SOFR_OIS_Quotes'!$H8 | G11: =SUM($I$8:I10) | H11: =1/(1+(E11/100)*D11) | I11: 0 | J11: =-LN(H11)/C11*100 | K11: =(H10/H11-1)/((B11-B10)/360)*100 | M11: =IF(L11="","",(J11-L11)*100) | N11: short OIS | O11: ='SOFR_Futures'!A10 | P11: ='SOFR_Futures'!H10 | Q11: ='SOFR_Futures'!H11 | R11: =MAX(0,(Q11-MAX(P11,$B$22))/360) | S11: ='SOFR_Futures'!F10 | T11: =0.5*$P$5^2*((P11-$B$4)/365)*((Q11-$B$4)/365)/10000 | U11: =(S11-T11/100)/100 | V11: =W10 | W11: =V11/(1+U11*R11) | Y11: =MAX(Q10,$B$22) | Z11: =W10
A12: 2M | B12: =EDATE($B$4,2) | C12: =(B12-$B$4)/365 | D12: =(B12-$B$4)/360 | E12: ='SOFR_OIS_Quotes'!$H9 | G12: =SUM($I$8:I11) | H12: =1/(1+(E12/100)*D12) | I12: 0 | J12: =-LN(H12)/C12*100 | K12: =(H11/H12-1)/((B12-B11)/360)*100 | M12: =IF(L12="","",(J12-L12)*100) | N12: short OIS | O12: ='SOFR_Futures'!A11 | P12: ='SOFR_Futures'!H11 | Q12: ='SOFR_Futures'!H12 | R12: =MAX(0,(Q12-MAX(P12,$B$22))/360) | S12: ='SOFR_Futures'!F11 | T12: =0.5*$P$5^2*((P12-$B$4)/365)*((Q12-$B$4)/365)/10000 | U12: =(S12-T12/100)/100 | V12: =W11 | W12: =V12/(1+U12*R12) | Y12: =MAX(Q11,$B$22) | Z12: =W11
A13: 3M | B13: =EDATE($B$4,3) | C13: =(B13-$B$4)/365 | D13: =(B13-$B$4)/360 | E13: ='SOFR_OIS_Quotes'!$H10 | G13: =SUM($I$8:I12) | H13: =1/(1+(E13/100)*D13) | I13: 0 | J13: =-LN(H13)/C13*100 | K13: =(H12/H13-1)/((B13-B12)/360)*100 | M13: =IF(L13="","",(J13-L13)*100) | N13: short OIS | O13: ='SOFR_Futures'!A12 | P13: ='SOFR_Futures'!H12 | Q13: ='SOFR_Futures'!H13 | R13: =MAX(0,(Q13-MAX(P13,$B$22))/360) | S13: ='SOFR_Futures'!F12 | T13: =0.5*$P$5^2*((P13-$B$4)/365)*((Q13-$B$4)/365)/10000 | U13: =(S13-T13/100)/100 | V13: =W12 | W13: =V13/(1+U13*R13) | Y13: =MAX(Q12,$B$22) | Z13: =W12
A14: 4M | B14: =EDATE($B$4,4) | C14: =(B14-$B$4)/365 | D14: =(B14-$B$4)/360 | E14: ='SOFR_OIS_Quotes'!$H11 | G14: =SUM($I$8:I13) | H14: =1/(1+(E14/100)*D14) | I14: 0 | J14: =-LN(H14)/C14*100 | K14: =(H13/H14-1)/((B14-B13)/360)*100 | M14: =IF(L14="","",(J14-L14)*100) | N14: short OIS | O14: ='SOFR_Futures'!A13 | P14: ='SOFR_Futures'!H13 | Q14: ='SOFR_Futures'!H14 | R14: =MAX(0,(Q14-MAX(P14,$B$22))/360) | S14: ='SOFR_Futures'!F13 | T14: =0.5*$P$5^2*((P14-$B$4)/365)*((Q14-$B$4)/365)/10000 | U14: =(S14-T14/100)/100 | V14: =W13 | W14: =V14/(1+U14*R14) | Y14: =MAX(Q13,$B$22) | Z14: =W13
A15: 5M | B15: =EDATE($B$4,5) | C15: =(B15-$B$4)/365 | D15: =(B15-$B$4)/360 | E15: ='SOFR_OIS_Quotes'!$H12 | G15: =SUM($I$8:I14) | H15: =1/(1+(E15/100)*D15) | I15: 0 | J15: =-LN(H15)/C15*100 | K15: =(H14/H15-1)/((B15-B14)/360)*100 | M15: =IF(L15="","",(J15-L15)*100) | N15: short OIS | O15: ='SOFR_Futures'!A14 | P15: ='SOFR_Futures'!H14 | Q15: ='SOFR_Futures'!H15 | R15: =MAX(0,(Q15-MAX(P15,$B$22))/360) | S15: ='SOFR_Futures'!F14 | T15: =0.5*$P$5^2*((P15-$B$4)/365)*((Q15-$B$4)/365)/10000 | U15: =(S15-T15/100)/100 | V15: =W14 | W15: =V15/(1+U15*R15) | Y15: =MAX(Q14,$B$22) | Z15: =W14
A16: 6M | B16: =EDATE($B$4,6) | C16: =(B16-$B$4)/365 | D16: =(B16-$B$4)/360 | E16: ='SOFR_OIS_Quotes'!$H13 | G16: =SUM($I$8:I15) | H16: =1/(1+(E16/100)*D16) | I16: 0 | J16: =-LN(H16)/C16*100 | K16: =(H15/H16-1)/((B16-B15)/360)*100 | M16: =IF(L16="","",(J16-L16)*100) | N16: short OIS | O16: ='SOFR_Futures'!A15 | P16: ='SOFR_Futures'!H15 | Q16: ='SOFR_Futures'!H16 | R16: =MAX(0,(Q16-MAX(P16,$B$22))/360) | S16: ='SOFR_Futures'!F15 | T16: =0.5*$P$5^2*((P16-$B$4)/365)*((Q16-$B$4)/365)/10000 | U16: =(S16-T16/100)/100 | V16: =W15 | W16: =V16/(1+U16*R16) | Y16: =MAX(Q15,$B$22) | Z16: =W15
A17: 7M | B17: =EDATE($B$4,7) | C17: =(B17-$B$4)/365 | D17: =(B17-$B$4)/360 | E17: ='SOFR_OIS_Quotes'!$H14 | G17: =SUM($I$8:I16) | H17: =1/(1+(E17/100)*D17) | I17: 0 | J17: =-LN(H17)/C17*100 | K17: =(H16/H17-1)/((B17-B16)/360)*100 | M17: =IF(L17="","",(J17-L17)*100) | N17: short OIS | O17: ='SOFR_Futures'!A16 | P17: ='SOFR_Futures'!H16 | Q17: ='SOFR_Futures'!H17 | R17: =MAX(0,(Q17-MAX(P17,$B$22))/360) | S17: ='SOFR_Futures'!F16 | T17: =0.5*$P$5^2*((P17-$B$4)/365)*((Q17-$B$4)/365)/10000 | U17: =(S17-T17/100)/100 | V17: =W16 | W17: =V17/(1+U17*R17) | Y17: =MAX(Q16,$B$22) | Z17: =W16
A18: 8M | B18: =EDATE($B$4,8) | C18: =(B18-$B$4)/365 | D18: =(B18-$B$4)/360 | E18: ='SOFR_OIS_Quotes'!$H15 | G18: =SUM($I$8:I17) | H18: =1/(1+(E18/100)*D18) | I18: 0 | J18: =-LN(H18)/C18*100 | K18: =(H17/H18-1)/((B18-B17)/360)*100 | M18: =IF(L18="","",(J18-L18)*100) | N18: short OIS | O18: ='SOFR_Futures'!A17 | P18: ='SOFR_Futures'!H17 | Q18: ='SOFR_Futures'!H18 | R18: =MAX(0,(Q18-MAX(P18,$B$22))/360) | S18: ='SOFR_Futures'!F17 | T18: =0.5*$P$5^2*((P18-$B$4)/365)*((Q18-$B$4)/365)/10000 | U18: =(S18-T18/100)/100 | V18: =W17 | W18: =V18/(1+U18*R18) | Y18: =MAX(Q17,$B$22) | Z18: =W17
A19: 9M | B19: =EDATE($B$4,9) | C19: =(B19-$B$4)/365 | D19: =(B19-$B$4)/360 | E19: ='SOFR_OIS_Quotes'!$H16 | G19: =SUM($I$8:I18) | H19: =1/(1+(E19/100)*D19) | I19: 0 | J19: =-LN(H19)/C19*100 | K19: =(H18/H19-1)/((B19-B18)/360)*100 | M19: =IF(L19="","",(J19-L19)*100) | N19: short OIS | O19: ='SOFR_Futures'!A18 | P19: ='SOFR_Futures'!H18 | Q19: ='SOFR_Futures'!H19 | R19: =MAX(0,(Q19-MAX(P19,$B$22))/360) | S19: ='SOFR_Futures'!F18 | T19: =0.5*$P$5^2*((P19-$B$4)/365)*((Q19-$B$4)/365)/10000 | U19: =(S19-T19/100)/100 | V19: =W18 | W19: =V19/(1+U19*R19) | Y19: =MAX(Q18,$B$22) | Z19: =W18
A20: 10M | B20: =EDATE($B$4,10) | C20: =(B20-$B$4)/365 | D20: =(B20-$B$4)/360 | E20: ='SOFR_OIS_Quotes'!$H17 | G20: =SUM($I$8:I19) | H20: =1/(1+(E20/100)*D20) | I20: 0 | J20: =-LN(H20)/C20*100 | K20: =(H19/H20-1)/((B20-B19)/360)*100 | M20: =IF(L20="","",(J20-L20)*100) | N20: short OIS | O20: ='SOFR_Futures'!A19 | P20: ='SOFR_Futures'!H19 | Q20: ='SOFR_Futures'!H20 | R20: =MAX(0,(Q20-MAX(P20,$B$22))/360) | S20: ='SOFR_Futures'!F19 | T20: =0.5*$P$5^2*((P20-$B$4)/365)*((Q20-$B$4)/365)/10000 | U20: =(S20-T20/100)/100 | V20: =W19 | W20: =V20/(1+U20*R20) | Y20: =MAX(Q19,$B$22) | Z20: =W19
A21: 11M | B21: =EDATE($B$4,11) | C21: =(B21-$B$4)/365 | D21: =(B21-$B$4)/360 | E21: ='SOFR_OIS_Quotes'!$H18 | G21: =SUM($I$8:I20) | H21: =1/(1+(E21/100)*D21) | I21: 0 | J21: =-LN(H21)/C21*100 | K21: =(H20/H21-1)/((B21-B20)/360)*100 | M21: =IF(L21="","",(J21-L21)*100) | N21: short OIS | O21: ='SOFR_Futures'!A20 | P21: ='SOFR_Futures'!H20 | Q21: ='SOFR_Futures'!H21 | R21: =MAX(0,(Q21-MAX(P21,$B$22))/360) | S21: ='SOFR_Futures'!F20 | T21: =0.5*$P$5^2*((P21-$B$4)/365)*((Q21-$B$4)/365)/10000 | U21: =(S21-T21/100)/100 | V21: =W20 | W21: =V21/(1+U21*R21) | Y21: =MAX(Q20,$B$22) | Z21: =W20
A22: 1Y | B22: =EDATE($B$4,12) | C22: =(B22-$B$4)/365 | D22: =(B22-$B$4)/360 | E22: ='SOFR_OIS_Quotes'!$H19 | F22: =(B22-$B$4)/360 | G22: =SUM($I$8:I21) | H22: =1/(1+(E22/100)*D22) | I22: =F22*H22 | J22: =-LN(H22)/C22*100 | K22: =(H21/H22-1)/((B22-B21)/360)*100 | M22: =IF(L22="","",(J22-L22)*100) | N22: short OIS | O22: ='SOFR_Futures'!A21 | P22: ='SOFR_Futures'!H21 | Q22: ='SOFR_Futures'!H22 | R22: =MAX(0,(Q22-MAX(P22,$B$22))/360) | S22: ='SOFR_Futures'!F21 | T22: =0.5*$P$5^2*((P22-$B$4)/365)*((Q22-$B$4)/365)/10000 | U22: =(S22-T22/100)/100 | V22: =W21 | W22: =V22/(1+U22*R22) | Y22: =MAX(Q21,$B$22) | Z22: =W21
A23: 18M | B23: =EDATE($B$4,18) | C23: =(B23-$B$4)/365 | D23: =(B23-$B$4)/360 | E23: ='SOFR_OIS_Quotes'!$H20 | F23: =(B23-$B$22)/360 | G23: =SUM($I$8:I22) | H23: =IFERROR(IF(ABS((IFERROR(INDEX($Z$8:$Z$28,MATCH(B23,$Y$8:$Y$28,1))*(INDEX($Z$8:$Z$28,MATCH(B23,$Y$8:$Y$28,1)+1)/INDEX($Z$8:$Z$28,MATCH(B23,$Y$8:$Y$28,1)))^((B23-INDEX($Y$8:$Y$28,MATCH(B23,$Y$8:$Y$28,1)))/(INDEX($Y$8:$Y$28,MATCH(B23,$Y$8:$Y$28,1)+1)-INDEX($Y$8:$Y$28,MATCH(B23,$Y$8:$Y$28,1)))),INDEX($Z$8:$Z$28,MATCH(B23,$Y$8:$Y$28,1))))-((1-(E23/100)*G23)/(1+(E23/100)*F23)))<0.03,(IFERROR(INDEX($Z$8:$Z$28,MATCH(B23,$Y$8:$Y$28,1))*(INDEX($Z$8:$Z$28,MATCH(B23,$Y$8:$Y$28,1)+1)/INDEX($Z$8:$Z$28,MATCH(B23,$Y$8:$Y$28,1)))^((B23-INDEX($Y$8:$Y$28,MATCH(B23,$Y$8:$Y$28,1)))/(INDEX($Y$8:$Y$28,MATCH(B23,$Y$8:$Y$28,1)+1)-INDEX($Y$8:$Y$28,MATCH(B23,$Y$8:$Y$28,1)))),INDEX($Z$8:$Z$28,MATCH(B23,$Y$8:$Y$28,1)))),((1-(E23/100)*G23)/(1+(E23/100)*F23))),((1-(E23/100)*G23)/(1+(E23/100)*F23))) | I23: 0 | J23: =-LN(H23)/C23*100 | K23: =(H22/H23-1)/((B23-B22)/360)*100 | M23: =IF(L23="","",(J23-L23)*100) | N23: =IF(AND(ISNUMBER(IFERROR(INDEX($Z$8:$Z$28,MATCH(B23,$Y$8:$Y$28,1))*(INDEX($Z$8:$Z$28,MATCH(B23,$Y$8:$Y$28,1)+1)/INDEX($Z$8:$Z$28,MATCH(B23,$Y$8:$Y$28,1)))^((B23-INDEX($Y$8:$Y$28,MATCH(B23,$Y$8:$Y$28,1)))/(INDEX($Y$8:$Y$28,MATCH(B23,$Y$8:$Y$28,1)+1)-INDEX($Y$8:$Y$28,MATCH(B23,$Y$8:$Y$28,1)))),INDEX($Z$8:$Z$28,MATCH(B23,$Y$8:$Y$28,1)))),ABS((IFERROR(INDEX($Z$8:$Z$28,MATCH(B23,$Y$8:$Y$28,1))*(INDEX($Z$8:$Z$28,MATCH(B23,$Y$8:$Y$28,1)+1)/INDEX($Z$8:$Z$28,MATCH(B23,$Y$8:$Y$28,1)))^((B23-INDEX($Y$8:$Y$28,MATCH(B23,$Y$8:$Y$28,1)))/(INDEX($Y$8:$Y$28,MATCH(B23,$Y$8:$Y$28,1)+1)-INDEX($Y$8:$Y$28,MATCH(B23,$Y$8:$Y$28,1)))),INDEX($Z$8:$Z$28,MATCH(B23,$Y$8:$Y$28,1))))-((1-(E23/100)*G23)/(1+(E23/100)*F23)))<0.03),"SR3 futures","OIS fallback") | O23: ='SOFR_Futures'!A22 | P23: ='SOFR_Futures'!H22 | Q23: ='SOFR_Futures'!H23 | R23: =MAX(0,(Q23-MAX(P23,$B$22))/360) | S23: ='SOFR_Futures'!F22 | T23: =0.5*$P$5^2*((P23-$B$4)/365)*((Q23-$B$4)/365)/10000 | U23: =(S23-T23/100)/100 | V23: =W22 | W23: =V23/(1+U23*R23) | Y23: =MAX(Q22,$B$22) | Z23: =W22
A24: 2Y | B24: =EDATE($B$4,24) | C24: =(B24-$B$4)/365 | D24: =(B24-$B$4)/360 | E24: ='SOFR_OIS_Quotes'!$H21 | F24: =(B24-$B$22)/360 | G24: =SUM($I$8:I23) | H24: =IFERROR(IF(ABS((IFERROR(INDEX($Z$8:$Z$28,MATCH(B24,$Y$8:$Y$28,1))*(INDEX($Z$8:$Z$28,MATCH(B24,$Y$8:$Y$28,1)+1)/INDEX($Z$8:$Z$28,MATCH(B24,$Y$8:$Y$28,1)))^((B24-INDEX($Y$8:$Y$28,MATCH(B24,$Y$8:$Y$28,1)))/(INDEX($Y$8:$Y$28,MATCH(B24,$Y$8:$Y$28,1)+1)-INDEX($Y$8:$Y$28,MATCH(B24,$Y$8:$Y$28,1)))),INDEX($Z$8:$Z$28,MATCH(B24,$Y$8:$Y$28,1))))-((1-(E24/100)*G24)/(1+(E24/100)*F24)))<0.03,(IFERROR(INDEX($Z$8:$Z$28,MATCH(B24,$Y$8:$Y$28,1))*(INDEX($Z$8:$Z$28,MATCH(B24,$Y$8:$Y$28,1)+1)/INDEX($Z$8:$Z$28,MATCH(B24,$Y$8:$Y$28,1)))^((B24-INDEX($Y$8:$Y$28,MATCH(B24,$Y$8:$Y$28,1)))/(INDEX($Y$8:$Y$28,MATCH(B24,$Y$8:$Y$28,1)+1)-INDEX($Y$8:$Y$28,MATCH(B24,$Y$8:$Y$28,1)))),INDEX($Z$8:$Z$28,MATCH(B24,$Y$8:$Y$28,1)))),((1-(E24/100)*G24)/(1+(E24/100)*F24))),((1-(E24/100)*G24)/(1+(E24/100)*F24))) | I24: =F24*H24 | J24: =-LN(H24)/C24*100 | K24: =(H23/H24-1)/((B24-B23)/360)*100 | M24: =IF(L24="","",(J24-L24)*100) | N24: =IF(AND(ISNUMBER(IFERROR(INDEX($Z$8:$Z$28,MATCH(B24,$Y$8:$Y$28,1))*(INDEX($Z$8:$Z$28,MATCH(B24,$Y$8:$Y$28,1)+1)/INDEX($Z$8:$Z$28,MATCH(B24,$Y$8:$Y$28,1)))^((B24-INDEX($Y$8:$Y$28,MATCH(B24,$Y$8:$Y$28,1)))/(INDEX($Y$8:$Y$28,MATCH(B24,$Y$8:$Y$28,1)+1)-INDEX($Y$8:$Y$28,MATCH(B24,$Y$8:$Y$28,1)))),INDEX($Z$8:$Z$28,MATCH(B24,$Y$8:$Y$28,1)))),ABS((IFERROR(INDEX($Z$8:$Z$28,MATCH(B24,$Y$8:$Y$28,1))*(INDEX($Z$8:$Z$28,MATCH(B24,$Y$8:$Y$28,1)+1)/INDEX($Z$8:$Z$28,MATCH(B24,$Y$8:$Y$28,1)))^((B24-INDEX($Y$8:$Y$28,MATCH(B24,$Y$8:$Y$28,1)))/(INDEX($Y$8:$Y$28,MATCH(B24,$Y$8:$Y$28,1)+1)-INDEX($Y$8:$Y$28,MATCH(B24,$Y$8:$Y$28,1)))),INDEX($Z$8:$Z$28,MATCH(B24,$Y$8:$Y$28,1))))-((1-(E24/100)*G24)/(1+(E24/100)*F24)))<0.03),"SR3 futures","OIS fallback") | O24: ='SOFR_Futures'!A23 | P24: ='SOFR_Futures'!H23 | Q24: ='SOFR_Futures'!H24 | R24: =MAX(0,(Q24-MAX(P24,$B$22))/360) | S24: ='SOFR_Futures'!F23 | T24: =0.5*$P$5^2*((P24-$B$4)/365)*((Q24-$B$4)/365)/10000 | U24: =(S24-T24/100)/100 | V24: =W23 | W24: =V24/(1+U24*R24) | Y24: =MAX(Q23,$B$22) | Z24: =W23
A25: 3Y | B25: =EDATE($B$4,36) | C25: =(B25-$B$4)/365 | D25: =(B25-$B$4)/360 | E25: ='SOFR_OIS_Quotes'!$H22 | F25: =(B25-$B$24)/360 | G25: =SUM($I$8:I24) | H25: =IFERROR(IF(ABS((IFERROR(INDEX($Z$8:$Z$28,MATCH(B25,$Y$8:$Y$28,1))*(INDEX($Z$8:$Z$28,MATCH(B25,$Y$8:$Y$28,1)+1)/INDEX($Z$8:$Z$28,MATCH(B25,$Y$8:$Y$28,1)))^((B25-INDEX($Y$8:$Y$28,MATCH(B25,$Y$8:$Y$28,1)))/(INDEX($Y$8:$Y$28,MATCH(B25,$Y$8:$Y$28,1)+1)-INDEX($Y$8:$Y$28,MATCH(B25,$Y$8:$Y$28,1)))),INDEX($Z$8:$Z$28,MATCH(B25,$Y$8:$Y$28,1))))-((1-(E25/100)*G25)/(1+(E25/100)*F25)))<0.03,(IFERROR(INDEX($Z$8:$Z$28,MATCH(B25,$Y$8:$Y$28,1))*(INDEX($Z$8:$Z$28,MATCH(B25,$Y$8:$Y$28,1)+1)/INDEX($Z$8:$Z$28,MATCH(B25,$Y$8:$Y$28,1)))^((B25-INDEX($Y$8:$Y$28,MATCH(B25,$Y$8:$Y$28,1)))/(INDEX($Y$8:$Y$28,MATCH(B25,$Y$8:$Y$28,1)+1)-INDEX($Y$8:$Y$28,MATCH(B25,$Y$8:$Y$28,1)))),INDEX($Z$8:$Z$28,MATCH(B25,$Y$8:$Y$28,1)))),((1-(E25/100)*G25)/(1+(E25/100)*F25))),((1-(E25/100)*G25)/(1+(E25/100)*F25))) | I25: =F25*H25 | J25: =-LN(H25)/C25*100 | K25: =(H24/H25-1)/((B25-B24)/360)*100 | M25: =IF(L25="","",(J25-L25)*100) | N25: =IF(AND(ISNUMBER(IFERROR(INDEX($Z$8:$Z$28,MATCH(B25,$Y$8:$Y$28,1))*(INDEX($Z$8:$Z$28,MATCH(B25,$Y$8:$Y$28,1)+1)/INDEX($Z$8:$Z$28,MATCH(B25,$Y$8:$Y$28,1)))^((B25-INDEX($Y$8:$Y$28,MATCH(B25,$Y$8:$Y$28,1)))/(INDEX($Y$8:$Y$28,MATCH(B25,$Y$8:$Y$28,1)+1)-INDEX($Y$8:$Y$28,MATCH(B25,$Y$8:$Y$28,1)))),INDEX($Z$8:$Z$28,MATCH(B25,$Y$8:$Y$28,1)))),ABS((IFERROR(INDEX($Z$8:$Z$28,MATCH(B25,$Y$8:$Y$28,1))*(INDEX($Z$8:$Z$28,MATCH(B25,$Y$8:$Y$28,1)+1)/INDEX($Z$8:$Z$28,MATCH(B25,$Y$8:$Y$28,1)))^((B25-INDEX($Y$8:$Y$28,MATCH(B25,$Y$8:$Y$28,1)))/(INDEX($Y$8:$Y$28,MATCH(B25,$Y$8:$Y$28,1)+1)-INDEX($Y$8:$Y$28,MATCH(B25,$Y$8:$Y$28,1)))),INDEX($Z$8:$Z$28,MATCH(B25,$Y$8:$Y$28,1))))-((1-(E25/100)*G25)/(1+(E25/100)*F25)))<0.03),"SR3 futures","OIS fallback") | O25: ='SOFR_Futures'!A24 | P25: ='SOFR_Futures'!H24 | Q25: ='SOFR_Futures'!H25 | R25: =MAX(0,(Q25-MAX(P25,$B$22))/360) | S25: ='SOFR_Futures'!F24 | T25: =0.5*$P$5^2*((P25-$B$4)/365)*((Q25-$B$4)/365)/10000 | U25: =(S25-T25/100)/100 | V25: =W24 | W25: =V25/(1+U25*R25) | Y25: =MAX(Q24,$B$22) | Z25: =W24
A26: 4Y | B26: =EDATE($B$4,48) | C26: =(B26-$B$4)/365 | D26: =(B26-$B$4)/360 | E26: ='SOFR_OIS_Quotes'!$H23 | F26: =(B26-$B$25)/360 | G26: =SUM($I$8:I25) | H26: =IFERROR(IF(ABS((IFERROR(INDEX($Z$8:$Z$28,MATCH(B26,$Y$8:$Y$28,1))*(INDEX($Z$8:$Z$28,MATCH(B26,$Y$8:$Y$28,1)+1)/INDEX($Z$8:$Z$28,MATCH(B26,$Y$8:$Y$28,1)))^((B26-INDEX($Y$8:$Y$28,MATCH(B26,$Y$8:$Y$28,1)))/(INDEX($Y$8:$Y$28,MATCH(B26,$Y$8:$Y$28,1)+1)-INDEX($Y$8:$Y$28,MATCH(B26,$Y$8:$Y$28,1)))),INDEX($Z$8:$Z$28,MATCH(B26,$Y$8:$Y$28,1))))-((1-(E26/100)*G26)/(1+(E26/100)*F26)))<0.03,(IFERROR(INDEX($Z$8:$Z$28,MATCH(B26,$Y$8:$Y$28,1))*(INDEX($Z$8:$Z$28,MATCH(B26,$Y$8:$Y$28,1)+1)/INDEX($Z$8:$Z$28,MATCH(B26,$Y$8:$Y$28,1)))^((B26-INDEX($Y$8:$Y$28,MATCH(B26,$Y$8:$Y$28,1)))/(INDEX($Y$8:$Y$28,MATCH(B26,$Y$8:$Y$28,1)+1)-INDEX($Y$8:$Y$28,MATCH(B26,$Y$8:$Y$28,1)))),INDEX($Z$8:$Z$28,MATCH(B26,$Y$8:$Y$28,1)))),((1-(E26/100)*G26)/(1+(E26/100)*F26))),((1-(E26/100)*G26)/(1+(E26/100)*F26))) | I26: =F26*H26 | J26: =-LN(H26)/C26*100 | K26: =(H25/H26-1)/((B26-B25)/360)*100 | M26: =IF(L26="","",(J26-L26)*100) | N26: =IF(AND(ISNUMBER(IFERROR(INDEX($Z$8:$Z$28,MATCH(B26,$Y$8:$Y$28,1))*(INDEX($Z$8:$Z$28,MATCH(B26,$Y$8:$Y$28,1)+1)/INDEX($Z$8:$Z$28,MATCH(B26,$Y$8:$Y$28,1)))^((B26-INDEX($Y$8:$Y$28,MATCH(B26,$Y$8:$Y$28,1)))/(INDEX($Y$8:$Y$28,MATCH(B26,$Y$8:$Y$28,1)+1)-INDEX($Y$8:$Y$28,MATCH(B26,$Y$8:$Y$28,1)))),INDEX($Z$8:$Z$28,MATCH(B26,$Y$8:$Y$28,1)))),ABS((IFERROR(INDEX($Z$8:$Z$28,MATCH(B26,$Y$8:$Y$28,1))*(INDEX($Z$8:$Z$28,MATCH(B26,$Y$8:$Y$28,1)+1)/INDEX($Z$8:$Z$28,MATCH(B26,$Y$8:$Y$28,1)))^((B26-INDEX($Y$8:$Y$28,MATCH(B26,$Y$8:$Y$28,1)))/(INDEX($Y$8:$Y$28,MATCH(B26,$Y$8:$Y$28,1)+1)-INDEX($Y$8:$Y$28,MATCH(B26,$Y$8:$Y$28,1)))),INDEX($Z$8:$Z$28,MATCH(B26,$Y$8:$Y$28,1))))-((1-(E26/100)*G26)/(1+(E26/100)*F26)))<0.03),"SR3 futures","OIS fallback") | O26: ='SOFR_Futures'!A25 | P26: ='SOFR_Futures'!H25 | Q26: ='SOFR_Futures'!H26 | R26: =MAX(0,(Q26-MAX(P26,$B$22))/360) | S26: ='SOFR_Futures'!F25 | T26: =0.5*$P$5^2*((P26-$B$4)/365)*((Q26-$B$4)/365)/10000 | U26: =(S26-T26/100)/100 | V26: =W25 | W26: =V26/(1+U26*R26) | Y26: =MAX(Q25,$B$22) | Z26: =W25
A27: 5Y | B27: =EDATE($B$4,60) | C27: =(B27-$B$4)/365 | D27: =(B27-$B$4)/360 | E27: ='SOFR_OIS_Quotes'!$H24 | F27: =(B27-$B$26)/360 | G27: =SUM($I$8:I26) | H27: =IFERROR(IF(ABS((IFERROR(INDEX($Z$8:$Z$28,MATCH(B27,$Y$8:$Y$28,1))*(INDEX($Z$8:$Z$28,MATCH(B27,$Y$8:$Y$28,1)+1)/INDEX($Z$8:$Z$28,MATCH(B27,$Y$8:$Y$28,1)))^((B27-INDEX($Y$8:$Y$28,MATCH(B27,$Y$8:$Y$28,1)))/(INDEX($Y$8:$Y$28,MATCH(B27,$Y$8:$Y$28,1)+1)-INDEX($Y$8:$Y$28,MATCH(B27,$Y$8:$Y$28,1)))),INDEX($Z$8:$Z$28,MATCH(B27,$Y$8:$Y$28,1))))-((1-(E27/100)*G27)/(1+(E27/100)*F27)))<0.03,(IFERROR(INDEX($Z$8:$Z$28,MATCH(B27,$Y$8:$Y$28,1))*(INDEX($Z$8:$Z$28,MATCH(B27,$Y$8:$Y$28,1)+1)/INDEX($Z$8:$Z$28,MATCH(B27,$Y$8:$Y$28,1)))^((B27-INDEX($Y$8:$Y$28,MATCH(B27,$Y$8:$Y$28,1)))/(INDEX($Y$8:$Y$28,MATCH(B27,$Y$8:$Y$28,1)+1)-INDEX($Y$8:$Y$28,MATCH(B27,$Y$8:$Y$28,1)))),INDEX($Z$8:$Z$28,MATCH(B27,$Y$8:$Y$28,1)))),((1-(E27/100)*G27)/(1+(E27/100)*F27))),((1-(E27/100)*G27)/(1+(E27/100)*F27))) | I27: =F27*H27 | J27: =-LN(H27)/C27*100 | K27: =(H26/H27-1)/((B27-B26)/360)*100 | M27: =IF(L27="","",(J27-L27)*100) | N27: =IF(AND(ISNUMBER(IFERROR(INDEX($Z$8:$Z$28,MATCH(B27,$Y$8:$Y$28,1))*(INDEX($Z$8:$Z$28,MATCH(B27,$Y$8:$Y$28,1)+1)/INDEX($Z$8:$Z$28,MATCH(B27,$Y$8:$Y$28,1)))^((B27-INDEX($Y$8:$Y$28,MATCH(B27,$Y$8:$Y$28,1)))/(INDEX($Y$8:$Y$28,MATCH(B27,$Y$8:$Y$28,1)+1)-INDEX($Y$8:$Y$28,MATCH(B27,$Y$8:$Y$28,1)))),INDEX($Z$8:$Z$28,MATCH(B27,$Y$8:$Y$28,1)))),ABS((IFERROR(INDEX($Z$8:$Z$28,MATCH(B27,$Y$8:$Y$28,1))*(INDEX($Z$8:$Z$28,MATCH(B27,$Y$8:$Y$28,1)+1)/INDEX($Z$8:$Z$28,MATCH(B27,$Y$8:$Y$28,1)))^((B27-INDEX($Y$8:$Y$28,MATCH(B27,$Y$8:$Y$28,1)))/(INDEX($Y$8:$Y$28,MATCH(B27,$Y$8:$Y$28,1)+1)-INDEX($Y$8:$Y$28,MATCH(B27,$Y$8:$Y$28,1)))),INDEX($Z$8:$Z$28,MATCH(B27,$Y$8:$Y$28,1))))-((1-(E27/100)*G27)/(1+(E27/100)*F27)))<0.03),"SR3 futures","OIS fallback") | O27: ='SOFR_Futures'!A26 | P27: ='SOFR_Futures'!H26 | Q27: =EDATE(P27,3) | R27: =MAX(0,(Q27-MAX(P27,$B$22))/360) | S27: ='SOFR_Futures'!F26 | T27: =0.5*$P$5^2*((P27-$B$4)/365)*((Q27-$B$4)/365)/10000 | U27: =(S27-T27/100)/100 | V27: =W26 | W27: =V27/(1+U27*R27) | Y27: =MAX(Q26,$B$22) | Z27: =W26
A28: 6Y | B28: =EDATE($B$4,72) | C28: =(B28-$B$4)/365 | D28: =(B28-$B$4)/360 | E28: ='SOFR_OIS_Quotes'!$H25 | F28: =(B28-$B$27)/360 | G28: =SUM($I$8:I27) | H28: =(1-(E28/100)*G28)/(1+(E28/100)*F28) | I28: =F28*H28 | J28: =-LN(H28)/C28*100 | K28: =(H27/H28-1)/((B28-B27)/360)*100 | M28: =IF(L28="","",(J28-L28)*100) | N28: OIS swap | Y28: =MAX(Q27,$B$22) | Z28: =W27
A29: 7Y | B29: =EDATE($B$4,84) | C29: =(B29-$B$4)/365 | D29: =(B29-$B$4)/360 | E29: ='SOFR_OIS_Quotes'!$H26 | F29: =(B29-$B$28)/360 | G29: =SUM($I$8:I28) | H29: =(1-(E29/100)*G29)/(1+(E29/100)*F29) | I29: =F29*H29 | J29: =-LN(H29)/C29*100 | K29: =(H28/H29-1)/((B29-B28)/360)*100 | M29: =IF(L29="","",(J29-L29)*100) | N29: OIS swap
A30: 8Y | B30: =EDATE($B$4,96) | C30: =(B30-$B$4)/365 | D30: =(B30-$B$4)/360 | E30: ='SOFR_OIS_Quotes'!$H27 | F30: =(B30-$B$29)/360 | G30: =SUM($I$8:I29) | H30: =(1-(E30/100)*G30)/(1+(E30/100)*F30) | I30: =F30*H30 | J30: =-LN(H30)/C30*100 | K30: =(H29/H30-1)/((B30-B29)/360)*100 | M30: =IF(L30="","",(J30-L30)*100) | N30: OIS swap
